Workbook

Sheet 使用说明
A1: Vgame 全玩法难度填写表｜使用说明
A3: 修正版V4已同步最新养成分配与平滑有效人数系数，并按原TTK/生存压力反推全部玩法怪物等级。黄色J列仍可直接覆盖，公式会自动更新；PVPVE继续使用双方属性对算。
A5: ① 必填 | B5: J列已填首版怪物等级，范围Lv1～Lv500；PVPVE不使用怪物等级，无限挑战本轮不纳入。
A6: ② 可选 | B6: G列是首版使用的玩家对照节点；H列仍可手动覆盖。F列怪物类型和K～P系数/目标时间保持可选。
A7: ③ 结果 | B7: Q～AC列是公式。X为预测TTK；Y为按怪物攻击估算的玩家存活时间；AA给出简要判断。
A8: ④ 整关 | B8: 标准模型是一只怪。若要估整关，把N列【整关EHP倍率】填成波次总EHP÷标准怪EHP；攻击压力用O列修正。
A9: ⑤ 对照 | B9: G列是默认玩家养成快照，主线按同关；其他玩法按开放节点/共用档位预置。若你不同意，直接在H列覆盖。
A10: ⑥ 汇总 | B10: “玩法汇总”会跨页签检查完成率、最低/最高等级、等级倒退和超范围。
A12: 颜色约定
A13: 黄色 + 蓝字 | B13: 怪物等级：主要填写区
A14: 浅蓝 + 蓝字 | B14: 可选输入/覆盖项
A15: 绿字 | B15: 引用本工作簿隐藏基线的公式
A16: 黑字 | B16: 普通计算公式
A18: 数据来源（复制为 VeryHidden 静态基线，工作簿无外链）
A19: 用途 | B19: 文件 | C19: 页签/字段 | D19: SHA256 | E19: 更新时间
A20: 玩家曲线 | B20: D:\数值文档\数值文档\框架v2\01_源表\养成属性分配.xlsx | C20: 玩家战力曲线 B/AL/AN/AO；关卡S1-279；有效人数系数见F；等价怪物等级按AO目标EHP重新匹配 | D20: 3453bacda197ab04334c73cf1f2e1e856f21e5be683d7537720aa68af2e6b0ec | E20: 46244.614
A21: 怪物模型 | B21: D:\数值文档\数值文档\框架v2\01_源表\战斗公式.xlsx | C21: 怪物标准模型 Lv1-500 / AS:BA | D21: 8c573a872e8e3b1029b738b372c1fc5d652d0d256da8197d768a4bfca6776c69 | E21: 46239.719
A22: 关卡节点 | B22: D:\Vgame\Config\GameConfig\Datas\level\LevelNode.xlsx | C22: LevelNode / LevelId / IsBoss | D22: 5546d887be1fec3387c6f1c5e973b2eac02afb36e5914621807b43783192a360 | E22: 46240.415
A23: 开放条件 | B23: D:\Vgame\Config\GameConfig\Datas\system_open\SystemOpen.xlsx | C23: SystemOpen / UnlockId / CloseSys | D23: 7d50f24030fbb173425c5f62ea28d4f0662d64d928be28dc05de27c716b27bf5 | E23: 46240.415
A26: 口径边界
A27: • 本表共有343个节点行：主线99关、其余玩法244行；需要怪物等级的节点341个，PVPVE 2个入口不使用等级。
A28: • 旅券按10档×4主题共用、映射按30档×5类型共用、爬塔按100层×4赛季包共用、Boss挑战按10档×7个Boss共用。
A29: • 肉鸽按5个难度行；大秘境按25层×4环境共用；PVPVE只保留入口，不使用怪物等级。
A30: • 本表是MVP静态基线。玩家源表或怪物公式更新后，需要重新同步隐藏基线，工作簿不会自动外链更新。
A33: 玩法页签快捷入口
A34: 主线 | B34: 点击进入 | C34: 困难主线 | D34: 点击进入 | E34: 角色经验 | F34: 点击进入 | G34: 金币 | H34: 点击进入
A35: 收容经验 | B35: 点击进入 | C35: 旅券 | D35: 点击进入 | E35: 映射 | F35: 点击进入 | G35: 爬塔 | H35: 点击进入
A36: Boss挑战 | B36: 点击进入 | C36: 肉鸽 | D36: 点击进入 | E36: 大秘境 | F36: 点击进入 | G36: PVPVE | H36: 点击进入
A39: 修正版V4难度同步口径｜2026-08-10
A40: 主线 | B40: 主线按当前99关顺序逐关对齐玩家曲线S1-S99；V4怪物等级Lv5-Lv236，保留原逐关TTK与Boss生存压力。
A41: 困难主线 | B41: 困难主线在5-15/S69后统一开放；35关连续对照S71-S105，V4使用Lv186-Lv247，仍略高于同期主线。
A42: 基础资源本 | B42: 角色经验、金币、收容经验定位为稳定供给；9档使用Lv27/Lv32/Lv51/Lv67/Lv85/Lv104/Lv126/Lv148/Lv171缓升，首档继续送进度。
A43: 旅券/映射 | B43: 旅券使用Lv169-Lv369；映射使用Lv37-Lv370。两者保留原开放顺序、前段赠送进度与长期定位。
A44: 爬塔/Boss | B44: 爬塔前20层由Lv37缓升至Lv169、100层Lv370；Boss挑战使用Lv111-Lv361。
A45: 肉鸽 | B45: 肉鸽5档使用Lv140/Lv199/Lv274/Lv330/Lv351，继续为玩法开启与局内成长预留容错。
A46: 大秘境 | B46: 大秘境按Lv37/S95开放口径，25层使用Lv234-Lv370；当前系统关闭状态不变。
A47: 边界 | B47: 本版只同步怪物等级与派生属性，不改波次、技能和玩法系数。养成源表AP46当前为手填2，本表按AO目标EHP重匹配为Lv93，未修改养成源表。

Sheet 玩法汇总
A1: 全玩法难度填写进度
A2: 每个玩法已拆成独立页签。点击A列玩法名可直接跳转；这里统一检查完成率、等级范围和同玩法内的等级倒退。
A4: 玩法 | B4: 状态 | C4: 节点口径 | D4: 节点数 | E4: 需填等级 | F4: 已填有效 | G4: 完成率 | H4: 最低等级 | I4: 最高等级 | J4: 等级下降 | K4: 超范围 | L4: 备注
A5: 主线 | B5: 修正版V4已同步 | C5: 99个当前关卡 | D5: =ROWS(主线!$B$5:$B$103) -> 99 | E5: =D5 -> 99 | F5: =COUNTIFS(主线!$J$5:$J$103,">=1",主线!$J$5:$J$103,"<=500") -> 99 | G5: =IF($E5=0,1,$F5/$E5) -> 1 | H5: =IF($F5=0,"",_xlfn.MINIFS(主线!$J$5:$J$103,主线!$J$5:$J$103,">=1",主线!$J$5:$J$103,"<=500")) -> 5 | I5: =IF($F5=0,"",_xlfn.MAXIFS(主线!$J$5:$J$103,主线!$J$5:$J$103,">=1",主线!$J$5:$J$103,"<=500")) -> 187 | J5: =COUNTIF(主线!$AC$5:$AC$103,"下降") -> 0 | K5: =COUNTIF(主线!$AB$5:$AB$103,"超范围") -> 0 | L5: 当前99关轴S1-S99，怪物等级Lv5-Lv236；V4已同步最新玩家曲线
A6: 困难主线 | B6: 修正版V4已同步 | C6: 35个LevelNode | D6: =ROWS(困难主线!$B$5:$B$39) -> 35 | E6: =D6 -> 35 | F6: =COUNTIFS(困难主线!$J$5:$J$39,">=1",困难主线!$J$5:$J$39,"<=500") -> 35 | G6: =IF($E6=0,1,$F6/$E6) -> 1 | H6: =IF($F6=0,"",_xlfn.MINIFS(困难主线!$J$5:$J$39,困难主线!$J$5:$J$39,">=1",困难主线!$J$5:$J$39,"<=500")) -> 146 | I6: =IF($F6=0,"",_xlfn.MAXIFS(困难主线!$J$5:$J$39,困难主线!$J$5:$J$39,">=1",困难主线!$J$5:$J$39,"<=500")) -> 193 | J6: =COUNTIF(困难主线!$AC$5:$AC$39,"下降") -> 0 | K6: =COUNTIF(困难主线!$AB$5:$AB$39,"超范围") -> 0 | L6: 通关5-15/S69后开放；35关对照S71-S105，Lv186-Lv247，略高于同期主线
A7: 角色经验 | B7: 修正版V4已同步 | C7: 9档 | D7: =ROWS(角色经验!$B$5:$B$13) -> 9 | E7: =D7 -> 9 | F7: =COUNTIFS(角色经验!$J$5:$J$13,">=1",角色经验!$J$5:$J$13,"<=500") -> 9 | G7: =IF($E7=0,1,$F7/$E7) -> 1 | H7: =IF($F7=0,"",_xlfn.MINIFS(角色经验!$J$5:$J$13,角色经验!$J$5:$J$13,">=1",角色经验!$J$5:$J$13,"<=500")) -> 22 | I7: =IF($F7=0,"",_xlfn.MAXIFS(角色经验!$J$5:$J$13,角色经验!$J$5:$J$13,">=1",角色经验!$J$5:$J$13,"<=500")) -> 126 | J7: =COUNTIF(角色经验!$AC$5:$AC$13,"下降") -> 0 | K7: =COUNTIF(角色经验!$AB$5:$AB$13,"超范围") -> 0 | L7: 2-4后开放；首档送进度，9档Lv27-Lv171缓升，定位稳定刷取
A8: 金币 | B8: 修正版V4已同步 | C8: 9档 | D8: =ROWS(金币!$B$5:$B$13) -> 9 | E8: =D8 -> 9 | F8: =COUNTIFS(金币!$J$5:$J$13,">=1",金币!$J$5:$J$13,"<=500") -> 9 | G8: =IF($E8=0,1,$F8/$E8) -> 1 | H8: =IF($F8=0,"",_xlfn.MINIFS(金币!$J$5:$J$13,金币!$J$5:$J$13,">=1",金币!$J$5:$J$13,"<=500")) -> 22 | I8: =IF($F8=0,"",_xlfn.MAXIFS(金币!$J$5:$J$13,金币!$J$5:$J$13,">=1",金币!$J$5:$J$13,"<=500")) -> 126 | J8: =COUNTIF(金币!$AC$5:$AC$13,"下降") -> 0 | K8: =COUNTIF(金币!$AB$5:$AB$13,"超范围") -> 0 | L8: 2-4后开放；首档送进度，9档Lv27-Lv171缓升，定位稳定刷取
A9: 收容经验 | B9: 修正版V4已同步 | C9: 9档 | D9: =ROWS(收容经验!$B$5:$B$13) -> 9 | E9: =D9 -> 9 | F9: =COUNTIFS(收容经验!$J$5:$J$13,">=1",收容经验!$J$5:$J$13,"<=500") -> 9 | G9: =IF($E9=0,1,$F9/$E9) -> 1 | H9: =IF($F9=0,"",_xlfn.MINIFS(收容经验!$J$5:$J$13,收容经验!$J$5:$J$13,">=1",收容经验!$J$5:$J$13,"<=500")) -> 22 | I9: =IF($F9=0,"",_xlfn.MAXIFS(收容经验!$J$5:$J$13,收容经验!$J$5:$J$13,">=1",收容经验!$J$5:$J$13,"<=500")) -> 126 | J9: =COUNTIF(收容经验!$AC$5:$AC$13,"下降") -> 0 | K9: =COUNTIF(收容经验!$AB$5:$AB$13,"超范围") -> 0 | L9: 2-4后开放；首档送进度，9档Lv27-Lv171缓升，定位稳定刷取
A10: 旅券 | B10: 修正版V4已同步 | C10: 10档×4主题共用 | D10: =ROWS(旅券!$B$5:$B$14) -> 10 | E10: =D10 -> 10 | F10: =COUNTIFS(旅券!$J$5:$J$14,">=1",旅券!$J$5:$J$14,"<=500") -> 10 | G10: =IF($E10=0,1,$F10/$E10) -> 1 | H10: =IF($F10=0,"",_xlfn.MINIFS(旅券!$J$5:$J$14,旅券!$J$5:$J$14,">=1",旅券!$J$5:$J$14,"<=500")) -> 129 | I10: =IF($F10=0,"",_xlfn.MAXIFS(旅券!$J$5:$J$14,旅券!$J$5:$J$14,">=1",旅券!$J$5:$J$14,"<=500")) -> 303 | J10: =COUNTIF(旅券!$AC$5:$AC$14,"下降") -> 0 | K10: =COUNTIF(旅券!$AB$5:$AB$14,"超范围") -> 0 | L10: Lv38/S100开放；首档Lv169送进度，前3档缓升，10档Lv369
A11: 映射 | B11: 修正版V4已同步 | C11: 30档×5类型共用 | D11: =ROWS(映射!$B$5:$B$34) -> 30 | E11: =D11 -> 30 | F11: =COUNTIFS(映射!$J$5:$J$34,">=1",映射!$J$5:$J$34,"<=500") -> 30 | G11: =IF($E11=0,1,$F11/$E11) -> 1 | H11: =IF($F11=0,"",_xlfn.MINIFS(映射!$J$5:$J$34,映射!$J$5:$J$34,">=1",映射!$J$5:$J$34,"<=500")) -> 26 | I11: =IF($F11=0,"",_xlfn.MAXIFS(映射!$J$5:$J$34,映射!$J$5:$J$34,">=1",映射!$J$5:$J$34,"<=500")) -> 296 | J11: =COUNTIF(映射!$AC$5:$AC$34,"下降") -> 0 | K11: =COUNTIF(映射!$AB$5:$AB$34,"超范围") -> 0 | L11: 2-12/S24开放；首档Lv37送进度，前5档缓升，30档Lv370
A12: 爬塔 | B12: 修正版V4已同步 | C12: 100层×4赛季包共用 | D12: =ROWS(爬塔!$B$5:$B$104) -> 100 | E12: =D12 -> 100 | F12: =COUNTIFS(爬塔!$J$5:$J$104,">=1",爬塔!$J$5:$J$104,"<=500") -> 100 | G12: =IF($E12=0,1,$F12/$E12) -> 1 | H12: =IF($F12=0,"",_xlfn.MINIFS(爬塔!$J$5:$J$104,爬塔!$J$5:$J$104,">=1",爬塔!$J$5:$J$104,"<=500")) -> 37 | I12: =IF($F12=0,"",_xlfn.MAXIFS(爬塔!$J$5:$J$104,爬塔!$J$5:$J$104,">=1",爬塔!$J$5:$J$104,"<=500")) -> 370 | J12: =COUNTIF(爬塔!$AC$5:$AC$104,"下降") -> 0 | K12: =COUNTIF(爬塔!$AB$5:$AB$104,"超范围") -> 0 | L12: 2-12/S24开放；前20层Lv37-Lv169缓升，100层Lv370
A13: Boss挑战 | B13: 修正版V4已同步 | C13: 10档×7个Boss共用 | D13: =ROWS(Boss挑战!$B$5:$B$14) -> 10 | E13: =D13 -> 10 | F13: =COUNTIFS(Boss挑战!$J$5:$J$14,">=1",Boss挑战!$J$5:$J$14,"<=500") -> 10 | G13: =IF($E13=0,1,$F13/$E13) -> 1 | H13: =IF($F13=0,"",_xlfn.MINIFS(Boss挑战!$J$5:$J$14,Boss挑战!$J$5:$J$14,">=1",Boss挑战!$J$5:$J$14,"<=500")) -> 87 | I13: =IF($F13=0,"",_xlfn.MAXIFS(Boss挑战!$J$5:$J$14,Boss挑战!$J$5:$J$14,">=1",Boss挑战!$J$5:$J$14,"<=500")) -> 295 | J13: =COUNTIF(Boss挑战!$AC$5:$AC$14,"下降") -> 0 | K13: =COUNTIF(Boss挑战!$AB$5:$AB$14,"超范围") -> 0 | L13: 4-15/S54开放；首档Lv111送进度，前5档缓升，10档Lv361
A14: 肉鸽 | B14: 修正版V4已同步 | C14: 5档 | D14: =ROWS(肉鸽!$B$5:$B$9) -> 5 | E14: =D14 -> 5 | F14: =COUNTIFS(肉鸽!$J$5:$J$9,">=1",肉鸽!$J$5:$J$9,"<=500") -> 5 | G14: =IF($E14=0,1,$F14/$E14) -> 1 | H14: =IF($F14=0,"",_xlfn.MINIFS(肉鸽!$J$5:$J$9,肉鸽!$J$5:$J$9,">=1",肉鸽!$J$5:$J$9,"<=500")) -> 106 | I14: =IF($F14=0,"",_xlfn.MAXIFS(肉鸽!$J$5:$J$9,肉鸽!$J$5:$J$9,">=1",肉鸽!$J$5:$J$9,"<=500")) -> 286 | J14: =COUNTIF(肉鸽!$AC$5:$AC$9,"下降") -> 0 | K14: =COUNTIF(肉鸽!$AB$5:$AB$9,"超范围") -> 0 | L14: Lv35/S85开放；5档Lv140/Lv199/Lv274/Lv330/Lv351，保留局内成长空间
A15: 大秘境 | B15: 当前关闭｜修正版V4已同步 | C15: 25层×4环境共用 | D15: =ROWS(大秘境!$B$5:$B$29) -> 25 | E15: =D15 -> 25 | F15: =COUNTIFS(大秘境!$J$5:$J$29,">=1",大秘境!$J$5:$J$29,"<=500") -> 25 | G15: =IF($E15=0,1,$F15/$E15) -> 1 | H15: =IF($F15=0,"",_xlfn.MINIFS(大秘境!$J$5:$J$29,大秘境!$J$5:$J$29,">=1",大秘境!$J$5:$J$29,"<=500")) -> 183 | I15: =IF($F15=0,"",_xlfn.MAXIFS(大秘境!$J$5:$J$29,大秘境!$J$5:$J$29,">=1",大秘境!$J$5:$J$29,"<=500")) -> 301 | J15: =COUNTIF(大秘境!$AC$5:$AC$29,"下降") -> 0 | K15: =COUNTIF(大秘境!$AB$5:$AB$29,"超范围") -> 0 | L15: Lv37/S95开放；25层Lv234-Lv370，关闭状态不变
A16: PVPVE | B16: 特殊口径 | C16: 2个入口 | D16: =ROWS(PVPVE!$B$5:$B$6) -> 2 | E16: =0 -> 0 | F16: =COUNTIFS(PVPVE!$J$5:$J$6,">=1",PVPVE!$J$5:$J$6,"<=500") -> 0 | G16: =IF($E16=0,1,$F16/$E16) -> 1 | H16: =IF($F16=0,"",_xlfn.MINIFS(PVPVE!$J$5:$J$6,PVPVE!$J$5:$J$6,">=1",PVPVE!$J$5:$J$6,"<=500")) | I16: =IF($F16=0,"",_xlfn.MAXIFS(PVPVE!$J$5:$J$6,PVPVE!$J$5:$J$6,">=1",PVPVE!$J$5:$J$6,"<=500")) | J16: =COUNTIF(PVPVE!$AC$5:$AC$6,"下降") -> 0 | K16: =COUNTIF(PVPVE!$AB$5:$AB$6,"超范围") -> 0 | L16: 双方属性对算，不使用怪物等级
A17: 合计 | D17: =SUM(D5:D16) -> 343 | E17: =SUM(E5:E16) -> 341 | F17: =SUM(F5:F16) -> 341 | G17: =IF(E17=0,1,F17/E17) -> 1 | J17: =SUM(J5:J16) -> 0 | K17: =SUM(K5:K16) -> 0

Sheet 主线
A1: 全玩法难度填写｜主线
A2: 当前页已按开启顺序和玩法定位填入首版怪物等级。黄色J列可直接覆盖；G列是本版使用的玩家曲线对照节点。
A3: 公式口径：怪物实际属性=战斗公式标准模型×可选系数；怪物EHP=实际生命÷(1-防御减伤)×整关EHP倍率；TTK=怪物EHP÷玩家DPS。
A4: 状态 | B4: 玩法 | C4: 子玩法/共用范围 | D4: 节点名称 | E4: LevelId/配置映射 | F4: 怪物类型 | G4: 默认对照关卡 | H4: 手动对照关卡 | I4: 实际对照关卡 | J4: 怪物等级 | K4: 生命系数 | L4: 攻击系数 | M4: 防御系数 | N4: 整关EHP倍率 | O4: 攻击压力倍率 | P4: 目标时间(s) | Q4: 玩家DPS | R4: 玩家队伍EHP | S4: 怪物实际生命 | T4: 怪物实际攻击 | U4: 怪物实际防御 | V4: 怪物减伤率 | W4: 整关目标EHP | X4: 预测TTK(s) | Y4: 预测存活(s) | Z4: TTK/目标 | AA4: 难度判断 | AB4: 等级检查 | AC4: 等级趋势 | AD4: 备注
A5: 当前配置 | B5: 主线 | C5: 序章 | D5: 0-1 | E5: 100001 | F5: 普通怪 | G5: 1 | I5: =IF($H5="",$G5,$H5) -> 1 | J5: 5 | Q5: =IF($I5="","",IFERROR(INDEX(_玩家曲线!$H$2:$H$286,MATCH($I5,_玩家曲线!$A$2:$A$286,0)),"")) -> 1535.625 | R5: =IF($I5="","",IFERROR(INDEX(_玩家曲线!$I$2:$I$286,MATCH($I5,_玩家曲线!$A$2:$A$286,0)),"")) -> 5208.3333 | S5: =IF(OR($J5="",$F5="不适用"),"",IFERROR(INDEX(_怪物模型!$D$2:$D$4501,MATCH(INT($J5)&"|"&$F5,_怪物模型!$A$2:$A$4501,0))*IF($K5="",1,$K5),"")) -> 531 | T5: =IF(OR($J5="",$F5="不适用"),"",IFERROR(INDEX(_怪物模型!$E$2:$E$4501,MATCH(INT($J5)&"|"&$F5,_怪物模型!$A$2:$A$4501,0))*IF($L5="",1,$L5),"")) -> 165 | U5: =IF(OR($J5="",$F5="不适用"),"",IFERROR(INDEX(_怪物模型!$F$2:$F$4501,MATCH(INT($J5)&"|"&$F5,_怪物模型!$A$2:$A$4501,0))*IF($M5="",1,$M5),"")) -> 356 | V5: =IF($U5="","",MIN(0.75,$U5/($U5+24000))) -> 0.014616522 | W5: =IF($S5="","",$S5/(1-$V5)*IF($N5="",1,$N5)) -> 538.8765 | X5: =IF(OR($W5="",$Q5="",$Q5=0),"",$W5/$Q5) -> 0.35091673 | Y5: =IF(OR($R5="",$T5="",$T5=0),"",$R5/($T5*IF($O5="",1,$O5))) -> 31.565657 | Z5: =IF(OR($X5="",$P5="",$P5=0),"",$X5/$P5) | AA5: =IF($J5="","待填怪物等级",IF(OR($I5="",$Q5=""),"待填对照关卡",IF($P5="","已计算",IF(AND($Y5<>"",$Y5<$X5),"生存不成立",IF($Z5<0.5,"碾压",IF($Z5<0.8,"偏简单",IF($Z5<=1.2,"适中",IF($Z5<=1.5,"偏难","过难")))))))) -> 已计算 | AB5: =IF($J5="","待填",IF(AND(ISNUMBER($J5),$J5>=1,$J5<=500,MOD($J5,1)=0),"有效","超范围")) -> 有效 | AC5: =IF(OR($J5="",ROW()=5,$B5<>$B4,$J4=""),"",IF($J5<$J4,"下降","")) | AD5: 0-1｜修正版V4：当前99关轴S1，同关标准｜曲线同步20260811：Lv5→Lv5，保持原玩法定位与TTK/生存压力
A6: 当前配置 | B6: 主线 | C6: 序章 | D6: 0-2 | E6: 100002 | F6: 普通怪 | G6: 2 | I6: =IF($H6="",$G6,$H6) -> 2 | J6: 6 | Q6: =IF($I6="","",IFERROR(INDEX(_玩家曲线!$H$2:$H$286,MATCH($I6,_玩家曲线!$A$2:$A$286,0)),"")) -> 1636.646 | R6: =IF($I6="","",IFERROR(INDEX(_玩家曲线!$I$2:$I$286,MATCH($I6,_玩家曲线!$A$2:$A$286,0)),"")) -> 5565.5699 | S6: =IF(OR($J6="",$F6="不适用"),"",IFERROR(INDEX(_怪物模型!$D$2:$D$4501,MATCH(INT($J6)&"|"&$F6,_怪物模型!$A$2:$A$4501,0))*IF($K6="",1,$K6),"")) -> 654 | T6: =IF(OR($J6="",$F6="不适用"),"",IFERROR(INDEX(_怪物模型!$E$2:$E$4501,MATCH(INT($J6)&"|"&$F6,_怪物模型!$A$2:$A$4501,0))*IF($L6="",1,$L6),"")) -> 200 | U6: =IF(OR($J6="",$F6="不适用"),"",IFERROR(INDEX(_怪物模型!$F$2:$F$4501,MATCH(INT($J6)&"|"&$F6,_怪物模型!$A$2:$A$4501,0))*IF($M6="",1,$M6),"")) -> 428 | V6: =IF($U6="","",MIN(0.75,$U6/($U6+24000))) -> 0.017520878 | W6: =IF($S6="","",$S6/(1-$V6)*IF($N6="",1,$N6)) -> 665.663 | X6: =IF(OR($W6="",$Q6="",$Q6=0),"",$W6/$Q6) -> 0.40672388 | Y6: =IF(OR($R6="",$T6="",$T6=0),"",$R6/($T6*IF($O6="",1,$O6))) -> 27.827849 | Z6: =IF(OR($X6="",$P6="",$P6=0),"",$X6/$P6) | AA6: =IF($J6="","待填怪物等级",IF(OR($I6="",$Q6=""),"待填对照关卡",IF($P6="","已计算",IF(AND($Y6<>"",$Y6<$X6),"生存不成立",IF($Z6<0.5,"碾压",IF($Z6<0.8,"偏简单",IF($Z6<=1.2,"适中",IF($Z6<=1.5,"偏难","过难")))))))) -> 已计算 | AB6: =IF($J6="","待填",IF(AND(ISNUMBER($J6),$J6>=1,$J6<=500,MOD($J6,1)=0),"有效","超范围")) -> 有效 | AC6: =IF(OR($J6="",ROW()=5,$B6<>$B5,$J5=""),"",IF($J6<$J5,"下降","")) | AD6: 0-2｜修正版V4：当前99关轴S2，同关标准｜曲线同步20260811：Lv6→Lv6，保持原玩法定位与TTK/生存压力
A7: 当前配置 | B7: 主线 | C7: 序章 | D7: 0-3 | E7: 100003 | F7: 普通怪 | G7: 3 | I7: =IF($H7="",$G7,$H7) -> 3 | J7: 8 | Q7: =IF($I7="","",IFERROR(INDEX(_玩家曲线!$H$2:$H$286,MATCH($I7,_玩家曲线!$A$2:$A$286,0)),"")) -> 2170.1895 | R7: =IF($I7="","",IFERROR(INDEX(_玩家曲线!$I$2:$I$286,MATCH($I7,_玩家曲线!$A$2:$A$286,0)),"")) -> 7399.0134 | S7: =IF(OR($J7="",$F7="不适用"),"",IFERROR(INDEX(_怪物模型!$D$2:$D$4501,MATCH(INT($J7)&"|"&$F7,_怪物模型!$A$2:$A$4501,0))*IF($K7="",1,$K7),"")) -> 914 | T7: =IF(OR($J7="",$F7="不适用"),"",IFERROR(INDEX(_怪物模型!$E$2:$E$4501,MATCH(INT($J7)&"|"&$F7,_怪物模型!$A$2:$A$4501,0))*IF($L7="",1,$L7),"")) -> 272 | U7: =IF(OR($J7="",$F7="不适用"),"",IFERROR(INDEX(_怪物模型!$F$2:$F$4501,MATCH(INT($J7)&"|"&$F7,_怪物模型!$A$2:$A$4501,0))*IF($M7="",1,$M7),"")) -> 572 | V7: =IF($U7="","",MIN(0.75,$U7/($U7+24000))) -> 0.023278528 | W7: =IF($S7="","",$S7/(1-$V7)*IF($N7="",1,$N7)) -> 935.78367 | X7: =IF(OR($W7="",$Q7="",$Q7=0),"",$W7/$Q7) -> 0.43119906 | Y7: =IF(OR($R7="",$T7="",$T7=0),"",$R7/($T7*IF($O7="",1,$O7))) -> 27.202255 | Z7: =IF(OR($X7="",$P7="",$P7=0),"",$X7/$P7) | AA7: =IF($J7="","待填怪物等级",IF(OR($I7="",$Q7=""),"待填对照关卡",IF($P7="","已计算",IF(AND($Y7<>"",$Y7<$X7),"生存不成立",IF($Z7<0.5,"碾压",IF($Z7<0.8,"偏简单",IF($Z7<=1.2,"适中",IF($Z7<=1.5,"偏难","过难")))))))) -> 已计算 | AB7: =IF($J7="","待填",IF(AND(ISNUMBER($J7),$J7>=1,$J7<=500,MOD($J7,1)=0),"有效","超范围")) -> 有效 | AC7: =IF(OR($J7="",ROW()=5,$B7<>$B6,$J6=""),"",IF($J7<$J6,"下降","")) | AD7: 0-3｜修正版V4：当前99关轴S3，同关标准｜V4同步最新玩家曲线：Lv12→Lv8，保留原TTK/生存压力目标｜曲线同步20260811：Lv8→Lv8，保持原玩法定位与TTK/生存压力
A8: 当前配置 | B8: 主线 | C8: 序章 | D8: 0-4 | E8: 100004 | F8: Boss | G8: 4 | I8: =IF($H8="",$G8,$H8) -> 4 | J8: 8 | Q8: =IF($I8="","",IFERROR(INDEX(_玩家曲线!$H$2:$H$286,MATCH($I8,_玩家曲线!$A$2:$A$286,0)),"")) -> 2751.247 | R8: =IF($I8="","",IFERROR(INDEX(_玩家曲线!$I$2:$I$286,MATCH($I8,_玩家曲线!$A$2:$A$286,0)),"")) -> 9403.8859 | S8: =IF(OR($J8="",$F8="不适用"),"",IFERROR(INDEX(_怪物模型!$D$2:$D$4501,MATCH(INT($J8)&"|"&$F8,_怪物模型!$A$2:$A$4501,0))*IF($K8="",1,$K8),"")) -> 90876 | T8: =IF(OR($J8="",$F8="不适用"),"",IFERROR(INDEX(_怪物模型!$E$2:$E$4501,MATCH(INT($J8)&"|"&$F8,_怪物模型!$A$2:$A$4501,0))*IF($L8="",1,$L8),"")) -> 272 | U8: =IF(OR($J8="",$F8="不适用"),"",IFERROR(INDEX(_怪物模型!$F$2:$F$4501,MATCH(INT($J8)&"|"&$F8,_怪物模型!$A$2:$A$4501,0))*IF($M8="",1,$M8),"")) -> 572 | V8: =IF($U8="","",MIN(0.75,$U8/($U8+24000))) -> 0.023278528 | W8: =IF($S8="","",$S8/(1-$V8)*IF($N8="",1,$N8)) -> 93041.878 | X8: =IF(OR($W8="",$Q8="",$Q8=0),"",$W8/$Q8) -> 33.818075 | Y8: =IF(OR($R8="",$T8="",$T8=0),"",$R8/($T8*IF($O8="",1,$O8))) -> 34.57311 | Z8: =IF(OR($X8="",$P8="",$P8=0),"",$X8/$P8) | AA8: =IF($J8="","待填怪物等级",IF(OR($I8="",$Q8=""),"待填对照关卡",IF($P8="","已计算",IF(AND($Y8<>"",$Y8<$X8),"生存不成立",IF($Z8<0.5,"碾压",IF($Z8<0.8,"偏简单",IF($Z8<=1.2,"适中",IF($Z8<=1.5,"偏难","过难")))))))) -> 已计算 | AB8: =IF($J8="","待填",IF(AND(ISNUMBER($J8),$J8>=1,$J8<=500,MOD($J8,1)=0),"有效","超范围")) -> 有效 | AC8: =IF(OR($J8="",ROW()=5,$B8<>$B7,$J7=""),"",IF($J8<$J7,"下降","")) | AD8: 0-4｜修正版V4：S4同关标准；为保证首个Boss生存成立，Lv13校正为Lv9｜V4同步最新玩家曲线：Lv12→Lv9，保留原TTK/生存压力目标｜曲线同步20260811：Lv9→Lv9，保持原玩法定位与TTK/生存压力
A9: 当前配置 | B9: 主线 | C9: 第一章 | D9: 1-1 | E9: 100101 | F9: 普通怪 | G9: 5 | I9: =IF($H9="",$G9,$H9) -> 5 | J9: 11 | Q9: =IF($I9="","",IFERROR(INDEX(_玩家曲线!$H$2:$H$286,MATCH($I9,_玩家曲线!$A$2:$A$286,0)),"")) -> 3378.7382 | R9: =IF($I9="","",IFERROR(INDEX(_玩家曲线!$I$2:$I$286,MATCH($I9,_玩家曲线!$A$2:$A$286,0)),"")) -> 11577.497 | S9: =IF(OR($J9="",$F9="不适用"),"",IFERROR(INDEX(_怪物模型!$D$2:$D$4501,MATCH(INT($J9)&"|"&$F9,_怪物模型!$A$2:$A$4501,0))*IF($K9="",1,$K9),"")) -> 1342 | T9: =IF(OR($J9="",$F9="不适用"),"",IFERROR(INDEX(_怪物模型!$E$2:$E$4501,MATCH(INT($J9)&"|"&$F9,_怪物模型!$A$2:$A$4501,0))*IF($L9="",1,$L9),"")) -> 384 | U9: =IF(OR($J9="",$F9="不适用"),"",IFERROR(INDEX(_怪物模型!$F$2:$F$4501,MATCH(INT($J9)&"|"&$F9,_怪物模型!$A$2:$A$4501,0))*IF($M9="",1,$M9),"")) -> 790 | V9: =IF($U9="","",MIN(0.75,$U9/($U9+24000))) -> 0.031867689 | W9: =IF($S9="","",$S9/(1-$V9)*IF($N9="",1,$N9)) -> 1386.1742 | X9: =IF(OR($W9="",$Q9="",$Q9=0),"",$W9/$Q9) -> 0.41026386 | Y9: =IF(OR($R9="",$T9="",$T9=0),"",$R9/($T9*IF($O9="",1,$O9))) -> 30.149731 | Z9: =IF(OR($X9="",$P9="",$P9=0),"",$X9/$P9) | AA9: =IF($J9="","待填怪物等级",IF(OR($I9="",$Q9=""),"待填对照关卡",IF($P9="","已计算",IF(AND($Y9<>"",$Y9<$X9),"生存不成立",IF($Z9<0.5,"碾压",IF($Z9<0.8,"偏简单",IF($Z9<=1.2,"适中",IF($Z9<=1.5,"偏难","过难")))))))) -> 已计算 | AB9: =IF($J9="","待填",IF(AND(ISNUMBER($J9),$J9>=1,$J9<=500,MOD($J9,1)=0),"有效","超范围")) -> 有效 | AC9: =IF(OR($J9="",ROW()=5,$B9<>$B8,$J8=""),"",IF($J9<$J8,"下降","")) | AD9: 1-1｜修正版V4：当前99关轴S5，同关标准｜V4同步最新玩家曲线：Lv14→Lv12，保留原TTK/生存压力目标｜曲线同步20260811：Lv12→Lv12，保持原玩法定位与TTK/生存压力
A10: 当前配置 | B10: 主线 | C10: 第一章 | D10: 1-2 | E10: 100102 | F10: 普通怪 | G10: 6 | I10: =IF($H10="",$G10,$H10) -> 6 | J10: 13 | Q10: =IF($I10="","",IFERROR(INDEX(_玩家曲线!$H$2:$H$286,MATCH($I10,_玩家曲线!$A$2:$A$286,0)),"")) -> 4051.6045 | R10: =IF($I10="","",IFERROR(INDEX(_玩家曲线!$I$2:$I$286,MATCH($I10,_玩家曲线!$A$2:$A$286,0)),"")) -> 13917.162 | S10: =IF(OR($J10="",$F10="不适用"),"",IFERROR(INDEX(_怪物模型!$D$2:$D$4501,MATCH(INT($J10)&"|"&$F10,_怪物模型!$A$2:$A$4501,0))*IF($K10="",1,$K10),"")) -> 1652 | T10: =IF(OR($J10="",$F10="不适用"),"",IFERROR(INDEX(_怪物模型!$E$2:$E$4501,MATCH(INT($J10)&"|"&$F10,_怪物模型!$A$2:$A$4501,0))*IF($L10="",1,$L10),"")) -> 461 | U10: =IF(OR($J10="",$F10="不适用"),"",IFERROR(INDEX(_怪物模型!$F$2:$F$4501,MATCH(INT($J10)&"|"&$F10,_怪物模型!$A$2:$A$4501,0))*IF($M10="",1,$M10),"")) -> 936 | V10: =IF($U10="","",MIN(0.75,$U10/($U10+24000))) -> 0.037536092 | W10: =IF($S10="","",$S10/(1-$V10)*IF($N10="",1,$N10)) -> 1716.428 | X10: =IF(OR($W10="",$Q10="",$Q10=0),"",$W10/$Q10) -> 0.42364155 | Y10: =IF(OR($R10="",$T10="",$T10=0),"",$R10/($T10*IF($O10="",1,$O10))) -> 30.189071 | Z10: =IF(OR($X10="",$P10="",$P10=0),"",$X10/$P10) | AA10: =IF($J10="","待填怪物等级",IF(OR($I10="",$Q10=""),"待填对照关卡",IF($P10="","已计算",IF(AND($Y10<>"",$Y10<$X10),"生存不成立",IF($Z10<0.5,"碾压",IF($Z10<0.8,"偏简单",IF($Z10<=1.2,"适中",IF($Z10<=1.5,"偏难","过难")))))))) -> 已计算 | AB10: =IF($J10="","待填",IF(AND(ISNUMBER($J10),$J10>=1,$J10<=500,MOD($J10,1)=0),"有效","超范围")) -> 有效 | AC10: =IF(OR($J10="",ROW()=5,$B10<>$B9,$J9=""),"",IF($J10<$J9,"下降","")) | AD10: 1-2｜修正版V4：当前99关轴S6，同关标准｜V4同步最新玩家曲线：Lv15→Lv14，保留原TTK/生存压力目标｜曲线同步20260811：Lv14→Lv14，保持原玩法定位与TTK/生存压力
A11: 当前配置 | B11: 主线 | C11: 第一章 | D11: 1-3 | E11: 100103 | F11: 普通怪 | G11: 7 | I11: =IF($H11="",$G11,$H11) -> 7 | J11: 15 | Q11: =IF($I11="","",IFERROR(INDEX(_玩家曲线!$H$2:$H$286,MATCH($I11,_玩家曲线!$A$2:$A$286,0)),"")) -> 4945.4313 | R11: =IF($I11="","",IFERROR(INDEX(_玩家曲线!$I$2:$I$286,MATCH($I11,_玩家曲线!$A$2:$A$286,0)),"")) -> 17028.36 | S11: =IF(OR($J11="",$F11="不适用"),"",IFERROR(INDEX(_怪物模型!$D$2:$D$4501,MATCH(INT($J11)&"|"&$F11,_怪物模型!$A$2:$A$4501,0))*IF($K11="",1,$K11),"")) -> 1982 | T11: =IF(OR($J11="",$F11="不适用"),"",IFERROR(INDEX(_怪物模型!$E$2:$E$4501,MATCH(INT($J11)&"|"&$F11,_怪物模型!$A$2:$A$4501,0))*IF($L11="",1,$L11),"")) -> 541 | U11: =IF(OR($J11="",$F11="不适用"),"",IFERROR(INDEX(_怪物模型!$F$2:$F$4501,MATCH(INT($J11)&"|"&$F11,_怪物模型!$A$2:$A$4501,0))*IF($M11="",1,$M11),"")) -> 1083 | V11: =IF($U11="","",MIN(0.75,$U11/($U11+24000))) -> 0.043176654 | W11: =IF($S11="","",$S11/(1-$V11)*IF($N11="",1,$N11)) -> 2071.4378 | X11: =IF(OR($W11="",$Q11="",$Q11=0),"",$W11/$Q11) -> 0.41885887 | Y11: =IF(OR($R11="",$T11="",$T11=0),"",$R11/($T11*IF($O11="",1,$O11))) -> 31.475711 | Z11: =IF(OR($X11="",$P11="",$P11=0),"",$X11/$P11) | AA11: =IF($J11="","待填怪物等级",IF(OR($I11="",$Q11=""),"待填对照关卡",IF($P11="","已计算",IF(AND($Y11<>"",$Y11<$X11),"生存不成立",IF($Z11<0.5,"碾压",IF($Z11<0.8,"偏简单",IF($Z11<=1.2,"适中",IF($Z11<=1.5,"偏难","过难")))))))) -> 已计算 | AB11: =IF($J11="","待填",IF(AND(ISNUMBER($J11),$J11>=1,$J11<=500,MOD($J11,1)=0),"有效","超范围")) -> 有效 | AC11: =IF(OR($J11="",ROW()=5,$B11<>$B10,$J10=""),"",IF($J11<$J10,"下降","")) | AD11: 1-3｜修正版V4：当前99关轴S7，同关标准｜V4同步最新玩家曲线：Lv22→Lv17，保留原TTK/生存压力目标｜曲线同步20260811：Lv17→Lv16，保持原玩法定位与TTK/生存压力
A12: 当前配置 | B12: 主线 | C12: 第一章 | D12: 1-4 | E12: 100104 | F12: 普通怪 | G12: 8 | I12: =IF($H12="",$G12,$H12) -> 8 | J12: 16 | Q12: =IF($I12="","",IFERROR(INDEX(_玩家曲线!$H$2:$H$286,MATCH($I12,_玩家曲线!$A$2:$A$286,0)),"")) -> 5897.9569 | R12: =IF($I12="","",IFERROR(INDEX(_玩家曲线!$I$2:$I$286,MATCH($I12,_玩家曲线!$A$2:$A$286,0)),"")) -> 20356.219 | S12: =IF(OR($J12="",$F12="不适用"),"",IFERROR(INDEX(_怪物模型!$D$2:$D$4501,MATCH(INT($J12)&"|"&$F12,_怪物模型!$A$2:$A$4501,0))*IF($K12="",1,$K12),"")) -> 2154 | T12: =IF(OR($J12="",$F12="不适用"),"",IFERROR(INDEX(_怪物模型!$E$2:$E$4501,MATCH(INT($J12)&"|"&$F12,_怪物模型!$A$2:$A$4501,0))*IF($L12="",1,$L12),"")) -> 582 | U12: =IF(OR($J12="",$F12="不适用"),"",IFERROR(INDEX(_怪物模型!$F$2:$F$4501,MATCH(INT($J12)&"|"&$F12,_怪物模型!$A$2:$A$4501,0))*IF($M12="",1,$M12),"")) -> 1157 | V12: =IF($U12="","",MIN(0.75,$U12/($U12+24000))) -> 0.045991175 | W12: =IF($S12="","",$S12/(1-$V12)*IF($N12="",1,$N12)) -> 2257.8407 | X12: =IF(OR($W12="",$Q12="",$Q12=0),"",$W12/$Q12) -> 0.38281744 | Y12: =IF(OR($R12="",$T12="",$T12=0),"",$R12/($T12*IF($O12="",1,$O12))) -> 34.976321 | Z12: =IF(OR($X12="",$P12="",$P12=0),"",$X12/$P12) | AA12: =IF($J12="","待填怪物等级",IF(OR($I12="",$Q12=""),"待填对照关卡",IF($P12="","已计算",IF(AND($Y12<>"",$Y12<$X12),"生存不成立",IF($Z12<0.5,"碾压",IF($Z12<0.8,"偏简单",IF($Z12<=1.2,"适中",IF($Z12<=1.5,"偏难","过难")))))))) -> 已计算 | AB12: =IF($J12="","待填",IF(AND(ISNUMBER($J12),$J12>=1,$J12<=500,MOD($J12,1)=0),"有效","超范围")) -> 有效 | AC12: =IF(OR($J12="",ROW()=5,$B12<>$B11,$J11=""),"",IF($J12<$J11,"下降","")) | AD12: 1-4｜修正版V4：当前99关轴S8，同关标准｜V4同步最新玩家曲线：Lv23→Lv19，保留原TTK/生存压力目标｜曲线同步20260811：Lv19→Lv18，保持原玩法定位与TTK/生存压力
A13: 当前配置 | B13: 主线 | C13: 第一章 | D13: 1-5 | E13: 100105 | F13: 普通怪 | G13: 9 | I13: =IF($H13="",$G13,$H13) -> 9 | J13: 19 | Q13: =IF($I13="","",IFERROR(INDEX(_玩家曲线!$H$2:$H$286,MATCH($I13,_玩家曲线!$A$2:$A$286,0)),"")) -> 6907.8395 | R13: =IF($I13="","",IFERROR(INDEX(_玩家曲线!$I$2:$I$286,MATCH($I13,_玩家曲线!$A$2:$A$286,0)),"")) -> 23897.191 | S13: =IF(OR($J13="",$F13="不适用"),"",IFERROR(INDEX(_怪物模型!$D$2:$D$4501,MATCH(INT($J13)&"|"&$F13,_怪物模型!$A$2:$A$4501,0))*IF($K13="",1,$K13),"")) -> 2700 | T13: =IF(OR($J13="",$F13="不适用"),"",IFERROR(INDEX(_怪物模型!$E$2:$E$4501,MATCH(INT($J13)&"|"&$F13,_怪物模型!$A$2:$A$4501,0))*IF($L13="",1,$L13),"")) -> 709 | U13: =IF(OR($J13="",$F13="不适用"),"",IFERROR(INDEX(_怪物模型!$F$2:$F$4501,MATCH(INT($J13)&"|"&$F13,_怪物模型!$A$2:$A$4501,0))*IF($M13="",1,$M13),"")) -> 1379 | V13: =IF($U13="","",MIN(0.75,$U13/($U13+24000))) -> 0.054336262 | W13: =IF($S13="","",$S13/(1-$V13)*IF($N13="",1,$N13)) -> 2855.1375 | X13: =IF(OR($W13="",$Q13="",$Q13=0),"",$W13/$Q13) -> 0.41331845 | Y13: =IF(OR($R13="",$T13="",$T13=0),"",$R13/($T13*IF($O13="",1,$O13))) -> 33.705489 | Z13: =IF(OR($X13="",$P13="",$P13=0),"",$X13/$P13) | AA13: =IF($J13="","待填怪物等级",IF(OR($I13="",$Q13=""),"待填对照关卡",IF($P13="","已计算",IF(AND($Y13<>"",$Y13<$X13),"生存不成立",IF($Z13<0.5,"碾压",IF($Z13<0.8,"偏简单",IF($Z13<=1.2,"适中",IF($Z13<=1.5,"偏难","过难")))))))) -> 已计算 | AB13: =IF($J13="","待填",IF(AND(ISNUMBER($J13),$J13>=1,$J13<=500,MOD($J13,1)=0),"有效","超范围")) -> 有效 | AC13: =IF(OR($J13="",ROW()=5,$B13<>$B12,$J12=""),"",IF($J13<$J12,"下降","")) | AD13: 1-5｜修正版V4：当前99关轴S9，同关标准｜V4同步最新玩家曲线：Lv24→Lv22，保留原TTK/生存压力目标｜曲线同步20260811：Lv22→Lv21，保持原玩法定位与TTK/生存压力
A14: 当前配置 | B14: 主线 | C14: 第一章 | D14: 1-6 | E14: 100106 | F14: 普通怪 | G14: 10 | I14: =IF($H14="",$G14,$H14) -> 10 | J14: 21 | Q14: =IF($I14="","",IFERROR(INDEX(_玩家曲线!$H$2:$H$286,MATCH($I14,_玩家曲线!$A$2:$A$286,0)),"")) -> 7654.8137 | R14: =IF($I14="","",IFERROR(INDEX(_玩家曲线!$I$2:$I$286,MATCH($I14,_玩家曲线!$A$2:$A$286,0)),"")) -> 26541.835 | S14: =IF(OR($J14="",$F14="不适用"),"",IFERROR(INDEX(_怪物模型!$D$2:$D$4501,MATCH(INT($J14)&"|"&$F14,_怪物模型!$A$2:$A$4501,0))*IF($K14="",1,$K14),"")) -> 3088 | T14: =IF(OR($J14="",$F14="不适用"),"",IFERROR(INDEX(_怪物模型!$E$2:$E$4501,MATCH(INT($J14)&"|"&$F14,_怪物模型!$A$2:$A$4501,0))*IF($L14="",1,$L14),"")) -> 797 | U14: =IF(OR($J14="",$F14="不适用"),"",IFERROR(INDEX(_怪物模型!$F$2:$F$4501,MATCH(INT($J14)&"|"&$F14,_怪物模型!$A$2:$A$4501,0))*IF($M14="",1,$M14),"")) -> 1528 | V14: =IF($U14="","",MIN(0.75,$U14/($U14+24000))) -> 0.059855845 | W14: =IF($S14="","",$S14/(1-$V14)*IF($N14="",1,$N14)) -> 3284.6027 | X14: =IF(OR($W14="",$Q14="",$Q14=0),"",$W14/$Q14) -> 0.42908982 | Y14: =IF(OR($R14="",$T14="",$T14=0),"",$R14/($T14*IF($O14="",1,$O14))) -> 33.302176 | Z14: =IF(OR($X14="",$P14="",$P14=0),"",$X14/$P14) | AA14: =IF($J14="","待填怪物等级",IF(OR($I14="",$Q14=""),"待填对照关卡",IF($P14="","已计算",IF(AND($Y14<>"",$Y14<$X14),"生存不成立",IF($Z14<0.5,"碾压",IF($Z14<0.8,"偏简单",IF($Z14<=1.2,"适中",IF($Z14<=1.5,"偏难","过难")))))))) -> 已计算 | AB14: =IF($J14="","待填",IF(AND(ISNUMBER($J14),$J14>=1,$J14<=500,MOD($J14,1)=0),"有效","超范围")) -> 有效 | AC14: =IF(OR($J14="",ROW()=5,$B14<>$B13,$J13=""),"",IF($J14<$J13,"下降","")) | AD14: 1-6｜修正版V4：当前99关轴S10，同关标准｜V4同步最新玩家曲线：Lv31→Lv24，保留原TTK/生存压力目标｜曲线同步20260811：Lv24→Lv23，保持原玩法定位与TTK/生存压力
A15: 当前配置 | B15: 主线 | C15: 第一章 | D15: 1-7 | E15: 100107 | F15: 普通怪 | G15: 11 | I15: =IF($H15="",$G15,$H15) -> 11 | J15: 22 | Q15: =IF($I15="","",IFERROR(INDEX(_玩家曲线!$H$2:$H$286,MATCH($I15,_玩家曲线!$A$2:$A$286,0)),"")) -> 8433.0291 | R15: =IF($I15="","",IFERROR(INDEX(_玩家曲线!$I$2:$I$286,MATCH($I15,_玩家曲线!$A$2:$A$286,0)),"")) -> 29305.863 | S15: =IF(OR($J15="",$F15="不适用"),"",IFERROR(INDEX(_怪物模型!$D$2:$D$4501,MATCH(INT($J15)&"|"&$F15,_怪物模型!$A$2:$A$4501,0))*IF($K15="",1,$K15),"")) -> 3288 | T15: =IF(OR($J15="",$F15="不适用"),"",IFERROR(INDEX(_怪物模型!$E$2:$E$4501,MATCH(INT($J15)&"|"&$F15,_怪物模型!$A$2:$A$4501,0))*IF($L15="",1,$L15),"")) -> 842 | U15: =IF(OR($J15="",$F15="不适用"),"",IFERROR(INDEX(_怪物模型!$F$2:$F$4501,MATCH(INT($J15)&"|"&$F15,_怪物模型!$A$2:$A$4501,0))*IF($M15="",1,$M15),"")) -> 1603 | V15: =IF($U15="","",MIN(0.75,$U15/($U15+24000))) -> 0.06260985 | W15: =IF($S15="","",$S15/(1-$V15)*IF($N15="",1,$N15)) -> 3507.611 | X15: =IF(OR($W15="",$Q15="",$Q15=0),"",$W15/$Q15) -> 0.41593726 | Y15: =IF(OR($R15="",$T15="",$T15=0),"",$R15/($T15*IF($O15="",1,$O15))) -> 34.805063 | Z15: =IF(OR($X15="",$P15="",$P15=0),"",$X15/$P15) | AA15: =IF($J15="","待填怪物等级",IF(OR($I15="",$Q15=""),"待填对照关卡",IF($P15="","已计算",IF(AND($Y15<>"",$Y15<$X15),"生存不成立",IF($Z15<0.5,"碾压",IF($Z15<0.8,"偏简单",IF($Z15<=1.2,"适中",IF($Z15<=1.5,"偏难","过难")))))))) -> 已计算 | AB15: =IF($J15="","待填",IF(AND(ISNUMBER($J15),$J15>=1,$J15<=500,MOD($J15,1)=0),"有效","超范围")) -> 有效 | AC15: =IF(OR($J15="",ROW()=5,$B15<>$B14,$J14=""),"",IF($J15<$J14,"下降","")) | AD15: 1-7｜修正版V4：当前99关轴S11，同关标准｜V4同步最新玩家曲线：Lv32→Lv26，保留原TTK/生存压力目标｜曲线同步20260811：Lv26→Lv25，保持原玩法定位与TTK/生存压力
A16: 当前配置 | B16: 主线 | C16: 第一章 | D16: 1-8 | E16: 100108 | F16: Boss | G16: 12 | I16: =IF($H16="",$G16,$H16) -> 12 | J16: 23 | Q16: =IF($I16="","",IFERROR(INDEX(_玩家曲线!$H$2:$H$286,MATCH($I16,_玩家曲线!$A$2:$A$286,0)),"")) -> 9241.7525 | R16: =IF($I16="","",IFERROR(INDEX(_玩家曲线!$I$2:$I$286,MATCH($I16,_玩家曲线!$A$2:$A$286,0)),"")) -> 32187.192 | S16: =IF(OR($J16="",$F16="不适用"),"",IFERROR(INDEX(_怪物模型!$D$2:$D$4501,MATCH(INT($J16)&"|"&$F16,_怪物模型!$A$2:$A$4501,0))*IF($K16="",1,$K16),"")) -> 299412 | T16: =IF(OR($J16="",$F16="不适用"),"",IFERROR(INDEX(_怪物模型!$E$2:$E$4501,MATCH(INT($J16)&"|"&$F16,_怪物模型!$A$2:$A$4501,0))*IF($L16="",1,$L16),"")) -> 887 | U16: =IF(OR($J16="",$F16="不适用"),"",IFERROR(INDEX(_怪物模型!$F$2:$F$4501,MATCH(INT($J16)&"|"&$F16,_怪物模型!$A$2:$A$4501,0))*IF($M16="",1,$M16),"")) -> 1678 | V16: =IF($U16="","",MIN(0.75,$U16/($U16+24000))) -> 0.065347769 | W16: =IF($S16="","",$S16/(1-$V16)*IF($N16="",1,$N16)) -> 320345.89 | X16: =IF(OR($W16="",$Q16="",$Q16=0),"",$W16/$Q16) -> 34.662894 | Y16: =IF(OR($R16="",$T16="",$T16=0),"",$R16/($T16*IF($O16="",1,$O16))) -> 36.287703 | Z16: =IF(OR($X16="",$P16="",$P16=0),"",$X16/$P16) | AA16: =IF($J16="","待填怪物等级",IF(OR($I16="",$Q16=""),"待填对照关卡",IF($P16="","已计算",IF(AND($Y16<>"",$Y16<$X16),"生存不成立",IF($Z16<0.5,"碾压",IF($Z16<0.8,"偏简单",IF($Z16<=1.2,"适中",IF($Z16<=1.5,"偏难","过难")))))))) -> 已计算 | AB16: =IF($J16="","待填",IF(AND(ISNUMBER($J16),$J16>=1,$J16<=500,MOD($J16,1)=0),"有效","超范围")) -> 有效 | AC16: =IF(OR($J16="",ROW()=5,$B16<>$B15,$J15=""),"",IF($J16<$J15,"下降","")) | AD16: 1-8｜修正版V4：当前99关轴S12，同关标准｜V4同步最新玩家曲线：Lv33→Lv27，保留原TTK/生存压力目标｜曲线同步20260811：Lv27→Lv26，保持原玩法定位与TTK/生存压力
... A103: 当前配置 | B103: 主线 | C103: 第七章 | D103: 7-15 | E103: 100715 | F103: Boss | G103: 99 | I103: =IF($H103="",$G103,$H103) -> 99 | J103: 187 | Q103: =IF($I103="","",IFERROR(INDEX(_玩家曲线!$H$2:$H$286,MATCH($I103,_玩家曲线!$A$2:$A$286,0)),"")) -> 721578.84 | R103: =IF($I103="","",IFERROR(INDEX(_玩家曲线!$I$2:$I$286,MATCH($I103,_玩家曲线!$A$2:$A$286,0)),"")) -> 1212579.3 | S103: =IF(OR($J103="",$F103="不适用"),"",IFERROR(INDEX(_怪物模型!$D$2:$D$4501,MATCH(INT($J103)&"|"&$F103,_怪物模型!$A$2:$A$4501,0))*IF($K103="",1,$K103),"")) -> 14140529 | T103: =IF(OR($J103="",$F103="不适用"),"",IFERROR(INDEX(_怪物模型!$E$2:$E$4501,MATCH(INT($J103)&"|"&$F103,_怪物模型!$A$2:$A$4501,0))*IF($L103="",1,$L103),"")) -> 20409 | U103: =IF(OR($J103="",$F103="不适用"),"",IFERROR(INDEX(_怪物模型!$F$2:$F$4501,MATCH(INT($J103)&"|"&$F103,_怪物模型!$A$2:$A$4501,0))*IF($M103="",1,$M103),"")) -> 16465 | V103: =IF($U103="","",MIN(0.75,$U103/($U103+24000))) -> 0.40689485 | W103: =IF($S103="","",$S103/(1-$V103)*IF($N103="",1,$N103)) -> 23841521 | X103: =IF(OR($W103="",$Q103="",$Q103=0),"",$W103/$Q103) -> 33.040771 | Y103: =IF(OR($R103="",$T103="",$T103=0),"",$R103/($T103*IF($O103="",1,$O103))) -> 59.413948 | Z103: =IF(OR($X103="",$P103="",$P103=0),"",$X103/$P103) | AA103: =IF($J103="","待填怪物等级",IF(OR($I103="",$Q103=""),"待填对照关卡",IF($P103="","已计算",IF(AND($Y103<>"",$Y103<$X103),"生存不成立",IF($Z103<0.5,"碾压",IF($Z103<0.8,"偏简单",IF($Z103<=1.2,"适中",IF($Z103<=1.5,"偏难","过难")))))))) -> 已计算 | AB103: =IF($J103="","待填",IF(AND(ISNUMBER($J103),$J103>=1,$J103<=500,MOD($J103,1)=0),"有效","超范围")) -> 有效 | AC103: =IF(OR($J103="",ROW()=5,$B103<>$B102,$J102=""),"",IF($J103<$J102,"下降","")) | AD103: 7-15｜修正版V4：当前99关轴S99，同关标准｜V4同步最新玩家曲线：Lv249→Lv236，保留原TTK/生存压力目标｜曲线同步20260811：Lv236→Lv204，保持原玩法定位与TTK/生存压力

Sheet 困难主线
A1: 全玩法难度填写｜困难主线
A2: 当前页已按开启顺序和玩法定位填入首版怪物等级。黄色J列可直接覆盖；G列是本版使用的玩家曲线对照节点。
A3: 公式口径：怪物实际属性=战斗公式标准模型×可选系数；怪物EHP=实际生命÷(1-防御减伤)×整关EHP倍率；TTK=怪物EHP÷玩家DPS。
A4: 状态 | B4: 玩法 | C4: 子玩法/共用范围 | D4: 节点名称 | E4: LevelId/配置映射 | F4: 怪物类型 | G4: 默认对照关卡 | H4: 手动对照关卡 | I4: 实际对照关卡 | J4: 怪物等级 | K4: 生命系数 | L4: 攻击系数 | M4: 防御系数 | N4: 整关EHP倍率 | O4: 攻击压力倍率 | P4: 目标时间(s) | Q4: 玩家DPS | R4: 玩家队伍EHP | S4: 怪物实际生命 | T4: 怪物实际攻击 | U4: 怪物实际防御 | V4: 怪物减伤率 | W4: 整关目标EHP | X4: 预测TTK(s) | Y4: 预测存活(s) | Z4: TTK/目标 | AA4: 难度判断 | AB4: 等级检查 | AC4: 等级趋势 | AD4: 备注
A5: 当前配置 | B5: 困难主线 | C5: 第1章 | D5: 高难1-1 | E5: 110101 | F5: 普通怪 | G5: 71 | I5: =IF($H5="",$G5,$H5) -> 71 | J5: 146 | Q5: =IF($I5="","",IFERROR(INDEX(_玩家曲线!$H$2:$H$286,MATCH($I5,_玩家曲线!$A$2:$A$286,0)),"")) -> 370088.03 | R5: =IF($I5="","",IFERROR(INDEX(_玩家曲线!$I$2:$I$286,MATCH($I5,_玩家曲线!$A$2:$A$286,0)),"")) -> 681502.87 | S5: =IF(OR($J5="",$F5="不适用"),"",IFERROR(INDEX(_怪物模型!$D$2:$D$4501,MATCH(INT($J5)&"|"&$F5,_怪物模型!$A$2:$A$4501,0))*IF($K5="",1,$K5),"")) -> 77230 | T5: =IF(OR($J5="",$F5="不适用"),"",IFERROR(INDEX(_怪物模型!$E$2:$E$4501,MATCH(INT($J5)&"|"&$F5,_怪物模型!$A$2:$A$4501,0))*IF($L5="",1,$L5),"")) -> 12789 | U5: =IF(OR($J5="",$F5="不适用"),"",IFERROR(INDEX(_怪物模型!$F$2:$F$4501,MATCH(INT($J5)&"|"&$F5,_怪物模型!$A$2:$A$4501,0))*IF($M5="",1,$M5),"")) -> 12303 | V5: =IF($U5="","",MIN(0.75,$U5/($U5+24000))) -> 0.33889761 | W5: =IF($S5="","",$S5/(1-$V5)*IF($N5="",1,$N5)) -> 116820.03 | X5: =IF(OR($W5="",$Q5="",$Q5=0),"",$W5/$Q5) -> 0.3156547 | Y5: =IF(OR($R5="",$T5="",$T5=0),"",$R5/($T5*IF($O5="",1,$O5))) -> 53.288206 | Z5: =IF(OR($X5="",$P5="",$P5=0),"",$X5/$P5) | AA5: =IF($J5="","待填怪物等级",IF(OR($I5="",$Q5=""),"待填对照关卡",IF($P5="","已计算",IF(AND($Y5<>"",$Y5<$X5),"生存不成立",IF($Z5<0.5,"碾压",IF($Z5<0.8,"偏简单",IF($Z5<=1.2,"适中",IF($Z5<=1.5,"偏难","过难")))))))) -> 已计算 | AB5: =IF($J5="","待填",IF(AND(ISNUMBER($J5),$J5>=1,$J5<=500,MOD($J5,1)=0),"有效","超范围")) -> 有效 | AC5: =IF(OR($J5="",ROW()=5,$B5<>$B4,$J4=""),"",IF($J5<$J4,"下降","")) | AD5: 高难1-1；通关5-15后统一开放｜修正版V4：对照S71，略高于开放基点S69/Lv194｜V4同步最新玩家曲线：Lv199→Lv186，保留原TTK/生存压力目标｜曲线同步20260811：Lv186→Lv160，保持原玩法定位与TTK/生存压力
A6: 当前配置 | B6: 困难主线 | C6: 第1章 | D6: 高难1-2 | E6: 110102 | F6: 普通怪 | G6: 72 | I6: =IF($H6="",$G6,$H6) -> 72 | J6: 147 | Q6: =IF($I6="","",IFERROR(INDEX(_玩家曲线!$H$2:$H$286,MATCH($I6,_玩家曲线!$A$2:$A$286,0)),"")) -> 382701.3 | R6: =IF($I6="","",IFERROR(INDEX(_玩家曲线!$I$2:$I$286,MATCH($I6,_玩家曲线!$A$2:$A$286,0)),"")) -> 701882 | S6: =IF(OR($J6="",$F6="不适用"),"",IFERROR(INDEX(_怪物模型!$D$2:$D$4501,MATCH(INT($J6)&"|"&$F6,_怪物模型!$A$2:$A$4501,0))*IF($K6="",1,$K6),"")) -> 78386 | T6: =IF(OR($J6="",$F6="不适用"),"",IFERROR(INDEX(_怪物模型!$E$2:$E$4501,MATCH(INT($J6)&"|"&$F6,_怪物模型!$A$2:$A$4501,0))*IF($L6="",1,$L6),"")) -> 12949 | U6: =IF(OR($J6="",$F6="不适用"),"",IFERROR(INDEX(_怪物模型!$F$2:$F$4501,MATCH(INT($J6)&"|"&$F6,_怪物模型!$A$2:$A$4501,0))*IF($M6="",1,$M6),"")) -> 12401 | V6: =IF($U6="","",MIN(0.75,$U6/($U6+24000))) -> 0.34067745 | W6: =IF($S6="","",$S6/(1-$V6)*IF($N6="",1,$N6)) -> 118888.7 | X6: =IF(OR($W6="",$Q6="",$Q6=0),"",$W6/$Q6) -> 0.31065664 | Y6: =IF(OR($R6="",$T6="",$T6=0),"",$R6/($T6*IF($O6="",1,$O6))) -> 54.203568 | Z6: =IF(OR($X6="",$P6="",$P6=0),"",$X6/$P6) | AA6: =IF($J6="","待填怪物等级",IF(OR($I6="",$Q6=""),"待填对照关卡",IF($P6="","已计算",IF(AND($Y6<>"",$Y6<$X6),"生存不成立",IF($Z6<0.5,"碾压",IF($Z6<0.8,"偏简单",IF($Z6<=1.2,"适中",IF($Z6<=1.5,"偏难","过难")))))))) -> 已计算 | AB6: =IF($J6="","待填",IF(AND(ISNUMBER($J6),$J6>=1,$J6<=500,MOD($J6,1)=0),"有效","超范围")) -> 有效 | AC6: =IF(OR($J6="",ROW()=5,$B6<>$B5,$J5=""),"",IF($J6<$J5,"下降","")) | AD6: 高难1-2；通关5-15后统一开放｜修正版V4：对照S72，略高于开放基点S69/Lv194｜V4同步最新玩家曲线：Lv202→Lv189，保留原TTK/生存压力目标｜曲线同步20260811：Lv189→Lv163，保持原玩法定位与TTK/生存压力
A7: 当前配置 | B7: 困难主线 | C7: 第1章 | D7: 高难1-3 | E7: 110103 | F7: 普通怪 | G7: 73 | I7: =IF($H7="",$G7,$H7) -> 73 | J7: 148 | Q7: =IF($I7="","",IFERROR(INDEX(_玩家曲线!$H$2:$H$286,MATCH($I7,_玩家曲线!$A$2:$A$286,0)),"")) -> 395361.77 | R7: =IF($I7="","",IFERROR(INDEX(_玩家曲线!$I$2:$I$286,MATCH($I7,_玩家曲线!$A$2:$A$286,0)),"")) -> 722215.24 | S7: =IF(OR($J7="",$F7="不适用"),"",IFERROR(INDEX(_怪物模型!$D$2:$D$4501,MATCH(INT($J7)&"|"&$F7,_怪物模型!$A$2:$A$4501,0))*IF($K7="",1,$K7),"")) -> 79554 | T7: =IF(OR($J7="",$F7="不适用"),"",IFERROR(INDEX(_怪物模型!$E$2:$E$4501,MATCH(INT($J7)&"|"&$F7,_怪物模型!$A$2:$A$4501,0))*IF($L7="",1,$L7),"")) -> 13110 | U7: =IF(OR($J7="",$F7="不适用"),"",IFERROR(INDEX(_怪物模型!$F$2:$F$4501,MATCH(INT($J7)&"|"&$F7,_怪物模型!$A$2:$A$4501,0))*IF($M7="",1,$M7),"")) -> 12499 | V7: =IF($U7="","",MIN(0.75,$U7/($U7+24000))) -> 0.34244774 | W7: =IF($S7="","",$S7/(1-$V7)*IF($N7="",1,$N7)) -> 120985.06 | X7: =IF(OR($W7="",$Q7="",$Q7=0),"",$W7/$Q7) -> 0.30601103 | Y7: =IF(OR($R7="",$T7="",$T7=0),"",$R7/($T7*IF($O7="",1,$O7))) -> 55.088882 | Z7: =IF(OR($X7="",$P7="",$P7=0),"",$X7/$P7) | AA7: =IF($J7="","待填怪物等级",IF(OR($I7="",$Q7=""),"待填对照关卡",IF($P7="","已计算",IF(AND($Y7<>"",$Y7<$X7),"生存不成立",IF($Z7<0.5,"碾压",IF($Z7<0.8,"偏简单",IF($Z7<=1.2,"适中",IF($Z7<=1.5,"偏难","过难")))))))) -> 已计算 | AB7: =IF($J7="","待填",IF(AND(ISNUMBER($J7),$J7>=1,$J7<=500,MOD($J7,1)=0),"有效","超范围")) -> 有效 | AC7: =IF(OR($J7="",ROW()=5,$B7<>$B6,$J6=""),"",IF($J7<$J6,"下降","")) | AD7: 高难1-3；通关5-15后统一开放｜修正版V4：对照S73，略高于开放基点S69/Lv194｜V4同步最新玩家曲线：Lv204→Lv191，保留原TTK/生存压力目标｜曲线同步20260811：Lv191→Lv164，保持原玩法定位与TTK/生存压力
A8: 当前配置 | B8: 困难主线 | C8: 第1章 | D8: 高难1-4 | E8: 110104 | F8: 普通怪 | G8: 74 | I8: =IF($H8="",$G8,$H8) -> 74 | J8: 150 | Q8: =IF($I8="","",IFERROR(INDEX(_玩家曲线!$H$2:$H$286,MATCH($I8,_玩家曲线!$A$2:$A$286,0)),"")) -> 408062.5 | R8: =IF($I8="","",IFERROR(INDEX(_玩家曲线!$I$2:$I$286,MATCH($I8,_玩家曲线!$A$2:$A$286,0)),"")) -> 742493.69 | S8: =IF(OR($J8="",$F8="不适用"),"",IFERROR(INDEX(_怪物模型!$D$2:$D$4501,MATCH(INT($J8)&"|"&$F8,_怪物模型!$A$2:$A$4501,0))*IF($K8="",1,$K8),"")) -> 81928 | T8: =IF(OR($J8="",$F8="不适用"),"",IFERROR(INDEX(_怪物模型!$E$2:$E$4501,MATCH(INT($J8)&"|"&$F8,_怪物模型!$A$2:$A$4501,0))*IF($L8="",1,$L8),"")) -> 13436 | U8: =IF(OR($J8="",$F8="不适用"),"",IFERROR(INDEX(_怪物模型!$F$2:$F$4501,MATCH(INT($J8)&"|"&$F8,_怪物模型!$A$2:$A$4501,0))*IF($M8="",1,$M8),"")) -> 12696 | V8: =IF($U8="","",MIN(0.75,$U8/($U8+24000))) -> 0.34597776 | W8: =IF($S8="","",$S8/(1-$V8)*IF($N8="",1,$N8)) -> 125267.91 | X8: =IF(OR($W8="",$Q8="",$Q8=0),"",$W8/$Q8) -> 0.30698217 | Y8: =IF(OR($R8="",$T8="",$T8=0),"",$R8/($T8*IF($O8="",1,$O8))) -> 55.261513 | Z8: =IF(OR($X8="",$P8="",$P8=0),"",$X8/$P8) | AA8: =IF($J8="","待填怪物等级",IF(OR($I8="",$Q8=""),"待填对照关卡",IF($P8="","已计算",IF(AND($Y8<>"",$Y8<$X8),"生存不成立",IF($Z8<0.5,"碾压",IF($Z8<0.8,"偏简单",IF($Z8<=1.2,"适中",IF($Z8<=1.5,"偏难","过难")))))))) -> 已计算 | AB8: =IF($J8="","待填",IF(AND(ISNUMBER($J8),$J8>=1,$J8<=500,MOD($J8,1)=0),"有效","超范围")) -> 有效 | AC8: =IF(OR($J8="",ROW()=5,$B8<>$B7,$J7=""),"",IF($J8<$J7,"下降","")) | AD8: 高难1-4；通关5-15后统一开放｜修正版V4：对照S74，略高于开放基点S69/Lv194｜V4同步最新玩家曲线：Lv206→Lv193，保留原TTK/生存压力目标｜曲线同步20260811：Lv193→Lv166，保持原玩法定位与TTK/生存压力
A9: 当前配置 | B9: 困难主线 | C9: 第1章 | D9: 高难1-5 | E9: 110105 | F9: 普通怪 | G9: 75 | I9: =IF($H9="",$G9,$H9) -> 75 | J9: 153 | Q9: =IF($I9="","",IFERROR(INDEX(_玩家曲线!$H$2:$H$286,MATCH($I9,_玩家曲线!$A$2:$A$286,0)),"")) -> 420796.71 | R9: =IF($I9="","",IFERROR(INDEX(_玩家曲线!$I$2:$I$286,MATCH($I9,_玩家曲线!$A$2:$A$286,0)),"")) -> 762708.81 | S9: =IF(OR($J9="",$F9="不适用"),"",IFERROR(INDEX(_怪物模型!$D$2:$D$4501,MATCH(INT($J9)&"|"&$F9,_怪物模型!$A$2:$A$4501,0))*IF($K9="",1,$K9),"")) -> 85582 | T9: =IF(OR($J9="",$F9="不适用"),"",IFERROR(INDEX(_怪物模型!$E$2:$E$4501,MATCH(INT($J9)&"|"&$F9,_怪物模型!$A$2:$A$4501,0))*IF($L9="",1,$L9),"")) -> 13934 | U9: =IF(OR($J9="",$F9="不适用"),"",IFERROR(INDEX(_怪物模型!$F$2:$F$4501,MATCH(INT($J9)&"|"&$F9,_怪物模型!$A$2:$A$4501,0))*IF($M9="",1,$M9),"")) -> 12992 | V9: =IF($U9="","",MIN(0.75,$U9/($U9+24000))) -> 0.35121107 | W9: =IF($S9="","",$S9/(1-$V9)*IF($N9="",1,$N9)) -> 131910.39 | X9: =IF(OR($W9="",$Q9="",$Q9=0),"",$W9/$Q9) -> 0.31347771 | Y9: =IF(OR($R9="",$T9="",$T9=0),"",$R9/($T9*IF($O9="",1,$O9))) -> 54.737248 | Z9: =IF(OR($X9="",$P9="",$P9=0),"",$X9/$P9) | AA9: =IF($J9="","待填怪物等级",IF(OR($I9="",$Q9=""),"待填对照关卡",IF($P9="","已计算",IF(AND($Y9<>"",$Y9<$X9),"生存不成立",IF($Z9<0.5,"碾压",IF($Z9<0.8,"偏简单",IF($Z9<=1.2,"适中",IF($Z9<=1.5,"偏难","过难")))))))) -> 已计算 | AB9: =IF($J9="","待填",IF(AND(ISNUMBER($J9),$J9>=1,$J9<=500,MOD($J9,1)=0),"有效","超范围")) -> 有效 | AC9: =IF(OR($J9="",ROW()=5,$B9<>$B8,$J8=""),"",IF($J9<$J8,"下降","")) | AD9: 高难1-5；通关5-15后统一开放｜修正版V4：对照S75，略高于开放基点S69/Lv194｜V4同步最新玩家曲线：Lv209→Lv196，保留原TTK/生存压力目标｜曲线同步20260811：Lv196→Lv169，保持原玩法定位与TTK/生存压力
A10: 当前配置 | B10: 困难主线 | C10: 第2章 | D10: 高难2-1 | E10: 110201 | F10: 普通怪 | G10: 76 | I10: =IF($H10="",$G10,$H10) -> 76 | J10: 154 | Q10: =IF($I10="","",IFERROR(INDEX(_玩家曲线!$H$2:$H$286,MATCH($I10,_玩家曲线!$A$2:$A$286,0)),"")) -> 433557.75 | R10: =IF($I10="","",IFERROR(INDEX(_玩家曲线!$I$2:$I$286,MATCH($I10,_玩家曲线!$A$2:$A$286,0)),"")) -> 782852.42 | S10: =IF(OR($J10="",$F10="不适用"),"",IFERROR(INDEX(_怪物模型!$D$2:$D$4501,MATCH(INT($J10)&"|"&$F10,_怪物模型!$A$2:$A$4501,0))*IF($K10="",1,$K10),"")) -> 86825 | T10: =IF(OR($J10="",$F10="不适用"),"",IFERROR(INDEX(_怪物模型!$E$2:$E$4501,MATCH(INT($J10)&"|"&$F10,_怪物模型!$A$2:$A$4501,0))*IF($L10="",1,$L10),"")) -> 14102 | U10: =IF(OR($J10="",$F10="不适用"),"",IFERROR(INDEX(_怪物模型!$F$2:$F$4501,MATCH(INT($J10)&"|"&$F10,_怪物模型!$A$2:$A$4501,0))*IF($M10="",1,$M10),"")) -> 13091 | V10: =IF($U10="","",MIN(0.75,$U10/($U10+24000))) -> 0.35294276 | W10: =IF($S10="","",$S10/(1-$V10)*IF($N10="",1,$N10)) -> 134184.42 | X10: =IF(OR($W10="",$Q10="",$Q10=0),"",$W10/$Q10) -> 0.30949607 | Y10: =IF(OR($R10="",$T10="",$T10=0),"",$R10/($T10*IF($O10="",1,$O10))) -> 55.513574 | Z10: =IF(OR($X10="",$P10="",$P10=0),"",$X10/$P10) | AA10: =IF($J10="","待填怪物等级",IF(OR($I10="",$Q10=""),"待填对照关卡",IF($P10="","已计算",IF(AND($Y10<>"",$Y10<$X10),"生存不成立",IF($Z10<0.5,"碾压",IF($Z10<0.8,"偏简单",IF($Z10<=1.2,"适中",IF($Z10<=1.5,"偏难","过难")))))))) -> 已计算 | AB10: =IF($J10="","待填",IF(AND(ISNUMBER($J10),$J10>=1,$J10<=500,MOD($J10,1)=0),"有效","超范围")) -> 有效 | AC10: =IF(OR($J10="",ROW()=5,$B10<>$B9,$J9=""),"",IF($J10<$J9,"下降","")) | AD10: 高难2-1；通关5-15后统一开放｜修正版V4：对照S76，略高于开放基点S69/Lv194｜V4同步最新玩家曲线：Lv211→Lv198，保留原TTK/生存压力目标｜曲线同步20260811：Lv198→Lv170，保持原玩法定位与TTK/生存压力
A11: 当前配置 | B11: 困难主线 | C11: 第2章 | D11: 高难2-2 | E11: 110202 | F11: 普通怪 | G11: 77 | I11: =IF($H11="",$G11,$H11) -> 77 | J11: 155 | Q11: =IF($I11="","",IFERROR(INDEX(_玩家曲线!$H$2:$H$286,MATCH($I11,_玩家曲线!$A$2:$A$286,0)),"")) -> 446339.12 | R11: =IF($I11="","",IFERROR(INDEX(_玩家曲线!$I$2:$I$286,MATCH($I11,_玩家曲线!$A$2:$A$286,0)),"")) -> 802916.73 | S11: =IF(OR($J11="",$F11="不适用"),"",IFERROR(INDEX(_怪物模型!$D$2:$D$4501,MATCH(INT($J11)&"|"&$F11,_怪物模型!$A$2:$A$4501,0))*IF($K11="",1,$K11),"")) -> 88082 | T11: =IF(OR($J11="",$F11="不适用"),"",IFERROR(INDEX(_怪物模型!$E$2:$E$4501,MATCH(INT($J11)&"|"&$F11,_怪物模型!$A$2:$A$4501,0))*IF($L11="",1,$L11),"")) -> 14272 | U11: =IF(OR($J11="",$F11="不适用"),"",IFERROR(INDEX(_怪物模型!$F$2:$F$4501,MATCH(INT($J11)&"|"&$F11,_怪物模型!$A$2:$A$4501,0))*IF($M11="",1,$M11),"")) -> 13190 | V11: =IF($U11="","",MIN(0.75,$U11/($U11+24000))) -> 0.35466523 | W11: =IF($S11="","",$S11/(1-$V11)*IF($N11="",1,$N11)) -> 136490.4 | X11: =IF(OR($W11="",$Q11="",$Q11=0),"",$W11/$Q11) -> 0.30579977 | Y11: =IF(OR($R11="",$T11="",$T11=0),"",$R11/($T11*IF($O11="",1,$O11))) -> 56.258179 | Z11: =IF(OR($X11="",$P11="",$P11=0),"",$X11/$P11) | AA11: =IF($J11="","待填怪物等级",IF(OR($I11="",$Q11=""),"待填对照关卡",IF($P11="","已计算",IF(AND($Y11<>"",$Y11<$X11),"生存不成立",IF($Z11<0.5,"碾压",IF($Z11<0.8,"偏简单",IF($Z11<=1.2,"适中",IF($Z11<=1.5,"偏难","过难")))))))) -> 已计算 | AB11: =IF($J11="","待填",IF(AND(ISNUMBER($J11),$J11>=1,$J11<=500,MOD($J11,1)=0),"有效","超范围")) -> 有效 | AC11: =IF(OR($J11="",ROW()=5,$B11<>$B10,$J10=""),"",IF($J11<$J10,"下降","")) | AD11: 高难2-2；通关5-15后统一开放｜修正版V4：对照S77，略高于开放基点S69/Lv194｜V4同步最新玩家曲线：Lv213→Lv199，保留原TTK/生存压力目标｜曲线同步20260811：Lv199→Lv171，保持原玩法定位与TTK/生存压力
A12: 当前配置 | B12: 困难主线 | C12: 第2章 | D12: 高难2-3 | E12: 110203 | F12: 普通怪 | G12: 78 | I12: =IF($H12="",$G12,$H12) -> 78 | J12: 157 | Q12: =IF($I12="","",IFERROR(INDEX(_玩家曲线!$H$2:$H$286,MATCH($I12,_玩家曲线!$A$2:$A$286,0)),"")) -> 459134.48 | R12: =IF($I12="","",IFERROR(INDEX(_玩家曲线!$I$2:$I$286,MATCH($I12,_玩家曲线!$A$2:$A$286,0)),"")) -> 822894.29 | S12: =IF(OR($J12="",$F12="不适用"),"",IFERROR(INDEX(_怪物模型!$D$2:$D$4501,MATCH(INT($J12)&"|"&$F12,_怪物模型!$A$2:$A$4501,0))*IF($K12="",1,$K12),"")) -> 90633 | T12: =IF(OR($J12="",$F12="不适用"),"",IFERROR(INDEX(_怪物模型!$E$2:$E$4501,MATCH(INT($J12)&"|"&$F12,_怪物模型!$A$2:$A$4501,0))*IF($L12="",1,$L12),"")) -> 14616 | U12: =IF(OR($J12="",$F12="不适用"),"",IFERROR(INDEX(_怪物模型!$F$2:$F$4501,MATCH(INT($J12)&"|"&$F12,_怪物模型!$A$2:$A$4501,0))*IF($M12="",1,$M12),"")) -> 13390 | V12: =IF($U12="","",MIN(0.75,$U12/($U12+24000))) -> 0.35811714 | W12: =IF($S12="","",$S12/(1-$V12)*IF($N12="",1,$N12)) -> 141198.66 | X12: =IF(OR($W12="",$Q12="",$Q12=0),"",$W12/$Q12) -> 0.30753225 | Y12: =IF(OR($R12="",$T12="",$T12=0),"",$R12/($T12*IF($O12="",1,$O12))) -> 56.300923 | Z12: =IF(OR($X12="",$P12="",$P12=0),"",$X12/$P12) | AA12: =IF($J12="","待填怪物等级",IF(OR($I12="",$Q12=""),"待填对照关卡",IF($P12="","已计算",IF(AND($Y12<>"",$Y12<$X12),"生存不成立",IF($Z12<0.5,"碾压",IF($Z12<0.8,"偏简单",IF($Z12<=1.2,"适中",IF($Z12<=1.5,"偏难","过难")))))))) -> 已计算 | AB12: =IF($J12="","待填",IF(AND(ISNUMBER($J12),$J12>=1,$J12<=500,MOD($J12,1)=0),"有效","超范围")) -> 有效 | AC12: =IF(OR($J12="",ROW()=5,$B12<>$B11,$J11=""),"",IF($J12<$J11,"下降","")) | AD12: 高难2-3；通关5-15后统一开放｜修正版V4：对照S78，略高于开放基点S69/Lv194｜V4同步最新玩家曲线：Lv215→Lv201，保留原TTK/生存压力目标｜曲线同步20260811：Lv201→Lv173，保持原玩法定位与TTK/生存压力
A13: 当前配置 | B13: 困难主线 | C13: 第2章 | D13: 高难2-4 | E13: 110204 | F13: 普通怪 | G13: 79 | I13: =IF($H13="",$G13,$H13) -> 79 | J13: 157 | Q13: =IF($I13="","",IFERROR(INDEX(_玩家曲线!$H$2:$H$286,MATCH($I13,_玩家曲线!$A$2:$A$286,0)),"")) -> 471937.64 | R13: =IF($I13="","",IFERROR(INDEX(_玩家曲线!$I$2:$I$286,MATCH($I13,_玩家曲线!$A$2:$A$286,0)),"")) -> 842778.01 | S13: =IF(OR($J13="",$F13="不适用"),"",IFERROR(INDEX(_怪物模型!$D$2:$D$4501,MATCH(INT($J13)&"|"&$F13,_怪物模型!$A$2:$A$4501,0))*IF($K13="",1,$K13),"")) -> 90633 | T13: =IF(OR($J13="",$F13="不适用"),"",IFERROR(INDEX(_怪物模型!$E$2:$E$4501,MATCH(INT($J13)&"|"&$F13,_怪物模型!$A$2:$A$4501,0))*IF($L13="",1,$L13),"")) -> 14616 | U13: =IF(OR($J13="",$F13="不适用"),"",IFERROR(INDEX(_怪物模型!$F$2:$F$4501,MATCH(INT($J13)&"|"&$F13,_怪物模型!$A$2:$A$4501,0))*IF($M13="",1,$M13),"")) -> 13390 | V13: =IF($U13="","",MIN(0.75,$U13/($U13+24000))) -> 0.35811714 | W13: =IF($S13="","",$S13/(1-$V13)*IF($N13="",1,$N13)) -> 141198.66 | X13: =IF(OR($W13="",$Q13="",$Q13=0),"",$W13/$Q13) -> 0.29918923 | Y13: =IF(OR($R13="",$T13="",$T13=0),"",$R13/($T13*IF($O13="",1,$O13))) -> 57.661331 | Z13: =IF(OR($X13="",$P13="",$P13=0),"",$X13/$P13) | AA13: =IF($J13="","待填怪物等级",IF(OR($I13="",$Q13=""),"待填对照关卡",IF($P13="","已计算",IF(AND($Y13<>"",$Y13<$X13),"生存不成立",IF($Z13<0.5,"碾压",IF($Z13<0.8,"偏简单",IF($Z13<=1.2,"适中",IF($Z13<=1.5,"偏难","过难")))))))) -> 已计算 | AB13: =IF($J13="","待填",IF(AND(ISNUMBER($J13),$J13>=1,$J13<=500,MOD($J13,1)=0),"有效","超范围")) -> 有效 | AC13: =IF(OR($J13="",ROW()=5,$B13<>$B12,$J12=""),"",IF($J13<$J12,"下降","")) | AD13: 高难2-4；通关5-15后统一开放｜修正版V4：对照S79，略高于开放基点S69/Lv194｜V4同步最新玩家曲线：Lv217→Lv203，保留原TTK/生存压力目标｜曲线同步20260811：Lv203→Lv174，保持原玩法定位与TTK/生存压力
A14: 当前配置 | B14: 困难主线 | C14: 第2章 | D14: 高难2-5 | E14: 110205 | F14: 普通怪 | G14: 80 | I14: =IF($H14="",$G14,$H14) -> 80 | J14: 159 | Q14: =IF($I14="","",IFERROR(INDEX(_玩家曲线!$H$2:$H$286,MATCH($I14,_玩家曲线!$A$2:$A$286,0)),"")) -> 484742.58 | R14: =IF($I14="","",IFERROR(INDEX(_玩家曲线!$I$2:$I$286,MATCH($I14,_玩家曲线!$A$2:$A$286,0)),"")) -> 862561.14 | S14: =IF(OR($J14="",$F14="不适用"),"",IFERROR(INDEX(_怪物模型!$D$2:$D$4501,MATCH(INT($J14)&"|"&$F14,_怪物模型!$A$2:$A$4501,0))*IF($K14="",1,$K14),"")) -> 93238 | T14: =IF(OR($J14="",$F14="不适用"),"",IFERROR(INDEX(_怪物模型!$E$2:$E$4501,MATCH(INT($J14)&"|"&$F14,_怪物模型!$A$2:$A$4501,0))*IF($L14="",1,$L14),"")) -> 14964 | U14: =IF(OR($J14="",$F14="不适用"),"",IFERROR(INDEX(_怪物模型!$F$2:$F$4501,MATCH(INT($J14)&"|"&$F14,_怪物模型!$A$2:$A$4501,0))*IF($M14="",1,$M14),"")) -> 13589 | V14: =IF($U14="","",MIN(0.75,$U14/($U14+24000))) -> 0.36151534 | W14: =IF($S14="","",$S14/(1-$V14)*IF($N14="",1,$N14)) -> 146030.13 | X14: =IF(OR($W14="",$Q14="",$Q14=0),"",$W14/$Q14) -> 0.30125295 | Y14: =IF(OR($R14="",$T14="",$T14=0),"",$R14/($T14*IF($O14="",1,$O14))) -> 57.642418 | Z14: =IF(OR($X14="",$P14="",$P14=0),"",$X14/$P14) | AA14: =IF($J14="","待填怪物等级",IF(OR($I14="",$Q14=""),"待填对照关卡",IF($P14="","已计算",IF(AND($Y14<>"",$Y14<$X14),"生存不成立",IF($Z14<0.5,"碾压",IF($Z14<0.8,"偏简单",IF($Z14<=1.2,"适中",IF($Z14<=1.5,"偏难","过难")))))))) -> 已计算 | AB14: =IF($J14="","待填",IF(AND(ISNUMBER($J14),$J14>=1,$J14<=500,MOD($J14,1)=0),"有效","超范围")) -> 有效 | AC14: =IF(OR($J14="",ROW()=5,$B14<>$B13,$J13=""),"",IF($J14<$J13,"下降","")) | AD14: 高难2-5；通关5-15后统一开放｜修正版V4：对照S80，略高于开放基点S69/Lv194｜V4同步最新玩家曲线：Lv219→Lv205，保留原TTK/生存压力目标｜曲线同步20260811：Lv205→Lv176，保持原玩法定位与TTK/生存压力
A15: 当前配置 | B15: 困难主线 | C15: 第3章 | D15: 高难3-1 | E15: 110301 | F15: 普通怪 | G15: 81 | I15: =IF($H15="",$G15,$H15) -> 81 | J15: 161 | Q15: =IF($I15="","",IFERROR(INDEX(_玩家曲线!$H$2:$H$286,MATCH($I15,_玩家曲线!$A$2:$A$286,0)),"")) -> 497543.42 | R15: =IF($I15="","",IFERROR(INDEX(_玩家曲线!$I$2:$I$286,MATCH($I15,_玩家曲线!$A$2:$A$286,0)),"")) -> 882237.26 | S15: =IF(OR($J15="",$F15="不适用"),"",IFERROR(INDEX(_怪物模型!$D$2:$D$4501,MATCH(INT($J15)&"|"&$F15,_怪物模型!$A$2:$A$4501,0))*IF($K15="",1,$K15),"")) -> 95895 | T15: =IF(OR($J15="",$F15="不适用"),"",IFERROR(INDEX(_怪物模型!$E$2:$E$4501,MATCH(INT($J15)&"|"&$F15,_怪物模型!$A$2:$A$4501,0))*IF($L15="",1,$L15),"")) -> 15318 | U15: =IF(OR($J15="",$F15="不适用"),"",IFERROR(INDEX(_怪物模型!$F$2:$F$4501,MATCH(INT($J15)&"|"&$F15,_怪物模型!$A$2:$A$4501,0))*IF($M15="",1,$M15),"")) -> 13790 | V15: =IF($U15="","",MIN(0.75,$U15/($U15+24000))) -> 0.36491135 | W15: =IF($S15="","",$S15/(1-$V15)*IF($N15="",1,$N15)) -> 150994.67 | X15: =IF(OR($W15="",$Q15="",$Q15=0),"",$W15/$Q15) -> 0.30348039 | Y15: =IF(OR($R15="",$T15="",$T15=0),"",$R15/($T15*IF($O15="",1,$O15))) -> 57.594808 | Z15: =IF(OR($X15="",$P15="",$P15=0),"",$X15/$P15) | AA15: =IF($J15="","待填怪物等级",IF(OR($I15="",$Q15=""),"待填对照关卡",IF($P15="","已计算",IF(AND($Y15<>"",$Y15<$X15),"生存不成立",IF($Z15<0.5,"碾压",IF($Z15<0.8,"偏简单",IF($Z15<=1.2,"适中",IF($Z15<=1.5,"偏难","过难")))))))) -> 已计算 | AB15: =IF($J15="","待填",IF(AND(ISNUMBER($J15),$J15>=1,$J15<=500,MOD($J15,1)=0),"有效","超范围")) -> 有效 | AC15: =IF(OR($J15="",ROW()=5,$B15<>$B14,$J14=""),"",IF($J15<$J14,"下降","")) | AD15: 高难3-1；通关5-15后统一开放｜修正版V4：对照S81，略高于开放基点S69/Lv194｜V4同步最新玩家曲线：Lv221→Lv207，保留原TTK/生存压力目标｜曲线同步20260811：Lv207→Lv178，保持原玩法定位与TTK/生存压力
A16: 当前配置 | B16: 困难主线 | C16: 第3章 | D16: 高难3-2 | E16: 110302 | F16: 普通怪 | G16: 82 | I16: =IF($H16="",$G16,$H16) -> 82 | J16: 163 | Q16: =IF($I16="","",IFERROR(INDEX(_玩家曲线!$H$2:$H$286,MATCH($I16,_玩家曲线!$A$2:$A$286,0)),"")) -> 510334.47 | R16: =IF($I16="","",IFERROR(INDEX(_玩家曲线!$I$2:$I$286,MATCH($I16,_玩家曲线!$A$2:$A$286,0)),"")) -> 901800.29 | S16: =IF(OR($J16="",$F16="不适用"),"",IFERROR(INDEX(_怪物模型!$D$2:$D$4501,MATCH(INT($J16)&"|"&$F16,_怪物模型!$A$2:$A$4501,0))*IF($K16="",1,$K16),"")) -> 98607 | T16: =IF(OR($J16="",$F16="不适用"),"",IFERROR(INDEX(_怪物模型!$E$2:$E$4501,MATCH(INT($J16)&"|"&$F16,_怪物模型!$A$2:$A$4501,0))*IF($L16="",1,$L16),"")) -> 15677 | U16: =IF(OR($J16="",$F16="不适用"),"",IFERROR(INDEX(_怪物模型!$F$2:$F$4501,MATCH(INT($J16)&"|"&$F16,_怪物模型!$A$2:$A$4501,0))*IF($M16="",1,$M16),"")) -> 13991 | V16: =IF($U16="","",MIN(0.75,$U16/($U16+24000))) -> 0.36827143 | W16: =IF($S16="","",$S16/(1-$V16)*IF($N16="",1,$N16)) -> 156090.77 | X16: =IF(OR($W16="",$Q16="",$Q16=0),"",$W16/$Q16) -> 0.30585975 | Y16: =IF(OR($R16="",$T16="",$T16=0),"",$R16/($T16*IF($O16="",1,$O16))) -> 57.523779 | Z16: =IF(OR($X16="",$P16="",$P16=0),"",$X16/$P16) | AA16: =IF($J16="","待填怪物等级",IF(OR($I16="",$Q16=""),"待填对照关卡",IF($P16="","已计算",IF(AND($Y16<>"",$Y16<$X16),"生存不成立",IF($Z16<0.5,"碾压",IF($Z16<0.8,"偏简单",IF($Z16<=1.2,"适中",IF($Z16<=1.5,"偏难","过难")))))))) -> 已计算 | AB16: =IF($J16="","待填",IF(AND(ISNUMBER($J16),$J16>=1,$J16<=500,MOD($J16,1)=0),"有效","超范围")) -> 有效 | AC16: =IF(OR($J16="",ROW()=5,$B16<>$B15,$J15=""),"",IF($J16<$J15,"下降","")) | AD16: 高难3-2；通关5-15后统一开放｜修正版V4：对照S82，略高于开放基点S69/Lv194｜V4同步最新玩家曲线：Lv223→Lv209，保留原TTK/生存压力目标｜曲线同步20260811：Lv209→Lv180，保持原玩法定位与TTK/生存压力
... A39: 当前配置 | B39: 困难主线 | C39: 第7章 | D39: 高难7-5 | E39: 110705 | F39: 普通怪 | G39: 105 | I39: =IF($H39="",$G39,$H39) -> 105 | J39: 193 | Q39: =IF($I39="","",IFERROR(INDEX(_玩家曲线!$H$2:$H$286,MATCH($I39,_玩家曲线!$A$2:$A$286,0)),"")) -> 838451.03 | R39: =IF($I39="","",IFERROR(INDEX(_玩家曲线!$I$2:$I$286,MATCH($I39,_玩家曲线!$A$2:$A$286,0)),"")) -> 1356957.6 | S39: =IF(OR($J39="",$F39="不适用"),"",IFERROR(INDEX(_怪物模型!$D$2:$D$4501,MATCH(INT($J39)&"|"&$F39,_怪物模型!$A$2:$A$4501,0))*IF($K39="",1,$K39),"")) -> 146294 | T39: =IF(OR($J39="",$F39="不适用"),"",IFERROR(INDEX(_怪物模型!$E$2:$E$4501,MATCH(INT($J39)&"|"&$F39,_怪物模型!$A$2:$A$4501,0))*IF($L39="",1,$L39),"")) -> 21721 | U39: =IF(OR($J39="",$F39="不适用"),"",IFERROR(INDEX(_怪物模型!$F$2:$F$4501,MATCH(INT($J39)&"|"&$F39,_怪物模型!$A$2:$A$4501,0))*IF($M39="",1,$M39),"")) -> 17100 | V39: =IF($U39="","",MIN(0.75,$U39/($U39+24000))) -> 0.41605839 | W39: =IF($S39="","",$S39/(1-$V39)*IF($N39="",1,$N39)) -> 250528.48 | X39: =IF(OR($W39="",$Q39="",$Q39=0),"",$W39/$Q39) -> 0.29879917 | Y39: =IF(OR($R39="",$T39="",$T39=0),"",$R39/($T39*IF($O39="",1,$O39))) -> 62.472153 | Z39: =IF(OR($X39="",$P39="",$P39=0),"",$X39/$P39) | AA39: =IF($J39="","待填怪物等级",IF(OR($I39="",$Q39=""),"待填对照关卡",IF($P39="","已计算",IF(AND($Y39<>"",$Y39<$X39),"生存不成立",IF($Z39<0.5,"碾压",IF($Z39<0.8,"偏简单",IF($Z39<=1.2,"适中",IF($Z39<=1.5,"偏难","过难")))))))) -> 已计算 | AB39: =IF($J39="","待填",IF(AND(ISNUMBER($J39),$J39>=1,$J39<=500,MOD($J39,1)=0),"有效","超范围")) -> 有效 | AC39: =IF(OR($J39="",ROW()=5,$B39<>$B38,$J38=""),"",IF($J39<$J38,"下降","")) | AD39: 高难7-5；通关5-15后统一开放｜修正版V4：对照S105，略高于开放基点S69/Lv194｜V4同步最新玩家曲线：Lv261→Lv247，保留原TTK/生存压力目标｜曲线同步20260811：Lv247→Lv212，保持原玩法定位与TTK/生存压力

Sheet 角色经验
A1: 全玩法难度填写｜角色经验
A2: 当前页已按开启顺序和玩法定位填入首版怪物等级。黄色J列可直接覆盖；G列是本版使用的玩家曲线对照节点。
A3: 公式口径：怪物实际属性=战斗公式标准模型×可选系数；怪物EHP=实际生命÷(1-防御减伤)×整关EHP倍率；TTK=怪物EHP÷玩家DPS。
A4: 状态 | B4: 玩法 | C4: 子玩法/共用范围 | D4: 节点名称 | E4: LevelId/配置映射 | F4: 怪物类型 | G4: 默认对照关卡 | H4: 手动对照关卡 | I4: 实际对照关卡 | J4: 怪物等级 | K4: 生命系数 | L4: 攻击系数 | M4: 防御系数 | N4: 整关EHP倍率 | O4: 攻击压力倍率 | P4: 目标时间(s) | Q4: 玩家DPS | R4: 玩家队伍EHP | S4: 怪物实际生命 | T4: 怪物实际攻击 | U4: 怪物实际防御 | V4: 怪物减伤率 | W4: 整关目标EHP | X4: 预测TTK(s) | Y4: 预测存活(s) | Z4: TTK/目标 | AA4: 难度判断 | AB4: 等级检查 | AC4: 等级趋势 | AD4: 备注
A5: 当前配置 | B5: 角色经验 | C5: 资源副本 | D5: 难度1 | E5: 210001 | F5: 普通怪 | G5: 16 | I5: =IF($H5="",$G5,$H5) -> 16 | J5: 22 | Q5: =IF($I5="","",IFERROR(INDEX(_玩家曲线!$H$2:$H$286,MATCH($I5,_玩家曲线!$A$2:$A$286,0)),"")) -> 12775.033 | R5: =IF($I5="","",IFERROR(INDEX(_玩家曲线!$I$2:$I$286,MATCH($I5,_玩家曲线!$A$2:$A$286,0)),"")) -> 43484.78 | S5: =IF(OR($J5="",$F5="不适用"),"",IFERROR(INDEX(_怪物模型!$D$2:$D$4501,MATCH(INT($J5)&"|"&$F5,_怪物模型!$A$2:$A$4501,0))*IF($K5="",1,$K5),"")) -> 3288 | T5: =IF(OR($J5="",$F5="不适用"),"",IFERROR(INDEX(_怪物模型!$E$2:$E$4501,MATCH(INT($J5)&"|"&$F5,_怪物模型!$A$2:$A$4501,0))*IF($L5="",1,$L5),"")) -> 842 | U5: =IF(OR($J5="",$F5="不适用"),"",IFERROR(INDEX(_怪物模型!$F$2:$F$4501,MATCH(INT($J5)&"|"&$F5,_怪物模型!$A$2:$A$4501,0))*IF($M5="",1,$M5),"")) -> 1603 | V5: =IF($U5="","",MIN(0.75,$U5/($U5+24000))) -> 0.06260985 | W5: =IF($S5="","",$S5/(1-$V5)*IF($N5="",1,$N5)) -> 3507.611 | X5: =IF(OR($W5="",$Q5="",$Q5=0),"",$W5/$Q5) -> 0.27456767 | Y5: =IF(OR($R5="",$T5="",$T5=0),"",$R5/($T5*IF($O5="",1,$O5))) -> 51.644632 | Z5: =IF(OR($X5="",$P5="",$P5=0),"",$X5/$P5) | AA5: =IF($J5="","待填怪物等级",IF(OR($I5="",$Q5=""),"待填对照关卡",IF($P5="","已计算",IF(AND($Y5<>"",$Y5<$X5),"生存不成立",IF($Z5<0.5,"碾压",IF($Z5<0.8,"偏简单",IF($Z5<=1.2,"适中",IF($Z5<=1.5,"偏难","过难")))))))) -> 已计算 | AB5: =IF($J5="","待填",IF(AND(ISNUMBER($J5),$J5>=1,$J5<=500,MOD($J5,1)=0),"有效","超范围")) -> 有效 | AC5: =IF(OR($J5="",ROW()=5,$B5<>$B4,$J4=""),"",IF($J5<$J4,"下降","")) | AD5: 档位解锁Lv10；修正版V4：首档送进度，9档共用Lv27→180缓升；对照节点S16｜V4同步最新玩家曲线：Lv30→Lv27，保留原TTK/生存压力目标｜曲线同步20260811：Lv27→Lv25，保持原玩法定位与TTK/生存压力
A6: 当前配置 | B6: 角色经验 | C6: 资源副本 | D6: 难度2 | E6: 210002 | F6: 普通怪 | G6: 20 | I6: =IF($H6="",$G6,$H6) -> 20 | J6: 26 | Q6: =IF($I6="","",IFERROR(INDEX(_玩家曲线!$H$2:$H$286,MATCH($I6,_玩家曲线!$A$2:$A$286,0)),"")) -> 18422.066 | R6: =IF($I6="","",IFERROR(INDEX(_玩家曲线!$I$2:$I$286,MATCH($I6,_玩家曲线!$A$2:$A$286,0)),"")) -> 58659.121 | S6: =IF(OR($J6="",$F6="不适用"),"",IFERROR(INDEX(_怪物模型!$D$2:$D$4501,MATCH(INT($J6)&"|"&$F6,_怪物模型!$A$2:$A$4501,0))*IF($K6="",1,$K6),"")) -> 4140 | T6: =IF(OR($J6="",$F6="不适用"),"",IFERROR(INDEX(_怪物模型!$E$2:$E$4501,MATCH(INT($J6)&"|"&$F6,_怪物模型!$A$2:$A$4501,0))*IF($L6="",1,$L6),"")) -> 1028 | U6: =IF(OR($J6="",$F6="不适用"),"",IFERROR(INDEX(_怪物模型!$F$2:$F$4501,MATCH(INT($J6)&"|"&$F6,_怪物模型!$A$2:$A$4501,0))*IF($M6="",1,$M6),"")) -> 1904 | V6: =IF($U6="","",MIN(0.75,$U6/($U6+24000))) -> 0.073502162 | W6: =IF($S6="","",$S6/(1-$V6)*IF($N6="",1,$N6)) -> 4468.44 | X6: =IF(OR($W6="",$Q6="",$Q6=0),"",$W6/$Q6) -> 0.24255912 | Y6: =IF(OR($R6="",$T6="",$T6=0),"",$R6/($T6*IF($O6="",1,$O6))) -> 57.061402 | Z6: =IF(OR($X6="",$P6="",$P6=0),"",$X6/$P6) | AA6: =IF($J6="","待填怪物等级",IF(OR($I6="",$Q6=""),"待填对照关卡",IF($P6="","已计算",IF(AND($Y6<>"",$Y6<$X6),"生存不成立",IF($Z6<0.5,"碾压",IF($Z6<0.8,"偏简单",IF($Z6<=1.2,"适中",IF($Z6<=1.5,"偏难","过难")))))))) -> 已计算 | AB6: =IF($J6="","待填",IF(AND(ISNUMBER($J6),$J6>=1,$J6<=500,MOD($J6,1)=0),"有效","超范围")) -> 有效 | AC6: =IF(OR($J6="",ROW()=5,$B6<>$B5,$J5=""),"",IF($J6<$J5,"下降","")) | AD6: 档位解锁Lv15；修正版V4：首档送进度，9档共用Lv30→180缓升；对照节点S20｜V4同步最新玩家曲线：Lv41→Lv32，保留原TTK/生存压力目标｜曲线同步20260811：Lv32→Lv29，保持原玩法定位与TTK/生存压力
A7: 当前配置 | B7: 角色经验 | C7: 资源副本 | D7: 难度3 | E7: 210003 | F7: 普通怪 | G7: 33 | I7: =IF($H7="",$G7,$H7) -> 33 | J7: 39 | Q7: =IF($I7="","",IFERROR(INDEX(_玩家曲线!$H$2:$H$286,MATCH($I7,_玩家曲线!$A$2:$A$286,0)),"")) -> 55490.611 | R7: =IF($I7="","",IFERROR(INDEX(_玩家曲线!$I$2:$I$286,MATCH($I7,_玩家曲线!$A$2:$A$286,0)),"")) -> 145674.72 | S7: =IF(OR($J7="",$F7="不适用"),"",IFERROR(INDEX(_怪物模型!$D$2:$D$4501,MATCH(INT($J7)&"|"&$F7,_怪物模型!$A$2:$A$4501,0))*IF($K7="",1,$K7),"")) -> 7437 | T7: =IF(OR($J7="",$F7="不适用"),"",IFERROR(INDEX(_怪物模型!$E$2:$E$4501,MATCH(INT($J7)&"|"&$F7,_怪物模型!$A$2:$A$4501,0))*IF($L7="",1,$L7),"")) -> 1707 | U7: =IF(OR($J7="",$F7="不适用"),"",IFERROR(INDEX(_怪物模型!$F$2:$F$4501,MATCH(INT($J7)&"|"&$F7,_怪物模型!$A$2:$A$4501,0))*IF($M7="",1,$M7),"")) -> 2902 | V7: =IF($U7="","",MIN(0.75,$U7/($U7+24000))) -> 0.10787302 | W7: =IF($S7="","",$S7/(1-$V7)*IF($N7="",1,$N7)) -> 8336.2573 | X7: =IF(OR($W7="",$Q7="",$Q7=0),"",$W7/$Q7) -> 0.15022825 | Y7: =IF(OR($R7="",$T7="",$T7=0),"",$R7/($T7*IF($O7="",1,$O7))) -> 85.339612 | Z7: =IF(OR($X7="",$P7="",$P7=0),"",$X7/$P7) | AA7: =IF($J7="","待填怪物等级",IF(OR($I7="",$Q7=""),"待填对照关卡",IF($P7="","已计算",IF(AND($Y7<>"",$Y7<$X7),"生存不成立",IF($Z7<0.5,"碾压",IF($Z7<0.8,"偏简单",IF($Z7<=1.2,"适中",IF($Z7<=1.5,"偏难","过难")))))))) -> 已计算 | AB7: =IF($J7="","待填",IF(AND(ISNUMBER($J7),$J7>=1,$J7<=500,MOD($J7,1)=0),"有效","超范围")) -> 有效 | AC7: =IF(OR($J7="",ROW()=5,$B7<>$B6,$J6=""),"",IF($J7<$J6,"下降","")) | AD7: 档位解锁Lv20；修正版V4：首档送进度，9档共用Lv30→180缓升；对照节点S33｜V4同步最新玩家曲线：Lv57→Lv51，保留原TTK/生存压力目标｜曲线同步20260811：Lv51→Lv44，保持原玩法定位与TTK/生存压力
A8: 当前配置 | B8: 角色经验 | C8: 资源副本 | D8: 难度4 | E8: 210004 | F8: 普通怪 | G8: 48 | I8: =IF($H8="",$G8,$H8) -> 48 | J8: 49 | Q8: =IF($I8="","",IFERROR(INDEX(_玩家曲线!$H$2:$H$286,MATCH($I8,_玩家曲线!$A$2:$A$286,0)),"")) -> 151226.5 | R8: =IF($I8="","",IFERROR(INDEX(_玩家曲线!$I$2:$I$286,MATCH($I8,_玩家曲线!$A$2:$A$286,0)),"")) -> 327050.13 | S8: =IF(OR($J8="",$F8="不适用"),"",IFERROR(INDEX(_怪物模型!$D$2:$D$4501,MATCH(INT($J8)&"|"&$F8,_怪物模型!$A$2:$A$4501,0))*IF($K8="",1,$K8),"")) -> 10544 | T8: =IF(OR($J8="",$F8="不适用"),"",IFERROR(INDEX(_怪物模型!$E$2:$E$4501,MATCH(INT($J8)&"|"&$F8,_怪物模型!$A$2:$A$4501,0))*IF($L8="",1,$L8),"")) -> 2313 | U8: =IF(OR($J8="",$F8="不适用"),"",IFERROR(INDEX(_怪物模型!$F$2:$F$4501,MATCH(INT($J8)&"|"&$F8,_怪物模型!$A$2:$A$4501,0))*IF($M8="",1,$M8),"")) -> 3691 | V8: =IF($U8="","",MIN(0.75,$U8/($U8+24000))) -> 0.13329241 | W8: =IF($S8="","",$S8/(1-$V8)*IF($N8="",1,$N8)) -> 12165.579 | X8: =IF(OR($W8="",$Q8="",$Q8=0),"",$W8/$Q8) -> 0.08044608 | Y8: =IF(OR($R8="",$T8="",$T8=0),"",$R8/($T8*IF($O8="",1,$O8))) -> 141.39651 | Z8: =IF(OR($X8="",$P8="",$P8=0),"",$X8/$P8) | AA8: =IF($J8="","待填怪物等级",IF(OR($I8="",$Q8=""),"待填对照关卡",IF($P8="","已计算",IF(AND($Y8<>"",$Y8<$X8),"生存不成立",IF($Z8<0.5,"碾压",IF($Z8<0.8,"偏简单",IF($Z8<=1.2,"适中",IF($Z8<=1.5,"偏难","过难")))))))) -> 已计算 | AB8: =IF($J8="","待填",IF(AND(ISNUMBER($J8),$J8>=1,$J8<=500,MOD($J8,1)=0),"有效","超范围")) -> 有效 | AC8: =IF(OR($J8="",ROW()=5,$B8<>$B7,$J7=""),"",IF($J8<$J7,"下降","")) | AD8: 档位解锁Lv25；修正版V4：首档送进度，9档共用Lv30→180缓升；对照节点S48｜V4同步最新玩家曲线：Lv74→Lv67，保留原TTK/生存压力目标｜曲线同步20260811：Lv67→Lv56，保持原玩法定位与TTK/生存压力
A9: 当前配置 | B9: 角色经验 | C9: 资源副本 | D9: 难度5 | E9: 210005 | F9: 普通怪 | G9: 64 | I9: =IF($H9="",$G9,$H9) -> 64 | J9: 61 | Q9: =IF($I9="","",IFERROR(INDEX(_玩家曲线!$H$2:$H$286,MATCH($I9,_玩家曲线!$A$2:$A$286,0)),"")) -> 283724.7 | R9: =IF($I9="","",IFERROR(INDEX(_玩家曲线!$I$2:$I$286,MATCH($I9,_玩家曲线!$A$2:$A$286,0)),"")) -> 538396.24 | S9: =IF(OR($J9="",$F9="不适用"),"",IFERROR(INDEX(_怪物模型!$D$2:$D$4501,MATCH(INT($J9)&"|"&$F9,_怪物模型!$A$2:$A$4501,0))*IF($K9="",1,$K9),"")) -> 14981 | T9: =IF(OR($J9="",$F9="不适用"),"",IFERROR(INDEX(_怪物模型!$E$2:$E$4501,MATCH(INT($J9)&"|"&$F9,_怪物模型!$A$2:$A$4501,0))*IF($L9="",1,$L9),"")) -> 3140 | U9: =IF(OR($J9="",$F9="不适用"),"",IFERROR(INDEX(_怪物模型!$F$2:$F$4501,MATCH(INT($J9)&"|"&$F9,_怪物模型!$A$2:$A$4501,0))*IF($M9="",1,$M9),"")) -> 4663 | V9: =IF($U9="","",MIN(0.75,$U9/($U9+24000))) -> 0.1626836 | W9: =IF($S9="","",$S9/(1-$V9)*IF($N9="",1,$N9)) -> 17891.683 | X9: =IF(OR($W9="",$Q9="",$Q9=0),"",$W9/$Q9) -> 0.063060014 | Y9: =IF(OR($R9="",$T9="",$T9=0),"",$R9/($T9*IF($O9="",1,$O9))) -> 171.46377 | Z9: =IF(OR($X9="",$P9="",$P9=0),"",$X9/$P9) | AA9: =IF($J9="","待填怪物等级",IF(OR($I9="",$Q9=""),"待填对照关卡",IF($P9="","已计算",IF(AND($Y9<>"",$Y9<$X9),"生存不成立",IF($Z9<0.5,"碾压",IF($Z9<0.8,"偏简单",IF($Z9<=1.2,"适中",IF($Z9<=1.5,"偏难","过难")))))))) -> 已计算 | AB9: =IF($J9="","待填",IF(AND(ISNUMBER($J9),$J9>=1,$J9<=500,MOD($J9,1)=0),"有效","超范围")) -> 有效 | AC9: =IF(OR($J9="",ROW()=5,$B9<>$B8,$J8=""),"",IF($J9<$J8,"下降","")) | AD9: 档位解锁Lv30；修正版V4：首档送进度，9档共用Lv30→180缓升；对照节点S64｜V4同步最新玩家曲线：Lv93→Lv85，保留原TTK/生存压力目标｜曲线同步20260811：Lv85→Lv70，保持原玩法定位与TTK/生存压力
