Workbook

Sheet 战斗公式
B3: 战斗计算规则
B5: 攻击行为
B7: 流程1 | C7: 每次攻击先判定是否命中
B9: 命中概率为=（攻击者命中 - 受击者闪避）， 如果数值大于等于1则必然命中，数值小于等于X则取最小命中概率X，在0-1之间随机，X为10%
B10: 技能未命中的情况默认不触发后续机制，除非有特殊说明
B13: 流程2 | C13: 进行伤害类型的判断
B15: 真实伤害
B16: 不进行伤害公式计算，不受护盾影响，直接扣除给定数值的生命（百分比or固定值）
B18: 物理伤害or魔法伤害
B19: 走以下伤害数值的计算
B21: 流程3 | C21: 计算初步伤害数值
B24: 伤害基数=带入伤害公式的数值，在子弹或攻击组件中计算得出
B25: 物理伤害/魔法伤害取决于伤害组件的配置，公式相同，作为逻辑标签使用
B26: 伤害=伤害基数*[（1-(受击者 防御*（1 - 攻击者 无视防御）/【(受击者 防御 *（1- 攻击者 无视防御）+X)】，X为常数根据需求调整（可配置在全局表中），最低伤害保底：伤害基数 * 5%
L27: X的值为 | M27: 24000
B28: 流程4 | C28: 判断是否暴击
B30: 由攻击者 暴击率 属性决定 ，数值大于等于1必暴击，数值小于等于0必不暴击
B31: 命中后判定暴击
B32: 如果勾选必定暴击，则判断为暴击，如果没勾选，则进行随机
B33: 如果暴击
B34: 暴击伤害 = 伤害 * 攻击者暴击伤害
B37: 流程5 | C37: 判断是否格挡 | E37: 如果既格挡又暴击，则在表现上只显示格挡
B39: 由攻击者 破击率 属性决定和防御者格挡率决定是否触发格挡
B40: 格挡概率=受击者格挡率-攻击者破击率，最低为0，最高为1
B41: 如果格挡
B42: 格挡后伤害=计算暴击后的伤害*(1-基础格挡伤害X-格挡强度）
D43: X | E43: 0.5
D44: 格挡强度∈【0,1】
B45: 举例
B46: 受击者的格挡强度为20%，受击者计算完暴击后，应该受到的伤害为1000，此时触发了格挡
B47: 触发格挡后，受到的伤害为1000*（1-50-20%）=300
B53: 流程6 | C53: 计算最终伤害
B54: 最终伤害 =
B55: 计算完暴击、格挡后伤害 *（1+ 攻击者 伤害加成）*（1 - 受击者 伤害减免）*（1 + 受击者受到伤害增加）*（1+ 攻击者 玩法伤害加成）*（1 - 受击者 玩法伤害减免）
B58: 所有类型的伤害加成的乘区相同
B59: 例如：A角色拥有10%伤害增加，20%单体伤害增加，30%群体伤害增加，40%技能伤害增加，50%必杀伤害增加，60%的物理伤害增加和70%的魔法伤害增加
B60: 那么他放单体物理技能时的伤害增加值为10%+20%+40%+60%=130%
B61: 那么他放群体魔法必杀时的伤害增加值为10%+30%+50%+70%=160%
B63: 公式中 受击者 伤害减免属性 计算结果 最大不超过X%，X为75
B64: 最终伤害数值保底为X,X为1
...

Sheet 预计投放属性数值
A2: 角色基础属性拍定 | B2: 生命 | C2: 攻击 | D2: 防御
B3: 5000 | C3: 1500 | D3: 1000
A4: 基础属性比例 | B4: 10 | C4: 3 | D4: 2
A6: 角色基础属性投放预计
B7: 裸体属性 | F7: 额外属性
B8: 初始属性 | C8: 升级属性 | D8: 升阶属性 | E8: 星盘属性 | F8: 收容物属性 | G8: 旅券 | H8: 主角装备属性 | I8: 房车养成
A9: 基础属性投放系数 | B9: 1 | C9: 4.2 | D9: 1.2 | E9: 1.5 | F9: 8 | G9: 6 | H9: 10 | I9: 5
B11: 裸体总和 | C11: 额外总和
B12: =SUM(B9:E9) -> 7.9 | C12: =SUM(F9:I9) -> 29
A14: 角色基础裸体属性 | B14: 生命 | C14: 攻击 | D14: 防御
B15: =$B$12*B3 -> 39500 | C15: =$B$12*C3 -> 11850 | D15: =$B$12*D3 -> 7900
A17: 角色额外属性 | B17: 生命 | C17: 攻击 | D17: 防御
B18: =$C$12*B3 -> 145000 | C18: =$C$12*C3 -> 43500 | D18: =$C$12*D3 -> 29000
A20: 角色总属性 | B20: 生命 | C20: 攻击 | D20: 防御
B21: =B15+B18 -> 184500 | C21: =C15*(1+C67)+C18 -> 98010 | D21: =D15+D18 -> 36900
B24: 战斗系数组成
B26: 普攻 | C26: 1 | D26: /s
B27: 必杀 | C27: 0.55 | D27: /s
B28: 技能 | C28: 0.4 | D28: /s
B29: 总和 | C29: =C28+C27+C26 -> 1.95 | D29: /s
B31: boss对战能量上限 | C31: 750
B32: 必杀能量上限 | C32: 1000 | D32: 必杀回复速度 | E32: 25 | F32: /s
B33: 技能释放间隔 | C33: 10 | D33: s
B34: 技能系数 | C34: =C33*C28 -> 4
B35: 技能数量 | C35: 2
B36: 单个技能系数 | C36: =C34/C35 -> 2
B38: 技能系数拆分
B39: 普攻 | C39: 必杀 | D39: 技能、能效
A40: 1 | B40: 0.5 | C40: 0.5 | D40: 0.5
A41: 2 | B41: 0.65 | C41: 0.65 | D41: 0.75
A42: 3 | B42: 0.8 | C42: 0.8 | D42: 1
A43: 4 | B43: 1 | C43: 1
B46: 必杀回复速度 | C46: 25 | D46: /s
B47: 必杀系数 | C47: =C31/E32*C27 -> 16.5
B49: 40 | C49: 秒伤害系数 | D49: 伤害占比
B50: 普攻伤害 | C50: =$B$49*C26 -> 40 | D50: =C50/$C$53 -> 0.51282051
B51: 必杀系数 | C51: =$B$49*C27 -> 22 | D51: =C51/$C$53 -> 0.28205128
B52: 技能伤害 | C52: =$B$49*C28 -> 16 | D52: =C52/$C$53 -> 0.20512821
C53: =SUM(C50:C52) -> 78
B55: 额外效果提升比例 | C55: 升星天赋 | D55: 0.5 | E55: =D55+1 -> 1.5
...

Sheet 怪物标准模型
B2: 怪物标准模型等级
B3: 500
C4: 生命 | D4: 攻击 | E4: 防御 | F4: 生命 | G4: 攻击 | H4: 防御 | I4: 生命 | J4: 攻击 | K4: 防御 | O4: 普攻系数倍率 | P4: 技能系数倍率 | Q4: 必杀系数倍率 | R4: 战斗支持倍率 | S4: 暴击率 | T4: 暴击伤害 | U4: 普攻乘区 | V4: 必杀乘区 | W4: 技能乘区 | X4: 增伤乘区 | AH4: 人数系数 | AI4: 攻击系数修正 | AJ4: BOSS生命系数修正 | AK4: 小怪生命系数修正 | AL4: 小怪攻击系数修正
B5: 最低 | C5: =预计投放属性数值!B$15/$B$3 -> 79 | D5: =预计投放属性数值!C$15/$B$3 -> 23.7 | E5: =预计投放属性数值!D$15/$B$3 -> 15.8 | F5: =预计投放属性数值!B$18/$B$3 -> 290 | G5: =预计投放属性数值!C$18/$B$3 -> 87 | H5: =预计投放属性数值!D$18/$B$3 -> 58 | I5: 0 | J5: =预计投放属性数值!$C$67/$B$3 -> 0.0072 | K5: =预计投放属性数值!$C$67/$B$3 -> 0.0072 | O5: =O6*预计投放属性数值!$B$40 -> 0.5 | P5: 0 | Q5: =Q6*预计投放属性数值!$C$40 -> 0.275 | R5: 1 | S5: 0 | T5: =预计投放属性数值!D66 -> 2 | U5: 1 | V5: 1 | W5: 1 | X5: 1 | AH5: 1 | AI5: 0.5 | AJ5: 2.15 | AK5: 1.8 | AL5: 0.8
B6: 最高 | C6: =预计投放属性数值!B$15 -> 39500 | D6: =预计投放属性数值!C$15 -> 11850 | E6: =预计投放属性数值!D$15 -> 7900 | F6: =预计投放属性数值!B$18 -> 145000 | G6: =预计投放属性数值!C$18 -> 43500 | H6: =预计投放属性数值!D$18 -> 29000 | I6: 0 | J6: =预计投放属性数值!$C$67 -> 3.6 | K6: =预计投放属性数值!$C$67 -> 3.6 | O6: =预计投放属性数值!C26 -> 1 | P6: =预计投放属性数值!C28 -> 0.4 | Q6: =预计投放属性数值!C27 -> 0.55 | R6: =预计投放属性数值!D62 -> 1.2 | S6: =预计投放属性数值!C65 -> 0.7 | T6: =预计投放属性数值!E66 -> 3.95 | U6: =1+预计投放属性数值!K68 -> 1 | V6: =1+预计投放属性数值!K69 -> 1.5452991 | W6: =预计投放属性数值!K70+1 -> 1.3076923 | X6: =1+预计投放属性数值!E71 -> 2.6 | AH6: 5 | AI6: 2.3 | AJ6: 1 | AK6: 1 | AL6: 0.95
B7: 曲率 | C7: 0.999999 | D7: 0.999999 | E7: 0.999999 | F7: 0.999999 | G7: 0.999999 | H7: 0.999999 | I7: 0.999999 | J7: 0.999999 | K7: 0.999999 | O7: 0.999999 | P7: 1.0015 | Q7: 0.999999 | R7: 0.999999 | S7: 0.999999 | T7: 0.999999 | U7: 0.999999 | V7: 0.999999 | W7: 0.999999 | X7: 0.999999 | AH7: 0.9925 | AI7: 1.002 | AJ7: 0.95 | AK7: 0.98 | AL7: 0.997 | AS7: 普通怪 | AT7: 普通盾怪 | AU7: 2级普通怪 | AV7: 站桩怪 | AW7: 炮灰怪 | AX7: 精英怪 | AY7: 精英盾怪 | AZ7: BOSS | BA7: 装备副本BOSS
AM9: BOSS | AP9: 小怪 | AS9: TTK时间 | AT9: TTK时间 | AU9: TTK时间 | AV9: TTK时间 | AW9: TTK时间 | AX9: TTK时间 | AY9: TTK时间 | AZ9: TTK时间 | BA9: TTK时间
C10: 裸体基础属性 | F10: 额外基础属性 | I10: 基础属性百分比 | L10: 算百分比后基础 | O10: 生命放大倍率 | AA10: 最终基础属性 | AM10: 单位秒，最终基础属性 | AP10: 单位秒，最终基础属性 | AS10: 1 | AT10: 3 | AU10: 1.8 | AV10: 0.5 | AW10: 0.15 | AX10: 4 | AY10: 9 | AZ10: 60 | BA10: 30
B11: 等级 | C11: 生命 | D11: 攻击 | E11: 防御 | F11: 生命 | G11: 攻击 | H11: 防御 | I11: 生命 | J11: 攻击 | K11: 防御 | L11: 生命 | M11: 攻击 | N11: 防御 | O11: 普攻系数倍率 | P11: 技能系数倍率 | Q11: 必杀系数倍率 | R11: 战斗支持倍率 | S11: 暴击率 | T11: 暴击伤害 | U11: 普攻乘区 | V11: 必杀乘区 | W11: 技能乘区 | X11: 增伤乘区 | Y11: 无必杀增伤倍率 | Z11: 有必杀增伤倍率 | AA11: 生命 | AB11: 攻击 | AC11: 防御 | AD11: 减伤率 | AE11: ehp | AF11: 无必杀TTK（单位/秒） | AG11: TTK（单位/秒） | AH11: 人数系数 | AI11: 攻击系数修正 | AJ11: BOSS生命系数修正 | AK11: 小怪生命系数修正 | AL11: 小怪攻击系数修正 | AM11: 生命 | AN11: 攻击 | AO11: 防御 | AP11: 生命 | AQ11: 攻击 | AS11: 生命 | AT11: 生命 | AU11: 生命 | AV11: 生命 | AW11: 生命 | AX11: 生命 | AY11: 生命 | AZ11: 生命 | BA11: 生命 | BC11: 等级
B12: {=_xlfn.SEQUENCE(B3,1,1,1)} -> 1 | C12: =C$5+(C$6-C$5)*(POWER(C$7,$B12-1)-1)/(POWER(C$7,$B$3-1)-1) -> 79 | D12: =D$5+(D$6-D$5)*(POWER(D$7,$B12-1)-1)/(POWER(D$7,$B$3-1)-1) -> 23.7 | E12: =E$5+(E$6-E$5)*(POWER(E$7,$B12-1)-1)/(POWER(E$7,$B$3-1)-1) -> 15.8 | F12: =F$5+(F$6-F$5)*(POWER(F$7,$B12-1)-1)/(POWER(F$7,$B$3-1)-1) -> 290 | G12: =G$5+(G$6-G$5)*(POWER(G$7,$B12-1)-1)/(POWER(G$7,$B$3-1)-1) -> 87 | H12: =H$5+(H$6-H$5)*(POWER(H$7,$B12-1)-1)/(POWER(H$7,$B$3-1)-1) -> 58 | I12: =I$5+(I$6-I$5)*(POWER(I$7,$B12-1)-1)/(POWER(I$7,$B$3-1)-1) -> 0 | J12: =[1]标准模型!$I$65/1*$B12/$B$3 -> 0.0072 | K12: =J12*[1]标准模型!$J$63 -> 0.0072 | L12: =C12*(1+I12)+F12 -> 369 | M12: =D12*(1+J12)+G12 -> 110.87064 | N12: =E12*(1+K12)+H12 -> 73.91376 | O12: =O$5+(O$6-O$5)*(POWER(O$7,$B12-1)-1)/(POWER(O$7,$B$3-1)-1) -> 0.5 | P12: =P$5+(P$6-P$5)*(POWER(P$7,$B12-1)-1)/(POWER(P$7,$B$3-1)-1) -> 0 | Q12: =Q$5+(Q$6-Q$5)*(POWER(Q$7,$B12-1)-1)/(POWER(Q$7,$B$3-1)-1) -> 0.275 | R12: =R$5+(R$6-R$5)*(POWER(R$7,$B12-1)-1)/(POWER(R$7,$B$3-1)-1) -> 1 | S12: =S$5+(S$6-S$5)*(POWER(S$7,$B12-1)-1)/(POWER(S$7,$B$3-1)-1) -> 0 | T12: =T$5+(T$6-T$5)*(POWER(T$7,$B12-1)-1)/(POWER(T$7,$B$3-1)-1) -> 2 | U12: =U$5+(U$6-U$5)*(POWER(U$7,$B12-1)-1)/(POWER(U$7,$B$3-1)-1) -> 1 | V12: =V$5+(V$6-V$5)*(POWER(V$7,$B12-1)-1)/(POWER(V$7,$B$3-1)-1) -> 1 | ... X12: =X$5+(X$6-X$5)*(POWER(X$7,$B12-1)-1)/(POWER(X$7,$B$3-1)-1) -> 1 | Y12: =(1+S12*(T12-1))*U12*X12*(O12+P12)*R12*W12 -> 0.5 | Z12: =(1+S12*(T12-1))*(O12+P12+Q12)*U12*V12*X12*R12*W12 -> 0.775 | AA12: =Z12*L12 -> 285.975 | AB12: =M12 -> 110.87064 | AC12: =N12 -> 73.91376 | AD12: =AC12/(AC12+[1]战斗公式!$M$27) -> 0.0030702843 | AE12: =AA12/(1-AD12) -> 286.85573 | AF12: =AE12/AB12/Y12 -> 5.1746022 | AG12: =AE12/AB12/Z12 -> 3.338453 | AH12: =AH$5+(AH$6-AH$5)*(POWER(AH$7,$B12-1)-1)/(POWER(AH$7,$B$3-1)-1) -> 1 | AI12: =$AI$5+($AI$6-$AI$5)*(POWER($AI$7,$B12-1)-1)/(POWER($AI$7,$B$3-1)-1) -> 0.5 | AJ12: =$AJ$5+($AJ$6-$AJ$5)*(POWER($AJ$7,$B12-1)-1)/(POWER($AJ$7,$B$3-1)-1) -> 2.15 | AK12: =$AK$5+($AK$6-$AK$5)*(POWER($AK$7,$B12-1)-1)/(POWER($AK$7,$B$3-1)-1) -> 1.8 | AL12: =$AL$5+($AL$6-$AL$5)*(POWER($AL$7,$B12-1)-1)/(POWER($AL$7,$B$3-1)-1) -> 0.8 | AM12: =ROUND(AA12/AG12*AH12,0) -> 86 | AN12: =ROUND(AB12*AI12,0) -> 55 | AO12: =ROUND(AC12,0) -> 74 | AP12: =ROUND(AA12/$AF12*AH12*AK12,0) -> 99 | AQ12: =ROUND(AN12*AL12,0) -> 44 | AS12: =ROUNDUP(AS$10*$AP12,0) -> 99 | AT12: =ROUNDUP(AT$10*$AP12,0) -> 297 | AU12: =ROUNDUP(AU$10*$AP12,0) -> 179 | AV12: =ROUNDUP(AV$10*$AP12,0) -> 50 | AW12: =ROUNDUP(AW$10*$AP12,0) -> 15 | AX12: =ROUNDUP(AX$10*$AP12,0) -> 396 | AY12: =ROUNDUP(AY$10*$AP12,0) -> 891 | AZ12: =ROUND(AM12*$AZ$10*AJ12,0) -> 11094 | BA12: =ROUND(AM12*$BA$10*AJ12,0) -> 5547 | BC12: =B12 -> 1
B13: 2 | C13: =C$5+(C$6-C$5)*(POWER(C$7,$B13-1)-1)/(POWER(C$7,$B$3-1)-1) -> 158.01967 | D13: =D$5+(D$6-D$5)*(POWER(D$7,$B13-1)-1)/(POWER(D$7,$B$3-1)-1) -> 47.405902 | E13: =E$5+(E$6-E$5)*(POWER(E$7,$B13-1)-1)/(POWER(E$7,$B$3-1)-1) -> 31.603935 | F13: =F$5+(F$6-F$5)*(POWER(F$7,$B13-1)-1)/(POWER(F$7,$B$3-1)-1) -> 580.07222 | G13: =G$5+(G$6-G$5)*(POWER(G$7,$B13-1)-1)/(POWER(G$7,$B$3-1)-1) -> 174.02166 | H13: =H$5+(H$6-H$5)*(POWER(H$7,$B13-1)-1)/(POWER(H$7,$B$3-1)-1) -> 116.01444 | I13: =I$5+(I$6-I$5)*(POWER(I$7,$B13-1)-1)/(POWER(I$7,$B$3-1)-1) -> 0 | J13: =[1]标准模型!$I$65/1*$B13/$B$3 -> 0.0144 | K13: =J13*[1]标准模型!$J$63 -> 0.0144 | L13: =C13*(1+I13)+F13 -> 738.09189 | M13: =D13*(1+J13)+G13 -> 222.11021 | N13: =E13*(1+K13)+H13 -> 148.07347 | O13: =O$5+(O$6-O$5)*(POWER(O$7,$B13-1)-1)/(POWER(O$7,$B$3-1)-1) -> 0.50100225 | P13: =P$5+(P$6-P$5)*(POWER(P$7,$B13-1)-1)/(POWER(P$7,$B$3-1)-1) -> 0.00053925713 | Q13: =Q$5+(Q$6-Q$5)*(POWER(Q$7,$B13-1)-1)/(POWER(Q$7,$B$3-1)-1) -> 0.27555124 | R13: =R$5+(R$6-R$5)*(POWER(R$7,$B13-1)-1)/(POWER(R$7,$B$3-1)-1) -> 1.0004009 | S13: =S$5+(S$6-S$5)*(POWER(S$7,$B13-1)-1)/(POWER(S$7,$B$3-1)-1) -> 0.0014031549 | T13: =T$5+(T$6-T$5)*(POWER(T$7,$B13-1)-1)/(POWER(T$7,$B$3-1)-1) -> 2.0039088 | U13: =U$5+(U$6-U$5)*(POWER(U$7,$B13-1)-1)/(POWER(U$7,$B$3-1)-1) -> 1 | V13: =V$5+(V$6-V$5)*(POWER(V$7,$B13-1)-1)/(POWER(V$7,$B$3-1)-1) -> 1.0010931 | ... X13: =X$5+(X$6-X$5)*(POWER(X$7,$B13-1)-1)/(POWER(X$7,$B$3-1)-1) -> 1.0032072 | Y13: =(1+S13*(T13-1))*U13*X13*(O13+P13)*R13*W13 -> 0.50437171 | Z13: =(1+S13*(T13-1))*(O13+P13+Q13)*U13*V13*X13*R13*W13 -> 0.78233208 | AA13: =Z13*L13 -> 577.43296 | AB13: =M13 -> 222.11021 | AC13: =N13 -> 148.07347 | AD13: =AC13/(AC13+[1]战斗公式!$M$27) -> 0.006131896 | AE13: =AA13/(1-AD13) -> 580.99556 | AF13: =AE13/AB13/Y13 -> 5.1862515 | AG13: =AE13/AB13/Z13 -> 3.343591 | AH13: =AH$5+(AH$6-AH$5)*(POWER(AH$7,$B13-1)-1)/(POWER(AH$7,$B$3-1)-1) -> 1.0307177 | AI13: =$AI$5+($AI$6-$AI$5)*(POWER($AI$7,$B13-1)-1)/(POWER($AI$7,$B$3-1)-1) -> 0.50210508 | AJ13: =$AJ$5+($AJ$6-$AJ$5)*(POWER($AJ$7,$B13-1)-1)/(POWER($AJ$7,$B$3-1)-1) -> 2.0925 | AK13: =$AK$5+($AK$6-$AK$5)*(POWER($AK$7,$B13-1)-1)/(POWER($AK$7,$B$3-1)-1) -> 1.7839993 | AL13: =$AL$5+($AL$6-$AL$5)*(POWER($AL$7,$B13-1)-1)/(POWER($AL$7,$B$3-1)-1) -> 0.80057937 | AM13: =ROUND(AA13/AG13*AH13,0) -> 178 | AN13: =ROUND(AB13*AI13,0) -> 112 | AO13: =ROUND(AC13,0) -> 148 | AP13: =ROUND(AA13/$AF13*AH13*AK13,0) -> 205 | AQ13: =ROUND(AN13*AL13,0) -> 90 | AS13: =ROUNDUP(AS$10*$AP13,0) -> 205 | AT13: =ROUNDUP(AT$10*$AP13,0) -> 615 | AU13: =ROUNDUP(AU$10*$AP13,0) -> 369 | AV13: =ROUNDUP(AV$10*$AP13,0) -> 103 | AW13: =ROUNDUP(AW$10*$AP13,0) -> 31 | AX13: =ROUNDUP(AX$10*$AP13,0) -> 820 | AY13: =ROUNDUP(AY$10*$AP13,0) -> 1845 | AZ13: =ROUND(AM13*$AZ$10*AJ13,0) -> 22348 | BA13: =ROUND(AM13*$BA$10*AJ13,0) -> 11174 | BC13: =B13 -> 2
B14: 3 | C14: =C$5+(C$6-C$5)*(POWER(C$7,$B14-1)-1)/(POWER(C$7,$B$3-1)-1) -> 237.03927 | D14: =D$5+(D$6-D$5)*(POWER(D$7,$B14-1)-1)/(POWER(D$7,$B$3-1)-1) -> 71.11178 | E14: =E$5+(E$6-E$5)*(POWER(E$7,$B14-1)-1)/(POWER(E$7,$B$3-1)-1) -> 47.407853 | F14: =F$5+(F$6-F$5)*(POWER(F$7,$B14-1)-1)/(POWER(F$7,$B$3-1)-1) -> 870.14414 | G14: =G$5+(G$6-G$5)*(POWER(G$7,$B14-1)-1)/(POWER(G$7,$B$3-1)-1) -> 261.04324 | H14: =H$5+(H$6-H$5)*(POWER(H$7,$B14-1)-1)/(POWER(H$7,$B$3-1)-1) -> 174.02883 | I14: =I$5+(I$6-I$5)*(POWER(I$7,$B14-1)-1)/(POWER(I$7,$B$3-1)-1) -> 0 | J14: =[1]标准模型!$I$65/1*$B14/$B$3 -> 0.0216 | K14: =J14*[1]标准模型!$J$63 -> 0.0216 | L14: =C14*(1+I14)+F14 -> 1107.1834 | M14: =D14*(1+J14)+G14 -> 333.69104 | N14: =E14*(1+K14)+H14 -> 222.46069 | O14: =O$5+(O$6-O$5)*(POWER(O$7,$B14-1)-1)/(POWER(O$7,$B$3-1)-1) -> 0.50200451 | P14: =P$5+(P$6-P$5)*(POWER(P$7,$B14-1)-1)/(POWER(P$7,$B$3-1)-1) -> 0.0010793231 | Q14: =Q$5+(Q$6-Q$5)*(POWER(Q$7,$B14-1)-1)/(POWER(Q$7,$B$3-1)-1) -> 0.27610248 | R14: =R$5+(R$6-R$5)*(POWER(R$7,$B14-1)-1)/(POWER(R$7,$B$3-1)-1) -> 1.0008018 | S14: =S$5+(S$6-S$5)*(POWER(S$7,$B14-1)-1)/(POWER(S$7,$B$3-1)-1) -> 0.0028063085 | T14: =T$5+(T$6-T$5)*(POWER(T$7,$B14-1)-1)/(POWER(T$7,$B$3-1)-1) -> 2.0078176 | U14: =U$5+(U$6-U$5)*(POWER(U$7,$B14-1)-1)/(POWER(U$7,$B$3-1)-1) -> 1 | V14: =V$5+(V$6-V$5)*(POWER(V$7,$B14-1)-1)/(POWER(V$7,$B$3-1)-1) -> 1.0021861 | ... X14: =X$5+(X$6-X$5)*(POWER(X$7,$B14-1)-1)/(POWER(X$7,$B$3-1)-1) -> 1.0064144 | Y14: =(1+S14*(T14-1))*U14*X14*(O14+P14)*R14*W14 -> 0.50877673 | Z14: =(1+S14*(T14-1))*(O14+P14+Q14)*U14*V14*X14*R14*W14 -> 0.78972624 | AA14: =Z14*L14 -> 874.37179 | AB14: =M14 -> 333.69104 | AC14: =N14 -> 222.46069 | AD14: =AC14/(AC14+[1]战斗公式!$M$27) -> 0.0091840666 | AE14: =AA14/(1-AD14) -> 882.47652 | AF14: =AE14/AB14/Y14 -> 5.1979414 | AG14: =AE14/AB14/Z14 -> 3.3487447 | AH14: =AH$5+(AH$6-AH$5)*(POWER(AH$7,$B14-1)-1)/(POWER(AH$7,$B$3-1)-1) -> 1.0612049 | AI14: =$AI$5+($AI$6-$AI$5)*(POWER($AI$7,$B14-1)-1)/(POWER($AI$7,$B$3-1)-1) -> 0.50421437 | AJ14: =$AJ$5+($AJ$6-$AJ$5)*(POWER($AJ$7,$B14-1)-1)/(POWER($AJ$7,$B$3-1)-1) -> 2.037875 | AK14: =$AK$5+($AK$6-$AK$5)*(POWER($AK$7,$B14-1)-1)/(POWER($AK$7,$B$3-1)-1) -> 1.7683187 | AL14: =$AL$5+($AL$6-$AL$5)*(POWER($AL$7,$B14-1)-1)/(POWER($AL$7,$B$3-1)-1) -> 0.80115701 | AM14: =ROUND(AA14/AG14*AH14,0) -> 277 | AN14: =ROUND(AB14*AI14,0) -> 168 | AO14: =ROUND(AC14,0) -> 222 | AP14: =ROUND(AA14/$AF14*AH14*AK14,0) -> 316 | AQ14: =ROUND(AN14*AL14,0) -> 135 | AS14: =ROUNDUP(AS$10*$AP14,0) -> 316 | AT14: =ROUNDUP(AT$10*$AP14,0) -> 948 | AU14: =ROUNDUP(AU$10*$AP14,0) -> 569 | AV14: =ROUNDUP(AV$10*$AP14,0) -> 158 | AW14: =ROUNDUP(AW$10*$AP14,0) -> 48 | AX14: =ROUNDUP(AX$10*$AP14,0) -> 1264 | AY14: =ROUNDUP(AY$10*$AP14,0) -> 2844 | AZ14: =ROUND(AM14*$AZ$10*AJ14,0) -> 33869 | BA14: =ROUND(AM14*$BA$10*AJ14,0) -> 16935 | BC14: =B14 -> 3
B15: 4 | C15: =C$5+(C$6-C$5)*(POWER(C$7,$B15-1)-1)/(POWER(C$7,$B$3-1)-1) -> 316.05878 | D15: =D$5+(D$6-D$5)*(POWER(D$7,$B15-1)-1)/(POWER(D$7,$B$3-1)-1) -> 94.817634 | E15: =E$5+(E$6-E$5)*(POWER(E$7,$B15-1)-1)/(POWER(E$7,$B$3-1)-1) -> 63.211756 | F15: =F$5+(F$6-F$5)*(POWER(F$7,$B15-1)-1)/(POWER(F$7,$B$3-1)-1) -> 1160.2158 | G15: =G$5+(G$6-G$5)*(POWER(G$7,$B15-1)-1)/(POWER(G$7,$B$3-1)-1) -> 348.06473 | H15: =H$5+(H$6-H$5)*(POWER(H$7,$B15-1)-1)/(POWER(H$7,$B$3-1)-1) -> 232.04316 | I15: =I$5+(I$6-I$5)*(POWER(I$7,$B15-1)-1)/(POWER(I$7,$B$3-1)-1) -> 0 | J15: =[1]标准模型!$I$65/1*$B15/$B$3 -> 0.0288 | K15: =J15*[1]标准模型!$J$63 -> 0.0288 | L15: =C15*(1+I15)+F15 -> 1476.2746 | M15: =D15*(1+J15)+G15 -> 445.61312 | N15: =E15*(1+K15)+H15 -> 297.07541 | O15: =O$5+(O$6-O$5)*(POWER(O$7,$B15-1)-1)/(POWER(O$7,$B$3-1)-1) -> 0.50300676 | P15: =P$5+(P$6-P$5)*(POWER(P$7,$B15-1)-1)/(POWER(P$7,$B$3-1)-1) -> 0.0016201992 | Q15: =Q$5+(Q$6-Q$5)*(POWER(Q$7,$B15-1)-1)/(POWER(Q$7,$B$3-1)-1) -> 0.27665372 | R15: =R$5+(R$6-R$5)*(POWER(R$7,$B15-1)-1)/(POWER(R$7,$B$3-1)-1) -> 1.0012027 | S15: =S$5+(S$6-S$5)*(POWER(S$7,$B15-1)-1)/(POWER(S$7,$B$3-1)-1) -> 0.0042094606 | T15: =T$5+(T$6-T$5)*(POWER(T$7,$B15-1)-1)/(POWER(T$7,$B$3-1)-1) -> 2.0117264 | U15: =U$5+(U$6-U$5)*(POWER(U$7,$B15-1)-1)/(POWER(U$7,$B$3-1)-1) -> 1 | V15: =V$5+(V$6-V$5)*(POWER(V$7,$B15-1)-1)/(POWER(V$7,$B$3-1)-1) -> 1.0032792 | ... X15: =X$5+(X$6-X$5)*(POWER(X$7,$B15-1)-1)/(POWER(X$7,$B$3-1)-1) -> 1.0096216 | Y15: =(1+S15*(T15-1))*U15*X15*(O15+P15)*R15*W15 -> 0.5132153 | Z15: =(1+S15*(T15-1))*(O15+P15+Q15)*U15*V15*X15*R15*W15 -> 0.79718299 | AA15: =Z15*L15 -> 1176.861 | AB15: =M15 -> 445.61312 | AC15: =N15 -> 297.07541 | AD15: =AC15/(AC15+[1]战斗公式!$M$27) -> 0.012226797 | AE15: =AA15/(1-AD15) -> 1191.4283 | AF15: =AE15/AB15/Y15 -> 5.2096717 | AG15: =AE15/AB15/Z15 -> 3.3539141 | AH15: =AH$5+(AH$6-AH$5)*(POWER(AH$7,$B15-1)-1)/(POWER(AH$7,$B$3-1)-1) -> 1.0914635 | AI15: =$AI$5+($AI$6-$AI$5)*(POWER($AI$7,$B15-1)-1)/(POWER($AI$7,$B$3-1)-1) -> 0.50632788 | AJ15: =$AJ$5+($AJ$6-$AJ$5)*(POWER($AJ$7,$B15-1)-1)/(POWER($AJ$7,$B$3-1)-1) -> 1.9859812 | AK15: =$AK$5+($AK$6-$AK$5)*(POWER($AK$7,$B15-1)-1)/(POWER($AK$7,$B$3-1)-1) -> 1.7529516 | AL15: =$AL$5+($AL$6-$AL$5)*(POWER($AL$7,$B15-1)-1)/(POWER($AL$7,$B$3-1)-1) -> 0.80173291 | AM15: =ROUND(AA15/AG15*AH15,0) -> 383 | AN15: =ROUND(AB15*AI15,0) -> 226 | AO15: =ROUND(AC15,0) -> 297 | AP15: =ROUND(AA15/$AF15*AH15*AK15,0) -> 432 | AQ15: =ROUND(AN15*AL15,0) -> 181 | AS15: =ROUNDUP(AS$10*$AP15,0) -> 432 | AT15: =ROUNDUP(AT$10*$AP15,0) -> 1296 | AU15: =ROUNDUP(AU$10*$AP15,0) -> 778 | AV15: =ROUNDUP(AV$10*$AP15,0) -> 216 | AW15: =ROUNDUP(AW$10*$AP15,0) -> 65 | AX15: =ROUNDUP(AX$10*$AP15,0) -> 1728 | AY15: =ROUNDUP(AY$10*$AP15,0) -> 3888 | AZ15: =ROUND(AM15*$AZ$10*AJ15,0) -> 45638 | BA15: =ROUND(AM15*$BA$10*AJ15,0) -> 22819 | BC15: =B15 -> 4
B16: 5 | C16: =C$5+(C$6-C$5)*(POWER(C$7,$B16-1)-1)/(POWER(C$7,$B$3-1)-1) -> 395.07822 | D16: =D$5+(D$6-D$5)*(POWER(D$7,$B16-1)-1)/(POWER(D$7,$B$3-1)-1) -> 118.52346 | E16: =E$5+(E$6-E$5)*(POWER(E$7,$B16-1)-1)/(POWER(E$7,$B$3-1)-1) -> 79.015643 | F16: =F$5+(F$6-F$5)*(POWER(F$7,$B16-1)-1)/(POWER(F$7,$B$3-1)-1) -> 1450.2871 | G16: =G$5+(G$6-G$5)*(POWER(G$7,$B16-1)-1)/(POWER(G$7,$B$3-1)-1) -> 435.08614 | H16: =H$5+(H$6-H$5)*(POWER(H$7,$B16-1)-1)/(POWER(H$7,$B$3-1)-1) -> 290.05742 | I16: =I$5+(I$6-I$5)*(POWER(I$7,$B16-1)-1)/(POWER(I$7,$B$3-1)-1) -> 0 | J16: =[1]标准模型!$I$65/1*$B16/$B$3 -> 0.036 | K16: =J16*[1]标准模型!$J$63 -> 0.036 | L16: =C16*(1+I16)+F16 -> 1845.3653 | M16: =D16*(1+J16)+G16 -> 557.87645 | N16: =E16*(1+K16)+H16 -> 371.91763 | O16: =O$5+(O$6-O$5)*(POWER(O$7,$B16-1)-1)/(POWER(O$7,$B$3-1)-1) -> 0.50400901 | P16: =P$5+(P$6-P$5)*(POWER(P$7,$B16-1)-1)/(POWER(P$7,$B$3-1)-1) -> 0.0021618867 | Q16: =Q$5+(Q$6-Q$5)*(POWER(Q$7,$B16-1)-1)/(POWER(Q$7,$B$3-1)-1) -> 0.27720495 | R16: =R$5+(R$6-R$5)*(POWER(R$7,$B16-1)-1)/(POWER(R$7,$B$3-1)-1) -> 1.0016036 | S16: =S$5+(S$6-S$5)*(POWER(S$7,$B16-1)-1)/(POWER(S$7,$B$3-1)-1) -> 0.0056126113 | T16: =T$5+(T$6-T$5)*(POWER(T$7,$B16-1)-1)/(POWER(T$7,$B$3-1)-1) -> 2.0156351 | U16: =U$5+(U$6-U$5)*(POWER(U$7,$B16-1)-1)/(POWER(U$7,$B$3-1)-1) -> 1 | V16: =V$5+(V$6-V$5)*(POWER(V$7,$B16-1)-1)/(POWER(V$7,$B$3-1)-1) -> 1.0043722 | ... X16: =X$5+(X$6-X$5)*(POWER(X$7,$B16-1)-1)/(POWER(X$7,$B$3-1)-1) -> 1.0128288 | Y16: =(1+S16*(T16-1))*U16*X16*(O16+P16)*R16*W16 -> 0.51768768 | Z16: =(1+S16*(T16-1))*(O16+P16+Q16)*U16*V16*X16*R16*W16 -> 0.80470283 | AA16: =Z16*L16 -> 1484.9707 | AB16: =M16 -> 557.87645 | AC16: =N16 -> 371.91763 | AD16: =AC16/(AC16+[1]战斗公式!$M$27) -> 0.015260089 | AE16: =AA16/(1-AD16) -> 1507.9827 | AF16: =AE16/AB16/Y16 -> 5.2214424 | AG16: =AE16/AB16/Z16 -> 3.3590989 | AH16: =AH$5+(AH$6-AH$5)*(POWER(AH$7,$B16-1)-1)/(POWER(AH$7,$B$3-1)-1) -> 1.1214952 | AI16: =$AI$5+($AI$6-$AI$5)*(POWER($AI$7,$B16-1)-1)/(POWER($AI$7,$B$3-1)-1) -> 0.50844562 | AJ16: =$AJ$5+($AJ$6-$AJ$5)*(POWER($AJ$7,$B16-1)-1)/(POWER($AJ$7,$B$3-1)-1) -> 1.9366822 | AK16: =$AK$5+($AK$6-$AK$5)*(POWER($AK$7,$B16-1)-1)/(POWER($AK$7,$B$3-1)-1) -> 1.7378919 | AL16: =$AL$5+($AL$6-$AL$5)*(POWER($AL$7,$B16-1)-1)/(POWER($AL$7,$B$3-1)-1) -> 0.80230708 | AM16: =ROUND(AA16/AG16*AH16,0) -> 496 | AN16: =ROUND(AB16*AI16,0) -> 284 | AO16: =ROUND(AC16,0) -> 372 | AP16: =ROUND(AA16/$AF16*AH16*AK16,0) -> 554 | AQ16: =ROUND(AN16*AL16,0) -> 228 | AS16: =ROUNDUP(AS$10*$AP16,0) -> 554 | AT16: =ROUNDUP(AT$10*$AP16,0) -> 1662 | AU16: =ROUNDUP(AU$10*$AP16,0) -> 998 | AV16: =ROUNDUP(AV$10*$AP16,0) -> 277 | AW16: =ROUNDUP(AW$10*$AP16,0) -> 84 | AX16: =ROUNDUP(AX$10*$AP16,0) -> 2216 | AY16: =ROUNDUP(AY$10*$AP16,0) -> 4986 | AZ16: =ROUND(AM16*$AZ$10*AJ16,0) -> 57636 | BA16: =ROUND(AM16*$BA$10*AJ16,0) -> 28818 | BC16: =B16 -> 5
B17: 6 | C17: =C$5+(C$6-C$5)*(POWER(C$7,$B17-1)-1)/(POWER(C$7,$B$3-1)-1) -> 474.09757 | D17: =D$5+(D$6-D$5)*(POWER(D$7,$B17-1)-1)/(POWER(D$7,$B$3-1)-1) -> 142.22927 | E17: =E$5+(E$6-E$5)*(POWER(E$7,$B17-1)-1)/(POWER(E$7,$B$3-1)-1) -> 94.819515 | F17: =F$5+(F$6-F$5)*(POWER(F$7,$B17-1)-1)/(POWER(F$7,$B$3-1)-1) -> 1740.3582 | G17: =G$5+(G$6-G$5)*(POWER(G$7,$B17-1)-1)/(POWER(G$7,$B$3-1)-1) -> 522.10745 | H17: =H$5+(H$6-H$5)*(POWER(H$7,$B17-1)-1)/(POWER(H$7,$B$3-1)-1) -> 348.07164 | I17: =I$5+(I$6-I$5)*(POWER(I$7,$B17-1)-1)/(POWER(I$7,$B$3-1)-1) -> 0 | J17: =[1]标准模型!$I$65/1*$B17/$B$3 -> 0.0432 | K17: =J17*[1]标准模型!$J$63 -> 0.0432 | L17: =C17*(1+I17)+F17 -> 2214.4558 | M17: =D17*(1+J17)+G17 -> 670.48103 | N17: =E17*(1+K17)+H17 -> 446.98735 | O17: =O$5+(O$6-O$5)*(POWER(O$7,$B17-1)-1)/(POWER(O$7,$B$3-1)-1) -> 0.50501126 | P17: =P$5+(P$6-P$5)*(POWER(P$7,$B17-1)-1)/(POWER(P$7,$B$3-1)-1) -> 0.0027043866 | Q17: =Q$5+(Q$6-Q$5)*(POWER(Q$7,$B17-1)-1)/(POWER(Q$7,$B$3-1)-1) -> 0.27775619 | R17: =R$5+(R$6-R$5)*(POWER(R$7,$B17-1)-1)/(POWER(R$7,$B$3-1)-1) -> 1.0020045 | S17: =S$5+(S$6-S$5)*(POWER(S$7,$B17-1)-1)/(POWER(S$7,$B$3-1)-1) -> 0.0070157607 | T17: =T$5+(T$6-T$5)*(POWER(T$7,$B17-1)-1)/(POWER(T$7,$B$3-1)-1) -> 2.0195439 | U17: =U$5+(U$6-U$5)*(POWER(U$7,$B17-1)-1)/(POWER(U$7,$B$3-1)-1) -> 1 | V17: =V$5+(V$6-V$5)*(POWER(V$7,$B17-1)-1)/(POWER(V$7,$B$3-1)-1) -> 1.0054653 | ... X17: =X$5+(X$6-X$5)*(POWER(X$7,$B17-1)-1)/(POWER(X$7,$B$3-1)-1) -> 1.016036 | Y17: =(1+S17*(T17-1))*U17*X17*(O17+P17)*R17*W17 -> 0.5221941 | Z17: =(1+S17*(T17-1))*(O17+P17+Q17)*U17*V17*X17*R17*W17 -> 0.81228626 | AA17: =Z17*L17 -> 1798.772 | AB17: =M17 -> 670.48103 | AC17: =N17 -> 446.98735 | AD17: =AC17/(AC17+[1]战斗公式!$M$27) -> 0.018283944 | AE17: =AA17/(1-AD17) -> 1832.2732 | AF17: =AE17/AB17/Y17 -> 5.2332534 | AG17: =AE17/AB17/Z17 -> 3.3642992 | AH17: =AH$5+(AH$6-AH$5)*(POWER(AH$7,$B17-1)-1)/(POWER(AH$7,$B$3-1)-1) -> 1.1513017 | AI17: =$AI$5+($AI$6-$AI$5)*(POWER($AI$7,$B17-1)-1)/(POWER($AI$7,$B$3-1)-1) -> 0.51056759 | AJ17: =$AJ$5+($AJ$6-$AJ$5)*(POWER($AJ$7,$B17-1)-1)/(POWER($AJ$7,$B$3-1)-1) -> 1.8898481 | AK17: =$AK$5+($AK$6-$AK$5)*(POWER($AK$7,$B17-1)-1)/(POWER($AK$7,$B$3-1)-1) -> 1.7231334 | AL17: =$AL$5+($AL$6-$AL$5)*(POWER($AL$7,$B17-1)-1)/(POWER($AL$7,$B$3-1)-1) -> 0.80287953 | AM17: =ROUND(AA17/AG17*AH17,0) -> 616 | AN17: =ROUND(AB17*AI17,0) -> 342 | AO17: =ROUND(AC17,0) -> 447 | AP17: =ROUND(AA17/$AF17*AH17*AK17,0) -> 682 | AQ17: =ROUND(AN17*AL17,0) -> 275 | AS17: =ROUNDUP(AS$10*$AP17,0) -> 682 | AT17: =ROUNDUP(AT$10*$AP17,0) -> 2046 | AU17: =ROUNDUP(AU$10*$AP17,0) -> 1228 | AV17: =ROUNDUP(AV$10*$AP17,0) -> 341 | AW17: =ROUNDUP(AW$10*$AP17,0) -> 103 | AX17: =ROUNDUP(AX$10*$AP17,0) -> 2728 | AY17: =ROUNDUP(AY$10*$AP17,0) -> 6138 | AZ17: =ROUND(AM17*$AZ$10*AJ17,0) -> 69849 | BA17: =ROUND(AM17*$BA$10*AJ17,0) -> 34924 | BC17: =B17 -> 6
B18: 7 | C18: =C$5+(C$6-C$5)*(POWER(C$7,$B18-1)-1)/(POWER(C$7,$B$3-1)-1) -> 553.11685 | D18: =D$5+(D$6-D$5)*(POWER(D$7,$B18-1)-1)/(POWER(D$7,$B$3-1)-1) -> 165.93506 | E18: =E$5+(E$6-E$5)*(POWER(E$7,$B18-1)-1)/(POWER(E$7,$B$3-1)-1) -> 110.62337 | F18: =F$5+(F$6-F$5)*(POWER(F$7,$B18-1)-1)/(POWER(F$7,$B$3-1)-1) -> 2030.4289 | G18: =G$5+(G$6-G$5)*(POWER(G$7,$B18-1)-1)/(POWER(G$7,$B$3-1)-1) -> 609.12868 | H18: =H$5+(H$6-H$5)*(POWER(H$7,$B18-1)-1)/(POWER(H$7,$B$3-1)-1) -> 406.08579 | I18: =I$5+(I$6-I$5)*(POWER(I$7,$B18-1)-1)/(POWER(I$7,$B$3-1)-1) -> 0 | J18: =[1]标准模型!$I$65/1*$B18/$B$3 -> 0.0504 | K18: =J18*[1]标准模型!$J$63 -> 0.0504 | L18: =C18*(1+I18)+F18 -> 2583.5458 | M18: =D18*(1+J18)+G18 -> 783.42687 | N18: =E18*(1+K18)+H18 -> 522.28458 | O18: =O$5+(O$6-O$5)*(POWER(O$7,$B18-1)-1)/(POWER(O$7,$B$3-1)-1) -> 0.50601351 | P18: =P$5+(P$6-P$5)*(POWER(P$7,$B18-1)-1)/(POWER(P$7,$B$3-1)-1) -> 0.0032477003 | Q18: =Q$5+(Q$6-Q$5)*(POWER(Q$7,$B18-1)-1)/(POWER(Q$7,$B$3-1)-1) -> 0.27830743 | R18: =R$5+(R$6-R$5)*(POWER(R$7,$B18-1)-1)/(POWER(R$7,$B$3-1)-1) -> 1.0024054 | S18: =S$5+(S$6-S$5)*(POWER(S$7,$B18-1)-1)/(POWER(S$7,$B$3-1)-1) -> 0.0084189086 | T18: =T$5+(T$6-T$5)*(POWER(T$7,$B18-1)-1)/(POWER(T$7,$B$3-1)-1) -> 2.0234527 | U18: =U$5+(U$6-U$5)*(POWER(U$7,$B18-1)-1)/(POWER(U$7,$B$3-1)-1) -> 1 | V18: =V$5+(V$6-V$5)*(POWER(V$7,$B18-1)-1)/(POWER(V$7,$B$3-1)-1) -> 1.0065583 | ... X18: =X$5+(X$6-X$5)*(POWER(X$7,$B18-1)-1)/(POWER(X$7,$B$3-1)-1) -> 1.0192432 | Y18: =(1+S18*(T18-1))*U18*X18*(O18+P18)*R18*W18 -> 0.52673481 | Z18: =(1+S18*(T18-1))*(O18+P18+Q18)*U18*V18*X18*R18*W18 -> 0.81993379 | AA18: =Z18*L18 -> 2118.3365 | AB18: =M18 -> 783.42687 | AC18: =N18 -> 522.28458 | AD18: =AC18/(AC18+[1]战斗公式!$M$27) -> 0.021298365 | AE18: =AA18/(1-AD18) -> 2164.4354 | AF18: =AE18/AB18/Y18 -> 5.2451046 | AG18: =AE18/AB18/Z18 -> 3.369515 | AH18: =AH$5+(AH$6-AH$5)*(POWER(AH$7,$B18-1)-1)/(POWER(AH$7,$B$3-1)-1) -> 1.1808846 | AI18: =$AI$5+($AI$6-$AI$5)*(POWER($AI$7,$B18-1)-1)/(POWER($AI$7,$B$3-1)-1) -> 0.51269381 | AJ18: =$AJ$5+($AJ$6-$AJ$5)*(POWER($AJ$7,$B18-1)-1)/(POWER($AJ$7,$B$3-1)-1) -> 1.8453557 | AK18: =$AK$5+($AK$6-$AK$5)*(POWER($AK$7,$B18-1)-1)/(POWER($AK$7,$B$3-1)-1) -> 1.7086701 | AL18: =$AL$5+($AL$6-$AL$5)*(POWER($AL$7,$B18-1)-1)/(POWER($AL$7,$B$3-1)-1) -> 0.80345027 | AM18: =ROUND(AA18/AG18*AH18,0) -> 742 | AN18: =ROUND(AB18*AI18,0) -> 402 | AO18: =ROUND(AC18,0) -> 522 | AP18: =ROUND(AA18/$AF18*AH18*AK18,0) -> 815 | AQ18: =ROUND(AN18*AL18,0) -> 323 | AS18: =ROUNDUP(AS$10*$AP18,0) -> 815 | AT18: =ROUNDUP(AT$10*$AP18,0) -> 2445 | AU18: =ROUNDUP(AU$10*$AP18,0) -> 1467 | AV18: =ROUNDUP(AV$10*$AP18,0) -> 408 | AW18: =ROUNDUP(AW$10*$AP18,0) -> 123 | AX18: =ROUNDUP(AX$10*$AP18,0) -> 3260 | AY18: =ROUNDUP(AY$10*$AP18,0) -> 7335 | AZ18: =ROUND(AM18*$AZ$10*AJ18,0) -> 82155 | BA18: =ROUND(AM18*$BA$10*AJ18,0) -> 41078 | BC18: =B18 -> 7
B19: 8 | C19: =C$5+(C$6-C$5)*(POWER(C$7,$B19-1)-1)/(POWER(C$7,$B$3-1)-1) -> 632.13605 | D19: =D$5+(D$6-D$5)*(POWER(D$7,$B19-1)-1)/(POWER(D$7,$B$3-1)-1) -> 189.64081 | E19: =E$5+(E$6-E$5)*(POWER(E$7,$B19-1)-1)/(POWER(E$7,$B$3-1)-1) -> 126.42721 | F19: =F$5+(F$6-F$5)*(POWER(F$7,$B19-1)-1)/(POWER(F$7,$B$3-1)-1) -> 2320.4994 | G19: =G$5+(G$6-G$5)*(POWER(G$7,$B19-1)-1)/(POWER(G$7,$B$3-1)-1) -> 696.14983 | H19: =H$5+(H$6-H$5)*(POWER(H$7,$B19-1)-1)/(POWER(H$7,$B$3-1)-1) -> 464.09988 | I19: =I$5+(I$6-I$5)*(POWER(I$7,$B19-1)-1)/(POWER(I$7,$B$3-1)-1) -> 0 | J19: =[1]标准模型!$I$65/1*$B19/$B$3 -> 0.0576 | K19: =J19*[1]标准模型!$J$63 -> 0.0576 | L19: =C19*(1+I19)+F19 -> 2952.6355 | M19: =D19*(1+J19)+G19 -> 896.71395 | N19: =E19*(1+K19)+H19 -> 597.8093 | O19: =O$5+(O$6-O$5)*(POWER(O$7,$B19-1)-1)/(POWER(O$7,$B$3-1)-1) -> 0.50701575 | P19: =P$5+(P$6-P$5)*(POWER(P$7,$B19-1)-1)/(POWER(P$7,$B$3-1)-1) -> 0.003791829 | Q19: =Q$5+(Q$6-Q$5)*(POWER(Q$7,$B19-1)-1)/(POWER(Q$7,$B$3-1)-1) -> 0.27885866 | R19: =R$5+(R$6-R$5)*(POWER(R$7,$B19-1)-1)/(POWER(R$7,$B$3-1)-1) -> 1.0028063 | S19: =S$5+(S$6-S$5)*(POWER(S$7,$B19-1)-1)/(POWER(S$7,$B$3-1)-1) -> 0.0098220551 | T19: =T$5+(T$6-T$5)*(POWER(T$7,$B19-1)-1)/(POWER(T$7,$B$3-1)-1) -> 2.0273614 | U19: =U$5+(U$6-U$5)*(POWER(U$7,$B19-1)-1)/(POWER(U$7,$B$3-1)-1) -> 1 | V19: =V$5+(V$6-V$5)*(POWER(V$7,$B19-1)-1)/(POWER(V$7,$B$3-1)-1) -> 1.0076514 | ... X19: =X$5+(X$6-X$5)*(POWER(X$7,$B19-1)-1)/(POWER(X$7,$B$3-1)-1) -> 1.0224504 | Y19: =(1+S19*(T19-1))*U19*X19*(O19+P19)*R19*W19 -> 0.53131006 | Z19: =(1+S19*(T19-1))*(O19+P19+Q19)*U19*V19*X19*R19*W19 -> 0.82764592 | AA19: =Z19*L19 -> 2443.7367 | AB19: =M19 -> 896.71395 | AC19: =N19 -> 597.8093 | AD19: =AC19/(AC19+[1]战斗公式!$M$27) -> 0.024303355 | AE19: =AA19/(1-AD19) -> 2504.6071 | AF19: =AE19/AB19/Y19 -> 5.2569958 | AG19: =AE19/AB19/Z19 -> 3.374746 | AH19: =AH$5+(AH$6-AH$5)*(POWER(AH$7,$B19-1)-1)/(POWER(AH$7,$B$3-1)-1) -> 1.2102456 | AI19: =$AI$5+($AI$6-$AI$5)*(POWER($AI$7,$B19-1)-1)/(POWER($AI$7,$B$3-1)-1) -> 0.51482427 | AJ19: =$AJ$5+($AJ$6-$AJ$5)*(POWER($AJ$7,$B19-1)-1)/(POWER($AJ$7,$B$3-1)-1) -> 1.8030879 | AK19: =$AK$5+($AK$6-$AK$5)*(POWER($AK$7,$B19-1)-1)/(POWER($AK$7,$B$3-1)-1) -> 1.694496 | AL19: =$AL$5+($AL$6-$AL$5)*(POWER($AL$7,$B19-1)-1)/(POWER($AL$7,$B$3-1)-1) -> 0.80401929 | AM19: =ROUND(AA19/AG19*AH19,0) -> 876 | AN19: =ROUND(AB19*AI19,0) -> 462 | AO19: =ROUND(AC19,0) -> 598 | AP19: =ROUND(AA19/$AF19*AH19*AK19,0) -> 953 | AQ19: =ROUND(AN19*AL19,0) -> 371 | AS19: =ROUNDUP(AS$10*$AP19,0) -> 953 | AT19: =ROUNDUP(AT$10*$AP19,0) -> 2859 | AU19: =ROUNDUP(AU$10*$AP19,0) -> 1716 | AV19: =ROUNDUP(AV$10*$AP19,0) -> 477 | AW19: =ROUNDUP(AW$10*$AP19,0) -> 143 | AX19: =ROUNDUP(AX$10*$AP19,0) -> 3812 | AY19: =ROUNDUP(AY$10*$AP19,0) -> 8577 | AZ19: =ROUND(AM19*$AZ$10*AJ19,0) -> 94770 | BA19: =ROUND(AM19*$BA$10*AJ19,0) -> 47385 | BC19: =B19 -> 8
B20: 9 | C20: =C$5+(C$6-C$5)*(POWER(C$7,$B20-1)-1)/(POWER(C$7,$B$3-1)-1) -> 711.15517 | D20: =D$5+(D$6-D$5)*(POWER(D$7,$B20-1)-1)/(POWER(D$7,$B$3-1)-1) -> 213.34655 | E20: =E$5+(E$6-E$5)*(POWER(E$7,$B20-1)-1)/(POWER(E$7,$B$3-1)-1) -> 142.23103 | F20: =F$5+(F$6-F$5)*(POWER(F$7,$B20-1)-1)/(POWER(F$7,$B$3-1)-1) -> 2610.5696 | G20: =G$5+(G$6-G$5)*(POWER(G$7,$B20-1)-1)/(POWER(G$7,$B$3-1)-1) -> 783.17088 | H20: =H$5+(H$6-H$5)*(POWER(H$7,$B20-1)-1)/(POWER(H$7,$B$3-1)-1) -> 522.11392 | I20: =I$5+(I$6-I$5)*(POWER(I$7,$B20-1)-1)/(POWER(I$7,$B$3-1)-1) -> 0 | J20: =[1]标准模型!$I$65/1*$B20/$B$3 -> 0.0648 | K20: =J20*[1]标准模型!$J$63 -> 0.0648 | L20: =C20*(1+I20)+F20 -> 3321.7248 | M20: =D20*(1+J20)+G20 -> 1010.3423 | N20: =E20*(1+K20)+H20 -> 673.56153 | O20: =O$5+(O$6-O$5)*(POWER(O$7,$B20-1)-1)/(POWER(O$7,$B$3-1)-1) -> 0.508018 | P20: =P$5+(P$6-P$5)*(POWER(P$7,$B20-1)-1)/(POWER(P$7,$B$3-1)-1) -> 0.0043367739 | Q20: =Q$5+(Q$6-Q$5)*(POWER(Q$7,$B20-1)-1)/(POWER(Q$7,$B$3-1)-1) -> 0.2794099 | R20: =R$5+(R$6-R$5)*(POWER(R$7,$B20-1)-1)/(POWER(R$7,$B$3-1)-1) -> 1.0032072 | S20: =S$5+(S$6-S$5)*(POWER(S$7,$B20-1)-1)/(POWER(S$7,$B$3-1)-1) -> 0.0112252 | T20: =T$5+(T$6-T$5)*(POWER(T$7,$B20-1)-1)/(POWER(T$7,$B$3-1)-1) -> 2.0312702 | U20: =U$5+(U$6-U$5)*(POWER(U$7,$B20-1)-1)/(POWER(U$7,$B$3-1)-1) -> 1 | V20: =V$5+(V$6-V$5)*(POWER(V$7,$B20-1)-1)/(POWER(V$7,$B$3-1)-1) -> 1.0087444 | ... X20: =X$5+(X$6-X$5)*(POWER(X$7,$B20-1)-1)/(POWER(X$7,$B$3-1)-1) -> 1.0256576 | Y20: =(1+S20*(T20-1))*U20*X20*(O20+P20)*R20*W20 -> 0.5359201 | Z20: =(1+S20*(T20-1))*(O20+P20+Q20)*U20*V20*X20*R20*W20 -> 0.83542319 | AA20: =Z20*L20 -> 2775.0459 | AB20: =M20 -> 1010.3423 | AC20: =N20 -> 673.56153 | AD20: =AC20/(AC20+[1]战斗公式!$M$27) -> 0.027298918 | AE20: =AA20/(1-AD20) -> 2852.9277 | AF20: =AE20/AB20/Y20 -> 5.2689271 | AG20: =AE20/AB20/Z20 -> 3.3799923 | AH20: =AH$5+(AH$6-AH$5)*(POWER(AH$7,$B20-1)-1)/(POWER(AH$7,$B$3-1)-1) -> 1.2393864 | AI20: =$AI$5+($AI$6-$AI$5)*(POWER($AI$7,$B20-1)-1)/(POWER($AI$7,$B$3-1)-1) -> 0.516959 | AJ20: =$AJ$5+($AJ$6-$AJ$5)*(POWER($AJ$7,$B20-1)-1)/(POWER($AJ$7,$B$3-1)-1) -> 1.7629335 | AK20: =$AK$5+($AK$6-$AK$5)*(POWER($AK$7,$B20-1)-1)/(POWER($AK$7,$B$3-1)-1) -> 1.6806054 | AL20: =$AL$5+($AL$6-$AL$5)*(POWER($AL$7,$B20-1)-1)/(POWER($AL$7,$B$3-1)-1) -> 0.8045866 | AM20: =ROUND(AA20/AG20*AH20,0) -> 1018 | AN20: =ROUND(AB20*AI20,0) -> 522 | AO20: =ROUND(AC20,0) -> 674 | AP20: =ROUND(AA20/$AF20*AH20*AK20,0) -> 1097 | AQ20: =ROUND(AN20*AL20,0) -> 420 | AS20: =ROUNDUP(AS$10*$AP20,0) -> 1097 | AT20: =ROUNDUP(AT$10*$AP20,0) -> 3291 | AU20: =ROUNDUP(AU$10*$AP20,0) -> 1975 | AV20: =ROUNDUP(AV$10*$AP20,0) -> 549 | AW20: =ROUNDUP(AW$10*$AP20,0) -> 165 | AX20: =ROUNDUP(AX$10*$AP20,0) -> 4388 | AY20: =ROUNDUP(AY$10*$AP20,0) -> 9873 | AZ20: =ROUND(AM20*$AZ$10*AJ20,0) -> 107680 | BA20: =ROUND(AM20*$BA$10*AJ20,0) -> 53840 | BC20: =B20 -> 9
B21: 10 | C21: =C$5+(C$6-C$5)*(POWER(C$7,$B21-1)-1)/(POWER(C$7,$B$3-1)-1) -> 790.17421 | D21: =D$5+(D$6-D$5)*(POWER(D$7,$B21-1)-1)/(POWER(D$7,$B$3-1)-1) -> 237.05226 | E21: =E$5+(E$6-E$5)*(POWER(E$7,$B21-1)-1)/(POWER(E$7,$B$3-1)-1) -> 158.03484 | F21: =F$5+(F$6-F$5)*(POWER(F$7,$B21-1)-1)/(POWER(F$7,$B$3-1)-1) -> 2900.6395 | G21: =G$5+(G$6-G$5)*(POWER(G$7,$B21-1)-1)/(POWER(G$7,$B$3-1)-1) -> 870.19185 | H21: =H$5+(H$6-H$5)*(POWER(H$7,$B21-1)-1)/(POWER(H$7,$B$3-1)-1) -> 580.1279 | I21: =I$5+(I$6-I$5)*(POWER(I$7,$B21-1)-1)/(POWER(I$7,$B$3-1)-1) -> 0 | J21: =[1]标准模型!$I$65/1*$B21/$B$3 -> 0.072 | K21: =J21*[1]标准模型!$J$63 -> 0.072 | L21: =C21*(1+I21)+F21 -> 3690.8137 | M21: =D21*(1+J21)+G21 -> 1124.3119 | N21: =E21*(1+K21)+H21 -> 749.54125 | O21: =O$5+(O$6-O$5)*(POWER(O$7,$B21-1)-1)/(POWER(O$7,$B$3-1)-1) -> 0.50902025 | P21: =P$5+(P$6-P$5)*(POWER(P$7,$B21-1)-1)/(POWER(P$7,$B$3-1)-1) -> 0.0048825362 | Q21: =Q$5+(Q$6-Q$5)*(POWER(Q$7,$B21-1)-1)/(POWER(Q$7,$B$3-1)-1) -> 0.27996114 | R21: =R$5+(R$6-R$5)*(POWER(R$7,$B21-1)-1)/(POWER(R$7,$B$3-1)-1) -> 1.0036081 | S21: =S$5+(S$6-S$5)*(POWER(S$7,$B21-1)-1)/(POWER(S$7,$B$3-1)-1) -> 0.012628344 | T21: =T$5+(T$6-T$5)*(POWER(T$7,$B21-1)-1)/(POWER(T$7,$B$3-1)-1) -> 2.035179 | U21: =U$5+(U$6-U$5)*(POWER(U$7,$B21-1)-1)/(POWER(U$7,$B$3-1)-1) -> 1 | V21: =V$5+(V$6-V$5)*(POWER(V$7,$B21-1)-1)/(POWER(V$7,$B$3-1)-1) -> 1.0098375 | ... X21: =X$5+(X$6-X$5)*(POWER(X$7,$B21-1)-1)/(POWER(X$7,$B$3-1)-1) -> 1.0288648 | Y21: =(1+S21*(T21-1))*U21*X21*(O21+P21)*R21*W21 -> 0.54056518 | Z21: =(1+S21*(T21-1))*(O21+P21+Q21)*U21*V21*X21*R21*W21 -> 0.84326609 | AA21: =Z21*L21 -> 3112.3381 | AB21: =M21 -> 1124.3119 | AC21: =N21 -> 749.54125 | AD21: =AC21/(AC21+[1]战斗公式!$M$27) -> 0.030285056 | AE21: =AA21/(1-AD21) -> 3209.5391 | AF21: =AE21/AB21/Y21 -> 5.2808984 | AG21: =AE21/AB21/Z21 -> 3.3852538 | AH21: =AH$5+(AH$6-AH$5)*(POWER(AH$7,$B21-1)-1)/(POWER(AH$7,$B$3-1)-1) -> 1.2683086 | AI21: =$AI$5+($AI$6-$AI$5)*(POWER($AI$7,$B21-1)-1)/(POWER($AI$7,$B$3-1)-1) -> 0.519098 | AJ21: =$AJ$5+($AJ$6-$AJ$5)*(POWER($AJ$7,$B21-1)-1)/(POWER($AJ$7,$B$3-1)-1) -> 1.7247868 | AK21: =$AK$5+($AK$6-$AK$5)*(POWER($AK$7,$B21-1)-1)/(POWER($AK$7,$B$3-1)-1) -> 1.6669926 | AL21: =$AL$5+($AL$6-$AL$5)*(POWER($AL$7,$B21-1)-1)/(POWER($AL$7,$B$3-1)-1) -> 0.80515222 | AM21: =ROUND(AA21/AG21*AH21,0) -> 1166 | AN21: =ROUND(AB21*AI21,0) -> 584 | AO21: =ROUND(AC21,0) -> 750 | AP21: =ROUND(AA21/$AF21*AH21*AK21,0) -> 1246 | AQ21: =ROUND(AN21*AL21,0) -> 470 | AS21: =ROUNDUP(AS$10*$AP21,0) -> 1246 | AT21: =ROUNDUP(AT$10*$AP21,0) -> 3738 | AU21: =ROUNDUP(AU$10*$AP21,0) -> 2243 | AV21: =ROUNDUP(AV$10*$AP21,0) -> 623 | AW21: =ROUNDUP(AW$10*$AP21,0) -> 187 | AX21: =ROUNDUP(AX$10*$AP21,0) -> 4984 | AY21: =ROUNDUP(AY$10*$AP21,0) -> 11214 | AZ21: =ROUND(AM21*$AZ$10*AJ21,0) -> 120666 | BA21: =ROUND(AM21*$BA$10*AJ21,0) -> 60333 | BC21: =B21 -> 10
B22: 11 | C22: =C$5+(C$6-C$5)*(POWER(C$7,$B22-1)-1)/(POWER(C$7,$B$3-1)-1) -> 869.19317 | D22: =D$5+(D$6-D$5)*(POWER(D$7,$B22-1)-1)/(POWER(D$7,$B$3-1)-1) -> 260.75795 | E22: =E$5+(E$6-E$5)*(POWER(E$7,$B22-1)-1)/(POWER(E$7,$B$3-1)-1) -> 173.83863 | F22: =F$5+(F$6-F$5)*(POWER(F$7,$B22-1)-1)/(POWER(F$7,$B$3-1)-1) -> 3190.7091 | G22: =G$5+(G$6-G$5)*(POWER(G$7,$B22-1)-1)/(POWER(G$7,$B$3-1)-1) -> 957.21273 | H22: =H$5+(H$6-H$5)*(POWER(H$7,$B22-1)-1)/(POWER(H$7,$B$3-1)-1) -> 638.14182 | I22: =I$5+(I$6-I$5)*(POWER(I$7,$B22-1)-1)/(POWER(I$7,$B$3-1)-1) -> 0 | J22: =[1]标准模型!$I$65/1*$B22/$B$3 -> 0.0792 | K22: =J22*[1]标准模型!$J$63 -> 0.0792 | L22: =C22*(1+I22)+F22 -> 4059.9023 | M22: =D22*(1+J22)+G22 -> 1238.6227 | N22: =E22*(1+K22)+H22 -> 825.74848 | O22: =O$5+(O$6-O$5)*(POWER(O$7,$B22-1)-1)/(POWER(O$7,$B$3-1)-1) -> 0.51002249 | P22: =P$5+(P$6-P$5)*(POWER(P$7,$B22-1)-1)/(POWER(P$7,$B$3-1)-1) -> 0.0054291171 | Q22: =Q$5+(Q$6-Q$5)*(POWER(Q$7,$B22-1)-1)/(POWER(Q$7,$B$3-1)-1) -> 0.28051237 | R22: =R$5+(R$6-R$5)*(POWER(R$7,$B22-1)-1)/(POWER(R$7,$B$3-1)-1) -> 1.004009 | S22: =S$5+(S$6-S$5)*(POWER(S$7,$B22-1)-1)/(POWER(S$7,$B$3-1)-1) -> 0.014031486 | T22: =T$5+(T$6-T$5)*(POWER(T$7,$B22-1)-1)/(POWER(T$7,$B$3-1)-1) -> 2.0390877 | U22: =U$5+(U$6-U$5)*(POWER(U$7,$B22-1)-1)/(POWER(U$7,$B$3-1)-1) -> 1 | V22: =V$5+(V$6-V$5)*(POWER(V$7,$B22-1)-1)/(POWER(V$7,$B$3-1)-1) -> 1.0109305 | ... X22: =X$5+(X$6-X$5)*(POWER(X$7,$B22-1)-1)/(POWER(X$7,$B$3-1)-1) -> 1.032072 | Y22: =(1+S22*(T22-1))*U22*X22*(O22+P22)*R22*W22 -> 0.54524554 | Z22: =(1+S22*(T22-1))*(O22+P22+Q22)*U22*V22*X22*R22*W22 -> 0.85117516 | AA22: =Z22*L22 -> 3455.688 | AB22: =M22 -> 1238.6227 | AC22: =N22 -> 825.74848 | AD22: =AC22/(AC22+[1]战斗公式!$M$27) -> 0.033261776 | AE22: =AA22/(1-AD22) -> 3574.585 | AF22: =AE22/AB22/Y22 -> 5.2929095 | AG22: =AE22/AB22/Z22 -> 3.3905305 | AH22: =AH$5+(AH$6-AH$5)*(POWER(AH$7,$B22-1)-1)/(POWER(AH$7,$B$3-1)-1) -> 1.297014 | AI22: =$AI$5+($AI$6-$AI$5)*(POWER($AI$7,$B22-1)-1)/(POWER($AI$7,$B$3-1)-1) -> 0.52124128 | AJ22: =$AJ$5+($AJ$6-$AJ$5)*(POWER($AJ$7,$B22-1)-1)/(POWER($AJ$7,$B$3-1)-1) -> 1.6885475 | AK22: =$AK$5+($AK$6-$AK$5)*(POWER($AK$7,$B22-1)-1)/(POWER($AK$7,$B$3-1)-1) -> 1.6536521 | AL22: =$AL$5+($AL$6-$AL$5)*(POWER($AL$7,$B22-1)-1)/(POWER($AL$7,$B$3-1)-1) -> 0.80571613 | AM22: =ROUND(AA22/AG22*AH22,0) -> 1322 | AN22: =ROUND(AB22*AI22,0) -> 646 | AO22: =ROUND(AC22,0) -> 826 | AP22: =ROUND(AA22/$AF22*AH22*AK22,0) -> 1400 | AQ22: =ROUND(AN22*AL22,0) -> 520 | AS22: =ROUNDUP(AS$10*$AP22,0) -> 1400 | AT22: =ROUNDUP(AT$10*$AP22,0) -> 4200 | AU22: =ROUNDUP(AU$10*$AP22,0) -> 2520 | AV22: =ROUNDUP(AV$10*$AP22,0) -> 700 | AW22: =ROUNDUP(AW$10*$AP22,0) -> 210 | AX22: =ROUNDUP(AX$10*$AP22,0) -> 5600 | AY22: =ROUNDUP(AY$10*$AP22,0) -> 12600 | AZ22: =ROUND(AM22*$AZ$10*AJ22,0) -> 133936 | BA22: =ROUND(AM22*$BA$10*AJ22,0) -> 66968 | BC22: =B22 -> 11
B23: 12 | C23: =C$5+(C$6-C$5)*(POWER(C$7,$B23-1)-1)/(POWER(C$7,$B$3-1)-1) -> 948.21205 | D23: =D$5+(D$6-D$5)*(POWER(D$7,$B23-1)-1)/(POWER(D$7,$B$3-1)-1) -> 284.46362 | E23: =E$5+(E$6-E$5)*(POWER(E$7,$B23-1)-1)/(POWER(E$7,$B$3-1)-1) -> 189.64241 | F23: =F$5+(F$6-F$5)*(POWER(F$7,$B23-1)-1)/(POWER(F$7,$B$3-1)-1) -> 3480.7784 | G23: =G$5+(G$6-G$5)*(POWER(G$7,$B23-1)-1)/(POWER(G$7,$B$3-1)-1) -> 1044.2335 | H23: =H$5+(H$6-H$5)*(POWER(H$7,$B23-1)-1)/(POWER(H$7,$B$3-1)-1) -> 696.15568 | I23: =I$5+(I$6-I$5)*(POWER(I$7,$B23-1)-1)/(POWER(I$7,$B$3-1)-1) -> 0 | J23: =[1]标准模型!$I$65/1*$B23/$B$3 -> 0.0864 | K23: =J23*[1]标准模型!$J$63 -> 0.0864 | L23: =C23*(1+I23)+F23 -> 4428.9905 | M23: =D23*(1+J23)+G23 -> 1353.2748 | N23: =E23*(1+K23)+H23 -> 902.1832 | O23: =O$5+(O$6-O$5)*(POWER(O$7,$B23-1)-1)/(POWER(O$7,$B$3-1)-1) -> 0.51102473 | P23: =P$5+(P$6-P$5)*(POWER(P$7,$B23-1)-1)/(POWER(P$7,$B$3-1)-1) -> 0.0059765179 | Q23: =Q$5+(Q$6-Q$5)*(POWER(Q$7,$B23-1)-1)/(POWER(Q$7,$B$3-1)-1) -> 0.2810636 | R23: =R$5+(R$6-R$5)*(POWER(R$7,$B23-1)-1)/(POWER(R$7,$B$3-1)-1) -> 1.0044099 | S23: =S$5+(S$6-S$5)*(POWER(S$7,$B23-1)-1)/(POWER(S$7,$B$3-1)-1) -> 0.015434627 | T23: =T$5+(T$6-T$5)*(POWER(T$7,$B23-1)-1)/(POWER(T$7,$B$3-1)-1) -> 2.0429965 | U23: =U$5+(U$6-U$5)*(POWER(U$7,$B23-1)-1)/(POWER(U$7,$B$3-1)-1) -> 1 | V23: =V$5+(V$6-V$5)*(POWER(V$7,$B23-1)-1)/(POWER(V$7,$B$3-1)-1) -> 1.0120236 | ... X23: =X$5+(X$6-X$5)*(POWER(X$7,$B23-1)-1)/(POWER(X$7,$B$3-1)-1) -> 1.0352791 | Y23: =(1+S23*(T23-1))*U23*X23*(O23+P23)*R23*W23 -> 0.54996145 | Z23: =(1+S23*(T23-1))*(O23+P23+Q23)*U23*V23*X23*R23*W23 -> 0.85915093 | AA23: =Z23*L23 -> 3805.1713 | AB23: =M23 -> 1353.2748 | AC23: =N23 -> 902.1832 | AD23: =AC23/(AC23+[1]战斗公式!$M$27) -> 0.03622908 | AE23: =AA23/(1-AD23) -> 3948.2113 | AF23: =AE23/AB23/Y23 -> 5.3049604 | AG23: =AE23/AB23/Z23 -> 3.3958221 | AH23: =AH$5+(AH$6-AH$5)*(POWER(AH$7,$B23-1)-1)/(POWER(AH$7,$B$3-1)-1) -> 1.325504 | AI23: =$AI$5+($AI$6-$AI$5)*(POWER($AI$7,$B23-1)-1)/(POWER($AI$7,$B$3-1)-1) -> 0.52338884 | AJ23: =$AJ$5+($AJ$6-$AJ$5)*(POWER($AJ$7,$B23-1)-1)/(POWER($AJ$7,$B$3-1)-1) -> 1.6541201 | AK23: =$AK$5+($AK$6-$AK$5)*(POWER($AK$7,$B23-1)-1)/(POWER($AK$7,$B$3-1)-1) -> 1.6405784 | AL23: =$AL$5+($AL$6-$AL$5)*(POWER($AL$7,$B23-1)-1)/(POWER($AL$7,$B$3-1)-1) -> 0.80627836 | AM23: =ROUND(AA23/AG23*AH23,0) -> 1485 | AN23: =ROUND(AB23*AI23,0) -> 708 | AO23: =ROUND(AC23,0) -> 902 | AP23: =ROUND(AA23/$AF23*AH23*AK23,0) -> 1560 | AQ23: =ROUND(AN23*AL23,0) -> 571 | AS23: =ROUNDUP(AS$10*$AP23,0) -> 1560 | AT23: =ROUNDUP(AT$10*$AP23,0) -> 4680 | AU23: =ROUNDUP(AU$10*$AP23,0) -> 2808 | AV23: =ROUNDUP(AV$10*$AP23,0) -> 780 | AW23: =ROUNDUP(AW$10*$AP23,0) -> 234 | AX23: =ROUNDUP(AX$10*$AP23,0) -> 6240 | AY23: =ROUNDUP(AY$10*$AP23,0) -> 14040 | AZ23: =ROUND(AM23*$AZ$10*AJ23,0) -> 147382 | BA23: =ROUND(AM23*$BA$10*AJ23,0) -> 73691 | BC23: =B23 -> 12
B24: 13 | C24: =C$5+(C$6-C$5)*(POWER(C$7,$B24-1)-1)/(POWER(C$7,$B$3-1)-1) -> 1027.2309 | D24: =D$5+(D$6-D$5)*(POWER(D$7,$B24-1)-1)/(POWER(D$7,$B$3-1)-1) -> 308.16926 | E24: =E$5+(E$6-E$5)*(POWER(E$7,$B24-1)-1)/(POWER(E$7,$B$3-1)-1) -> 205.44617 | F24: =F$5+(F$6-F$5)*(POWER(F$7,$B24-1)-1)/(POWER(F$7,$B$3-1)-1) -> 3770.8474 | G24: =G$5+(G$6-G$5)*(POWER(G$7,$B24-1)-1)/(POWER(G$7,$B$3-1)-1) -> 1131.2542 | H24: =H$5+(H$6-H$5)*(POWER(H$7,$B24-1)-1)/(POWER(H$7,$B$3-1)-1) -> 754.16949 | I24: =I$5+(I$6-I$5)*(POWER(I$7,$B24-1)-1)/(POWER(I$7,$B$3-1)-1) -> 0 | J24: =[1]标准模型!$I$65/1*$B24/$B$3 -> 0.0936 | K24: =J24*[1]标准模型!$J$63 -> 0.0936 | L24: =C24*(1+I24)+F24 -> 4798.0783 | M24: =D24*(1+J24)+G24 -> 1468.2681 | N24: =E24*(1+K24)+H24 -> 978.84542 | O24: =O$5+(O$6-O$5)*(POWER(O$7,$B24-1)-1)/(POWER(O$7,$B$3-1)-1) -> 0.51202698 | P24: =P$5+(P$6-P$5)*(POWER(P$7,$B24-1)-1)/(POWER(P$7,$B$3-1)-1) -> 0.0065247398 | Q24: =Q$5+(Q$6-Q$5)*(POWER(Q$7,$B24-1)-1)/(POWER(Q$7,$B$3-1)-1) -> 0.28161484 | R24: =R$5+(R$6-R$5)*(POWER(R$7,$B24-1)-1)/(POWER(R$7,$B$3-1)-1) -> 1.0048108 | S24: =S$5+(S$6-S$5)*(POWER(S$7,$B24-1)-1)/(POWER(S$7,$B$3-1)-1) -> 0.016837767 | T24: =T$5+(T$6-T$5)*(POWER(T$7,$B24-1)-1)/(POWER(T$7,$B$3-1)-1) -> 2.0469052 | U24: =U$5+(U$6-U$5)*(POWER(U$7,$B24-1)-1)/(POWER(U$7,$B$3-1)-1) -> 1 | V24: =V$5+(V$6-V$5)*(POWER(V$7,$B24-1)-1)/(POWER(V$7,$B$3-1)-1) -> 1.0131166 | ... X24: =X$5+(X$6-X$5)*(POWER(X$7,$B24-1)-1)/(POWER(X$7,$B$3-1)-1) -> 1.0384863 | Y24: =(1+S24*(T24-1))*U24*X24*(O24+P24)*R24*W24 -> 0.55471316 | Z24: =(1+S24*(T24-1))*(O24+P24+Q24)*U24*V24*X24*R24*W24 -> 0.86719391 | AA24: =Z24*L24 -> 4160.8643 | AB24: =M24 -> 1468.2681 | AC24: =N24 -> 978.84542 | AD24: =AC24/(AC24+[1]战斗公式!$M$27) -> 0.039186976 | AE24: =AA24/(1-AD24) -> 4330.5661 | AF24: =AE24/AB24/Y24 -> 5.317051 | AG24: =AE24/AB24/Z24 -> 3.4011288 | AH24: =AH$5+(AH$6-AH$5)*(POWER(AH$7,$B24-1)-1)/(POWER(AH$7,$B$3-1)-1) -> 1.3537804 | AI24: =$AI$5+($AI$6-$AI$5)*(POWER($AI$7,$B24-1)-1)/(POWER($AI$7,$B$3-1)-1) -> 0.5255407 | AJ24: =$AJ$5+($AJ$6-$AJ$5)*(POWER($AJ$7,$B24-1)-1)/(POWER($AJ$7,$B$3-1)-1) -> 1.6214141 | AK24: =$AK$5+($AK$6-$AK$5)*(POWER($AK$7,$B24-1)-1)/(POWER($AK$7,$B$3-1)-1) -> 1.6277662 | AL24: =$AL$5+($AL$6-$AL$5)*(POWER($AL$7,$B24-1)-1)/(POWER($AL$7,$B$3-1)-1) -> 0.80683889 | AM24: =ROUND(AA24/AG24*AH24,0) -> 1656 | AN24: =ROUND(AB24*AI24,0) -> 772 | AO24: =ROUND(AC24,0) -> 979 | AP24: =ROUND(AA24/$AF24*AH24*AK24,0) -> 1724 | AQ24: =ROUND(AN24*AL24,0) -> 623 | AS24: =ROUNDUP(AS$10*$AP24,0) -> 1724 | AT24: =ROUNDUP(AT$10*$AP24,0) -> 5172 | AU24: =ROUNDUP(AU$10*$AP24,0) -> 3104 | AV24: =ROUNDUP(AV$10*$AP24,0) -> 862 | AW24: =ROUNDUP(AW$10*$AP24,0) -> 259 | AX24: =ROUNDUP(AX$10*$AP24,0) -> 6896 | AY24: =ROUNDUP(AY$10*$AP24,0) -> 15516 | AZ24: =ROUND(AM24*$AZ$10*AJ24,0) -> 161104 | BA24: =ROUND(AM24*$BA$10*AJ24,0) -> 80552 | BC24: =B24 -> 13
... B511: 500 | C511: =C$5+(C$6-C$5)*(POWER(C$7,$B511-1)-1)/(POWER(C$7,$B$3-1)-1) -> 39500 | D511: =D$5+(D$6-D$5)*(POWER(D$7,$B511-1)-1)/(POWER(D$7,$B$3-1)-1) -> 11850 | E511: =E$5+(E$6-E$5)*(POWER(E$7,$B511-1)-1)/(POWER(E$7,$B$3-1)-1) -> 7900 | F511: =F$5+(F$6-F$5)*(POWER(F$7,$B511-1)-1)/(POWER(F$7,$B$3-1)-1) -> 145000 | G511: =G$5+(G$6-G$5)*(POWER(G$7,$B511-1)-1)/(POWER(G$7,$B$3-1)-1) -> 43500 | H511: =H$5+(H$6-H$5)*(POWER(H$7,$B511-1)-1)/(POWER(H$7,$B$3-1)-1) -> 29000 | I511: =I$5+(I$6-I$5)*(POWER(I$7,$B511-1)-1)/(POWER(I$7,$B$3-1)-1) -> 0 | J511: =[1]标准模型!$I$65/1*$B511/$B$3 -> 3.6 | K511: =J511*[1]标准模型!$J$63 -> 3.6 | L511: =C511*(1+I511)+F511 -> 184500 | M511: =D511*(1+J511)+G511 -> 98010 | N511: =E511*(1+K511)+H511 -> 65340 | O511: =O$5+(O$6-O$5)*(POWER(O$7,$B511-1)-1)/(POWER(O$7,$B$3-1)-1) -> 1 | P511: =P$5+(P$6-P$5)*(POWER(P$7,$B511-1)-1)/(POWER(P$7,$B$3-1)-1) -> 0.4 | Q511: =Q$5+(Q$6-Q$5)*(POWER(Q$7,$B511-1)-1)/(POWER(Q$7,$B$3-1)-1) -> 0.55 | R511: =R$5+(R$6-R$5)*(POWER(R$7,$B511-1)-1)/(POWER(R$7,$B$3-1)-1) -> 1.2 | S511: =S$5+(S$6-S$5)*(POWER(S$7,$B511-1)-1)/(POWER(S$7,$B$3-1)-1) -> 0.7 | T511: =T$5+(T$6-T$5)*(POWER(T$7,$B511-1)-1)/(POWER(T$7,$B$3-1)-1) -> 3.95 | U511: =U$5+(U$6-U$5)*(POWER(U$7,$B511-1)-1)/(POWER(U$7,$B$3-1)-1) -> 1 | V511: =V$5+(V$6-V$5)*(POWER(V$7,$B511-1)-1)/(POWER(V$7,$B$3-1)-1) -> 1.5452991 | ... X511: =X$5+(X$6-X$5)*(POWER(X$7,$B511-1)-1)/(POWER(X$7,$B$3-1)-1) -> 2.6 | Y511: =(1+S511*(T511-1))*U511*X511*(O511+P511)*R511*W511 -> 17.50728 | Z511: =(1+S511*(T511-1))*(O511+P511+Q511)*U511*V511*X511*R511*W511 -> 37.682336 | AA511: =Z511*L511 -> 6952391 | AB511: =M511 -> 98010 | AC511: =N511 -> 65340 | AD511: =AC511/(AC511+[1]战斗公式!$M$27) -> 0.73136333 | AE511: =AA511/(1-AD511) -> 25880275 | AF511: =AE511/AB511/Y511 -> 15.082726 | AG511: =AE511/AB511/Z511 -> 7.007461 | AH511: =AH$5+(AH$6-AH$5)*(POWER(AH$7,$B511-1)-1)/(POWER(AH$7,$B$3-1)-1) -> 5 | AI511: =$AI$5+($AI$6-$AI$5)*(POWER($AI$7,$B511-1)-1)/(POWER($AI$7,$B$3-1)-1) -> 2.3 | AJ511: =$AJ$5+($AJ$6-$AJ$5)*(POWER($AJ$7,$B511-1)-1)/(POWER($AJ$7,$B$3-1)-1) -> 1 | AK511: =$AK$5+($AK$6-$AK$5)*(POWER($AK$7,$B511-1)-1)/(POWER($AK$7,$B$3-1)-1) -> 1 | AL511: =$AL$5+($AL$6-$AL$5)*(POWER($AL$7,$B511-1)-1)/(POWER($AL$7,$B$3-1)-1) -> 0.95 | AM511: =ROUND(AA511/AG511*AH511,0) -> 4960706 | AN511: =ROUND(AB511*AI511,0) -> 225423 | AO511: =ROUND(AC511,0) -> 65340 | AP511: =ROUND(AA511/$AF511*AH511*AK511,0) -> 2304753 | AQ511: =ROUND(AN511*AL511,0) -> 214152 | AS511: =ROUNDUP(AS$10*$AP511,0) -> 2304753 | AT511: =ROUNDUP(AT$10*$AP511,0) -> 6914259 | AU511: =ROUNDUP(AU$10*$AP511,0) -> 4148556 | AV511: =ROUNDUP(AV$10*$AP511,0) -> 1152377 | AW511: =ROUNDUP(AW$10*$AP511,0) -> 345713 | AX511: =ROUNDUP(AX$10*$AP511,0) -> 9219012 | AY511: =ROUNDUP(AY$10*$AP511,0) -> 20742777 | AZ511: =ROUND(AM511*$AZ$10*AJ511,0) -> 297642360 | BA511: =ROUND(AM511*$BA$10*AJ511,0) -> 148821180 | BC511: =B511 -> 500

Sheet 技能系数
B2: 技能系数 | C2: 2 | G2: 技能系数计算 | J2: 拆分系数 | N2: 品质系数 | Q2: 攻血比
B3: 技能当前品质 | C3: SSR
B4: 单体伤害 | G4: 基础技能系数 | H4: =[1]标准模型!H81 -> 2 | J4: 1 | K4: 0.7 | L4: =$L$7/$K$7*K4 -> 4.76 | N4: R | O4: 0.9 | Q4: 血量 | R4: 12 | S4: =$S$5*$R$5/R4 -> 0.25
B5: 单体系数 | C5: 1 | G5: 基础冷却时间 | H5: =预计投放属性数值!C33 -> 10 | J5: 2 | K5: 0.8 | L5: =$L$7/$K$7*K5 -> 5.44 | N5: SR | O5: 0.95 | Q5: 攻击 | R5: 3 | S5: 1
B6: 品质系数 | C6: =$C$3 -> SSR | D6: =VLOOKUP(C6,$N$4:$O$6,2,0) -> 1 | G6: 实际冷却时间 | H6: 10 | J6: 3 | K6: 0.9 | L6: =$L$7/$K$7*K6 -> 6.12 | N6: SSR | O6: 1 | Q6: 防御 | R6: 2 | S6: =$S$5*$R$5/R6 -> 1.5
B7: 攻速 | C7: 1 | G7: 最终技能系数 | H7: =H4*H6/H5 -> 2 | J7: 4 | K7: 1 | L7: 6.8
B8: 伤害系数 | C8: =C5/C7*D6*C2 -> 2 | G8: 普攻基础系数 | H8: =100% -> 1
G9: 必杀基础系数 | H9: =预计投放属性数值!C47 -> 16.5
B10: 穿透子弹
B11: 穿透子弹系数 | C11: 0.7
B12: 品质系数 | C12: =$C$3 -> SSR | D12: =VLOOKUP(C12,$N$4:$O$6,2,0) -> 1
B13: 攻速 | C13: 1
B14: 伤害系数 | C14: =C11/C13*D12*C2 -> 1.4
B16: 跟踪子弹 | N16: 普攻、必杀系数 | O16: 0.5 | P16: 0.65 | Q16: 0.8 | R16: 1
B17: 跟踪子弹系数 | C17: 0.93
B18: 品质系数 | C18: =$C$3 -> SSR | D18: =VLOOKUP(C18,$N$4:$O$6,2,0) -> 1 | N18: 技能系数 | O18: 0.5 | P18: 0.75 | Q18: 1
B19: 攻速 | C19: 1 | T19: %/ | U19: %
B20: 伤害系数 | C20: =C17/C19*D18*C2 -> 1.86 | O20: =MROUND($R$20*O16,5) -> 25 | P20: =MROUND($R$20*P16,5) -> 35 | Q20: =MROUND($R$20*Q16,5) -> 40 | R20: 50 | T20: =_xlfn.CONCAT(O20,$T$19,P20,$T$19,Q20,$T$19,R20,$U$19) -> 25%/35%/40%/50%
O22: =MROUND(O18*$R$20,5) -> 25 | P22: =MROUND(P18*$R$20,5) -> 40 | Q22: =MROUND(Q18*$R$20,5) -> 50 | T22: =_xlfn.CONCAT(O22,$T$19,P22,$T$19,Q22,$U$19) -> 25%/40%/50%
B23: AOE子弹
B24: AOE系数 | C24: 0.75
B25: 品质系数 | C25: =$C$3 -> SSR | D25: =VLOOKUP(C25,$N$4:$O$6,2,0) -> 1
B26: 标准范围半径 | C26: 1
B27: 实际范围半径（标准倍数） | C27: 1
B28: 衰减系数 | C28: 1.2
B29: 攻速 | C29: 1
B30: 伤害系数 | C30: =POWER(C26,C28)/POWER(C27,C28)*C24*D25*C2/C29 -> 1.5
B32: DOT
B33: DOT系数 | C33: 1.2
B34: 品质系数 | C34: =$C$3 -> SSR | D34: =VLOOKUP(C34,$N$4:$O$6,2,0) -> 1
B35: DOT持续时间 | C35: 5
B36: DOT标准持续时间 | C36: 5
B37: DOT持续系数 | C37: 1.39 | D37: =POWER(C35,C37)/POWER(C36,C37)/C35*C36 -> 1
B38: DOT标准最大层数 | C38: 5
B39: DOT最大层数 | C39: 2
B40: DOT最大层数系数 | C40: 1.21 | D40: =POWER(C38,C40)/POWER(C39,C40)*C39/C38 -> 1.2121808
B41: DOT单层系数 | C41: =C33/C35*D37*D40*D34*C2 -> 0.58184679
B44: 回血
B45: 回血系数 | C45: 0.14
B46: 品质系数 | C46: =$C$3 -> SSR | D46: =VLOOKUP(C46,$N$4:$O$6,2,0) -> 1
...
