Workbook

Sheet 角色抽卡概率
H2: 基础概率 | I2: 实际概率 | K2: 首次抽到 | L2: 非首次抽到 | N2: 价值 | O2: 未抽满单抽数量 | P2: 单抽数量
B3: 角色星级 | C3: 升到下一星级需要角色 | F3: 抽卡概率设定 | G3: SSR | H3: 0.01 | I3: =1/G10 -> 0.019795656 | J3: 抽卡大代币 | K3: 2 | L3: 10 | N3: =I3*[1]道具定价!$F$15*L3 -> 2.9693484 | O3: =L3*I3 -> 0.19795656 | P3: =L3*I3 -> 0.19795656
B4: 0 | C4: 1 | G4: SR | H4: 0.1 | I4: =K28*H4/(H3+H4) -> 0.14531023 | J4: 抽卡大代币 | K4: 1 | L4: 3 | N4: =I4*[1]道具定价!$F$16*L4 -> 0.65389603 | O4: =I4*L4 -> 0.43593069 | P4: =L4*I4 -> 0.43593069
B5: 1 | C5: 1 | G5: R | H5: =1-H4-H3 -> 0.89 | I5: =1-I4-I3 -> 0.83489412 | J5: 抽卡小代币 | K5: 3 | L5: 6 | N5: =I5*[1]道具定价!$F$17*L5 -> 5.0093647 | O5: =I5*L5 -> 5.0093647 | P5: =L5*I5 -> 5.0093647
B6: 2 | C6: 1 | N6: =SUM(N3:N5) -> 8.6326091
B7: 3 | C7: 1 | F7: 十连保底1个SR
B8: 4 | C8: 1 | F8: 单抽定价 | G8: 150 | H8: 钻石 | N8: 单抽代币数量 | O8: 前期 | P8: 后期 | Q8: 大后期
B9: 5 | C9: 1 | F9: 保底次数 | G9: 70 | N9: 抽卡大代币 | O9: =O4 -> 0.43593069 | P9: =P4+O3 -> 0.63388724 | Q9: =P4+P3 -> 0.63388724
B10: 6 | C10: 0 | F10: 期望次数 | G10: {=SUMPRODUCT(_xlfn.ANCHORARRAY(F16),G16:G85)} -> 50.516134 | N10: 抽卡小代币 | O10: =P5 -> 5.0093647 | P10: =P5 -> 5.0093647 | Q10: =P5 -> 5.0093647
F11: SSR角色价值 | G11: =G8*G10 -> 7577.4201 | H11: 钻石
F12: SR角色价值 | G12: =G11/H4*H3 -> 757.74201 | H12: 钻石
F13: R角色价值 | G13: =G11/H5*H3 -> 85.139552 | H13: 钻石 | J13: SR/SSR10连概率
F15: 抽卡次数 | G15: 概率 | H15: 不出概率 | J15: 抽卡次数 | K15: 概率 | L15: 不出概率
F16: {=_xlfn.SEQUENCE(G9,1,1,1)} -> 1 | G16: =$H$3 -> 0.01 | H16: =1-G16 -> 0.99 | J16: 1 | K16: =H3+H4 -> 0.11 | L16: =1-K16 -> 0.89
F17: 2 | G17: =$H$3*H16 -> 0.0099 | H17: =POWER(1-$H$3,F17) -> 0.9801 | J17: 2 | K17: =$K$16*L16 -> 0.0979 | L17: =POWER(1-K$16,J17) -> 0.7921
F18: 3 | G18: =$H$3*H17 -> 0.009801 | H18: =POWER(1-$H$3,F18) -> 0.970299 | J18: 3 | K18: =$K$16*L17 -> 0.087131 | L18: =POWER(1-K$16,J18) -> 0.704969
F19: 4 | G19: =$H$3*H18 -> 0.00970299 | H19: =POWER(1-$H$3,F19) -> 0.96059601 | J19: 4 | K19: =$K$16*L18 -> 0.07754659 | L19: =POWER(1-K$16,J19) -> 0.62742241
F20: 5 | G20: =$H$3*H19 -> 0.0096059601 | H20: =POWER(1-$H$3,F20) -> 0.95099005 | J20: 5 | K20: =$K$16*L19 -> 0.069016465 | L20: =POWER(1-K$16,J20) -> 0.55840594
F21: 6 | G21: =$H$3*H20 -> 0.0095099005 | H21: =POWER(1-$H$3,F21) -> 0.94148015 | J21: 6 | K21: =$K$16*L20 -> 0.061424654 | L21: =POWER(1-K$16,J21) -> 0.49698129
F22: 7 | G22: =$H$3*H21 -> 0.0094148015 | H22: =POWER(1-$H$3,F22) -> 0.93206535 | J22: 7 | K22: =$K$16*L21 -> 0.054667942 | L22: =POWER(1-K$16,J22) -> 0.44231335 | N22: 抽卡额外货币规则
F23: 8 | G23: =$H$3*H22 -> 0.0093206535 | H23: =POWER(1-$H$3,F23) -> 0.92274469 | J23: 8 | K23: =$K$16*L22 -> 0.048654468 | L23: =POWER(1-K$16,J23) -> 0.39365888 | N23: 抽到角色时，根据已经抽到的角色数量和角色品质给予一定的额外货币（可配置）
F24: 9 | G24: =$H$3*H23 -> 0.0092274469 | H24: =POWER(1-$H$3,F24) -> 0.91351725 | J24: 9 | K24: =$K$16*L23 -> 0.043302477 | L24: =POWER(1-K$16,J24) -> 0.3503564
F25: 10 | G25: =$H$3*H24 -> 0.0091351725 | H25: =POWER(1-$H$3,F25) -> 0.90438208 | J25: 10 | K25: =1-SUM(K16:K24) -> 0.3503564 | N25: 该额外货币可以在抽卡商店兑换道具，主要兑换的内容是部分养成材料和抽卡道具（限量）
F26: 11 | G26: =$H$3*H25 -> 0.0090438208 | H26: =POWER(1-$H$3,F26) -> 0.89533825
F27: 12 | G27: =$H$3*H26 -> 0.0089533825 | H27: =POWER(1-$H$3,F27) -> 0.88638487 | K27: {=SUMPRODUCT(J16:J25,K16:K25)} -> 6.2562073
F28: 13 | G28: =$H$3*H27 -> 0.0088638487 | H28: =POWER(1-$H$3,F28) -> 0.87752102 | K28: =1/K27 -> 0.15984125
F29: 14 | G29: =$H$3*H28 -> 0.0087752102 | H29: =POWER(1-$H$3,F29) -> 0.86874581
F30: 15 | G30: =$H$3*H29 -> 0.0086874581 | H30: =POWER(1-$H$3,F30) -> 0.86005835
F31: 16 | G31: =$H$3*H30 -> 0.0086005835 | H31: =POWER(1-$H$3,F31) -> 0.85145777
F32: 17 | G32: =$H$3*H31 -> 0.0085145777 | H32: =POWER(1-$H$3,F32) -> 0.84294319
F33: 18 | G33: =$H$3*H32 -> 0.0084294319 | H33: =POWER(1-$H$3,F33) -> 0.83451376
F34: 19 | G34: =$H$3*H33 -> 0.0083451376 | H34: =POWER(1-$H$3,F34) -> 0.82616862
F35: 20 | G35: =$H$3*H34 -> 0.0082616862 | H35: =POWER(1-$H$3,F35) -> 0.81790694
F36: 21 | G36: =$H$3*H35 -> 0.0081790694 | H36: =POWER(1-$H$3,F36) -> 0.80972787
F37: 22 | G37: =$H$3*H36 -> 0.0080972787 | H37: =POWER(1-$H$3,F37) -> 0.80163059
F38: 23 | G38: =$H$3*H37 -> 0.0080163059 | H38: =POWER(1-$H$3,F38) -> 0.79361428
F39: 24 | G39: =$H$3*H38 -> 0.0079361428 | H39: =POWER(1-$H$3,F39) -> 0.78567814
F40: 25 | G40: =$H$3*H39 -> 0.0078567814 | H40: =POWER(1-$H$3,F40) -> 0.77782136
... F84: 69 | G84: =$H$3*H83 -> 0.0050488589 | H84: =POWER(1-$H$3,F84) -> 0.49983703
F85: 70 | G85: =1-SUM(G16:G84) -> 0.49983703 | H85: =POWER(1-$H$3,F85) -> 0.49483866

Sheet 专武抽卡概率
D2: 基础概率 | E2: 实际概率 | G2: 首次抽到 | H2: 非首次抽到 | J2: 价值 | K2: 未抽满单抽数量 | L2: 单抽数量
B3: 抽卡概率设定 | C3: SSR | D3: 0.02 | E3: =1/C13 -> 0.028471905 | F3: 抽卡大代币 | G3: 2 | H3: 6 | J3: =E3*[1]道具定价!$F$15*H3 -> 2.5624714 | K3: =H3*E3 -> 0.17083143 | L3: =H3*E3 -> 0.17083143
C4: SR | D4: 0.13 | E4: =G38*D4/(D3+D4) -> 0.16186758 | F4: 抽卡大代币 | G4: 1 | H4: 2 | J4: =E4*[1]道具定价!$F$16*H4 -> 0.48560275 | K4: =E4*H4 -> 0.32373517 | L4: =H4*E4 -> 0.32373517
C5: R | D5: =1-D4-D3 -> 0.85 | E5: =1-E3-E4 -> 0.80966051 | F5: 抽卡小代币 | G5: 1 | H5: 4 | J5: =E5*[1]道具定价!$F$17*H5 -> 3.238642 | K5: =E5*H5 -> 3.238642 | L5: =H5*E5 -> 3.238642
J6: =SUM(J3:J5) -> 6.2867162
J8: 单抽代币数量 | K8: 前期 | L8: 后期 | M8: 大后期
J9: 抽卡大代币 | K9: =K4 -> 0.32373517 | L9: =L4+K3 -> 0.4945666 | M9: =L4+L3 -> 0.4945666
J10: 抽卡小代币 | K10: =L5 -> 3.238642 | L10: =L5 -> 3.238642 | M10: =L5 -> 3.238642
B11: 单抽定价 | C11: 150 | D11: 钻石
B12: 保底次数 | C12: 60 | M12: 0.5 | N12: 0.2
B13: 期望次数 | C13: {=SUMPRODUCT(_xlfn.ANCHORARRAY(B17),C17:C76)} -> 35.122343 | L13: SSR | M13: SR | N13: R
B14: SSR专武价值 | C14: =C11*C13 -> 5268.3514 | D14: 钻石 | F14: SR专武价值 | G14: =C14/D4*D3 -> 810.5156 | H14: 钻石 | J14: 专武星级 | K14: 升到下一星级需要专武 | L14: 升到下一星级需要金币 | M14: 升到下一星级需要金币 | N14: 升到下一星级需要金币
F15: R专武价值 | G15: =C14/D5*D3 -> 123.96121 | H15: 钻石 | J15: 1 | K15: 1 | L15: 10000 | M15: =L15*$M$12 -> 5000 | N15: =$N$12*L15 -> 2000
B16: 抽卡次数 | C16: 概率 | D16: 不出概率 | J16: 2 | K16: 1 | L16: 20000 | M16: =L16*$M$12 -> 10000 | N16: =$N$12*L16 -> 4000
B17: {=_xlfn.SEQUENCE(C12,1,1,1)} -> 1 | C17: =$D$3 -> 0.02 | D17: =1-C17 -> 0.98 | J17: 3 | K17: 1 | L17: 50000 | M17: =L17*$M$12 -> 25000 | N17: =$N$12*L17 -> 10000
B18: 2 | C18: =$D$3*D17 -> 0.0196 | D18: =POWER(1-$D$3,B18) -> 0.9604 | J18: 4 | K18: 1 | L18: 80000 | M18: =L18*$M$12 -> 40000 | N18: =$N$12*L18 -> 16000
B19: 3 | C19: =$D$3*D18 -> 0.019208 | D19: =POWER(1-$D$3,B19) -> 0.941192 | J19: 5 | K19: 0
B20: 4 | C20: =$D$3*D19 -> 0.01882384 | D20: =POWER(1-$D$3,B20) -> 0.92236816
B21: 5 | C21: =$D$3*D20 -> 0.018447363 | D21: =POWER(1-$D$3,B21) -> 0.9039208
B22: 6 | C22: =$D$3*D21 -> 0.018078416 | D22: =POWER(1-$D$3,B22) -> 0.88584238
B23: 7 | C23: =$D$3*D22 -> 0.017716848 | D23: =POWER(1-$D$3,B23) -> 0.86812553 | F23: SR/SSR10连概率 | L23: 1,
B24: 8 | C24: =$D$3*D23 -> 0.017362511 | D24: =POWER(1-$D$3,B24) -> 0.85076302 | L24: =_xlfn.CONCAT($L$23,L15) -> 1,10000 | M24: =_xlfn.CONCAT($L$23,M15) -> 1,5000 | N24: =_xlfn.CONCAT($L$23,N15) -> 1,2000
B25: 9 | C25: =$D$3*D24 -> 0.01701526 | D25: =POWER(1-$D$3,B25) -> 0.83374776 | F25: 抽卡次数 | G25: 概率 | H25: 不出概率 | L25: =_xlfn.CONCAT($L$23,L16) -> 1,20000 | M25: =_xlfn.CONCAT($L$23,M16) -> 1,10000 | N25: =_xlfn.CONCAT($L$23,N16) -> 1,4000
B26: 10 | C26: =$D$3*D25 -> 0.016674955 | D26: =POWER(1-$D$3,B26) -> 0.81707281 | F26: 1 | G26: =D3+D4 -> 0.15 | H26: =1-G26 -> 0.85 | L26: =_xlfn.CONCAT($L$23,L17) -> 1,50000 | M26: =_xlfn.CONCAT($L$23,M17) -> 1,25000 | N26: =_xlfn.CONCAT($L$23,N17) -> 1,10000
B27: 11 | C27: =$D$3*D26 -> 0.016341456 | D27: =POWER(1-$D$3,B27) -> 0.80073135 | F27: 2 | G27: =$G$26*H26 -> 0.1275 | H27: =POWER(1-G$26,F27) -> 0.7225 | L27: =_xlfn.CONCAT($L$23,L18) -> 1,80000 | M27: =_xlfn.CONCAT($L$23,M18) -> 1,40000 | N27: =_xlfn.CONCAT($L$23,N18) -> 1,16000
B28: 12 | C28: =$D$3*D27 -> 0.016014627 | D28: =POWER(1-$D$3,B28) -> 0.78471672 | F28: 3 | G28: =$G$26*H27 -> 0.108375 | H28: =POWER(1-G$26,F28) -> 0.614125
B29: 13 | C29: =$D$3*D28 -> 0.015694334 | D29: =POWER(1-$D$3,B29) -> 0.76902239 | F29: 4 | G29: =$G$26*H28 -> 0.09211875 | H29: =POWER(1-G$26,F29) -> 0.52200625
B30: 14 | C30: =$D$3*D29 -> 0.015380448 | D30: =POWER(1-$D$3,B30) -> 0.75364194 | F30: 5 | G30: =$G$26*H29 -> 0.078300938 | H30: =POWER(1-G$26,F30) -> 0.44370531
B31: 15 | C31: =$D$3*D30 -> 0.015072839 | D31: =POWER(1-$D$3,B31) -> 0.7385691 | F31: 6 | G31: =$G$26*H30 -> 0.066555797 | H31: =POWER(1-G$26,F31) -> 0.37714952
B32: 16 | C32: =$D$3*D31 -> 0.014771382 | D32: =POWER(1-$D$3,B32) -> 0.72379772 | F32: 7 | G32: =$G$26*H31 -> 0.056572427 | H32: =POWER(1-G$26,F32) -> 0.32057709
B33: 17 | C33: =$D$3*D32 -> 0.014475954 | D33: =POWER(1-$D$3,B33) -> 0.70932177 | F33: 8 | G33: =$G$26*H32 -> 0.048086563 | H33: =POWER(1-G$26,F33) -> 0.27249053
B34: 18 | C34: =$D$3*D33 -> 0.014186435 | D34: =POWER(1-$D$3,B34) -> 0.69513533 | F34: 9 | G34: =$G$26*H33 -> 0.040873579 | H34: =POWER(1-G$26,F34) -> 0.23161695
B35: 19 | C35: =$D$3*D34 -> 0.013902707 | D35: =POWER(1-$D$3,B35) -> 0.68123262 | F35: 10 | G35: =1-SUM(G26:G34) -> 0.23161695
B36: 20 | C36: =$D$3*D35 -> 0.013624652 | D36: =POWER(1-$D$3,B36) -> 0.66760797
B37: 21 | C37: =$D$3*D36 -> 0.013352159 | D37: =POWER(1-$D$3,B37) -> 0.65425581 | G37: {=SUMPRODUCT(F26:F35,G26:G35)} -> 5.3541706
B38: 22 | C38: =$D$3*D37 -> 0.013085116 | D38: =POWER(1-$D$3,B38) -> 0.6411707 | G38: =1/G37 -> 0.18677029
B39: 23 | C39: =$D$3*D38 -> 0.012823414 | D39: =POWER(1-$D$3,B39) -> 0.62834728
B40: 24 | C40: =$D$3*D39 -> 0.012566946 | D40: =POWER(1-$D$3,B40) -> 0.61578034
B41: 25 | C41: =$D$3*D40 -> 0.012315607 | D41: =POWER(1-$D$3,B41) -> 0.60346473
B42: 26 | C42: =$D$3*D41 -> 0.012069295 | D42: =POWER(1-$D$3,B42) -> 0.59139544
...
