Workbook

Sheet 使用说明
A1: 爬塔 TeamHero 属性配置表
A2: 黄色单元格为可配置输入；其余区域由公式自动生成。
B4: 使用步骤
B6: 1. 在“难度节点”C列黄格调整关键楼层等级；“楼层配置”D列按相邻节点线性插值，100层当前280级。
B7: 2. 如需整体或局部微调，可修改“参数”职业系数、精英怪系数、玩法全局倍率，或楼层E～G三项倍率。
B8: 3. “TeamHero生成”按 TeamHero.CfgId → Hero.HeroClass 自动识别 Tank / DPS / Support，并生成 Hp、Attack、Armor。
B9: 4. “落表结果”按 TeamHero.Id 升序整理；将D～F列以“粘贴值”方式覆盖 TeamHero.xlsx 的 Hp、Attack、Armor。
B10: 5. TeamHero.Level仅作核对，不参与怪物模型等级查找；实际查找使用“楼层配置”的难度等级。
B13: 生成公式
B15: 精英基准 = 普通怪基准 × MonsterAttributeType(200101)：生命×4、攻击×1.2、防御×1。
B16: TeamHero.Hp = 精英生命 × 职业生命系数 × 楼层生命倍率 × 玩法全局生命倍率。
B17: TeamHero.Attack = 精英攻击 × 职业攻击系数 × 楼层攻击倍率 × 玩法全局攻击倍率。
B18: TeamHero.Armor = 精英防御 × 职业防御系数 × 楼层防御倍率 × 玩法全局防御倍率。
B21: 数据来源
... B26: 职业映射：D:\Vgame\Config\GameConfig\Datas\Hero\Hero.xlsx｜HeroClass；生成日期：2026-08-10

Sheet 参数
A1: 爬塔 TeamHero 生成参数
A2: 黄色参数可调；当前职业偏移沿用 TeamHero 现有口径。
A4: 职业 | B4: 生命系数 | C4: 攻击系数 | D4: 防御系数 | E4: 说明 | F4: 来源
A5: Tank | B5: 1.5 | C5: 1 | D5: 1.5 | E5: 高生命、高防御 | F5: 当前TeamHero职业偏移
A6: DPS | B6: 1 | C6: 1.2 | D6: 1 | E6: 高攻击 | F6: 当前TeamHero职业偏移
A7: Support | B7: 1.25 | C7: 1 | D7: 1.25 | E7: 中等生存 | F7: 当前TeamHero职业偏移
A9: 怪物类型 | B9: 生命系数 | C9: 攻击系数 | D9: 防御系数 | E9: AttributeTypeID | F9: 来源
A10: 精英怪 | B10: 4 | C10: 1.2 | D10: 1 | E10: 200101 | F10: D:\Vgame\Config\GameConfig\Datas\Monster\MonsterAttributeType.xlsx
A12: 玩法全局倍率 | B12: 生命 | C12: 攻击 | D12: 防御 | E12: 说明
A13: 爬塔 | B13: 1 | C13: 1 | D13: 1 | E13: 默认1；用于整条曲线统一微调

Sheet 楼层配置
A1: 爬塔楼层难度配置
A2: 等级改“难度节点”C列黄格；D列自动插值，E～G倍率仍可微调。
A4: 状态 | B4: 层数 | C4: TeamId | D4: 难度等级 | E4: 生命倍率 | F4: 攻击倍率 | G4: 防御倍率 | H4: Pack1 LevelId | I4: Pack2 LevelId | J4: Pack3 LevelId | K4: Pack4 LevelId | L4: 全部LevelId | M4: TeamHero数量 | N4: 等级检查 | O4: 等级趋势 | P4: 备注
A5: 当前配置 | B5: 1 | C5: 1 | D5: =ROUND(难度节点!$C$2+($B5-难度节点!$A$2)*(难度节点!$C$3-难度节点!$C$2)/(难度节点!$A$3-难度节点!$A$2),0) -> 15 | E5: 1.0411519 | F5: 0.87879946 | G5: 1 | H5: 300001 | L5: 300001 | M5: =COUNTIF(TeamHero生成!$J$5:$J$504,$C5) -> 5 | N5: =IF(AND(ISNUMBER($D5),$D5>=1,$D5<=500,MOD($D5,1)=0),"有效","无效") -> 有效 | P5: 统一标准模型；只列TowerEnemyFormation未停用的包体1 ID，包体2～4停用引用已清空
A6: 当前配置 | B6: 2 | C6: 2 | D6: =ROUND(难度节点!$C$2+($B6-难度节点!$A$2)*(难度节点!$C$3-难度节点!$C$2)/(难度节点!$A$3-难度节点!$A$2),0) -> 18 | E6: 1.0663889 | F6: 0.88169731 | G6: 1 | H6: 300002 | L6: 300002 | M6: =COUNTIF(TeamHero生成!$J$5:$J$504,$C6) -> 5 | N6: =IF(AND(ISNUMBER($D6),$D6>=1,$D6<=500,MOD($D6,1)=0),"有效","无效") -> 有效 | O6: =IF($D6<$D5,"下降","") | P6: 统一标准模型；只列TowerEnemyFormation未停用的包体1 ID，包体2～4停用引用已清空
A7: 当前配置 | B7: 3 | C7: 3 | D7: =ROUND(难度节点!$C$2+($B7-难度节点!$A$2)*(难度节点!$C$3-难度节点!$C$2)/(难度节点!$A$3-难度节点!$A$2),0) -> 22 | E7: 1.0598272 | F7: 0.86525003 | G7: 1 | H7: 300003 | L7: 300003 | M7: =COUNTIF(TeamHero生成!$J$5:$J$504,$C7) -> 5 | N7: =IF(AND(ISNUMBER($D7),$D7>=1,$D7<=500,MOD($D7,1)=0),"有效","无效") -> 有效 | O7: =IF($D7<$D6,"下降","") | P7: 统一标准模型；只列TowerEnemyFormation未停用的包体1 ID，包体2～4停用引用已清空
A8: 当前配置 | B8: 4 | C8: 4 | D8: =ROUND(难度节点!$C$2+($B8-难度节点!$A$2)*(难度节点!$C$3-难度节点!$C$2)/(难度节点!$A$3-难度节点!$A$2),0) -> 25 | E8: 1.09015 | F8: 0.86749593 | G8: 1 | H8: 300004 | L8: 300004 | M8: =COUNTIF(TeamHero生成!$J$5:$J$504,$C8) -> 5 | N8: =IF(AND(ISNUMBER($D8),$D8>=1,$D8<=500,MOD($D8,1)=0),"有效","无效") -> 有效 | O8: =IF($D8<$D7,"下降","") | P8: 统一标准模型；只列TowerEnemyFormation未停用的包体1 ID，包体2～4停用引用已清空
A9: 当前配置 | B9: 5 | C9: 5 | D9: =ROUND(难度节点!$C$2+($B9-难度节点!$A$2)*(难度节点!$C$3-难度节点!$C$2)/(难度节点!$A$3-难度节点!$A$2),0) -> 28 | E9: 1.0715188 | F9: 0.84741358 | G9: 1 | H9: 300005 | L9: 300005 | M9: =COUNTIF(TeamHero生成!$J$5:$J$504,$C9) -> 5 | N9: =IF(AND(ISNUMBER($D9),$D9>=1,$D9<=500,MOD($D9,1)=0),"有效","无效") -> 有效 | O9: =IF($D9<$D8,"下降","") | P9: 统一标准模型；只列TowerEnemyFormation未停用的包体1 ID，包体2～4停用引用已清空
A10: 当前配置 | B10: 6 | C10: 6 | D10: =ROUND(难度节点!$C$2+($B10-难度节点!$A$2)*(难度节点!$C$3-难度节点!$C$2)/(难度节点!$A$3-难度节点!$A$2),0) -> 32 | E10: 1.0928102 | F10: 0.8355873 | G10: 1 | H10: 300006 | L10: 300006 | M10: =COUNTIF(TeamHero生成!$J$5:$J$504,$C10) -> 5 | N10: =IF(AND(ISNUMBER($D10),$D10>=1,$D10<=500,MOD($D10,1)=0),"有效","无效") -> 有效 | O10: =IF($D10<$D9,"下降","") | P10: 统一标准模型；只列TowerEnemyFormation未停用的包体1 ID，包体2～4停用引用已清空
A11: 当前配置 | B11: 7 | C11: 7 | D11: =ROUND(难度节点!$C$2+($B11-难度节点!$A$2)*(难度节点!$C$3-难度节点!$C$2)/(难度节点!$A$3-难度节点!$A$2),0) -> 35 | E11: 1.103671 | F11: 0.82198923 | G11: 1 | H11: 300007 | L11: 300007 | M11: =COUNTIF(TeamHero生成!$J$5:$J$504,$C11) -> 5 | N11: =IF(AND(ISNUMBER($D11),$D11>=1,$D11<=500,MOD($D11,1)=0),"有效","无效") -> 有效 | O11: =IF($D11<$D10,"下降","") | P11: 统一标准模型；只列TowerEnemyFormation未停用的包体1 ID，包体2～4停用引用已清空
A12: 当前配置 | B12: 8 | C12: 8 | D12: =ROUND(难度节点!$C$2+($B12-难度节点!$A$2)*(难度节点!$C$3-难度节点!$C$2)/(难度节点!$A$3-难度节点!$A$2),0) -> 38 | E12: 1.0863731 | F12: 0.79367059 | G12: 1 | H12: 300008 | L12: 300008 | M12: =COUNTIF(TeamHero生成!$J$5:$J$504,$C12) -> 5 | N12: =IF(AND(ISNUMBER($D12),$D12>=1,$D12<=500,MOD($D12,1)=0),"有效","无效") -> 有效 | O12: =IF($D12<$D11,"下降","") | P12: 统一标准模型；只列TowerEnemyFormation未停用的包体1 ID，包体2～4停用引用已清空
A13: 当前配置 | B13: 9 | C13: 9 | D13: =ROUND(难度节点!$C$2+($B13-难度节点!$A$2)*(难度节点!$C$3-难度节点!$C$2)/(难度节点!$A$3-难度节点!$A$2),0) -> 42 | E13: 1.1075471 | F13: 0.78794838 | G13: 1 | H13: 300009 | L13: 300009 | M13: =COUNTIF(TeamHero生成!$J$5:$J$504,$C13) -> 5 | N13: =IF(AND(ISNUMBER($D13),$D13>=1,$D13<=500,MOD($D13,1)=0),"有效","无效") -> 有效 | O13: =IF($D13<$D12,"下降","") | P13: 统一标准模型；只列TowerEnemyFormation未停用的包体1 ID，包体2～4停用引用已清空
A14: 当前配置 | B14: 10 | C14: 10 | D14: =ROUND(难度节点!$C$2+($B14-难度节点!$A$2)*(难度节点!$C$3-难度节点!$C$2)/(难度节点!$A$3-难度节点!$A$2),0) -> 45 | E14: 1.1319268 | F14: 0.78501188 | G14: 1 | H14: 300011 | L14: 300011 | M14: =COUNTIF(TeamHero生成!$J$5:$J$504,$C14) -> 5 | N14: =IF(AND(ISNUMBER($D14),$D14>=1,$D14<=500,MOD($D14,1)=0),"有效","无效") -> 有效 | O14: =IF($D14<$D13,"下降","") | P14: 统一标准模型；只列TowerEnemyFormation未停用的包体1 ID，包体2～4停用引用已清空
A15: 当前配置 | B15: 11 | C15: 11 | D15: =ROUND(难度节点!$C$3+($B15-难度节点!$A$3)*(难度节点!$C$4-难度节点!$C$3)/(难度节点!$A$4-难度节点!$A$3),0) -> 49 | E15: 1.1302696 | F15: 0.77362222 | G15: 1 | H15: 300012 | L15: 300012 | M15: =COUNTIF(TeamHero生成!$J$5:$J$504,$C15) -> 5 | N15: =IF(AND(ISNUMBER($D15),$D15>=1,$D15<=500,MOD($D15,1)=0),"有效","无效") -> 有效 | O15: =IF($D15<$D14,"下降","") | P15: 统一标准模型；只列TowerEnemyFormation未停用的包体1 ID，包体2～4停用引用已清空
A16: 当前配置 | B16: 12 | C16: 12 | D16: =ROUND(难度节点!$C$3+($B16-难度节点!$A$3)*(难度节点!$C$4-难度节点!$C$3)/(难度节点!$A$4-难度节点!$A$3),0) -> 52 | E16: 1.1319637 | F16: 0.76171845 | G16: 1 | H16: 300013 | L16: 300013 | M16: =COUNTIF(TeamHero生成!$J$5:$J$504,$C16) -> 5 | N16: =IF(AND(ISNUMBER($D16),$D16>=1,$D16<=500,MOD($D16,1)=0),"有效","无效") -> 有效 | O16: =IF($D16<$D15,"下降","") | P16: 统一标准模型；只列TowerEnemyFormation未停用的包体1 ID，包体2～4停用引用已清空
A17: 当前配置 | B17: 13 | C17: 13 | D17: =ROUND(难度节点!$C$3+($B17-难度节点!$A$3)*(难度节点!$C$4-难度节点!$C$3)/(难度节点!$A$4-难度节点!$A$3),0) -> 56 | E17: 1.1237878 | F17: 0.751671 | G17: 1 | H17: 300014 | L17: 300014 | M17: =COUNTIF(TeamHero生成!$J$5:$J$504,$C17) -> 5 | N17: =IF(AND(ISNUMBER($D17),$D17>=1,$D17<=500,MOD($D17,1)=0),"有效","无效") -> 有效 | O17: =IF($D17<$D16,"下降","") | P17: 统一标准模型；只列TowerEnemyFormation未停用的包体1 ID，包体2～4停用引用已清空
A18: 当前配置 | B18: 14 | C18: 14 | D18: =ROUND(难度节点!$C$3+($B18-难度节点!$A$3)*(难度节点!$C$4-难度节点!$C$3)/(难度节点!$A$4-难度节点!$A$3),0) -> 59 | E18: 1.1201058 | F18: 0.73899075 | G18: 1 | H18: 300015 | L18: 300015 | M18: =COUNTIF(TeamHero生成!$J$5:$J$504,$C18) -> 5 | N18: =IF(AND(ISNUMBER($D18),$D18>=1,$D18<=500,MOD($D18,1)=0),"有效","无效") -> 有效 | O18: =IF($D18<$D17,"下降","") | P18: 统一标准模型；只列TowerEnemyFormation未停用的包体1 ID，包体2～4停用引用已清空
A19: 当前配置 | B19: 15 | C19: 15 | D19: =ROUND(难度节点!$C$3+($B19-难度节点!$A$3)*(难度节点!$C$4-难度节点!$C$3)/(难度节点!$A$4-难度节点!$A$3),0) -> 63 | E19: 1.1318191 | F19: 0.73724483 | G19: 1 | H19: 300016 | L19: 300016 | M19: =COUNTIF(TeamHero生成!$J$5:$J$504,$C19) -> 5 | N19: =IF(AND(ISNUMBER($D19),$D19>=1,$D19<=500,MOD($D19,1)=0),"有效","无效") -> 有效 | O19: =IF($D19<$D18,"下降","") | P19: 统一标准模型；只列TowerEnemyFormation未停用的包体1 ID，包体2～4停用引用已清空
A20: 当前配置 | B20: 16 | C20: 16 | D20: =ROUND(难度节点!$C$3+($B20-难度节点!$A$3)*(难度节点!$C$4-难度节点!$C$3)/(难度节点!$A$4-难度节点!$A$3),0) -> 66 | E20: 1.1458169 | F20: 0.73431413 | G20: 1 | H20: 300017 | L20: 300017 | M20: =COUNTIF(TeamHero生成!$J$5:$J$504,$C20) -> 5 | N20: =IF(AND(ISNUMBER($D20),$D20>=1,$D20<=500,MOD($D20,1)=0),"有效","无效") -> 有效 | O20: =IF($D20<$D19,"下降","") | P20: 统一标准模型；只列TowerEnemyFormation未停用的包体1 ID，包体2～4停用引用已清空
A21: 当前配置 | B21: 17 | C21: 17 | D21: =ROUND(难度节点!$C$3+($B21-难度节点!$A$3)*(难度节点!$C$4-难度节点!$C$3)/(难度节点!$A$4-难度节点!$A$3),0) -> 70 | E21: 1.1336283 | F21: 0.72302684 | G21: 1 | H21: 300018 | L21: 300018 | M21: =COUNTIF(TeamHero生成!$J$5:$J$504,$C21) -> 5 | N21: =IF(AND(ISNUMBER($D21),$D21>=1,$D21<=500,MOD($D21,1)=0),"有效","无效") -> 有效 | O21: =IF($D21<$D20,"下降","") | P21: 统一标准模型；只列TowerEnemyFormation未停用的包体1 ID，包体2～4停用引用已清空
A22: 当前配置 | B22: 18 | C22: 18 | D22: =ROUND(难度节点!$C$3+($B22-难度节点!$A$3)*(难度节点!$C$4-难度节点!$C$3)/(难度节点!$A$4-难度节点!$A$3),0) -> 73 | E22: 1.1503681 | F22: 0.72431241 | G22: 1 | H22: 300019 | L22: 300019 | M22: =COUNTIF(TeamHero生成!$J$5:$J$504,$C22) -> 5 | N22: =IF(AND(ISNUMBER($D22),$D22>=1,$D22<=500,MOD($D22,1)=0),"有效","无效") -> 有效 | O22: =IF($D22<$D21,"下降","") | P22: 统一标准模型；只列TowerEnemyFormation未停用的包体1 ID，包体2～4停用引用已清空
A23: 当前配置 | B23: 19 | C23: 19 | D23: =ROUND(难度节点!$C$3+($B23-难度节点!$A$3)*(难度节点!$C$4-难度节点!$C$3)/(难度节点!$A$4-难度节点!$A$3),0) -> 77 | E23: 1.1378215 | F23: 0.71120347 | G23: 1 | H23: 300020 | L23: 300020 | M23: =COUNTIF(TeamHero生成!$J$5:$J$504,$C23) -> 5 | N23: =IF(AND(ISNUMBER($D23),$D23>=1,$D23<=500,MOD($D23,1)=0),"有效","无效") -> 有效 | O23: =IF($D23<$D22,"下降","") | P23: 统一标准模型；只列TowerEnemyFormation未停用的包体1 ID，包体2～4停用引用已清空
A24: 当前配置 | B24: 20 | C24: 20 | D24: =ROUND(难度节点!$C$3+($B24-难度节点!$A$3)*(难度节点!$C$4-难度节点!$C$3)/(难度节点!$A$4-难度节点!$A$3),0) -> 80 | E24: 1.1401954 | F24: 0.70930654 | G24: 1 | H24: 300021 | L24: 300021 | M24: =COUNTIF(TeamHero生成!$J$5:$J$504,$C24) -> 5 | N24: =IF(AND(ISNUMBER($D24),$D24>=1,$D24<=500,MOD($D24,1)=0),"有效","无效") -> 有效 | O24: =IF($D24<$D23,"下降","") | P24: 统一标准模型；只列TowerEnemyFormation未停用的包体1 ID，包体2～4停用引用已清空
A25: 当前配置 | B25: 21 | C25: 21 | D25: =ROUND(难度节点!$C$4+($B25-难度节点!$A$4)*(难度节点!$C$5-难度节点!$C$4)/(难度节点!$A$5-难度节点!$A$4),0) -> 84 | E25: 1.1560373 | F25: 0.70629692 | G25: 1 | H25: 300022 | L25: 300022 | M25: =COUNTIF(TeamHero生成!$J$5:$J$504,$C25) -> 5 | N25: =IF(AND(ISNUMBER($D25),$D25>=1,$D25<=500,MOD($D25,1)=0),"有效","无效") -> 有效 | O25: =IF($D25<$D24,"下降","") | P25: 统一标准模型；只列TowerEnemyFormation未停用的包体1 ID，包体2～4停用引用已清空
A26: 当前配置 | B26: 22 | C26: 22 | D26: =ROUND(难度节点!$C$4+($B26-难度节点!$A$4)*(难度节点!$C$5-难度节点!$C$4)/(难度节点!$A$5-难度节点!$A$4),0) -> 88 | E26: 1.1643979 | F26: 0.70448637 | G26: 1 | H26: 300023 | L26: 300023 | M26: =COUNTIF(TeamHero生成!$J$5:$J$504,$C26) -> 5 | N26: =IF(AND(ISNUMBER($D26),$D26>=1,$D26<=500,MOD($D26,1)=0),"有效","无效") -> 有效 | O26: =IF($D26<$D25,"下降","") | P26: 统一标准模型；只列TowerEnemyFormation未停用的包体1 ID，包体2～4停用引用已清空
A27: 当前配置 | B27: 23 | C27: 23 | D27: =ROUND(难度节点!$C$4+($B27-难度节点!$A$4)*(难度节点!$C$5-难度节点!$C$4)/(难度节点!$A$5-难度节点!$A$4),0) -> 92 | E27: 1.1455862 | F27: 0.69327297 | G27: 1 | H27: 300024 | L27: 300024 | M27: =COUNTIF(TeamHero生成!$J$5:$J$504,$C27) -> 5 | N27: =IF(AND(ISNUMBER($D27),$D27>=1,$D27<=500,MOD($D27,1)=0),"有效","无效") -> 有效 | O27: =IF($D27<$D26,"下降","") | P27: 统一标准模型；只列TowerEnemyFormation未停用的包体1 ID，包体2～4停用引用已清空
A28: 当前配置 | B28: 24 | C28: 24 | D28: =ROUND(难度节点!$C$4+($B28-难度节点!$A$4)*(难度节点!$C$5-难度节点!$C$4)/(难度节点!$A$5-难度节点!$A$4),0) -> 96 | E28: 1.1627278 | F28: 0.69279146 | G28: 1 | H28: 300025 | L28: 300025 | M28: =COUNTIF(TeamHero生成!$J$5:$J$504,$C28) -> 5 | N28: =IF(AND(ISNUMBER($D28),$D28>=1,$D28<=500,MOD($D28,1)=0),"有效","无效") -> 有效 | O28: =IF($D28<$D27,"下降","") | P28: 统一标准模型；只列TowerEnemyFormation未停用的包体1 ID，包体2～4停用引用已清空
A29: 当前配置 | B29: 25 | C29: 25 | D29: =ROUND(难度节点!$C$4+($B29-难度节点!$A$4)*(难度节点!$C$5-难度节点!$C$4)/(难度节点!$A$5-难度节点!$A$4),0) -> 100 | E29: 1.1496943 | F29: 0.6842368 | G29: 1 | H29: 300026 | L29: 300026 | M29: =COUNTIF(TeamHero生成!$J$5:$J$504,$C29) -> 5 | N29: =IF(AND(ISNUMBER($D29),$D29>=1,$D29<=500,MOD($D29,1)=0),"有效","无效") -> 有效 | O29: =IF($D29<$D28,"下降","") | P29: 统一标准模型；只列TowerEnemyFormation未停用的包体1 ID，包体2～4停用引用已清空
A30: 当前配置 | B30: 26 | C30: 26 | D30: =ROUND(难度节点!$C$4+($B30-难度节点!$A$4)*(难度节点!$C$5-难度节点!$C$4)/(难度节点!$A$5-难度节点!$A$4),0) -> 104 | E30: 1.1672412 | F30: 0.68941774 | G30: 1 | H30: 300027 | L30: 300027 | M30: =COUNTIF(TeamHero生成!$J$5:$J$504,$C30) -> 5 | N30: =IF(AND(ISNUMBER($D30),$D30>=1,$D30<=500,MOD($D30,1)=0),"有效","无效") -> 有效 | O30: =IF($D30<$D29,"下降","") | P30: 统一标准模型；只列TowerEnemyFormation未停用的包体1 ID，包体2～4停用引用已清空
A31: 当前配置 | B31: 27 | C31: 27 | D31: =ROUND(难度节点!$C$4+($B31-难度节点!$A$4)*(难度节点!$C$5-难度节点!$C$4)/(难度节点!$A$5-难度节点!$A$4),0) -> 108 | E31: 1.1630315 | F31: 0.68146449 | G31: 1 | H31: 300028 | L31: 300028 | M31: =COUNTIF(TeamHero生成!$J$5:$J$504,$C31) -> 5 | N31: =IF(AND(ISNUMBER($D31),$D31>=1,$D31<=500,MOD($D31,1)=0),"有效","无效") -> 有效 | O31: =IF($D31<$D30,"下降","") | P31: 统一标准模型；只列TowerEnemyFormation未停用的包体1 ID，包体2～4停用引用已清空
A32: 当前配置 | B32: 28 | C32: 28 | D32: =ROUND(难度节点!$C$4+($B32-难度节点!$A$4)*(难度节点!$C$5-难度节点!$C$4)/(难度节点!$A$5-难度节点!$A$4),0) -> 112 | E32: 1.1664009 | F32: 0.68050186 | G32: 1 | H32: 300029 | L32: 300029 | M32: =COUNTIF(TeamHero生成!$J$5:$J$504,$C32) -> 5 | N32: =IF(AND(ISNUMBER($D32),$D32>=1,$D32<=500,MOD($D32,1)=0),"有效","无效") -> 有效 | O32: =IF($D32<$D31,"下降","") | P32: 统一标准模型；只列TowerEnemyFormation未停用的包体1 ID，包体2～4停用引用已清空
A33: 当前配置 | B33: 29 | C33: 29 | D33: =ROUND(难度节点!$C$4+($B33-难度节点!$A$4)*(难度节点!$C$5-难度节点!$C$4)/(难度节点!$A$5-难度节点!$A$4),0) -> 116 | E33: 1.1628408 | F33: 0.67944892 | G33: 1 | H33: 300030 | L33: 300030 | M33: =COUNTIF(TeamHero生成!$J$5:$J$504,$C33) -> 5 | N33: =IF(AND(ISNUMBER($D33),$D33>=1,$D33<=500,MOD($D33,1)=0),"有效","无效") -> 有效 | O33: =IF($D33<$D32,"下降","") | P33: 统一标准模型；只列TowerEnemyFormation未停用的包体1 ID，包体2～4停用引用已清空
A34: 当前配置 | B34: 30 | C34: 30 | D34: =ROUND(难度节点!$C$4+($B34-难度节点!$A$4)*(难度节点!$C$5-难度节点!$C$4)/(难度节点!$A$5-难度节点!$A$4),0) -> 120 | E34: 1.157902 | F34: 0.67548508 | G34: 1 | H34: 300031 | L34: 300031 | M34: =COUNTIF(TeamHero生成!$J$5:$J$504,$C34) -> 5 | N34: =IF(AND(ISNUMBER($D34),$D34>=1,$D34<=500,MOD($D34,1)=0),"有效","无效") -> 有效 | O34: =IF($D34<$D33,"下降","") | P34: 统一标准模型；只列TowerEnemyFormation未停用的包体1 ID，包体2～4停用引用已清空
A35: 当前配置 | B35: 31 | C35: 31 | D35: =ROUND(难度节点!$C$5+($B35-难度节点!$A$5)*(难度节点!$C$6-难度节点!$C$5)/(难度节点!$A$6-难度节点!$A$5),0) -> 124 | E35: 1.1696774 | F35: 0.6763702 | G35: 1 | H35: 300032 | L35: 300032 | M35: =COUNTIF(TeamHero生成!$J$5:$J$504,$C35) -> 5 | N35: =IF(AND(ISNUMBER($D35),$D35>=1,$D35<=500,MOD($D35,1)=0),"有效","无效") -> 有效 | O35: =IF($D35<$D34,"下降","") | P35: 统一标准模型；只列TowerEnemyFormation未停用的包体1 ID，包体2～4停用引用已清空
A36: 当前配置 | B36: 32 | C36: 32 | D36: =ROUND(难度节点!$C$5+($B36-难度节点!$A$5)*(难度节点!$C$6-难度节点!$C$5)/(难度节点!$A$6-难度节点!$A$5),0) -> 128 | E36: 1.173971 | F36: 0.675279 | G36: 1 | H36: 300033 | L36: 300033 | M36: =COUNTIF(TeamHero生成!$J$5:$J$504,$C36) -> 5 | N36: =IF(AND(ISNUMBER($D36),$D36>=1,$D36<=500,MOD($D36,1)=0),"有效","无效") -> 有效 | O36: =IF($D36<$D35,"下降","") | P36: 统一标准模型；只列TowerEnemyFormation未停用的包体1 ID，包体2～4停用引用已清空
A37: 当前配置 | B37: 33 | C37: 33 | D37: =ROUND(难度节点!$C$5+($B37-难度节点!$A$5)*(难度节点!$C$6-难度节点!$C$5)/(难度节点!$A$6-难度节点!$A$5),0) -> 132 | E37: 1.1699448 | F37: 0.6728636 | G37: 1 | H37: 300034 | L37: 300034 | M37: =COUNTIF(TeamHero生成!$J$5:$J$504,$C37) -> 5 | N37: =IF(AND(ISNUMBER($D37),$D37>=1,$D37<=500,MOD($D37,1)=0),"有效","无效") -> 有效 | O37: =IF($D37<$D36,"下降","") | P37: 统一标准模型；只列TowerEnemyFormation未停用的包体1 ID，包体2～4停用引用已清空
A38: 当前配置 | B38: 34 | C38: 34 | D38: =ROUND(难度节点!$C$5+($B38-难度节点!$A$5)*(难度节点!$C$6-难度节点!$C$5)/(难度节点!$A$6-难度节点!$A$5),0) -> 136 | E38: 1.176199 | F38: 0.673957 | G38: 1 | H38: 300035 | L38: 300035 | M38: =COUNTIF(TeamHero生成!$J$5:$J$504,$C38) -> 5 | N38: =IF(AND(ISNUMBER($D38),$D38>=1,$D38<=500,MOD($D38,1)=0),"有效","无效") -> 有效 | O38: =IF($D38<$D37,"下降","") | P38: 统一标准模型；只列TowerEnemyFormation未停用的包体1 ID，包体2～4停用引用已清空
A39: 当前配置 | B39: 35 | C39: 35 | D39: =ROUND(难度节点!$C$5+($B39-难度节点!$A$5)*(难度节点!$C$6-难度节点!$C$5)/(难度节点!$A$6-难度节点!$A$5),0) -> 140 | E39: 1.1630435 | F39: 0.66801095 | G39: 1 | H39: 300036 | L39: 300036 | M39: =COUNTIF(TeamHero生成!$J$5:$J$504,$C39) -> 5 | N39: =IF(AND(ISNUMBER($D39),$D39>=1,$D39<=500,MOD($D39,1)=0),"有效","无效") -> 有效 | O39: =IF($D39<$D38,"下降","") | P39: 统一标准模型；只列TowerEnemyFormation未停用的包体1 ID，包体2～4停用引用已清空
A40: 当前配置 | B40: 36 | C40: 36 | D40: =ROUND(难度节点!$C$5+($B40-难度节点!$A$5)*(难度节点!$C$6-难度节点!$C$5)/(难度节点!$A$6-难度节点!$A$5),0) -> 144 | E40: 1.1754256 | F40: 0.67135959 | G40: 1 | H40: 300037 | L40: 300037 | M40: =COUNTIF(TeamHero生成!$J$5:$J$504,$C40) -> 5 | N40: =IF(AND(ISNUMBER($D40),$D40>=1,$D40<=500,MOD($D40,1)=0),"有效","无效") -> 有效 | O40: =IF($D40<$D39,"下降","") | P40: 统一标准模型；只列TowerEnemyFormation未停用的包体1 ID，包体2～4停用引用已清空
A41: 当前配置 | B41: 37 | C41: 37 | D41: =ROUND(难度节点!$C$5+($B41-难度节点!$A$5)*(难度节点!$C$6-难度节点!$C$5)/(难度节点!$A$6-难度节点!$A$5),0) -> 148 | E41: 1.1723789 | F41: 0.66793176 | G41: 1 | H41: 300038 | L41: 300038 | M41: =COUNTIF(TeamHero生成!$J$5:$J$504,$C41) -> 5 | N41: =IF(AND(ISNUMBER($D41),$D41>=1,$D41<=500,MOD($D41,1)=0),"有效","无效") -> 有效 | O41: =IF($D41<$D40,"下降","") | P41: 统一标准模型；只列TowerEnemyFormation未停用的包体1 ID，包体2～4停用引用已清空
...

Sheet _怪物基线
A1: 等级 | B1: 普通怪生命 | C1: 普通怪攻击 | D1: 普通怪防御 | E1: 来源
A2: 1 | B2: 99 | C2: 44 | D2: 74 | E2: 战斗公式.xlsx/怪物标准模型 AS/AQ/AO；2026-08-27
A3: 2 | B3: 205 | C3: 89 | D3: 148 | E3: 战斗公式.xlsx/怪物标准模型 AS/AQ/AO；2026-08-27
A4: 3 | B4: 316 | C4: 134 | D4: 222 | E4: 战斗公式.xlsx/怪物标准模型 AS/AQ/AO；2026-08-27
A5: 4 | B5: 432 | C5: 180 | D5: 297 | E5: 战斗公式.xlsx/怪物标准模型 AS/AQ/AO；2026-08-27
A6: 5 | B6: 554 | C6: 225 | D6: 372 | E6: 战斗公式.xlsx/怪物标准模型 AS/AQ/AO；2026-08-27
A7: 6 | B7: 682 | C7: 271 | D7: 447 | E7: 战斗公式.xlsx/怪物标准模型 AS/AQ/AO；2026-08-27
A8: 7 | B8: 815 | C8: 318 | D8: 522 | E8: 战斗公式.xlsx/怪物标准模型 AS/AQ/AO；2026-08-27
A9: 8 | B9: 953 | C9: 365 | D9: 598 | E9: 战斗公式.xlsx/怪物标准模型 AS/AQ/AO；2026-08-27
A10: 9 | B10: 1097 | C10: 413 | D10: 674 | E10: 战斗公式.xlsx/怪物标准模型 AS/AQ/AO；2026-08-27
A11: 10 | B11: 1246 | C11: 461 | D11: 750 | E11: 战斗公式.xlsx/怪物标准模型 AS/AQ/AO；2026-08-27
A12: 11 | B12: 1400 | C12: 508 | D12: 826 | E12: 战斗公式.xlsx/怪物标准模型 AS/AQ/AO；2026-08-27
A13: 12 | B13: 1560 | C13: 557 | D13: 902 | E13: 战斗公式.xlsx/怪物标准模型 AS/AQ/AO；2026-08-27
... A501: 500 | B501: 2304753 | C501: 148975 | D501: 65340 | E501: 战斗公式.xlsx/怪物标准模型 AS/AQ/AO；2026-08-27

Sheet _角色基线
A1: HeroId | B1: 角色名 | C1: HeroClass | D1: 来源
A2: 1000 | B2: 测试 | C2: DPS | D2: Hero.xlsx
A3: 1001 | B3: 星海 | C3: DPS | D3: Hero.xlsx
A4: 1002 | B4: 大暑 | C4: Tank | D4: Hero.xlsx
A5: 1003 | B5: 塔拉夏 | C5: Tank | D5: Hero.xlsx
A6: 1004 | B6: 阿芭 | C6: Tank | D6: Hero.xlsx
A7: 1005 | B7: 陈单单 | C7: DPS | D7: Hero.xlsx
A8: 1006 | B8: 莉莉娅 | C8: DPS | D8: Hero.xlsx
A9: 1007 | B9: 萨萨莉安 | C9: Support | D9: Hero.xlsx
A10: 1008 | B10: 薇 | C10: DPS | D10: Hero.xlsx
A11: 1009 | B11: 约瑟夫 | C11: Support | D11: Hero.xlsx
A12: 1011 | B12: 陈双双 | C12: Support | D12: Hero.xlsx
A13: 1012 | B13: 艾德琳 | C13: Support | D13: Hero.xlsx
... A33: 1040 | B33: 小寒 | C33: Support | D33: Hero.xlsx

Sheet TeamHero生成
A1: 爬塔 TeamHero 属性生成
A2: D～F为最终生成值；公式基于楼层难度等级、精英怪基准和HeroClass职业偏移。
A4: TeamHero.Id | B4: CfgId | C4: Level | D4: Hp（生成） | E4: Attack（生成） | F4: Armor（生成） | G4: 当前Hp | H4: 当前Attack | I4: 当前Armor | J4: TeamId | K4: 层数 | L4: 难度等级 | M4: 角色名 | N4: HeroClass | O4: 普通怪生命 | P4: 普通怪攻击 | Q4: 普通怪防御 | R4: 精英生命系数 | S4: 精英攻击系数 | T4: 精英防御系数 | U4: 精英怪生命 | V4: 精英怪攻击 | W4: 精英怪防御 | X4: 职业生命系数 | Y4: 职业攻击系数 | Z4: 职业防御系数 | AA4: 楼层生命倍率 | AB4: 楼层攻击倍率 | AC4: 楼层防御倍率 | AD4: Hp变化 | AE4: Attack变化 | AF4: Armor变化 | AG4: 校验 | AH4: 有效生命（75%减伤上限）
A5: 1 | B5: 1002 | C5: 10 | D5: =IFERROR(ROUND($U5*$X5*$AA5*参数!$B$13,0),"") -> 12925 | E5: =IFERROR(ROUND($V5*$Y5*$AB5*参数!$C$13,0),"") -> 743 | F5: =IFERROR(ROUND($W5*$Z5*$AC5*参数!$D$13,0),"") -> 1700 | G5: 17474 | H5: 847 | I5: 1394 | J5: 1 | K5: 1 | L5: =IFERROR(INDEX(楼层配置!$D$5:$D$104,MATCH($K5,楼层配置!$B$5:$B$104,0)),"") -> 15 | M5: =IFERROR(INDEX(_角色基线!$B$2:$B$100,MATCH($B5,_角色基线!$A$2:$A$100,0)),"") -> 大暑 | N5: =IFERROR(INDEX(_角色基线!$C$2:$C$100,MATCH($B5,_角色基线!$A$2:$A$100,0)),"") -> Tank | O5: =IFERROR(INDEX(_怪物基线!$B$2:$B$501,MATCH(INT($L5),_怪物基线!$A$2:$A$501,0)),"") -> 2069 | P5: =IFERROR(INDEX(_怪物基线!$C$2:$C$501,MATCH(INT($L5),_怪物基线!$A$2:$A$501,0)),"") -> 705 | Q5: =IFERROR(INDEX(_怪物基线!$D$2:$D$501,MATCH(INT($L5),_怪物基线!$A$2:$A$501,0)),"") -> 1133 | R5: =参数!$B$10 -> 4 | S5: =参数!$C$10 -> 1.2 | T5: =参数!$D$10 -> 1 | U5: =IF($O5="","",$O5*$R5) -> 8276 | V5: =IF($P5="","",$P5*$S5) -> 846 | W5: =IF($Q5="","",$Q5*$T5) -> 1133 | X5: =IFERROR(INDEX(参数!$B$5:$B$7,MATCH($N5,参数!$A$5:$A$7,0)),"") -> 1.5 | Y5: =IFERROR(INDEX(参数!$C$5:$C$7,MATCH($N5,参数!$A$5:$A$7,0)),"") -> 1 | Z5: =IFERROR(INDEX(参数!$D$5:$D$7,MATCH($N5,参数!$A$5:$A$7,0)),"") -> 1.5 | AA5: =IFERROR(INDEX(楼层配置!$E$5:$E$104,MATCH($K5,楼层配置!$B$5:$B$104,0)),1) -> 1.0411519 | AB5: =IFERROR(INDEX(楼层配置!$F$5:$F$104,MATCH($K5,楼层配置!$B$5:$B$104,0)),1) -> 0.87879946 | AC5: =IFERROR(INDEX(楼层配置!$G$5:$G$104,MATCH($K5,楼层配置!$B$5:$B$104,0)),1) -> 1 | AD5: =IFERROR($D5/$G5-1,"") -> -0.26032963 | AE5: =IFERROR($E5/$H5-1,"") -> -0.1227863 | AF5: =IFERROR($F5/$I5-1,"") -> 0.2195122 | AG5: =IF(AND($A5>=1,$L5>=1,$L5<=500,OR($N5="Tank",$N5="DPS",$N5="Support"),ISNUMBER($D5),ISNUMBER($E5),ISNUMBER($F5)),"有效","异常") -> 有效 | AH5: =D5/(1-MIN(0.75,F5/(24000+F5))) -> 13840.521
A6: 2 | B6: 1001 | C6: 10 | D6: =IFERROR(ROUND($U6*$X6*$AA6*参数!$B$13,0),"") -> 8617 | E6: =IFERROR(ROUND($V6*$Y6*$AB6*参数!$C$13,0),"") -> 892 | F6: =IFERROR(ROUND($W6*$Z6*$AC6*参数!$D$13,0),"") -> 1133 | G6: 11649 | H6: 1016 | I6: 929 | J6: 1 | K6: 1 | L6: =IFERROR(INDEX(楼层配置!$D$5:$D$104,MATCH($K6,楼层配置!$B$5:$B$104,0)),"") -> 15 | M6: =IFERROR(INDEX(_角色基线!$B$2:$B$100,MATCH($B6,_角色基线!$A$2:$A$100,0)),"") -> 星海 | N6: =IFERROR(INDEX(_角色基线!$C$2:$C$100,MATCH($B6,_角色基线!$A$2:$A$100,0)),"") -> DPS | O6: =IFERROR(INDEX(_怪物基线!$B$2:$B$501,MATCH(INT($L6),_怪物基线!$A$2:$A$501,0)),"") -> 2069 | P6: =IFERROR(INDEX(_怪物基线!$C$2:$C$501,MATCH(INT($L6),_怪物基线!$A$2:$A$501,0)),"") -> 705 | Q6: =IFERROR(INDEX(_怪物基线!$D$2:$D$501,MATCH(INT($L6),_怪物基线!$A$2:$A$501,0)),"") -> 1133 | R6: =参数!$B$10 -> 4 | S6: =参数!$C$10 -> 1.2 | T6: =参数!$D$10 -> 1 | U6: =IF($O6="","",$O6*$R6) -> 8276 | V6: =IF($P6="","",$P6*$S6) -> 846 | W6: =IF($Q6="","",$Q6*$T6) -> 1133 | X6: =IFERROR(INDEX(参数!$B$5:$B$7,MATCH($N6,参数!$A$5:$A$7,0)),"") -> 1 | Y6: =IFERROR(INDEX(参数!$C$5:$C$7,MATCH($N6,参数!$A$5:$A$7,0)),"") -> 1.2 | Z6: =IFERROR(INDEX(参数!$D$5:$D$7,MATCH($N6,参数!$A$5:$A$7,0)),"") -> 1 | AA6: =IFERROR(INDEX(楼层配置!$E$5:$E$104,MATCH($K6,楼层配置!$B$5:$B$104,0)),1) -> 1.0411519 | AB6: =IFERROR(INDEX(楼层配置!$F$5:$F$104,MATCH($K6,楼层配置!$B$5:$B$104,0)),1) -> 0.87879946 | AC6: =IFERROR(INDEX(楼层配置!$G$5:$G$104,MATCH($K6,楼层配置!$B$5:$B$104,0)),1) -> 1 | AD6: =IFERROR($D6/$G6-1,"") -> -0.26027985 | AE6: =IFERROR($E6/$H6-1,"") -> -0.12204724 | AF6: =IFERROR($F6/$I6-1,"") -> 0.21959096 | AG6: =IF(AND($A6>=1,$L6>=1,$L6<=500,OR($N6="Tank",$N6="DPS",$N6="Support"),ISNUMBER($D6),ISNUMBER($E6),ISNUMBER($F6)),"有效","异常") -> 有效 | AH6: =D6/(1-MIN(0.75,F6/(24000+F6))) -> 9023.7942
A7: 3 | B7: 1001 | C7: 10 | D7: =IFERROR(ROUND($U7*$X7*$AA7*参数!$B$13,0),"") -> 8617 | E7: =IFERROR(ROUND($V7*$Y7*$AB7*参数!$C$13,0),"") -> 892 | F7: =IFERROR(ROUND($W7*$Z7*$AC7*参数!$D$13,0),"") -> 1133 | G7: 11649 | H7: 1016 | I7: 929 | J7: 1 | K7: 1 | L7: =IFERROR(INDEX(楼层配置!$D$5:$D$104,MATCH($K7,楼层配置!$B$5:$B$104,0)),"") -> 15 | M7: =IFERROR(INDEX(_角色基线!$B$2:$B$100,MATCH($B7,_角色基线!$A$2:$A$100,0)),"") -> 星海 | N7: =IFERROR(INDEX(_角色基线!$C$2:$C$100,MATCH($B7,_角色基线!$A$2:$A$100,0)),"") -> DPS | O7: =IFERROR(INDEX(_怪物基线!$B$2:$B$501,MATCH(INT($L7),_怪物基线!$A$2:$A$501,0)),"") -> 2069 | P7: =IFERROR(INDEX(_怪物基线!$C$2:$C$501,MATCH(INT($L7),_怪物基线!$A$2:$A$501,0)),"") -> 705 | Q7: =IFERROR(INDEX(_怪物基线!$D$2:$D$501,MATCH(INT($L7),_怪物基线!$A$2:$A$501,0)),"") -> 1133 | R7: =参数!$B$10 -> 4 | S7: =参数!$C$10 -> 1.2 | T7: =参数!$D$10 -> 1 | U7: =IF($O7="","",$O7*$R7) -> 8276 | V7: =IF($P7="","",$P7*$S7) -> 846 | W7: =IF($Q7="","",$Q7*$T7) -> 1133 | X7: =IFERROR(INDEX(参数!$B$5:$B$7,MATCH($N7,参数!$A$5:$A$7,0)),"") -> 1 | Y7: =IFERROR(INDEX(参数!$C$5:$C$7,MATCH($N7,参数!$A$5:$A$7,0)),"") -> 1.2 | Z7: =IFERROR(INDEX(参数!$D$5:$D$7,MATCH($N7,参数!$A$5:$A$7,0)),"") -> 1 | AA7: =IFERROR(INDEX(楼层配置!$E$5:$E$104,MATCH($K7,楼层配置!$B$5:$B$104,0)),1) -> 1.0411519 | AB7: =IFERROR(INDEX(楼层配置!$F$5:$F$104,MATCH($K7,楼层配置!$B$5:$B$104,0)),1) -> 0.87879946 | AC7: =IFERROR(INDEX(楼层配置!$G$5:$G$104,MATCH($K7,楼层配置!$B$5:$B$104,0)),1) -> 1 | AD7: =IFERROR($D7/$G7-1,"") -> -0.26027985 | AE7: =IFERROR($E7/$H7-1,"") -> -0.12204724 | AF7: =IFERROR($F7/$I7-1,"") -> 0.21959096 | AG7: =IF(AND($A7>=1,$L7>=1,$L7<=500,OR($N7="Tank",$N7="DPS",$N7="Support"),ISNUMBER($D7),ISNUMBER($E7),ISNUMBER($F7)),"有效","异常") -> 有效 | AH7: =D7/(1-MIN(0.75,F7/(24000+F7))) -> 9023.7942
A8: 4 | B8: 1001 | C8: 10 | D8: =IFERROR(ROUND($U8*$X8*$AA8*参数!$B$13,0),"") -> 8617 | E8: =IFERROR(ROUND($V8*$Y8*$AB8*参数!$C$13,0),"") -> 892 | F8: =IFERROR(ROUND($W8*$Z8*$AC8*参数!$D$13,0),"") -> 1133 | G8: 11649 | H8: 1016 | I8: 929 | J8: 1 | K8: 1 | L8: =IFERROR(INDEX(楼层配置!$D$5:$D$104,MATCH($K8,楼层配置!$B$5:$B$104,0)),"") -> 15 | M8: =IFERROR(INDEX(_角色基线!$B$2:$B$100,MATCH($B8,_角色基线!$A$2:$A$100,0)),"") -> 星海 | N8: =IFERROR(INDEX(_角色基线!$C$2:$C$100,MATCH($B8,_角色基线!$A$2:$A$100,0)),"") -> DPS | O8: =IFERROR(INDEX(_怪物基线!$B$2:$B$501,MATCH(INT($L8),_怪物基线!$A$2:$A$501,0)),"") -> 2069 | P8: =IFERROR(INDEX(_怪物基线!$C$2:$C$501,MATCH(INT($L8),_怪物基线!$A$2:$A$501,0)),"") -> 705 | Q8: =IFERROR(INDEX(_怪物基线!$D$2:$D$501,MATCH(INT($L8),_怪物基线!$A$2:$A$501,0)),"") -> 1133 | R8: =参数!$B$10 -> 4 | S8: =参数!$C$10 -> 1.2 | T8: =参数!$D$10 -> 1 | U8: =IF($O8="","",$O8*$R8) -> 8276 | V8: =IF($P8="","",$P8*$S8) -> 846 | W8: =IF($Q8="","",$Q8*$T8) -> 1133 | X8: =IFERROR(INDEX(参数!$B$5:$B$7,MATCH($N8,参数!$A$5:$A$7,0)),"") -> 1 | Y8: =IFERROR(INDEX(参数!$C$5:$C$7,MATCH($N8,参数!$A$5:$A$7,0)),"") -> 1.2 | Z8: =IFERROR(INDEX(参数!$D$5:$D$7,MATCH($N8,参数!$A$5:$A$7,0)),"") -> 1 | AA8: =IFERROR(INDEX(楼层配置!$E$5:$E$104,MATCH($K8,楼层配置!$B$5:$B$104,0)),1) -> 1.0411519 | AB8: =IFERROR(INDEX(楼层配置!$F$5:$F$104,MATCH($K8,楼层配置!$B$5:$B$104,0)),1) -> 0.87879946 | AC8: =IFERROR(INDEX(楼层配置!$G$5:$G$104,MATCH($K8,楼层配置!$B$5:$B$104,0)),1) -> 1 | AD8: =IFERROR($D8/$G8-1,"") -> -0.26027985 | AE8: =IFERROR($E8/$H8-1,"") -> -0.12204724 | AF8: =IFERROR($F8/$I8-1,"") -> 0.21959096 | AG8: =IF(AND($A8>=1,$L8>=1,$L8<=500,OR($N8="Tank",$N8="DPS",$N8="Support"),ISNUMBER($D8),ISNUMBER($E8),ISNUMBER($F8)),"有效","异常") -> 有效 | AH8: =D8/(1-MIN(0.75,F8/(24000+F8))) -> 9023.7942
A9: 5 | B9: 1040 | C9: 10 | D9: =IFERROR(ROUND($U9*$X9*$AA9*参数!$B$13,0),"") -> 10771 | E9: =IFERROR(ROUND($V9*$Y9*$AB9*参数!$C$13,0),"") -> 743 | F9: =IFERROR(ROUND($W9*$Z9*$AC9*参数!$D$13,0),"") -> 1416 | G9: 14562 | H9: 847 | I9: 1162 | J9: 1 | K9: 1 | L9: =IFERROR(INDEX(楼层配置!$D$5:$D$104,MATCH($K9,楼层配置!$B$5:$B$104,0)),"") -> 15 | M9: =IFERROR(INDEX(_角色基线!$B$2:$B$100,MATCH($B9,_角色基线!$A$2:$A$100,0)),"") -> 小寒 | N9: =IFERROR(INDEX(_角色基线!$C$2:$C$100,MATCH($B9,_角色基线!$A$2:$A$100,0)),"") -> Support | O9: =IFERROR(INDEX(_怪物基线!$B$2:$B$501,MATCH(INT($L9),_怪物基线!$A$2:$A$501,0)),"") -> 2069 | P9: =IFERROR(INDEX(_怪物基线!$C$2:$C$501,MATCH(INT($L9),_怪物基线!$A$2:$A$501,0)),"") -> 705 | Q9: =IFERROR(INDEX(_怪物基线!$D$2:$D$501,MATCH(INT($L9),_怪物基线!$A$2:$A$501,0)),"") -> 1133 | R9: =参数!$B$10 -> 4 | S9: =参数!$C$10 -> 1.2 | T9: =参数!$D$10 -> 1 | U9: =IF($O9="","",$O9*$R9) -> 8276 | V9: =IF($P9="","",$P9*$S9) -> 846 | W9: =IF($Q9="","",$Q9*$T9) -> 1133 | X9: =IFERROR(INDEX(参数!$B$5:$B$7,MATCH($N9,参数!$A$5:$A$7,0)),"") -> 1.25 | Y9: =IFERROR(INDEX(参数!$C$5:$C$7,MATCH($N9,参数!$A$5:$A$7,0)),"") -> 1 | Z9: =IFERROR(INDEX(参数!$D$5:$D$7,MATCH($N9,参数!$A$5:$A$7,0)),"") -> 1.25 | AA9: =IFERROR(INDEX(楼层配置!$E$5:$E$104,MATCH($K9,楼层配置!$B$5:$B$104,0)),1) -> 1.0411519 | AB9: =IFERROR(INDEX(楼层配置!$F$5:$F$104,MATCH($K9,楼层配置!$B$5:$B$104,0)),1) -> 0.87879946 | AC9: =IFERROR(INDEX(楼层配置!$G$5:$G$104,MATCH($K9,楼层配置!$B$5:$B$104,0)),1) -> 1 | AD9: =IFERROR($D9/$G9-1,"") -> -0.26033512 | AE9: =IFERROR($E9/$H9-1,"") -> -0.1227863 | AF9: =IFERROR($F9/$I9-1,"") -> 0.21858864 | AG9: =IF(AND($A9>=1,$L9>=1,$L9<=500,OR($N9="Tank",$N9="DPS",$N9="Support"),ISNUMBER($D9),ISNUMBER($E9),ISNUMBER($F9)),"有效","异常") -> 有效 | AH9: =D9/(1-MIN(0.75,F9/(24000+F9))) -> 11406.489
A10: 6 | B10: 1038 | C10: 11 | D10: =IFERROR(ROUND($U10*$X10*$AA10*参数!$B$13,0),"") -> 16789 | E10: =IFERROR(ROUND($V10*$Y10*$AB10*参数!$C$13,0),"") -> 907 | F10: =IFERROR(ROUND($W10*$Z10*$AC10*参数!$D$13,0),"") -> 2049 | G10: 22442 | H10: 1028 | I10: 1686 | J10: 2 | K10: 2 | L10: =IFERROR(INDEX(楼层配置!$D$5:$D$104,MATCH($K10,楼层配置!$B$5:$B$104,0)),"") -> 18 | M10: =IFERROR(INDEX(_角色基线!$B$2:$B$100,MATCH($B10,_角色基线!$A$2:$A$100,0)),"") -> 商队战斗员 | N10: =IFERROR(INDEX(_角色基线!$C$2:$C$100,MATCH($B10,_角色基线!$A$2:$A$100,0)),"") -> Tank | O10: =IFERROR(INDEX(_怪物基线!$B$2:$B$501,MATCH(INT($L10),_怪物基线!$A$2:$A$501,0)),"") -> 2624 | P10: =IFERROR(INDEX(_怪物基线!$C$2:$C$501,MATCH(INT($L10),_怪物基线!$A$2:$A$501,0)),"") -> 857 | Q10: =IFERROR(INDEX(_怪物基线!$D$2:$D$501,MATCH(INT($L10),_怪物基线!$A$2:$A$501,0)),"") -> 1366 | R10: =参数!$B$10 -> 4 | S10: =参数!$C$10 -> 1.2 | T10: =参数!$D$10 -> 1 | U10: =IF($O10="","",$O10*$R10) -> 10496 | V10: =IF($P10="","",$P10*$S10) -> 1028.4 | W10: =IF($Q10="","",$Q10*$T10) -> 1366 | X10: =IFERROR(INDEX(参数!$B$5:$B$7,MATCH($N10,参数!$A$5:$A$7,0)),"") -> 1.5 | Y10: =IFERROR(INDEX(参数!$C$5:$C$7,MATCH($N10,参数!$A$5:$A$7,0)),"") -> 1 | Z10: =IFERROR(INDEX(参数!$D$5:$D$7,MATCH($N10,参数!$A$5:$A$7,0)),"") -> 1.5 | AA10: =IFERROR(INDEX(楼层配置!$E$5:$E$104,MATCH($K10,楼层配置!$B$5:$B$104,0)),1) -> 1.0663889 | AB10: =IFERROR(INDEX(楼层配置!$F$5:$F$104,MATCH($K10,楼层配置!$B$5:$B$104,0)),1) -> 0.88169731 | AC10: =IFERROR(INDEX(楼层配置!$G$5:$G$104,MATCH($K10,楼层配置!$B$5:$B$104,0)),1) -> 1 | AD10: =IFERROR($D10/$G10-1,"") -> -0.25189377 | AE10: =IFERROR($E10/$H10-1,"") -> -0.11770428 | AF10: =IFERROR($F10/$I10-1,"") -> 0.21530249 | AG10: =IF(AND($A10>=1,$L10>=1,$L10<=500,OR($N10="Tank",$N10="DPS",$N10="Support"),ISNUMBER($D10),ISNUMBER($E10),ISNUMBER($F10)),"有效","异常") -> 有效 | AH10: =D10/(1-MIN(0.75,F10/(24000+F10))) -> 18222.361
A11: 7 | B11: 1035 | C11: 11 | D11: =IFERROR(ROUND($U11*$X11*$AA11*参数!$B$13,0),"") -> 11193 | E11: =IFERROR(ROUND($V11*$Y11*$AB11*参数!$C$13,0),"") -> 1088 | F11: =IFERROR(ROUND($W11*$Z11*$AC11*参数!$D$13,0),"") -> 1366 | G11: 14961 | H11: 1233 | I11: 1124 | J11: 2 | K11: 2 | L11: =IFERROR(INDEX(楼层配置!$D$5:$D$104,MATCH($K11,楼层配置!$B$5:$B$104,0)),"") -> 18 | M11: =IFERROR(INDEX(_角色基线!$B$2:$B$100,MATCH($B11,_角色基线!$A$2:$A$100,0)),"") -> 碎冰者 | N11: =IFERROR(INDEX(_角色基线!$C$2:$C$100,MATCH($B11,_角色基线!$A$2:$A$100,0)),"") -> DPS | O11: =IFERROR(INDEX(_怪物基线!$B$2:$B$501,MATCH(INT($L11),_怪物基线!$A$2:$A$501,0)),"") -> 2624 | P11: =IFERROR(INDEX(_怪物基线!$C$2:$C$501,MATCH(INT($L11),_怪物基线!$A$2:$A$501,0)),"") -> 857 | Q11: =IFERROR(INDEX(_怪物基线!$D$2:$D$501,MATCH(INT($L11),_怪物基线!$A$2:$A$501,0)),"") -> 1366 | R11: =参数!$B$10 -> 4 | S11: =参数!$C$10 -> 1.2 | T11: =参数!$D$10 -> 1 | U11: =IF($O11="","",$O11*$R11) -> 10496 | V11: =IF($P11="","",$P11*$S11) -> 1028.4 | W11: =IF($Q11="","",$Q11*$T11) -> 1366 | X11: =IFERROR(INDEX(参数!$B$5:$B$7,MATCH($N11,参数!$A$5:$A$7,0)),"") -> 1 | Y11: =IFERROR(INDEX(参数!$C$5:$C$7,MATCH($N11,参数!$A$5:$A$7,0)),"") -> 1.2 | Z11: =IFERROR(INDEX(参数!$D$5:$D$7,MATCH($N11,参数!$A$5:$A$7,0)),"") -> 1 | AA11: =IFERROR(INDEX(楼层配置!$E$5:$E$104,MATCH($K11,楼层配置!$B$5:$B$104,0)),1) -> 1.0663889 | AB11: =IFERROR(INDEX(楼层配置!$F$5:$F$104,MATCH($K11,楼层配置!$B$5:$B$104,0)),1) -> 0.88169731 | AC11: =IFERROR(INDEX(楼层配置!$G$5:$G$104,MATCH($K11,楼层配置!$B$5:$B$104,0)),1) -> 1 | AD11: =IFERROR($D11/$G11-1,"") -> -0.25185482 | AE11: =IFERROR($E11/$H11-1,"") -> -0.11759935 | AF11: =IFERROR($F11/$I11-1,"") -> 0.21530249 | AG11: =IF(AND($A11>=1,$L11>=1,$L11<=500,OR($N11="Tank",$N11="DPS",$N11="Support"),ISNUMBER($D11),ISNUMBER($E11),ISNUMBER($F11)),"有效","异常") -> 有效 | AH11: =D11/(1-MIN(0.75,F11/(24000+F11))) -> 11830.068
A12: 8 | B12: 1035 | C12: 11 | D12: =IFERROR(ROUND($U12*$X12*$AA12*参数!$B$13,0),"") -> 11193 | E12: =IFERROR(ROUND($V12*$Y12*$AB12*参数!$C$13,0),"") -> 1088 | F12: =IFERROR(ROUND($W12*$Z12*$AC12*参数!$D$13,0),"") -> 1366 | G12: 14961 | H12: 1233 | I12: 1124 | J12: 2 | K12: 2 | L12: =IFERROR(INDEX(楼层配置!$D$5:$D$104,MATCH($K12,楼层配置!$B$5:$B$104,0)),"") -> 18 | M12: =IFERROR(INDEX(_角色基线!$B$2:$B$100,MATCH($B12,_角色基线!$A$2:$A$100,0)),"") -> 碎冰者 | N12: =IFERROR(INDEX(_角色基线!$C$2:$C$100,MATCH($B12,_角色基线!$A$2:$A$100,0)),"") -> DPS | O12: =IFERROR(INDEX(_怪物基线!$B$2:$B$501,MATCH(INT($L12),_怪物基线!$A$2:$A$501,0)),"") -> 2624 | P12: =IFERROR(INDEX(_怪物基线!$C$2:$C$501,MATCH(INT($L12),_怪物基线!$A$2:$A$501,0)),"") -> 857 | Q12: =IFERROR(INDEX(_怪物基线!$D$2:$D$501,MATCH(INT($L12),_怪物基线!$A$2:$A$501,0)),"") -> 1366 | R12: =参数!$B$10 -> 4 | S12: =参数!$C$10 -> 1.2 | T12: =参数!$D$10 -> 1 | U12: =IF($O12="","",$O12*$R12) -> 10496 | V12: =IF($P12="","",$P12*$S12) -> 1028.4 | W12: =IF($Q12="","",$Q12*$T12) -> 1366 | X12: =IFERROR(INDEX(参数!$B$5:$B$7,MATCH($N12,参数!$A$5:$A$7,0)),"") -> 1 | Y12: =IFERROR(INDEX(参数!$C$5:$C$7,MATCH($N12,参数!$A$5:$A$7,0)),"") -> 1.2 | Z12: =IFERROR(INDEX(参数!$D$5:$D$7,MATCH($N12,参数!$A$5:$A$7,0)),"") -> 1 | AA12: =IFERROR(INDEX(楼层配置!$E$5:$E$104,MATCH($K12,楼层配置!$B$5:$B$104,0)),1) -> 1.0663889 | AB12: =IFERROR(INDEX(楼层配置!$F$5:$F$104,MATCH($K12,楼层配置!$B$5:$B$104,0)),1) -> 0.88169731 | AC12: =IFERROR(INDEX(楼层配置!$G$5:$G$104,MATCH($K12,楼层配置!$B$5:$B$104,0)),1) -> 1 | AD12: =IFERROR($D12/$G12-1,"") -> -0.25185482 | AE12: =IFERROR($E12/$H12-1,"") -> -0.11759935 | AF12: =IFERROR($F12/$I12-1,"") -> 0.21530249 | AG12: =IF(AND($A12>=1,$L12>=1,$L12<=500,OR($N12="Tank",$N12="DPS",$N12="Support"),ISNUMBER($D12),ISNUMBER($E12),ISNUMBER($F12)),"有效","异常") -> 有效 | AH12: =D12/(1-MIN(0.75,F12/(24000+F12))) -> 11830.068
A13: 9 | B13: 1035 | C13: 11 | D13: =IFERROR(ROUND($U13*$X13*$AA13*参数!$B$13,0),"") -> 11193 | E13: =IFERROR(ROUND($V13*$Y13*$AB13*参数!$C$13,0),"") -> 1088 | F13: =IFERROR(ROUND($W13*$Z13*$AC13*参数!$D$13,0),"") -> 1366 | G13: 14961 | H13: 1233 | I13: 1124 | J13: 2 | K13: 2 | L13: =IFERROR(INDEX(楼层配置!$D$5:$D$104,MATCH($K13,楼层配置!$B$5:$B$104,0)),"") -> 18 | M13: =IFERROR(INDEX(_角色基线!$B$2:$B$100,MATCH($B13,_角色基线!$A$2:$A$100,0)),"") -> 碎冰者 | N13: =IFERROR(INDEX(_角色基线!$C$2:$C$100,MATCH($B13,_角色基线!$A$2:$A$100,0)),"") -> DPS | O13: =IFERROR(INDEX(_怪物基线!$B$2:$B$501,MATCH(INT($L13),_怪物基线!$A$2:$A$501,0)),"") -> 2624 | P13: =IFERROR(INDEX(_怪物基线!$C$2:$C$501,MATCH(INT($L13),_怪物基线!$A$2:$A$501,0)),"") -> 857 | Q13: =IFERROR(INDEX(_怪物基线!$D$2:$D$501,MATCH(INT($L13),_怪物基线!$A$2:$A$501,0)),"") -> 1366 | R13: =参数!$B$10 -> 4 | S13: =参数!$C$10 -> 1.2 | T13: =参数!$D$10 -> 1 | U13: =IF($O13="","",$O13*$R13) -> 10496 | V13: =IF($P13="","",$P13*$S13) -> 1028.4 | W13: =IF($Q13="","",$Q13*$T13) -> 1366 | X13: =IFERROR(INDEX(参数!$B$5:$B$7,MATCH($N13,参数!$A$5:$A$7,0)),"") -> 1 | Y13: =IFERROR(INDEX(参数!$C$5:$C$7,MATCH($N13,参数!$A$5:$A$7,0)),"") -> 1.2 | Z13: =IFERROR(INDEX(参数!$D$5:$D$7,MATCH($N13,参数!$A$5:$A$7,0)),"") -> 1 | AA13: =IFERROR(INDEX(楼层配置!$E$5:$E$104,MATCH($K13,楼层配置!$B$5:$B$104,0)),1) -> 1.0663889 | AB13: =IFERROR(INDEX(楼层配置!$F$5:$F$104,MATCH($K13,楼层配置!$B$5:$B$104,0)),1) -> 0.88169731 | AC13: =IFERROR(INDEX(楼层配置!$G$5:$G$104,MATCH($K13,楼层配置!$B$5:$B$104,0)),1) -> 1 | AD13: =IFERROR($D13/$G13-1,"") -> -0.25185482 | AE13: =IFERROR($E13/$H13-1,"") -> -0.11759935 | AF13: =IFERROR($F13/$I13-1,"") -> 0.21530249 | AG13: =IF(AND($A13>=1,$L13>=1,$L13<=500,OR($N13="Tank",$N13="DPS",$N13="Support"),ISNUMBER($D13),ISNUMBER($E13),ISNUMBER($F13)),"有效","异常") -> 有效 | AH13: =D13/(1-MIN(0.75,F13/(24000+F13))) -> 11830.068
A14: 10 | B14: 1036 | C14: 11 | D14: =IFERROR(ROUND($U14*$X14*$AA14*参数!$B$13,0),"") -> 11193 | E14: =IFERROR(ROUND($V14*$Y14*$AB14*参数!$C$13,0),"") -> 1088 | F14: =IFERROR(ROUND($W14*$Z14*$AC14*参数!$D$13,0),"") -> 1366 | G14: 14961 | H14: 1233 | I14: 1124 | J14: 2 | K14: 2 | L14: =IFERROR(INDEX(楼层配置!$D$5:$D$104,MATCH($K14,楼层配置!$B$5:$B$104,0)),"") -> 18 | M14: =IFERROR(INDEX(_角色基线!$B$2:$B$100,MATCH($B14,_角色基线!$A$2:$A$100,0)),"") -> 霜狼法师 | N14: =IFERROR(INDEX(_角色基线!$C$2:$C$100,MATCH($B14,_角色基线!$A$2:$A$100,0)),"") -> DPS | O14: =IFERROR(INDEX(_怪物基线!$B$2:$B$501,MATCH(INT($L14),_怪物基线!$A$2:$A$501,0)),"") -> 2624 | P14: =IFERROR(INDEX(_怪物基线!$C$2:$C$501,MATCH(INT($L14),_怪物基线!$A$2:$A$501,0)),"") -> 857 | Q14: =IFERROR(INDEX(_怪物基线!$D$2:$D$501,MATCH(INT($L14),_怪物基线!$A$2:$A$501,0)),"") -> 1366 | R14: =参数!$B$10 -> 4 | S14: =参数!$C$10 -> 1.2 | T14: =参数!$D$10 -> 1 | U14: =IF($O14="","",$O14*$R14) -> 10496 | V14: =IF($P14="","",$P14*$S14) -> 1028.4 | W14: =IF($Q14="","",$Q14*$T14) -> 1366 | X14: =IFERROR(INDEX(参数!$B$5:$B$7,MATCH($N14,参数!$A$5:$A$7,0)),"") -> 1 | Y14: =IFERROR(INDEX(参数!$C$5:$C$7,MATCH($N14,参数!$A$5:$A$7,0)),"") -> 1.2 | Z14: =IFERROR(INDEX(参数!$D$5:$D$7,MATCH($N14,参数!$A$5:$A$7,0)),"") -> 1 | AA14: =IFERROR(INDEX(楼层配置!$E$5:$E$104,MATCH($K14,楼层配置!$B$5:$B$104,0)),1) -> 1.0663889 | AB14: =IFERROR(INDEX(楼层配置!$F$5:$F$104,MATCH($K14,楼层配置!$B$5:$B$104,0)),1) -> 0.88169731 | AC14: =IFERROR(INDEX(楼层配置!$G$5:$G$104,MATCH($K14,楼层配置!$B$5:$B$104,0)),1) -> 1 | AD14: =IFERROR($D14/$G14-1,"") -> -0.25185482 | AE14: =IFERROR($E14/$H14-1,"") -> -0.11759935 | AF14: =IFERROR($F14/$I14-1,"") -> 0.21530249 | AG14: =IF(AND($A14>=1,$L14>=1,$L14<=500,OR($N14="Tank",$N14="DPS",$N14="Support"),ISNUMBER($D14),ISNUMBER($E14),ISNUMBER($F14)),"有效","异常") -> 有效 | AH14: =D14/(1-MIN(0.75,F14/(24000+F14))) -> 11830.068
A15: 11 | B15: 1002 | C15: 11 | D15: =IFERROR(ROUND($U15*$X15*$AA15*参数!$B$13,0),"") -> 21843 | E15: =IFERROR(ROUND($V15*$Y15*$AB15*参数!$C$13,0),"") -> 1105 | F15: =IFERROR(ROUND($W15*$Z15*$AC15*参数!$D$13,0),"") -> 2519 | G15: 27900 | H15: 1213 | I15: 1982 | J15: 3 | K15: 3 | L15: =IFERROR(INDEX(楼层配置!$D$5:$D$104,MATCH($K15,楼层配置!$B$5:$B$104,0)),"") -> 22 | M15: =IFERROR(INDEX(_角色基线!$B$2:$B$100,MATCH($B15,_角色基线!$A$2:$A$100,0)),"") -> 大暑 | N15: =IFERROR(INDEX(_角色基线!$C$2:$C$100,MATCH($B15,_角色基线!$A$2:$A$100,0)),"") -> Tank | O15: =IFERROR(INDEX(_怪物基线!$B$2:$B$501,MATCH(INT($L15),_怪物基线!$A$2:$A$501,0)),"") -> 3435 | P15: =IFERROR(INDEX(_怪物基线!$C$2:$C$501,MATCH(INT($L15),_怪物基线!$A$2:$A$501,0)),"") -> 1064 | Q15: =IFERROR(INDEX(_怪物基线!$D$2:$D$501,MATCH(INT($L15),_怪物基线!$A$2:$A$501,0)),"") -> 1679 | R15: =参数!$B$10 -> 4 | S15: =参数!$C$10 -> 1.2 | T15: =参数!$D$10 -> 1 | U15: =IF($O15="","",$O15*$R15) -> 13740 | V15: =IF($P15="","",$P15*$S15) -> 1276.8 | W15: =IF($Q15="","",$Q15*$T15) -> 1679 | X15: =IFERROR(INDEX(参数!$B$5:$B$7,MATCH($N15,参数!$A$5:$A$7,0)),"") -> 1.5 | Y15: =IFERROR(INDEX(参数!$C$5:$C$7,MATCH($N15,参数!$A$5:$A$7,0)),"") -> 1 | Z15: =IFERROR(INDEX(参数!$D$5:$D$7,MATCH($N15,参数!$A$5:$A$7,0)),"") -> 1.5 | AA15: =IFERROR(INDEX(楼层配置!$E$5:$E$104,MATCH($K15,楼层配置!$B$5:$B$104,0)),1) -> 1.0598272 | AB15: =IFERROR(INDEX(楼层配置!$F$5:$F$104,MATCH($K15,楼层配置!$B$5:$B$104,0)),1) -> 0.86525003 | AC15: =IFERROR(INDEX(楼层配置!$G$5:$G$104,MATCH($K15,楼层配置!$B$5:$B$104,0)),1) -> 1 | AD15: =IFERROR($D15/$G15-1,"") -> -0.21709677 | AE15: =IFERROR($E15/$H15-1,"") -> -0.089035449 | AF15: =IFERROR($F15/$I15-1,"") -> 0.27093845 | AG15: =IF(AND($A15>=1,$L15>=1,$L15<=500,OR($N15="Tank",$N15="DPS",$N15="Support"),ISNUMBER($D15),ISNUMBER($E15),ISNUMBER($F15)),"有效","异常") -> 有效 | AH15: =D15/(1-MIN(0.75,F15/(24000+F15))) -> 24135.605
A16: 12 | B16: 1002 | C16: 11 | D16: =IFERROR(ROUND($U16*$X16*$AA16*参数!$B$13,0),"") -> 21843 | E16: =IFERROR(ROUND($V16*$Y16*$AB16*参数!$C$13,0),"") -> 1105 | F16: =IFERROR(ROUND($W16*$Z16*$AC16*参数!$D$13,0),"") -> 2519 | G16: 27900 | H16: 1213 | I16: 1982 | J16: 3 | K16: 3 | L16: =IFERROR(INDEX(楼层配置!$D$5:$D$104,MATCH($K16,楼层配置!$B$5:$B$104,0)),"") -> 22 | M16: =IFERROR(INDEX(_角色基线!$B$2:$B$100,MATCH($B16,_角色基线!$A$2:$A$100,0)),"") -> 大暑 | N16: =IFERROR(INDEX(_角色基线!$C$2:$C$100,MATCH($B16,_角色基线!$A$2:$A$100,0)),"") -> Tank | O16: =IFERROR(INDEX(_怪物基线!$B$2:$B$501,MATCH(INT($L16),_怪物基线!$A$2:$A$501,0)),"") -> 3435 | P16: =IFERROR(INDEX(_怪物基线!$C$2:$C$501,MATCH(INT($L16),_怪物基线!$A$2:$A$501,0)),"") -> 1064 | Q16: =IFERROR(INDEX(_怪物基线!$D$2:$D$501,MATCH(INT($L16),_怪物基线!$A$2:$A$501,0)),"") -> 1679 | R16: =参数!$B$10 -> 4 | S16: =参数!$C$10 -> 1.2 | T16: =参数!$D$10 -> 1 | U16: =IF($O16="","",$O16*$R16) -> 13740 | V16: =IF($P16="","",$P16*$S16) -> 1276.8 | W16: =IF($Q16="","",$Q16*$T16) -> 1679 | X16: =IFERROR(INDEX(参数!$B$5:$B$7,MATCH($N16,参数!$A$5:$A$7,0)),"") -> 1.5 | Y16: =IFERROR(INDEX(参数!$C$5:$C$7,MATCH($N16,参数!$A$5:$A$7,0)),"") -> 1 | Z16: =IFERROR(INDEX(参数!$D$5:$D$7,MATCH($N16,参数!$A$5:$A$7,0)),"") -> 1.5 | AA16: =IFERROR(INDEX(楼层配置!$E$5:$E$104,MATCH($K16,楼层配置!$B$5:$B$104,0)),1) -> 1.0598272 | AB16: =IFERROR(INDEX(楼层配置!$F$5:$F$104,MATCH($K16,楼层配置!$B$5:$B$104,0)),1) -> 0.86525003 | AC16: =IFERROR(INDEX(楼层配置!$G$5:$G$104,MATCH($K16,楼层配置!$B$5:$B$104,0)),1) -> 1 | AD16: =IFERROR($D16/$G16-1,"") -> -0.21709677 | AE16: =IFERROR($E16/$H16-1,"") -> -0.089035449 | AF16: =IFERROR($F16/$I16-1,"") -> 0.27093845 | AG16: =IF(AND($A16>=1,$L16>=1,$L16<=500,OR($N16="Tank",$N16="DPS",$N16="Support"),ISNUMBER($D16),ISNUMBER($E16),ISNUMBER($F16)),"有效","异常") -> 有效 | AH16: =D16/(1-MIN(0.75,F16/(24000+F16))) -> 24135.605
... A504: 500 | B504: 1029 | C504: 60 | D504: =IFERROR(ROUND($U504*$X504*$AA504*参数!$B$13,0),"") -> 2237855 | E504: =IFERROR(ROUND($V504*$Y504*$AB504*参数!$C$13,0),"") -> 32431 | F504: =IFERROR(ROUND($W504*$Z504*$AC504*参数!$D$13,0),"") -> 36983 | G504: 5950560 | H504: 61451 | I504: 43505 | J504: 100 | K504: 100 | L504: =IFERROR(INDEX(楼层配置!$D$5:$D$104,MATCH($K504,楼层配置!$B$5:$B$104,0)),"") -> 280 | M504: =IFERROR(INDEX(_角色基线!$B$2:$B$100,MATCH($B504,_角色基线!$A$2:$A$100,0)),"") -> 凯兰 | N504: =IFERROR(INDEX(_角色基线!$C$2:$C$100,MATCH($B504,_角色基线!$A$2:$A$100,0)),"") -> Support | O504: =IFERROR(INDEX(_怪物基线!$B$2:$B$501,MATCH(INT($L504),_怪物基线!$A$2:$A$501,0)),"") -> 397235 | P504: =IFERROR(INDEX(_怪物基线!$C$2:$C$501,MATCH(INT($L504),_怪物基线!$A$2:$A$501,0)),"") -> 36960 | Q504: =IFERROR(INDEX(_怪物基线!$D$2:$D$501,MATCH(INT($L504),_怪物基线!$A$2:$A$501,0)),"") -> 29586 | R504: =参数!$B$10 -> 4 | S504: =参数!$C$10 -> 1.2 | T504: =参数!$D$10 -> 1 | U504: =IF($O504="","",$O504*$R504) -> 1588940 | V504: =IF($P504="","",$P504*$S504) -> 44352 | W504: =IF($Q504="","",$Q504*$T504) -> 29586 | X504: =IFERROR(INDEX(参数!$B$5:$B$7,MATCH($N504,参数!$A$5:$A$7,0)),"") -> 1.25 | Y504: =IFERROR(INDEX(参数!$C$5:$C$7,MATCH($N504,参数!$A$5:$A$7,0)),"") -> 1 | Z504: =IFERROR(INDEX(参数!$D$5:$D$7,MATCH($N504,参数!$A$5:$A$7,0)),"") -> 1.25 | AA504: =IFERROR(INDEX(楼层配置!$E$5:$E$104,MATCH($K504,楼层配置!$B$5:$B$104,0)),1) -> 1.1267159 | AB504: =IFERROR(INDEX(楼层配置!$F$5:$F$104,MATCH($K504,楼层配置!$B$5:$B$104,0)),1) -> 0.73122951 | AC504: =IFERROR(INDEX(楼层配置!$G$5:$G$104,MATCH($K504,楼层配置!$B$5:$B$104,0)),1) -> 1 | AD504: =IFERROR($D504/$G504-1,"") -> -0.62392531 | AE504: =IFERROR($E504/$H504-1,"") -> -0.47224618 | AF504: =IFERROR($F504/$I504-1,"") -> -0.1499138 | AG504: =IF(AND($A504>=1,$L504>=1,$L504<=500,OR($N504="Tank",$N504="DPS",$N504="Support"),ISNUMBER($D504),ISNUMBER($E504),ISNUMBER($F504)),"有效","异常") -> 有效 | AH504: =D504/(1-MIN(0.75,F504/(24000+F504))) -> 5686296.3
A505: 501 | B505: 1003 | C505: 60 | D505: =IFERROR(ROUND($U505*$X505*$AA505*参数!$B$13,0),"") -> 2709589 | E505: =IFERROR(ROUND($V505*$Y505*$AB505*参数!$C$13,0),"") -> 32607 | F505: =IFERROR(ROUND($W505*$Z505*$AC505*参数!$D$13,0),"") -> 44586 | J505: 101 | K505: 101 | L505: =IFERROR(INDEX(楼层配置!$D$5:$D$204,MATCH($K505,楼层配置!$B$5:$B$204,0)),"") -> 281 | M505: =IFERROR(INDEX(_角色基线!$B$2:$B$100,MATCH($B505,_角色基线!$A$2:$A$100,0)),"") -> 塔拉夏 | N505: =IFERROR(INDEX(_角色基线!$C$2:$C$100,MATCH($B505,_角色基线!$A$2:$A$100,0)),"") -> Tank | O505: =IFERROR(INDEX(_怪物基线!$B$2:$B$501,MATCH(INT($L505),_怪物基线!$A$2:$A$501,0)),"") -> 401128 | P505: =IFERROR(INDEX(_怪物基线!$C$2:$C$501,MATCH(INT($L505),_怪物基线!$A$2:$A$501,0)),"") -> 37231 | Q505: =IFERROR(INDEX(_怪物基线!$D$2:$D$501,MATCH(INT($L505),_怪物基线!$A$2:$A$501,0)),"") -> 29724 | R505: =参数!$B$10 -> 4 | S505: =参数!$C$10 -> 1.2 | T505: =参数!$D$10 -> 1 | U505: =IF($O505="","",$O505*$R505) -> 1604512 | V505: =IF($P505="","",$P505*$S505) -> 44677.2 | W505: =IF($Q505="","",$Q505*$T505) -> 29724 | X505: =IFERROR(INDEX(参数!$B$5:$B$7,MATCH($N505,参数!$A$5:$A$7,0)),"") -> 1.5 | Y505: =IFERROR(INDEX(参数!$C$5:$C$7,MATCH($N505,参数!$A$5:$A$7,0)),"") -> 1 | Z505: =IFERROR(INDEX(参数!$D$5:$D$7,MATCH($N505,参数!$A$5:$A$7,0)),"") -> 1.5 | AA505: =IFERROR(INDEX(楼层配置!$E$5:$E$204,MATCH($K505,楼层配置!$B$5:$B$204,0)),1) -> 1.1258207 | AB505: =IFERROR(INDEX(楼层配置!$F$5:$F$204,MATCH($K505,楼层配置!$B$5:$B$204,0)),1) -> 0.72983489 | AC505: =IFERROR(INDEX(楼层配置!$G$5:$G$204,MATCH($K505,楼层配置!$B$5:$B$204,0)),1) -> 1 | AD505: =IFERROR($D505/$G505-1,"") | AE505: =IFERROR($E505/$H505-1,"") | AF505: =IFERROR($F505/$I505-1,"") | AG505: =IF(AND($A505>=1,$L505>=1,$L505<=500,OR($N505="Tank",$N505="DPS",$N505="Support"),ISNUMBER($D505),ISNUMBER($E505),ISNUMBER($F505)),"有效","异常") -> 有效 | AH505: =D505/(1-MIN(0.75,F505/(24000+F505))) -> 7743328
A506: 502 | B506: 1005 | C506: 60 | D506: =IFERROR(ROUND($U506*$X506*$AA506*参数!$B$13,0),"") -> 1806393 | E506: =IFERROR(ROUND($V506*$Y506*$AB506*参数!$C$13,0),"") -> 39128 | F506: =IFERROR(ROUND($W506*$Z506*$AC506*参数!$D$13,0),"") -> 29724 | J506: 101 | K506: 101 | L506: =IFERROR(INDEX(楼层配置!$D$5:$D$204,MATCH($K506,楼层配置!$B$5:$B$204,0)),"") -> 281 | M506: =IFERROR(INDEX(_角色基线!$B$2:$B$100,MATCH($B506,_角色基线!$A$2:$A$100,0)),"") -> 陈单单 | N506: =IFERROR(INDEX(_角色基线!$C$2:$C$100,MATCH($B506,_角色基线!$A$2:$A$100,0)),"") -> DPS | O506: =IFERROR(INDEX(_怪物基线!$B$2:$B$501,MATCH(INT($L506),_怪物基线!$A$2:$A$501,0)),"") -> 401128 | P506: =IFERROR(INDEX(_怪物基线!$C$2:$C$501,MATCH(INT($L506),_怪物基线!$A$2:$A$501,0)),"") -> 37231 | Q506: =IFERROR(INDEX(_怪物基线!$D$2:$D$501,MATCH(INT($L506),_怪物基线!$A$2:$A$501,0)),"") -> 29724 | R506: =参数!$B$10 -> 4 | S506: =参数!$C$10 -> 1.2 | T506: =参数!$D$10 -> 1 | U506: =IF($O506="","",$O506*$R506) -> 1604512 | V506: =IF($P506="","",$P506*$S506) -> 44677.2 | W506: =IF($Q506="","",$Q506*$T506) -> 29724 | X506: =IFERROR(INDEX(参数!$B$5:$B$7,MATCH($N506,参数!$A$5:$A$7,0)),"") -> 1 | Y506: =IFERROR(INDEX(参数!$C$5:$C$7,MATCH($N506,参数!$A$5:$A$7,0)),"") -> 1.2 | Z506: =IFERROR(INDEX(参数!$D$5:$D$7,MATCH($N506,参数!$A$5:$A$7,0)),"") -> 1 | AA506: =IFERROR(INDEX(楼层配置!$E$5:$E$204,MATCH($K506,楼层配置!$B$5:$B$204,0)),1) -> 1.1258207 | AB506: =IFERROR(INDEX(楼层配置!$F$5:$F$204,MATCH($K506,楼层配置!$B$5:$B$204,0)),1) -> 0.72983489 | AC506: =IFERROR(INDEX(楼层配置!$G$5:$G$204,MATCH($K506,楼层配置!$B$5:$B$204,0)),1) -> 1 | AD506: =IFERROR($D506/$G506-1,"") | AE506: =IFERROR($E506/$H506-1,"") | AF506: =IFERROR($F506/$I506-1,"") | AG506: =IF(AND($A506>=1,$L506>=1,$L506<=500,OR($N506="Tank",$N506="DPS",$N506="Support"),ISNUMBER($D506),ISNUMBER($E506),ISNUMBER($F506)),"有效","异常") -> 有效 | AH506: =D506/(1-MIN(0.75,F506/(24000+F506))) -> 4043610.7
A507: 503 | B507: 1005 | C507: 60 | D507: =IFERROR(ROUND($U507*$X507*$AA507*参数!$B$13,0),"") -> 1806393 | E507: =IFERROR(ROUND($V507*$Y507*$AB507*参数!$C$13,0),"") -> 39128 | F507: =IFERROR(ROUND($W507*$Z507*$AC507*参数!$D$13,0),"") -> 29724 | J507: 101 | K507: 101 | L507: =IFERROR(INDEX(楼层配置!$D$5:$D$204,MATCH($K507,楼层配置!$B$5:$B$204,0)),"") -> 281 | M507: =IFERROR(INDEX(_角色基线!$B$2:$B$100,MATCH($B507,_角色基线!$A$2:$A$100,0)),"") -> 陈单单 | N507: =IFERROR(INDEX(_角色基线!$C$2:$C$100,MATCH($B507,_角色基线!$A$2:$A$100,0)),"") -> DPS | O507: =IFERROR(INDEX(_怪物基线!$B$2:$B$501,MATCH(INT($L507),_怪物基线!$A$2:$A$501,0)),"") -> 401128 | P507: =IFERROR(INDEX(_怪物基线!$C$2:$C$501,MATCH(INT($L507),_怪物基线!$A$2:$A$501,0)),"") -> 37231 | Q507: =IFERROR(INDEX(_怪物基线!$D$2:$D$501,MATCH(INT($L507),_怪物基线!$A$2:$A$501,0)),"") -> 29724 | R507: =参数!$B$10 -> 4 | S507: =参数!$C$10 -> 1.2 | T507: =参数!$D$10 -> 1 | U507: =IF($O507="","",$O507*$R507) -> 1604512 | V507: =IF($P507="","",$P507*$S507) -> 44677.2 | W507: =IF($Q507="","",$Q507*$T507) -> 29724 | X507: =IFERROR(INDEX(参数!$B$5:$B$7,MATCH($N507,参数!$A$5:$A$7,0)),"") -> 1 | Y507: =IFERROR(INDEX(参数!$C$5:$C$7,MATCH($N507,参数!$A$5:$A$7,0)),"") -> 1.2 | Z507: =IFERROR(INDEX(参数!$D$5:$D$7,MATCH($N507,参数!$A$5:$A$7,0)),"") -> 1 | AA507: =IFERROR(INDEX(楼层配置!$E$5:$E$204,MATCH($K507,楼层配置!$B$5:$B$204,0)),1) -> 1.1258207 | AB507: =IFERROR(INDEX(楼层配置!$F$5:$F$204,MATCH($K507,楼层配置!$B$5:$B$204,0)),1) -> 0.72983489 | AC507: =IFERROR(INDEX(楼层配置!$G$5:$G$204,MATCH($K507,楼层配置!$B$5:$B$204,0)),1) -> 1 | AD507: =IFERROR($D507/$G507-1,"") | AE507: =IFERROR($E507/$H507-1,"") | AF507: =IFERROR($F507/$I507-1,"") | AG507: =IF(AND($A507>=1,$L507>=1,$L507<=500,OR($N507="Tank",$N507="DPS",$N507="Support"),ISNUMBER($D507),ISNUMBER($E507),ISNUMBER($F507)),"有效","异常") -> 有效 | AH507: =D507/(1-MIN(0.75,F507/(24000+F507))) -> 4043610.7
A508: 504 | B508: 1005 | C508: 60 | D508: =IFERROR(ROUND($U508*$X508*$AA508*参数!$B$13,0),"") -> 1806393 | E508: =IFERROR(ROUND($V508*$Y508*$AB508*参数!$C$13,0),"") -> 39128 | F508: =IFERROR(ROUND($W508*$Z508*$AC508*参数!$D$13,0),"") -> 29724 | J508: 101 | K508: 101 | L508: =IFERROR(INDEX(楼层配置!$D$5:$D$204,MATCH($K508,楼层配置!$B$5:$B$204,0)),"") -> 281 | M508: =IFERROR(INDEX(_角色基线!$B$2:$B$100,MATCH($B508,_角色基线!$A$2:$A$100,0)),"") -> 陈单单 | N508: =IFERROR(INDEX(_角色基线!$C$2:$C$100,MATCH($B508,_角色基线!$A$2:$A$100,0)),"") -> DPS | O508: =IFERROR(INDEX(_怪物基线!$B$2:$B$501,MATCH(INT($L508),_怪物基线!$A$2:$A$501,0)),"") -> 401128 | P508: =IFERROR(INDEX(_怪物基线!$C$2:$C$501,MATCH(INT($L508),_怪物基线!$A$2:$A$501,0)),"") -> 37231 | Q508: =IFERROR(INDEX(_怪物基线!$D$2:$D$501,MATCH(INT($L508),_怪物基线!$A$2:$A$501,0)),"") -> 29724 | R508: =参数!$B$10 -> 4 | S508: =参数!$C$10 -> 1.2 | T508: =参数!$D$10 -> 1 | U508: =IF($O508="","",$O508*$R508) -> 1604512 | V508: =IF($P508="","",$P508*$S508) -> 44677.2 | W508: =IF($Q508="","",$Q508*$T508) -> 29724 | X508: =IFERROR(INDEX(参数!$B$5:$B$7,MATCH($N508,参数!$A$5:$A$7,0)),"") -> 1 | Y508: =IFERROR(INDEX(参数!$C$5:$C$7,MATCH($N508,参数!$A$5:$A$7,0)),"") -> 1.2 | Z508: =IFERROR(INDEX(参数!$D$5:$D$7,MATCH($N508,参数!$A$5:$A$7,0)),"") -> 1 | AA508: =IFERROR(INDEX(楼层配置!$E$5:$E$204,MATCH($K508,楼层配置!$B$5:$B$204,0)),1) -> 1.1258207 | AB508: =IFERROR(INDEX(楼层配置!$F$5:$F$204,MATCH($K508,楼层配置!$B$5:$B$204,0)),1) -> 0.72983489 | AC508: =IFERROR(INDEX(楼层配置!$G$5:$G$204,MATCH($K508,楼层配置!$B$5:$B$204,0)),1) -> 1 | AD508: =IFERROR($D508/$G508-1,"") | AE508: =IFERROR($E508/$H508-1,"") | AF508: =IFERROR($F508/$I508-1,"") | AG508: =IF(AND($A508>=1,$L508>=1,$L508<=500,OR($N508="Tank",$N508="DPS",$N508="Support"),ISNUMBER($D508),ISNUMBER($E508),ISNUMBER($F508)),"有效","异常") -> 有效 | AH508: =D508/(1-MIN(0.75,F508/(24000+F508))) -> 4043610.7
A509: 505 | B509: 1029 | C509: 60 | D509: =IFERROR(ROUND($U509*$X509*$AA509*参数!$B$13,0),"") -> 2257991 | E509: =IFERROR(ROUND($V509*$Y509*$AB509*参数!$C$13,0),"") -> 32607 | F509: =IFERROR(ROUND($W509*$Z509*$AC509*参数!$D$13,0),"") -> 37155 | J509: 101 | K509: 101 | L509: =IFERROR(INDEX(楼层配置!$D$5:$D$204,MATCH($K509,楼层配置!$B$5:$B$204,0)),"") -> 281 | M509: =IFERROR(INDEX(_角色基线!$B$2:$B$100,MATCH($B509,_角色基线!$A$2:$A$100,0)),"") -> 凯兰 | N509: =IFERROR(INDEX(_角色基线!$C$2:$C$100,MATCH($B509,_角色基线!$A$2:$A$100,0)),"") -> Support | O509: =IFERROR(INDEX(_怪物基线!$B$2:$B$501,MATCH(INT($L509),_怪物基线!$A$2:$A$501,0)),"") -> 401128 | P509: =IFERROR(INDEX(_怪物基线!$C$2:$C$501,MATCH(INT($L509),_怪物基线!$A$2:$A$501,0)),"") -> 37231 | Q509: =IFERROR(INDEX(_怪物基线!$D$2:$D$501,MATCH(INT($L509),_怪物基线!$A$2:$A$501,0)),"") -> 29724 | R509: =参数!$B$10 -> 4 | S509: =参数!$C$10 -> 1.2 | T509: =参数!$D$10 -> 1 | U509: =IF($O509="","",$O509*$R509) -> 1604512 | V509: =IF($P509="","",$P509*$S509) -> 44677.2 | W509: =IF($Q509="","",$Q509*$T509) -> 29724 | X509: =IFERROR(INDEX(参数!$B$5:$B$7,MATCH($N509,参数!$A$5:$A$7,0)),"") -> 1.25 | Y509: =IFERROR(INDEX(参数!$C$5:$C$7,MATCH($N509,参数!$A$5:$A$7,0)),"") -> 1 | Z509: =IFERROR(INDEX(参数!$D$5:$D$7,MATCH($N509,参数!$A$5:$A$7,0)),"") -> 1.25 | AA509: =IFERROR(INDEX(楼层配置!$E$5:$E$204,MATCH($K509,楼层配置!$B$5:$B$204,0)),1) -> 1.1258207 | AB509: =IFERROR(INDEX(楼层配置!$F$5:$F$204,MATCH($K509,楼层配置!$B$5:$B$204,0)),1) -> 0.72983489 | AC509: =IFERROR(INDEX(楼层配置!$G$5:$G$204,MATCH($K509,楼层配置!$B$5:$B$204,0)),1) -> 1 | AD509: =IFERROR($D509/$G509-1,"") | AE509: =IFERROR($E509/$H509-1,"") | AF509: =IFERROR($F509/$I509-1,"") | AG509: =IF(AND($A509>=1,$L509>=1,$L509<=500,OR($N509="Tank",$N509="DPS",$N509="Support"),ISNUMBER($D509),ISNUMBER($E509),ISNUMBER($F509)),"有效","异常") -> 有效 | AH509: =D509/(1-MIN(0.75,F509/(24000+F509))) -> 5753643.3
A510: 506 | B510: 1003 | C510: 60 | D510: =IFERROR(ROUND($U510*$X510*$AA510*参数!$B$13,0),"") -> 2736075 | E510: =IFERROR(ROUND($V510*$Y510*$AB510*参数!$C$13,0),"") -> 32846 | F510: =IFERROR(ROUND($W510*$Z510*$AC510*参数!$D$13,0),"") -> 44792 | J510: 102 | K510: 102 | L510: =IFERROR(INDEX(楼层配置!$D$5:$D$204,MATCH($K510,楼层配置!$B$5:$B$204,0)),"") -> 282 | M510: =IFERROR(INDEX(_角色基线!$B$2:$B$100,MATCH($B510,_角色基线!$A$2:$A$100,0)),"") -> 塔拉夏 | N510: =IFERROR(INDEX(_角色基线!$C$2:$C$100,MATCH($B510,_角色基线!$A$2:$A$100,0)),"") -> Tank | O510: =IFERROR(INDEX(_怪物基线!$B$2:$B$501,MATCH(INT($L510),_怪物基线!$A$2:$A$501,0)),"") -> 405049 | P510: =IFERROR(INDEX(_怪物基线!$C$2:$C$501,MATCH(INT($L510),_怪物基线!$A$2:$A$501,0)),"") -> 37504 | Q510: =IFERROR(INDEX(_怪物基线!$D$2:$D$501,MATCH(INT($L510),_怪物基线!$A$2:$A$501,0)),"") -> 29861 | R510: =参数!$B$10 -> 4 | S510: =参数!$C$10 -> 1.2 | T510: =参数!$D$10 -> 1 | U510: =IF($O510="","",$O510*$R510) -> 1620196 | V510: =IF($P510="","",$P510*$S510) -> 45004.8 | W510: =IF($Q510="","",$Q510*$T510) -> 29861 | X510: =IFERROR(INDEX(参数!$B$5:$B$7,MATCH($N510,参数!$A$5:$A$7,0)),"") -> 1.5 | Y510: =IFERROR(INDEX(参数!$C$5:$C$7,MATCH($N510,参数!$A$5:$A$7,0)),"") -> 1 | Z510: =IFERROR(INDEX(参数!$D$5:$D$7,MATCH($N510,参数!$A$5:$A$7,0)),"") -> 1.5 | AA510: =IFERROR(INDEX(楼层配置!$E$5:$E$204,MATCH($K510,楼层配置!$B$5:$B$204,0)),1) -> 1.1258207 | AB510: =IFERROR(INDEX(楼层配置!$F$5:$F$204,MATCH($K510,楼层配置!$B$5:$B$204,0)),1) -> 0.72983489 | AC510: =IFERROR(INDEX(楼层配置!$G$5:$G$204,MATCH($K510,楼层配置!$B$5:$B$204,0)),1) -> 1 | AD510: =IFERROR($D510/$G510-1,"") | AE510: =IFERROR($E510/$H510-1,"") | AF510: =IFERROR($F510/$I510-1,"") | AG510: =IF(AND($A510>=1,$L510>=1,$L510<=500,OR($N510="Tank",$N510="DPS",$N510="Support"),ISNUMBER($D510),ISNUMBER($E510),ISNUMBER($F510)),"有效","异常") -> 有效 | AH510: =D510/(1-MIN(0.75,F510/(24000+F510))) -> 7842503
A511: 507 | B511: 1005 | C511: 60 | D511: =IFERROR(ROUND($U511*$X511*$AA511*参数!$B$13,0),"") -> 1824050 | E511: =IFERROR(ROUND($V511*$Y511*$AB511*参数!$C$13,0),"") -> 39415 | F511: =IFERROR(ROUND($W511*$Z511*$AC511*参数!$D$13,0),"") -> 29861 | J511: 102 | K511: 102 | L511: =IFERROR(INDEX(楼层配置!$D$5:$D$204,MATCH($K511,楼层配置!$B$5:$B$204,0)),"") -> 282 | M511: =IFERROR(INDEX(_角色基线!$B$2:$B$100,MATCH($B511,_角色基线!$A$2:$A$100,0)),"") -> 陈单单 | N511: =IFERROR(INDEX(_角色基线!$C$2:$C$100,MATCH($B511,_角色基线!$A$2:$A$100,0)),"") -> DPS | O511: =IFERROR(INDEX(_怪物基线!$B$2:$B$501,MATCH(INT($L511),_怪物基线!$A$2:$A$501,0)),"") -> 405049 | P511: =IFERROR(INDEX(_怪物基线!$C$2:$C$501,MATCH(INT($L511),_怪物基线!$A$2:$A$501,0)),"") -> 37504 | Q511: =IFERROR(INDEX(_怪物基线!$D$2:$D$501,MATCH(INT($L511),_怪物基线!$A$2:$A$501,0)),"") -> 29861 | R511: =参数!$B$10 -> 4 | S511: =参数!$C$10 -> 1.2 | T511: =参数!$D$10 -> 1 | U511: =IF($O511="","",$O511*$R511) -> 1620196 | V511: =IF($P511="","",$P511*$S511) -> 45004.8 | W511: =IF($Q511="","",$Q511*$T511) -> 29861 | X511: =IFERROR(INDEX(参数!$B$5:$B$7,MATCH($N511,参数!$A$5:$A$7,0)),"") -> 1 | Y511: =IFERROR(INDEX(参数!$C$5:$C$7,MATCH($N511,参数!$A$5:$A$7,0)),"") -> 1.2 | Z511: =IFERROR(INDEX(参数!$D$5:$D$7,MATCH($N511,参数!$A$5:$A$7,0)),"") -> 1 | AA511: =IFERROR(INDEX(楼层配置!$E$5:$E$204,MATCH($K511,楼层配置!$B$5:$B$204,0)),1) -> 1.1258207 | AB511: =IFERROR(INDEX(楼层配置!$F$5:$F$204,MATCH($K511,楼层配置!$B$5:$B$204,0)),1) -> 0.72983489 | AC511: =IFERROR(INDEX(楼层配置!$G$5:$G$204,MATCH($K511,楼层配置!$B$5:$B$204,0)),1) -> 1 | AD511: =IFERROR($D511/$G511-1,"") | AE511: =IFERROR($E511/$H511-1,"") | AF511: =IFERROR($F511/$I511-1,"") | AG511: =IF(AND($A511>=1,$L511>=1,$L511<=500,OR($N511="Tank",$N511="DPS",$N511="Support"),ISNUMBER($D511),ISNUMBER($E511),ISNUMBER($F511)),"有效","异常") -> 有效 | AH511: =D511/(1-MIN(0.75,F511/(24000+F511))) -> 4093548.2
A512: 508 | B512: 1005 | C512: 60 | D512: =IFERROR(ROUND($U512*$X512*$AA512*参数!$B$13,0),"") -> 1824050 | E512: =IFERROR(ROUND($V512*$Y512*$AB512*参数!$C$13,0),"") -> 39415 | F512: =IFERROR(ROUND($W512*$Z512*$AC512*参数!$D$13,0),"") -> 29861 | J512: 102 | K512: 102 | L512: =IFERROR(INDEX(楼层配置!$D$5:$D$204,MATCH($K512,楼层配置!$B$5:$B$204,0)),"") -> 282 | M512: =IFERROR(INDEX(_角色基线!$B$2:$B$100,MATCH($B512,_角色基线!$A$2:$A$100,0)),"") -> 陈单单 | N512: =IFERROR(INDEX(_角色基线!$C$2:$C$100,MATCH($B512,_角色基线!$A$2:$A$100,0)),"") -> DPS | O512: =IFERROR(INDEX(_怪物基线!$B$2:$B$501,MATCH(INT($L512),_怪物基线!$A$2:$A$501,0)),"") -> 405049 | P512: =IFERROR(INDEX(_怪物基线!$C$2:$C$501,MATCH(INT($L512),_怪物基线!$A$2:$A$501,0)),"") -> 37504 | Q512: =IFERROR(INDEX(_怪物基线!$D$2:$D$501,MATCH(INT($L512),_怪物基线!$A$2:$A$501,0)),"") -> 29861 | R512: =参数!$B$10 -> 4 | S512: =参数!$C$10 -> 1.2 | T512: =参数!$D$10 -> 1 | U512: =IF($O512="","",$O512*$R512) -> 1620196 | V512: =IF($P512="","",$P512*$S512) -> 45004.8 | W512: =IF($Q512="","",$Q512*$T512) -> 29861 | X512: =IFERROR(INDEX(参数!$B$5:$B$7,MATCH($N512,参数!$A$5:$A$7,0)),"") -> 1 | Y512: =IFERROR(INDEX(参数!$C$5:$C$7,MATCH($N512,参数!$A$5:$A$7,0)),"") -> 1.2 | Z512: =IFERROR(INDEX(参数!$D$5:$D$7,MATCH($N512,参数!$A$5:$A$7,0)),"") -> 1 | AA512: =IFERROR(INDEX(楼层配置!$E$5:$E$204,MATCH($K512,楼层配置!$B$5:$B$204,0)),1) -> 1.1258207 | AB512: =IFERROR(INDEX(楼层配置!$F$5:$F$204,MATCH($K512,楼层配置!$B$5:$B$204,0)),1) -> 0.72983489 | AC512: =IFERROR(INDEX(楼层配置!$G$5:$G$204,MATCH($K512,楼层配置!$B$5:$B$204,0)),1) -> 1 | AD512: =IFERROR($D512/$G512-1,"") | AE512: =IFERROR($E512/$H512-1,"") | AF512: =IFERROR($F512/$I512-1,"") | AG512: =IF(AND($A512>=1,$L512>=1,$L512<=500,OR($N512="Tank",$N512="DPS",$N512="Support"),ISNUMBER($D512),ISNUMBER($E512),ISNUMBER($F512)),"有效","异常") -> 有效 | AH512: =D512/(1-MIN(0.75,F512/(24000+F512))) -> 4093548.2
A513: 509 | B513: 1005 | C513: 60 | D513: =IFERROR(ROUND($U513*$X513*$AA513*参数!$B$13,0),"") -> 1824050 | E513: =IFERROR(ROUND($V513*$Y513*$AB513*参数!$C$13,0),"") -> 39415 | F513: =IFERROR(ROUND($W513*$Z513*$AC513*参数!$D$13,0),"") -> 29861 | J513: 102 | K513: 102 | L513: =IFERROR(INDEX(楼层配置!$D$5:$D$204,MATCH($K513,楼层配置!$B$5:$B$204,0)),"") -> 282 | M513: =IFERROR(INDEX(_角色基线!$B$2:$B$100,MATCH($B513,_角色基线!$A$2:$A$100,0)),"") -> 陈单单 | N513: =IFERROR(INDEX(_角色基线!$C$2:$C$100,MATCH($B513,_角色基线!$A$2:$A$100,0)),"") -> DPS | O513: =IFERROR(INDEX(_怪物基线!$B$2:$B$501,MATCH(INT($L513),_怪物基线!$A$2:$A$501,0)),"") -> 405049 | P513: =IFERROR(INDEX(_怪物基线!$C$2:$C$501,MATCH(INT($L513),_怪物基线!$A$2:$A$501,0)),"") -> 37504 | Q513: =IFERROR(INDEX(_怪物基线!$D$2:$D$501,MATCH(INT($L513),_怪物基线!$A$2:$A$501,0)),"") -> 29861 | R513: =参数!$B$10 -> 4 | S513: =参数!$C$10 -> 1.2 | T513: =参数!$D$10 -> 1 | U513: =IF($O513="","",$O513*$R513) -> 1620196 | V513: =IF($P513="","",$P513*$S513) -> 45004.8 | W513: =IF($Q513="","",$Q513*$T513) -> 29861 | X513: =IFERROR(INDEX(参数!$B$5:$B$7,MATCH($N513,参数!$A$5:$A$7,0)),"") -> 1 | Y513: =IFERROR(INDEX(参数!$C$5:$C$7,MATCH($N513,参数!$A$5:$A$7,0)),"") -> 1.2 | Z513: =IFERROR(INDEX(参数!$D$5:$D$7,MATCH($N513,参数!$A$5:$A$7,0)),"") -> 1 | AA513: =IFERROR(INDEX(楼层配置!$E$5:$E$204,MATCH($K513,楼层配置!$B$5:$B$204,0)),1) -> 1.1258207 | AB513: =IFERROR(INDEX(楼层配置!$F$5:$F$204,MATCH($K513,楼层配置!$B$5:$B$204,0)),1) -> 0.72983489 | AC513: =IFERROR(INDEX(楼层配置!$G$5:$G$204,MATCH($K513,楼层配置!$B$5:$B$204,0)),1) -> 1 | AD513: =IFERROR($D513/$G513-1,"") | AE513: =IFERROR($E513/$H513-1,"") | AF513: =IFERROR($F513/$I513-1,"") | AG513: =IF(AND($A513>=1,$L513>=1,$L513<=500,OR($N513="Tank",$N513="DPS",$N513="Support"),ISNUMBER($D513),ISNUMBER($E513),ISNUMBER($F513)),"有效","异常") -> 有效 | AH513: =D513/(1-MIN(0.75,F513/(24000+F513))) -> 4093548.2
