Workbook

Sheet 资源定价
B2: 道具备注 | C2: 道具 | D2: 道具id | E2: 道具定价(rmb) | F2: 道具定价(钻石)
A3: 外观道具 | C3: 无 | D3: 0 | E3: 0 | F3: 0
C4: 头像框 | D4: 0 | E4: 0 | F4: 0
C5: 头像 | D5: 0 | E5: 0 | F5: 0
C6: 时装 | D6: 0 | E6: 68 | F6: =E6*10 -> 680
A9: 通用资源 | C9: 体力 | D9: 3 | E9: 0.4 | F9: =E9*10 -> 4
C10: 钻石 | D10: 2 | E10: 0.1 | F10: =E10*10 -> 1
C11: 金币 | D11: 1 | E11: 0.0001 | F11: =E11*10 -> 0.001
C12: 玩家经验 | D12: 4 | E12: 0.04 | F12: =E12*10 -> 0.4
C13: 角色抽卡券普通 | D13: 106 | E13: 15 | F13: =E13*10 -> 150
C14: 专武抽卡券普通 | D14: 107 | E14: 5 | F14: =E14*10 -> 50
C15: 抽卡大代币 | D15: 21 | E15: 1.5 | F15: =E15*10 -> 15
C16: 抽卡小代币 | D16: 22 | E16: 0.15 | F16: =E16*10 -> 1.5
C17: 爬塔代币 | D17: 27 | E17: 0.1 | F17: =E17*10 -> 1
C18: 体力药 | D18: 105 | E18: =E9*60 -> 24 | F18: =F9*60 -> 240
C19: 竞技场代币 | D19: 19 | E19: 1 | F19: =E19*10 -> 10
C20: 角色抽卡券限时 | D20: 111 | E20: 15 | F20: =E20*10 -> 150
C21: 专武抽卡券限时 | D21: 112 | E21: 5 | F21: =E21*10 -> 50
A22: 公会 | C22: 公会个人代币 | D22: 15 | E22: 0.1 | F22: =E22*10 -> 1
C23: 公会集体代币 | D23: 14 | E23: 0.1 | F23: =E23*10 -> 1
A25: 角色升级升阶 | C25: 角色经验 | E25: 0.0001 | F25: =E25*10 -> 0.001
C26: 角色经验低500 | D26: 100 | E26: =E25*500 -> 0.05 | F26: =E26*10 -> 0.5
C27: 角色经验中2000 | D27: 101 | E27: =E25*2000 -> 0.2 | F27: =E27*10 -> 2
C28: 角色经验高10000 | D28: 102 | E28: =E25*10000 -> 1 | F28: =E28*10 -> 10
C30: 角色万能升阶材料 | E30: =E31 -> 0.4 | F30: =E30*10 -> 4
B31: 可能根据职业 分成多个类型 | C31: 角色升阶材料低 | E31: 0.4 | F31: =E31*10 -> 4
C32: 角色升阶材料中 | E32: =E31*3 -> 1.2 | F32: =E32*10 -> 12
C33: 角色升阶材料高 | E33: =E32*3 -> 3.6 | F33: =E33*10 -> 36
C34: 角色升阶材料低攻击 | D34: 1001 | E34: =E31 -> 0.4 | F34: =E34*10 -> 4
C35: 角色升阶材料中攻击 | D35: 1004 | E35: =E32 -> 1.2 | F35: =E35*10 -> 12
C36: 角色升阶材料高攻击 | D36: 1007 | E36: =E33 -> 3.6 | F36: =E36*10 -> 36
C37: 角色升阶材料低防御 | D37: 1002 | E37: =E34 -> 0.4 | F37: =E37*10 -> 4
C38: 角色升阶材料中防御 | D38: 1005 | E38: =E35 -> 1.2 | F38: =E38*10 -> 12
C39: 角色升阶材料高防御 | D39: 1008 | E39: =E36 -> 3.6 | F39: =E39*10 -> 36
C40: 角色升阶材料低辅助 | D40: 1003 | E40: =E37 -> 0.4 | F40: =E40*10 -> 4
C41: 角色升阶材料中辅助 | D41: 1006 | E41: =E38 -> 1.2 | F41: =E41*10 -> 12
C42: 角色升阶材料高辅助 | D42: 1009 | E42: =E39 -> 3.6 | F42: =E42*10 -> 36
C43: SSR角色 | E43: 750 | F43: =E43*10 -> 7500
C44: SR角色 | E44: 50 | F44: =E44*10 -> 500
C45: R角色 | E45: 9 | F45: =E45*10 -> 90
...
