Workbook

Sheet 战斗属性
B2: 属性类别 | C2: 具体属性 | D2: 属性说明 | E2: 数据类型 | F2: 默认值 | G2: 展示位置 | H2: 备注
B3: 基础属性 | C3: 生命 | D3: 角色生命值，生命值为0角色死亡 | E3: int | F3: 0 | G3: 基础属性 | H3: 分为裸体属性和额外属性，裸体属性只包含角色基础、角色升级、角色能效
C4: 攻击 | D4: 影响战斗中角色物理伤害 | E4: int | F4: 0 | G4: 基础属性 | H4: 分为裸体属性和额外属性，裸体属性只包含角色基础、角色升级、角色能效
C5: 攻击 | D5: 影响战斗中角色魔法伤害 | E5: int | F5: 0 | G5: 基础属性 | H5: 分为裸体属性和额外属性，裸体属性只包含角色基础、角色升级、角色能效
C6: 防御力 | D6: 影响战斗中减伤效果 | E6: int | F6: 0 | G6: 基础属性 | H6: 分为裸体属性和额外属性，裸体属性只包含角色基础、角色升级、角色能效
B8: 战斗属性 | C8: 能量上限 | D8: 能量值上限，能量达到上限角色即可释放必杀技 | E8: int | F8: 100 | G8: 建议展示在必杀技能中 | H8: 达到该值时，角色可以释放必杀，建议配置在角色表
C9: 能量初始值 | D9: 角色进入战斗时初始的能量值 | E9: int | F9: 0 | G9: 建议展示在必杀技能中 | H9: 角色进入战斗时初始的能量值，建议配置在角色表
C10: 能量回复速度 | D10: 角色每秒获取的能量值 | E10: float | F10: 2.5 | G10: 进阶属性 | H10: 每秒能量的回复值
C11: 暴击 | D11: 影响战斗中造成暴击的概率 | E11: float | F11: 0.05 | G11: 进阶属性
C12: 暴击伤害 | D12: 影响战斗中造成暴击的伤害倍数 | E12: float | F12: 2 | G12: 进阶属性
C13: 闪避 | D13: 降低战斗中受到伤害的概率 | E13: float | F13: 0 | G13: 进阶属性 | H13: 暂时只在角色技能和被动中投放
C14: 命中 | D14: 影响战斗中造成伤害的概率 | E14: float | F14: 1 | G14: 进阶属性 | H14: 暂时只在角色技能和被动中投放
C15: 效果命中 | D15: 提高战斗中负面效果命中概率，暂时不使用，可以忽略 | E15: float | F15: 0 | G15: 进阶属性
C16: 效果抵抗 | D16: 降低战斗中负面效果命中概率，暂时不使用，可以忽略 | E16: float | F16: 0 | G16: 进阶属性
C17: 无视防御 | D17: 降低战斗中对方的防御效果 | E17: float | F17: 0 | G17: 面板不显示 | H17: 最多100%
C18: 普攻攻击速度 | D18: 影响战斗中角色每秒发射的普攻，例如3点攻速代表1秒发射3次普攻 | E18: float | F18: 每个角色不同 | G18: 进阶属性 | H18: 英雄普攻1秒进行打X个子弹，计算方式为x*(1+攻速加成%)=最终攻速 例如该角色1s释放2次普攻，攻击速度加成为100%，则该角色显示的攻速为4 另外建议每个角色的攻击速度单独配置在角色表中
C19: 伤害加成 | D19: 增加战斗中造成的伤害（所有的伤害加成属于同一乘区） | E19: float | F19: 0 | G19: 面板不显示 | H19: 暂时只在角色技能和被动中投放
C20: 物理伤害加成 | D20: 增加战斗中造成的物理伤害 | E20: float | F20: 0 | G20: 面板不显示 | H20: 暂时只在角色技能和被动中投放
C21: 魔法伤害加成 | D21: 增加战斗中造成的魔法伤害 | E21: float | F21: 0 | G21: 面板不显示 | H21: 暂时只在角色技能和被动中投放
C22: 普攻伤害加成 | D22: 增加战斗中普攻造成的伤害 | E22: float | F22: 0 | G22: 面板显示
C23: 技能伤害加成 | D23: 增加战斗中技能造成的伤害 | E23: float | F23: 0 | G23: 面板显示
C24: 必杀伤害加成 | D24: 增加战斗中必杀造成的伤害 | E24: float | F24: 0 | G24: 面板显示
C25: 单体伤害加成 | D25: 增加战斗中穿单体果造成的伤害 | E25: float | F25: 0 | G25: 面板显示
C26: 穿透伤害加成 | D26: 增加战斗中穿透效果造成的伤害 | E26: float | F26: 0 | G26: 面板显示
C27: 范围伤害加成 | D27: 增加战斗中范围效果造成的伤害 | E27: float | F27: 0 | G27: 面板显示
C28: 持续伤害加成 | D28: 增加战斗中持续效果造成的伤害（包括流血、灼烧、中毒） | E28: float | F28: 0 | G28: 面板显示
C29: 流血伤害加成 | D29: 增加战斗中流血效果造成的伤害 | E29: float | F29: 0 | G29: 面板不显示
C30: 灼烧伤害加成 | D30: 增加战斗中持续效果造成的伤害 | E30: float | F30: 0 | G30: 面板不显示
C31: 中毒伤害加成 | D31: 增加战斗中持续效果造成的伤害 | E31: float | F31: 0 | G31: 面板不显示
C32: 伤害减免 | D32: 减免战斗中造成的伤害 | E32: float | F32: 0 | G32: 面板不显示
C33: 治疗加成 | D33: 治疗时，调整治疗值 | E33: float | F33: 0 | G33: 面板不显示
... C35: 受治疗加成 | D35: 受到治疗时，调整治疗值 | E35: float | F35: 0 | G35: 面板不显示
C36: 施加护盾加成 | D36: 战斗中释放护盾时，数值加成 | E36: float | F36: 0 | G36: 面板不显示 | H36: 暂时只在角色技能和被动中投放
C37: 受到护盾加成 | D37: 战斗中受到护盾时，数值加成 | E37: float | F37: 0 | G37: 面板不显示 | H37: 暂时只在角色技能和被动中投放
C38: 释放盾牌加成 | D38: 战斗中释放护盾时，盾牌生命数值加成 | E38: float | F38: 0 | G38: 面板不显示 | H38: 暂时只在角色技能和被动中投放
C39: 格挡 | D39: 受到伤害时，触发格挡的概率 | E39: float | F39: 0 | G39: 面板不显示 | H39: 暂时只在角色技能和被动中投放
C40: 格挡强度 | D40: 触发格挡时，受到的最终伤害 | E40: float | F40: 0 | G40: 面板不显示 | H40: 暂时只在角色技能和被动中投放
C41: 破击 | D41: 降低敌方触发格挡的概率 | E41: float | F41: 0 | G41: 面板不显示 | H41: 暂时只在角色技能和被动中投放
C42: 冷却缩减 | D42: 释放技能的冷却缩减 | E42: float | F42: 0 | G42: 面板不显示 | H42: 角色技能释放的技能间隔缩减，最高上限为75%，可拉出来配置 例如一个角色的技能间隔为5s，获得20%的技能冷却缩减，则技能间隔变为4s
C43: 玩法伤害加成 | D43: 增加战斗中造成的伤害 | E43: float | F43: 0 | G43: 面板不显示 | H43: 玩法中才会投放，和伤害加成和减免不是一个乘区
...

Sheet 战斗公式
B3: 战斗计算规则
B5: 攻击行为
B7: 流程1 | C7: 每次攻击先判定是否命中
B9: 命中概率为=（攻击者命中 - 受击者闪避）， 如果数值大于等于1则必然命中，数值小于等于X则取最小命中概率X，在0-1之间随机，X为10%
B10: 技能未命中的情况默认不触发后续机制，除非有特殊说明
B13: 流程2 | C13: 进行伤害类型的判断
B15: 真实伤害
B16: 不进行伤害公式计算，不受护盾影响，直接扣除给定数值的生命（百分比or固定值）
B18: 物理伤害or魔法伤害
B19: 走以下伤害数值的计算
B21: 流程3 | C21: 计算初步伤害数值
B24: 伤害基数=带入伤害公式的数值，在子弹或攻击组件中计算得出
B25: 物理伤害/魔法伤害取决于伤害组件的配置，公式相同，作为逻辑标签使用
B26: 伤害=伤害基数*[（1-(受击者 防御*（1 - 攻击者 无视防御）/【(受击者 防御 *（1- 攻击者 无视防御）+X)】，X为常数根据需求调整（可配置在全局表中），最低伤害保底：伤害基数 * 5%
L27: X的值为 | M27: 24000
B28: 流程4 | C28: 判断是否暴击
B30: 由攻击者 暴击率 属性决定 ，数值大于等于1必暴击，数值小于等于0必不暴击
B31: 命中后判定暴击
B32: 如果勾选必定暴击，则判断为暴击，如果没勾选，则进行随机
B33: 如果暴击
B34: 暴击伤害 = 伤害 * 攻击者暴击伤害
B37: 流程5 | C37: 判断是否格挡 | E37: 如果既格挡又暴击，则在表现上只显示格挡
B39: 由攻击者 破击率 属性决定和防御者格挡率决定是否触发格挡
B40: 格挡概率=受击者格挡率-攻击者破击率，最低为0，最高为1
B41: 如果格挡
B42: 格挡后伤害=计算暴击后的伤害*(1-基础格挡伤害X-格挡强度）
D43: X | E43: 0.5
D44: 格挡强度∈【0,1】
B45: 举例
B46: 受击者的格挡强度为20%，受击者计算完暴击后，应该受到的伤害为1000，此时触发了格挡
B47: 触发格挡后，受到的伤害为1000*（1-50-20%）=300
B53: 流程6 | C53: 计算最终伤害
B54: 最终伤害 =
B55: 计算完暴击、格挡后伤害 *（1+ 攻击者 伤害加成）*（1 - 受击者 伤害减免）*（1 + 受击者受到伤害增加）*（1+ 攻击者 玩法伤害加成）*（1 - 受击者 玩法伤害减免）
B58: 所有类型的伤害加成的乘区相同
B59: 例如：A角色拥有10%伤害增加，20%单体伤害增加，30%群体伤害增加，40%技能伤害增加，50%必杀伤害增加，60%的物理伤害增加和70%的魔法伤害增加
B60: 那么他放单体物理技能时的伤害增加值为10%+20%+40%+60%=130%
B61: 那么他放群体魔法必杀时的伤害增加值为10%+30%+50%+70%=160%
B63: 公式中 受击者 伤害减免属性 计算结果 最大不超过X%，X为75
B64: 最终伤害数值保底为X,X为1
...

Sheet 标准模型
C2: 战斗节奏
C3: 整场战斗时间
C5: 前期 | D5: 中期 | E5: 后期
B6: 总体战斗时长（秒） | C6: 60 | D6: 120 | E6: 150
B7: boss战时长占比 | C7: 0.5 | D7: 0.75 | E7: 0.8
B9: boss战时长（秒） | C9: =C6*C7 | D9: =D6*D7 | E9: =E6*E7
C11: 在标准模型下预估整场boss战的时长和节奏,以3人放普攻、5人放必杀
C12: 考虑主要的是pve体验，玩家的生命值和防御主要决定有效生命值，实际表现为挨怪物多少下打会死，攻击力主要表现为打怪物的时间
C13: 理论上怪攻击击和同等级的玩家应该相同，所以玩家的攻防血比应该就是怪攻击击自己多少下会死
C14: 假设怪物的dps系数为
C15: 1 | D15: 攻击力/s
C17: 实际血攻防投放比例比
C18: 生命 | D18: 攻击 | E18: 防御
C19: 10 | D19: 3 | E19: 2
C21: 基础属性组成
B22: 裸体属性 | C22: 1 | D22: 初始属性
C23: 2 | D23: 升级属性
C24: 3 | D24: 升阶属性
C25: 4 | D25: 星盘属性的固定值
C27: 5 | D27: 专武属性
C28: 6 | D28: 旅券
C29: 7 | D29: 主角装备属性
B31: 角色基础属性拍定 | C31: 生命 | D31: 攻击 | E31: 防御
C32: 5000 | D32: 1500 | E32: 1000
C33: 10 | D33: 3 | E33: 2
B36: 角色基础属性投放预计
C37: 裸体属性 | G37: 额外属性
C38: 初始属性 | D38: 升级属性 | E38: 升阶属性 | F38: 星盘属性 | G38: 专武属性 | H38: 旅券 | I38: 主角装备属性 | M38: 裸体总和 | N38: 额外总和
B39: 基础属性投放系数 | C39: 1 | D39: 4.2 | E39: 1.5 | F39: 1.2 | G39: 4 | H39: 6 | I39: 10 | M39: =SUM(C39:F39) | N39: =SUM(G39:I39)
B42: 初始标准人属性 | C42: 生命 | D42: 攻击 | E42: 防御
C43: =C32 | D43: =D32 | E43: =E32 | G43: 减伤率 | H43: =ROUND(E43/(E43+战斗公式!$M$27),2) | I43: eHP | J43: =ROUND(C43/(1-H43),0)
I44: ttk | J44: =J43/(D43*$C$15) | K44: 秒
A46: 中期 | B46: 无百分比标准人属性
B48: 裸体属性 | C48: 生命 | D48: 攻击 | E48: 防御
C49: =C$32*$M$39 | D49: =D$32*$M$39 | E49: =E$32*$M$39
B51: 额外基础属性 | C51: 生命 | D51: 攻击 | E51: 防御
C52: =$N$39*C$32 | D52: =$N$39*D$32 | E52: =$N$39*E$32
B54: 总基础属性 | C54: 生命 | D54: 攻击 | E54: 防御
C55: =C49+C52 | D55: =D49+D52 | E55: =E49+E52 | G55: 减伤率 | H55: =ROUND(E55/(E55+战斗公式!$M$27),2) | I55: eHP | J55: =ROUND(C55/(1-H55),0)
I56: ttk | J56: =J55/(D55*$C$15) | K56: 秒
...

Sheet 技能系数
B2: 技能系数 | C2: 16.5 | G2: 技能系数计算 | J2: 拆分系数 | N2: 品质系数 | Q2: 攻血比
B3: 技能当前品质 | C3: R
B4: 单体伤害 | G4: 基础技能系数 | H4: =标准模型!H81 | J4: 1 | K4: 0.7 | L4: =$L$7/$K$7*K4 | N4: R | O4: 0.9 | Q4: 血量 | R4: 12 | S4: =$S$5*$R$5/R4
B5: 单体系数 | C5: 1 | G5: 基础冷却时间 | H5: =标准模型!H78 | J5: 2 | K5: 0.8 | L5: =$L$7/$K$7*K5 | N5: SR | O5: 0.95 | Q5: 攻击 | R5: 3 | S5: 12
B6: 品质系数 | C6: =$C$3 | D6: =VLOOKUP(C6,$N$4:$O$6,2,0) | G6: 实际冷却时间 | H6: 12 | J6: 3 | K6: 0.9 | L6: =$L$7/$K$7*K6 | N6: SSR | O6: 1 | Q6: 防御 | R6: 2 | S6: =$S$5*$R$5/R6
B7: 攻速 | C7: 7 | G7: 最终技能系数 | H7: =H4*H6/H5 | J7: 4 | K7: 1 | L7: 6.8
B8: 伤害系数 | C8: =C5/C7*D6*C2 | G8: 普攻基础系数 | H8: =100%
G9: 必杀基础系数 | H9: =标准模型!H82
B10: 穿透子弹
B11: 穿透子弹系数 | C11: 0.7
B12: 品质系数 | C12: =$C$3 | D12: =VLOOKUP(C12,$N$4:$O$6,2,0)
B13: 攻速 | C13: 1
B14: 伤害系数 | C14: =C11/C13*D12*C2
B16: 跟踪子弹 | N16: 普攻、必杀系数 | O16: 0.5 | P16: 0.65 | Q16: 0.8 | R16: 1
B17: 跟踪子弹系数 | C17: 0.93
B18: 品质系数 | C18: =$C$3 | D18: =VLOOKUP(C18,$N$4:$O$6,2,0) | N18: 技能系数 | O18: 0.5 | P18: 0.75 | Q18: 1
B19: 攻速 | C19: 1 | T19: %/ | U19: %
B20: 伤害系数 | C20: =C17/C19*D18*C2 | O20: =MROUND($R$20*O16,5) | P20: =MROUND($R$20*P16,5) | Q20: =MROUND($R$20*Q16,5) | R20: 40 | T20: =_xlfn.CONCAT(O20,$T$19,P20,$T$19,Q20,$T$19,R20,$U$19)
O22: =MROUND(O18*$R$20,5) | P22: =MROUND(P18*$R$20,5) | Q22: =MROUND(Q18*$R$20,5) | T22: =_xlfn.CONCAT(O22,$T$19,P22,$T$19,Q22,$U$19)
B23: AOE子弹
B24: AOE系数 | C24: 0.75
B25: 品质系数 | C25: =$C$3 | D25: =VLOOKUP(C25,$N$4:$O$6,2,0)
B26: 标准范围半径 | C26: 1
B27: 实际范围半径（标准倍数） | C27: 1
B28: 衰减系数 | C28: 1.2
B29: 攻速 | C29: 1
B30: 伤害系数 | C30: =POWER(C26,C28)/POWER(C27,C28)*C24*D25*C2/C29
B32: DOT
B33: DOT系数 | C33: 1.2
B34: 品质系数 | C34: =$C$3 | D34: =VLOOKUP(C34,$N$4:$O$6,2,0)
B35: DOT持续时间 | C35: 5
B36: DOT标准持续时间 | C36: 5
B37: DOT持续系数 | C37: 1.39 | D37: =POWER(C35,C37)/POWER(C36,C37)/C35*C36
B38: DOT标准最大层数 | C38: 5
B39: DOT最大层数 | C39: 2
B40: DOT最大层数系数 | C40: 1.21 | D40: =POWER(C38,C40)/POWER(C39,C40)*C39/C38
B41: DOT单层系数 | C41: =C33/C35*D37*D40*D34*C2
B44: 回血
B45: 回血系数 | C45: =标准模型!I75
B46: 品质系数 | C46: =$C$3 | D46: =VLOOKUP(C46,$N$4:$O$6,2,0)
...
