Workbook

Sheet 00_口径
A1: 项 | B1: 值 | C1: 备注
A2: 生成日期 | B2: 2026-09-05
A3: 生成物 | B3: D:\Vgame_design\output\numerical-production-workflow-v2\runs\20260905-120414-220437\framework-v2\养成\生成_映射装备数值总表.xlsx | C3: 运行时不读取04终稿
A4: 口径 | B4: 01_源表提供全局事实校验；03_沉淀MD提供系统参数与公式
A5: 公式说明 | B5: 派生项使用 Excel 公式；蓝字为源值/输入，黑字为公式
A6: 源表 | B6: 01_源表\属性定价.xlsx | C6: 6490dadd4bbc418d
A7: 源表 | B7: 01_源表\养成属性分配.xlsx | C7: 09bb311622181f46
A8: 源表 | B8: 01_源表\道具定价.xlsx | C8: 3a1b101606ec61d2
A9: 源表 | B9: 01_源表\经济口径.xlsx | C9: 3fcfbef83b98376e
A10: 源沉淀MD | B10: 03_沉淀MD\养成\映射装备养成数值沉淀-2026-07-07.md | C10: ee97552147e2c0d7
A11: 源沉淀MD | B11: 03_沉淀MD\经济\21_养成_映射装备经济消耗沉淀-2026-07-09.md | C11: 45cbc283729e204c
A12: 源沉淀MD | B12: 03_沉淀MD\经济\05_玩法_映射副本经济沉淀-2026-07-08.md | C12: 5526879278b1a396
A13: 源沉淀MD | B13: 03_沉淀MD\经济\08_玩法_爬塔经济沉淀-2026-07-09.md | C13: fe8eeeef2e452022
A14: 源沉淀MD | B14: 03_沉淀MD\养成\映射装备数值总表生成参数-2026-07-10.md | C14: 9c2df89f29ca8eb3
A15: 01校验 | B15: 映射装备投放系数=10；生命/攻击/防御={'生命': 50000, '攻击': 15000, '防御': 10000} | C15: 三项60红目标=01投放的75%
A16: 金币锚点 | B16: 金币(1)，钻石定价=0.001 | C16: 来自01_源表/道具定价.xlsx
A17: 经济边界 | B17: 升级、打孔、鉴定已删除 | C17: 来自01_源表/经济口径.xlsx
A18: 新增汇总 | B18: 18_产销汇总：按前/中/后期汇总日产出、打造/合成承载和金币压力 | C18: 阶段假设维护在生成参数MD

Sheet 01_循环总览
A1: 环节 | B1: 投入/对象 | C1: 系统 | D1: 产出/去向 | E1: 备注
A2: 副本入场 | B2: 映射之匙(25)x1 | C2: 映射装备副本 | D2: 每日/周期由钥匙投放控制 | E2: 进入消耗，不归养成消耗
A3: 装备产出 | B3: 宝箱 | C3: 副本通关掉落 | D3: 装备进入穿戴/合成/分解 | E3: 红宝箱必出红装
A4: 打造材料产出 | B4: 主材/副材 | C4: 映射装备副本常驻 | D4: 打造指定等级/部位装备 | E4: 爬塔新版不再投放装备材料；主材决定打造档位和品质池
A5: 装备消耗 | B5: 9件同品质装备 + 金币 | C5: 合成 | D5: 随机部位，品质受锻造台影响 | E5: 合成给锻造台经验
A6: 材料消耗 | B6: 主材x1 + 2种副材 + 金币 | C6: 打造 | D6: 指定档内等级/部位，品质受锻造台影响 | E6: 打造不给锻造台经验
A7: 回收 | B7: 非目标装备 | C7: 分解 | D7: 金币 + 锻造台经验；红装额外高阶零件(23) | E7: 洗练本版不做
A8: 沉淀 | B8: 高阶零件(23) | C8: 红装分解 | D8: 后续版本装备高级材料储备 | E8: 当前无消耗

Sheet 02_品质等级
A1: 品质 | B1: 品质顺序 | C1: 主属性品质系数 | D1: 副属性品质系数 | E1: 合成金币系数 | F1: 分解金币系数 | G1: 随机倍率下限 | H1: 随机倍率上限
A2: 绿 | B2: 1 | C2: 0.2 | D2: 0.35 | E2: 0.5 | F2: 0.2 | G2: 1 | H2: 1
A3: 蓝 | B3: 2 | C3: 0.3 | D3: 0.5 | E3: 0.7 | F3: 0.4 | G3: 1 | H3: 1
A4: 紫 | B4: 3 | C4: 0.45 | D4: 0.65 | E4: 1 | F4: 0.8 | G4: 1 | H4: 1
A5: 金 | B5: 4 | C5: 0.7 | D5: 0.85 | E5: 1.4 | F5: 1.3 | G5: 1 | H5: 1.2
A6: 红 | B6: 5 | C6: 1 | D6: 1 | E6: 2 | F6: 2 | G6: 1.2 | H6: 1.4

Sheet 03_主属性基础
A1: 部位 | B1: 主属性 | C1: 口径 | E1: 主属性 | F1: 60级红装目标值 | G1: 单位 | I1: 等级 | J1: 主属性等级倍率
A2: 武器 | B2: 攻击 | C2: 基础攻击来源 | E2: 攻击 | F2: 11250 | G2: 数值 | I2: 5 | J2: 0.05
A3: 头盔 | B3: 生命 | C3: 基础生存来源之一 | E3: 生命 | F3: 18750 | G3: 数值 | I3: 10 | J3: 0.087
A4: 护甲（衣服） | B4: 生命 | C4: 基础生存来源之一 | E4: 生命 | F4: 18750 | G4: 数值 | I4: 15 | J4: 0.145
A5: 手套 | B5: 防御 | C5: 基础防御来源之一 | E5: 防御 | F5: 2500 | G5: 数值 | I5: 20 | J5: 0.214
A6: 腰带 | B6: 防御 | C6: 基础防御来源之一 | E6: 防御 | F6: 2500 | G6: 数值 | I6: 25 | J6: 0.292
A7: 鞋子 | B7: 防御 | C7: 基础防御来源之一 | E7: 防御 | F7: 2500 | G7: 数值 | I7: 30 | J7: 0.378
A8: 装置 | B8: 暴击伤害等级 | C8: 暴击体系高价值追求入口 | E8: 暴击伤害等级 | F8: 8800 | G8: 等级 | I8: 35 | J8: 0.469
A9: 饰品 | B9: 暴击等级 | C9: 攻击向随机追求入口 | E9: 暴击等级 | F9: 7200 | G9: 等级 | I9: 40 | J9: 0.566
I10: 45 | J10: 0.668
I11: 50 | J11: 0.775
I12: 55 | J12: 0.885
I13: 60 | J13: 1

Sheet 04_主属性计算
A1: 部位 | B1: 主属性 | C1: 品质 | D1: 等级 | E1: 60红目标 | F1: 主属性品质系数 | G1: 主属性等级倍率 | H1: 主属性值
A2: 武器 | B2: =INDEX('03_主属性基础'!$B$2:$B$9,MATCH(A2,'03_主属性基础'!$A$2:$A$9,0)) | C2: 绿 | D2: 5 | E2: =INDEX('03_主属性基础'!$F$2:$F$9,MATCH(B2,'03_主属性基础'!$E$2:$E$9,0)) | F2: =INDEX('02_品质等级'!$C$2:$C$6,MATCH(C2,'02_品质等级'!$A$2:$A$6,0)) | G2: =INDEX('03_主属性基础'!$J$2:$J$13,MATCH(D2,'03_主属性基础'!$I$2:$I$13,0)) | H2: =E2*F2*G2
A3: 武器 | B3: =INDEX('03_主属性基础'!$B$2:$B$9,MATCH(A3,'03_主属性基础'!$A$2:$A$9,0)) | C3: 绿 | D3: 10 | E3: =INDEX('03_主属性基础'!$F$2:$F$9,MATCH(B3,'03_主属性基础'!$E$2:$E$9,0)) | F3: =INDEX('02_品质等级'!$C$2:$C$6,MATCH(C3,'02_品质等级'!$A$2:$A$6,0)) | G3: =INDEX('03_主属性基础'!$J$2:$J$13,MATCH(D3,'03_主属性基础'!$I$2:$I$13,0)) | H3: =E3*F3*G3
A4: 武器 | B4: =INDEX('03_主属性基础'!$B$2:$B$9,MATCH(A4,'03_主属性基础'!$A$2:$A$9,0)) | C4: 绿 | D4: 15 | E4: =INDEX('03_主属性基础'!$F$2:$F$9,MATCH(B4,'03_主属性基础'!$E$2:$E$9,0)) | F4: =INDEX('02_品质等级'!$C$2:$C$6,MATCH(C4,'02_品质等级'!$A$2:$A$6,0)) | G4: =INDEX('03_主属性基础'!$J$2:$J$13,MATCH(D4,'03_主属性基础'!$I$2:$I$13,0)) | H4: =E4*F4*G4
A5: 武器 | B5: =INDEX('03_主属性基础'!$B$2:$B$9,MATCH(A5,'03_主属性基础'!$A$2:$A$9,0)) | C5: 绿 | D5: 20 | E5: =INDEX('03_主属性基础'!$F$2:$F$9,MATCH(B5,'03_主属性基础'!$E$2:$E$9,0)) | F5: =INDEX('02_品质等级'!$C$2:$C$6,MATCH(C5,'02_品质等级'!$A$2:$A$6,0)) | G5: =INDEX('03_主属性基础'!$J$2:$J$13,MATCH(D5,'03_主属性基础'!$I$2:$I$13,0)) | H5: =E5*F5*G5
A6: 武器 | B6: =INDEX('03_主属性基础'!$B$2:$B$9,MATCH(A6,'03_主属性基础'!$A$2:$A$9,0)) | C6: 绿 | D6: 25 | E6: =INDEX('03_主属性基础'!$F$2:$F$9,MATCH(B6,'03_主属性基础'!$E$2:$E$9,0)) | F6: =INDEX('02_品质等级'!$C$2:$C$6,MATCH(C6,'02_品质等级'!$A$2:$A$6,0)) | G6: =INDEX('03_主属性基础'!$J$2:$J$13,MATCH(D6,'03_主属性基础'!$I$2:$I$13,0)) | H6: =E6*F6*G6
A7: 武器 | B7: =INDEX('03_主属性基础'!$B$2:$B$9,MATCH(A7,'03_主属性基础'!$A$2:$A$9,0)) | C7: 绿 | D7: 30 | E7: =INDEX('03_主属性基础'!$F$2:$F$9,MATCH(B7,'03_主属性基础'!$E$2:$E$9,0)) | F7: =INDEX('02_品质等级'!$C$2:$C$6,MATCH(C7,'02_品质等级'!$A$2:$A$6,0)) | G7: =INDEX('03_主属性基础'!$J$2:$J$13,MATCH(D7,'03_主属性基础'!$I$2:$I$13,0)) | H7: =E7*F7*G7
A8: 武器 | B8: =INDEX('03_主属性基础'!$B$2:$B$9,MATCH(A8,'03_主属性基础'!$A$2:$A$9,0)) | C8: 绿 | D8: 35 | E8: =INDEX('03_主属性基础'!$F$2:$F$9,MATCH(B8,'03_主属性基础'!$E$2:$E$9,0)) | F8: =INDEX('02_品质等级'!$C$2:$C$6,MATCH(C8,'02_品质等级'!$A$2:$A$6,0)) | G8: =INDEX('03_主属性基础'!$J$2:$J$13,MATCH(D8,'03_主属性基础'!$I$2:$I$13,0)) | H8: =E8*F8*G8
A9: 武器 | B9: =INDEX('03_主属性基础'!$B$2:$B$9,MATCH(A9,'03_主属性基础'!$A$2:$A$9,0)) | C9: 绿 | D9: 40 | E9: =INDEX('03_主属性基础'!$F$2:$F$9,MATCH(B9,'03_主属性基础'!$E$2:$E$9,0)) | F9: =INDEX('02_品质等级'!$C$2:$C$6,MATCH(C9,'02_品质等级'!$A$2:$A$6,0)) | G9: =INDEX('03_主属性基础'!$J$2:$J$13,MATCH(D9,'03_主属性基础'!$I$2:$I$13,0)) | H9: =E9*F9*G9
A10: 武器 | B10: =INDEX('03_主属性基础'!$B$2:$B$9,MATCH(A10,'03_主属性基础'!$A$2:$A$9,0)) | C10: 绿 | D10: 45 | E10: =INDEX('03_主属性基础'!$F$2:$F$9,MATCH(B10,'03_主属性基础'!$E$2:$E$9,0)) | F10: =INDEX('02_品质等级'!$C$2:$C$6,MATCH(C10,'02_品质等级'!$A$2:$A$6,0)) | G10: =INDEX('03_主属性基础'!$J$2:$J$13,MATCH(D10,'03_主属性基础'!$I$2:$I$13,0)) | H10: =E10*F10*G10
A11: 武器 | B11: =INDEX('03_主属性基础'!$B$2:$B$9,MATCH(A11,'03_主属性基础'!$A$2:$A$9,0)) | C11: 绿 | D11: 50 | E11: =INDEX('03_主属性基础'!$F$2:$F$9,MATCH(B11,'03_主属性基础'!$E$2:$E$9,0)) | F11: =INDEX('02_品质等级'!$C$2:$C$6,MATCH(C11,'02_品质等级'!$A$2:$A$6,0)) | G11: =INDEX('03_主属性基础'!$J$2:$J$13,MATCH(D11,'03_主属性基础'!$I$2:$I$13,0)) | H11: =E11*F11*G11
A12: 武器 | B12: =INDEX('03_主属性基础'!$B$2:$B$9,MATCH(A12,'03_主属性基础'!$A$2:$A$9,0)) | C12: 绿 | D12: 55 | E12: =INDEX('03_主属性基础'!$F$2:$F$9,MATCH(B12,'03_主属性基础'!$E$2:$E$9,0)) | F12: =INDEX('02_品质等级'!$C$2:$C$6,MATCH(C12,'02_品质等级'!$A$2:$A$6,0)) | G12: =INDEX('03_主属性基础'!$J$2:$J$13,MATCH(D12,'03_主属性基础'!$I$2:$I$13,0)) | H12: =E12*F12*G12
A13: 武器 | B13: =INDEX('03_主属性基础'!$B$2:$B$9,MATCH(A13,'03_主属性基础'!$A$2:$A$9,0)) | C13: 绿 | D13: 60 | E13: =INDEX('03_主属性基础'!$F$2:$F$9,MATCH(B13,'03_主属性基础'!$E$2:$E$9,0)) | F13: =INDEX('02_品质等级'!$C$2:$C$6,MATCH(C13,'02_品质等级'!$A$2:$A$6,0)) | G13: =INDEX('03_主属性基础'!$J$2:$J$13,MATCH(D13,'03_主属性基础'!$I$2:$I$13,0)) | H13: =E13*F13*G13
... A481: 饰品 | B481: =INDEX('03_主属性基础'!$B$2:$B$9,MATCH(A481,'03_主属性基础'!$A$2:$A$9,0)) | C481: 红 | D481: 60 | E481: =INDEX('03_主属性基础'!$F$2:$F$9,MATCH(B481,'03_主属性基础'!$E$2:$E$9,0)) | F481: =INDEX('02_品质等级'!$C$2:$C$6,MATCH(C481,'02_品质等级'!$A$2:$A$6,0)) | G481: =INDEX('03_主属性基础'!$J$2:$J$13,MATCH(D481,'03_主属性基础'!$I$2:$I$13,0)) | H481: =E481*F481*G481

Sheet 05_副属性基础
A1: 副属性 | B1: 当前ValueMax | C1: 新标准值S | D1: Lv60红装随机区间 | E1: 单位 | G1: 等级 | H1: 百分比等级倍率 | I1: 固定值等级倍率
A2: 攻击百分比 | B2: 0.329 | C2: 0.1645 | D2: 19.74%～23.03% | E2: 比例 | G2: 5 | H2: 0.45 | I2: 0.03
A3: 防御百分比 | B3: 0.329 | C3: 0.1645 | D3: 19.74%～23.03% | E3: 比例 | G3: 10 | H3: 0.5 | I3: 0.068
A4: 生命百分比 | B4: 0.329 | C4: 0.1645 | D4: 19.74%～23.03% | E4: 比例 | G4: 15 | H4: 0.55 | I4: 0.106
A5: 攻击 | B5: 3701 | C5: 1850.5 | D5: 2,220.6～2,590.7 | E5: 数值 | G5: 20 | H5: 0.6 | I5: 0.16
A6: 防御 | B6: 2468 | C6: 1234 | D6: 1,480.8～1,727.6 | E6: 数值 | G6: 25 | H6: 0.65 | I6: 0.227
A7: 生命 | B7: 12338 | C7: 6169 | D7: 7,402.8～8,636.6 | E7: 数值 | G7: 30 | H7: 0.7 | I7: 0.305
A8: 暴击等级 | B8: 2961 | C8: 1480.5 | D8: 1,776.6～2,072.7 | E8: 等级 | G8: 35 | H8: 0.75 | I8: 0.395
A9: 暴击伤害等级 | B9: 3619 | C9: 1809.5 | D9: 2,171.4～2,533.3 | E9: 等级 | G9: 40 | H9: 0.8 | I9: 0.495
A10: 能量回复等级 | B10: 2961 | C10: 1480.5 | D10: 1,776.6～2,072.7 | E10: 等级 | G10: 45 | H10: 0.85 | I10: 0.607
A11: 技能冷却等级 | B11: 4277 | C11: 2138.5 | D11: 2,566.2～2,993.9 | E11: 等级 | G11: 50 | H11: 0.9 | I11: 0.729
G12: 55 | H12: 0.95 | I12: 0.86
G13: 60 | H13: 1 | I13: 1

Sheet 06_副属性计算
A1: 副属性 | B1: 类别 | C1: 品质 | D1: 等级 | E1: 标准值S | F1: 副属性品质系数 | G1: 类别等级倍率 | H1: 随机倍率下限 | I1: 随机倍率上限 | J1: 副属性值下限 | K1: 副属性值上限
A2: 攻击百分比 | B2: 百分比 | C2: 绿 | D2: 5 | E2: =INDEX('05_副属性基础'!$C$2:$C$11,MATCH(A2,'05_副属性基础'!$A$2:$A$11,0)) | F2: =INDEX('02_品质等级'!$D$2:$D$6,MATCH(C2,'02_品质等级'!$A$2:$A$6,0)) | G2: =INDEX('05_副属性基础'!$H$2:$H$13,MATCH(D2,'05_副属性基础'!$G$2:$G$13,0)) | H2: =INDEX('02_品质等级'!$G$2:$G$6,MATCH(C2,'02_品质等级'!$A$2:$A$6,0)) | I2: =INDEX('02_品质等级'!$H$2:$H$6,MATCH(C2,'02_品质等级'!$A$2:$A$6,0)) | J2: =E2*F2*G2*H2 | K2: =E2*F2*G2*I2
A3: 攻击百分比 | B3: 百分比 | C3: 绿 | D3: 10 | E3: =INDEX('05_副属性基础'!$C$2:$C$11,MATCH(A3,'05_副属性基础'!$A$2:$A$11,0)) | F3: =INDEX('02_品质等级'!$D$2:$D$6,MATCH(C3,'02_品质等级'!$A$2:$A$6,0)) | G3: =INDEX('05_副属性基础'!$H$2:$H$13,MATCH(D3,'05_副属性基础'!$G$2:$G$13,0)) | H3: =INDEX('02_品质等级'!$G$2:$G$6,MATCH(C3,'02_品质等级'!$A$2:$A$6,0)) | I3: =INDEX('02_品质等级'!$H$2:$H$6,MATCH(C3,'02_品质等级'!$A$2:$A$6,0)) | J3: =E3*F3*G3*H3 | K3: =E3*F3*G3*I3
A4: 攻击百分比 | B4: 百分比 | C4: 绿 | D4: 15 | E4: =INDEX('05_副属性基础'!$C$2:$C$11,MATCH(A4,'05_副属性基础'!$A$2:$A$11,0)) | F4: =INDEX('02_品质等级'!$D$2:$D$6,MATCH(C4,'02_品质等级'!$A$2:$A$6,0)) | G4: =INDEX('05_副属性基础'!$H$2:$H$13,MATCH(D4,'05_副属性基础'!$G$2:$G$13,0)) | H4: =INDEX('02_品质等级'!$G$2:$G$6,MATCH(C4,'02_品质等级'!$A$2:$A$6,0)) | I4: =INDEX('02_品质等级'!$H$2:$H$6,MATCH(C4,'02_品质等级'!$A$2:$A$6,0)) | J4: =E4*F4*G4*H4 | K4: =E4*F4*G4*I4
A5: 攻击百分比 | B5: 百分比 | C5: 绿 | D5: 20 | E5: =INDEX('05_副属性基础'!$C$2:$C$11,MATCH(A5,'05_副属性基础'!$A$2:$A$11,0)) | F5: =INDEX('02_品质等级'!$D$2:$D$6,MATCH(C5,'02_品质等级'!$A$2:$A$6,0)) | G5: =INDEX('05_副属性基础'!$H$2:$H$13,MATCH(D5,'05_副属性基础'!$G$2:$G$13,0)) | H5: =INDEX('02_品质等级'!$G$2:$G$6,MATCH(C5,'02_品质等级'!$A$2:$A$6,0)) | I5: =INDEX('02_品质等级'!$H$2:$H$6,MATCH(C5,'02_品质等级'!$A$2:$A$6,0)) | J5: =E5*F5*G5*H5 | K5: =E5*F5*G5*I5
A6: 攻击百分比 | B6: 百分比 | C6: 绿 | D6: 25 | E6: =INDEX('05_副属性基础'!$C$2:$C$11,MATCH(A6,'05_副属性基础'!$A$2:$A$11,0)) | F6: =INDEX('02_品质等级'!$D$2:$D$6,MATCH(C6,'02_品质等级'!$A$2:$A$6,0)) | G6: =INDEX('05_副属性基础'!$H$2:$H$13,MATCH(D6,'05_副属性基础'!$G$2:$G$13,0)) | H6: =INDEX('02_品质等级'!$G$2:$G$6,MATCH(C6,'02_品质等级'!$A$2:$A$6,0)) | I6: =INDEX('02_品质等级'!$H$2:$H$6,MATCH(C6,'02_品质等级'!$A$2:$A$6,0)) | J6: =E6*F6*G6*H6 | K6: =E6*F6*G6*I6
A7: 攻击百分比 | B7: 百分比 | C7: 绿 | D7: 30 | E7: =INDEX('05_副属性基础'!$C$2:$C$11,MATCH(A7,'05_副属性基础'!$A$2:$A$11,0)) | F7: =INDEX('02_品质等级'!$D$2:$D$6,MATCH(C7,'02_品质等级'!$A$2:$A$6,0)) | G7: =INDEX('05_副属性基础'!$H$2:$H$13,MATCH(D7,'05_副属性基础'!$G$2:$G$13,0)) | H7: =INDEX('02_品质等级'!$G$2:$G$6,MATCH(C7,'02_品质等级'!$A$2:$A$6,0)) | I7: =INDEX('02_品质等级'!$H$2:$H$6,MATCH(C7,'02_品质等级'!$A$2:$A$6,0)) | J7: =E7*F7*G7*H7 | K7: =E7*F7*G7*I7
A8: 攻击百分比 | B8: 百分比 | C8: 绿 | D8: 35 | E8: =INDEX('05_副属性基础'!$C$2:$C$11,MATCH(A8,'05_副属性基础'!$A$2:$A$11,0)) | F8: =INDEX('02_品质等级'!$D$2:$D$6,MATCH(C8,'02_品质等级'!$A$2:$A$6,0)) | G8: =INDEX('05_副属性基础'!$H$2:$H$13,MATCH(D8,'05_副属性基础'!$G$2:$G$13,0)) | H8: =INDEX('02_品质等级'!$G$2:$G$6,MATCH(C8,'02_品质等级'!$A$2:$A$6,0)) | I8: =INDEX('02_品质等级'!$H$2:$H$6,MATCH(C8,'02_品质等级'!$A$2:$A$6,0)) | J8: =E8*F8*G8*H8 | K8: =E8*F8*G8*I8
A9: 攻击百分比 | B9: 百分比 | C9: 绿 | D9: 40 | E9: =INDEX('05_副属性基础'!$C$2:$C$11,MATCH(A9,'05_副属性基础'!$A$2:$A$11,0)) | F9: =INDEX('02_品质等级'!$D$2:$D$6,MATCH(C9,'02_品质等级'!$A$2:$A$6,0)) | G9: =INDEX('05_副属性基础'!$H$2:$H$13,MATCH(D9,'05_副属性基础'!$G$2:$G$13,0)) | H9: =INDEX('02_品质等级'!$G$2:$G$6,MATCH(C9,'02_品质等级'!$A$2:$A$6,0)) | I9: =INDEX('02_品质等级'!$H$2:$H$6,MATCH(C9,'02_品质等级'!$A$2:$A$6,0)) | J9: =E9*F9*G9*H9 | K9: =E9*F9*G9*I9
A10: 攻击百分比 | B10: 百分比 | C10: 绿 | D10: 45 | E10: =INDEX('05_副属性基础'!$C$2:$C$11,MATCH(A10,'05_副属性基础'!$A$2:$A$11,0)) | F10: =INDEX('02_品质等级'!$D$2:$D$6,MATCH(C10,'02_品质等级'!$A$2:$A$6,0)) | G10: =INDEX('05_副属性基础'!$H$2:$H$13,MATCH(D10,'05_副属性基础'!$G$2:$G$13,0)) | H10: =INDEX('02_品质等级'!$G$2:$G$6,MATCH(C10,'02_品质等级'!$A$2:$A$6,0)) | I10: =INDEX('02_品质等级'!$H$2:$H$6,MATCH(C10,'02_品质等级'!$A$2:$A$6,0)) | J10: =E10*F10*G10*H10 | K10: =E10*F10*G10*I10
A11: 攻击百分比 | B11: 百分比 | C11: 绿 | D11: 50 | E11: =INDEX('05_副属性基础'!$C$2:$C$11,MATCH(A11,'05_副属性基础'!$A$2:$A$11,0)) | F11: =INDEX('02_品质等级'!$D$2:$D$6,MATCH(C11,'02_品质等级'!$A$2:$A$6,0)) | G11: =INDEX('05_副属性基础'!$H$2:$H$13,MATCH(D11,'05_副属性基础'!$G$2:$G$13,0)) | H11: =INDEX('02_品质等级'!$G$2:$G$6,MATCH(C11,'02_品质等级'!$A$2:$A$6,0)) | I11: =INDEX('02_品质等级'!$H$2:$H$6,MATCH(C11,'02_品质等级'!$A$2:$A$6,0)) | J11: =E11*F11*G11*H11 | K11: =E11*F11*G11*I11
A12: 攻击百分比 | B12: 百分比 | C12: 绿 | D12: 55 | E12: =INDEX('05_副属性基础'!$C$2:$C$11,MATCH(A12,'05_副属性基础'!$A$2:$A$11,0)) | F12: =INDEX('02_品质等级'!$D$2:$D$6,MATCH(C12,'02_品质等级'!$A$2:$A$6,0)) | G12: =INDEX('05_副属性基础'!$H$2:$H$13,MATCH(D12,'05_副属性基础'!$G$2:$G$13,0)) | H12: =INDEX('02_品质等级'!$G$2:$G$6,MATCH(C12,'02_品质等级'!$A$2:$A$6,0)) | I12: =INDEX('02_品质等级'!$H$2:$H$6,MATCH(C12,'02_品质等级'!$A$2:$A$6,0)) | J12: =E12*F12*G12*H12 | K12: =E12*F12*G12*I12
A13: 攻击百分比 | B13: 百分比 | C13: 绿 | D13: 60 | E13: =INDEX('05_副属性基础'!$C$2:$C$11,MATCH(A13,'05_副属性基础'!$A$2:$A$11,0)) | F13: =INDEX('02_品质等级'!$D$2:$D$6,MATCH(C13,'02_品质等级'!$A$2:$A$6,0)) | G13: =INDEX('05_副属性基础'!$H$2:$H$13,MATCH(D13,'05_副属性基础'!$G$2:$G$13,0)) | H13: =INDEX('02_品质等级'!$G$2:$G$6,MATCH(C13,'02_品质等级'!$A$2:$A$6,0)) | I13: =INDEX('02_品质等级'!$H$2:$H$6,MATCH(C13,'02_品质等级'!$A$2:$A$6,0)) | J13: =E13*F13*G13*H13 | K13: =E13*F13*G13*I13
... A181: 生命百分比 | B181: 百分比 | C181: 红 | D181: 60 | E181: =INDEX('05_副属性基础'!$C$2:$C$11,MATCH(A181,'05_副属性基础'!$A$2:$A$11,0)) | F181: =INDEX('02_品质等级'!$D$2:$D$6,MATCH(C181,'02_品质等级'!$A$2:$A$6,0)) | G181: =INDEX('05_副属性基础'!$H$2:$H$13,MATCH(D181,'05_副属性基础'!$G$2:$G$13,0)) | H181: =INDEX('02_品质等级'!$G$2:$G$6,MATCH(C181,'02_品质等级'!$A$2:$A$6,0)) | I181: =INDEX('02_品质等级'!$H$2:$H$6,MATCH(C181,'02_品质等级'!$A$2:$A$6,0)) | J181: =E181*F181*G181*H181 | K181: =E181*F181*G181*I181
A182: 攻击 | B182: 固定值 | C182: 绿 | D182: 5 | E182: =INDEX('05_副属性基础'!$C$2:$C$11,MATCH(A182,'05_副属性基础'!$A$2:$A$11,0)) | F182: =INDEX('02_品质等级'!$D$2:$D$6,MATCH(C182,'02_品质等级'!$A$2:$A$6,0)) | G182: =INDEX('05_副属性基础'!$I$2:$I$13,MATCH(D182,'05_副属性基础'!$G$2:$G$13,0)) | H182: =INDEX('02_品质等级'!$G$2:$G$6,MATCH(C182,'02_品质等级'!$A$2:$A$6,0)) | I182: =INDEX('02_品质等级'!$H$2:$H$6,MATCH(C182,'02_品质等级'!$A$2:$A$6,0)) | J182: =E182*F182*G182*H182 | K182: =E182*F182*G182*I182
A183: 攻击 | B183: 固定值 | C183: 绿 | D183: 10 | E183: =INDEX('05_副属性基础'!$C$2:$C$11,MATCH(A183,'05_副属性基础'!$A$2:$A$11,0)) | F183: =INDEX('02_品质等级'!$D$2:$D$6,MATCH(C183,'02_品质等级'!$A$2:$A$6,0)) | G183: =INDEX('05_副属性基础'!$I$2:$I$13,MATCH(D183,'05_副属性基础'!$G$2:$G$13,0)) | H183: =INDEX('02_品质等级'!$G$2:$G$6,MATCH(C183,'02_品质等级'!$A$2:$A$6,0)) | I183: =INDEX('02_品质等级'!$H$2:$H$6,MATCH(C183,'02_品质等级'!$A$2:$A$6,0)) | J183: =E183*F183*G183*H183 | K183: =E183*F183*G183*I183
A184: 攻击 | B184: 固定值 | C184: 绿 | D184: 15 | E184: =INDEX('05_副属性基础'!$C$2:$C$11,MATCH(A184,'05_副属性基础'!$A$2:$A$11,0)) | F184: =INDEX('02_品质等级'!$D$2:$D$6,MATCH(C184,'02_品质等级'!$A$2:$A$6,0)) | G184: =INDEX('05_副属性基础'!$I$2:$I$13,MATCH(D184,'05_副属性基础'!$G$2:$G$13,0)) | H184: =INDEX('02_品质等级'!$G$2:$G$6,MATCH(C184,'02_品质等级'!$A$2:$A$6,0)) | I184: =INDEX('02_品质等级'!$H$2:$H$6,MATCH(C184,'02_品质等级'!$A$2:$A$6,0)) | J184: =E184*F184*G184*H184 | K184: =E184*F184*G184*I184
A185: 攻击 | B185: 固定值 | C185: 绿 | D185: 20 | E185: =INDEX('05_副属性基础'!$C$2:$C$11,MATCH(A185,'05_副属性基础'!$A$2:$A$11,0)) | F185: =INDEX('02_品质等级'!$D$2:$D$6,MATCH(C185,'02_品质等级'!$A$2:$A$6,0)) | G185: =INDEX('05_副属性基础'!$I$2:$I$13,MATCH(D185,'05_副属性基础'!$G$2:$G$13,0)) | H185: =INDEX('02_品质等级'!$G$2:$G$6,MATCH(C185,'02_品质等级'!$A$2:$A$6,0)) | I185: =INDEX('02_品质等级'!$H$2:$H$6,MATCH(C185,'02_品质等级'!$A$2:$A$6,0)) | J185: =E185*F185*G185*H185 | K185: =E185*F185*G185*I185
A186: 攻击 | B186: 固定值 | C186: 绿 | D186: 25 | E186: =INDEX('05_副属性基础'!$C$2:$C$11,MATCH(A186,'05_副属性基础'!$A$2:$A$11,0)) | F186: =INDEX('02_品质等级'!$D$2:$D$6,MATCH(C186,'02_品质等级'!$A$2:$A$6,0)) | G186: =INDEX('05_副属性基础'!$I$2:$I$13,MATCH(D186,'05_副属性基础'!$G$2:$G$13,0)) | H186: =INDEX('02_品质等级'!$G$2:$G$6,MATCH(C186,'02_品质等级'!$A$2:$A$6,0)) | I186: =INDEX('02_品质等级'!$H$2:$H$6,MATCH(C186,'02_品质等级'!$A$2:$A$6,0)) | J186: =E186*F186*G186*H186 | K186: =E186*F186*G186*I186
A187: 攻击 | B187: 固定值 | C187: 绿 | D187: 30 | E187: =INDEX('05_副属性基础'!$C$2:$C$11,MATCH(A187,'05_副属性基础'!$A$2:$A$11,0)) | F187: =INDEX('02_品质等级'!$D$2:$D$6,MATCH(C187,'02_品质等级'!$A$2:$A$6,0)) | G187: =INDEX('05_副属性基础'!$I$2:$I$13,MATCH(D187,'05_副属性基础'!$G$2:$G$13,0)) | H187: =INDEX('02_品质等级'!$G$2:$G$6,MATCH(C187,'02_品质等级'!$A$2:$A$6,0)) | I187: =INDEX('02_品质等级'!$H$2:$H$6,MATCH(C187,'02_品质等级'!$A$2:$A$6,0)) | J187: =E187*F187*G187*H187 | K187: =E187*F187*G187*I187
A188: 攻击 | B188: 固定值 | C188: 绿 | D188: 35 | E188: =INDEX('05_副属性基础'!$C$2:$C$11,MATCH(A188,'05_副属性基础'!$A$2:$A$11,0)) | F188: =INDEX('02_品质等级'!$D$2:$D$6,MATCH(C188,'02_品质等级'!$A$2:$A$6,0)) | G188: =INDEX('05_副属性基础'!$I$2:$I$13,MATCH(D188,'05_副属性基础'!$G$2:$G$13,0)) | H188: =INDEX('02_品质等级'!$G$2:$G$6,MATCH(C188,'02_品质等级'!$A$2:$A$6,0)) | I188: =INDEX('02_品质等级'!$H$2:$H$6,MATCH(C188,'02_品质等级'!$A$2:$A$6,0)) | J188: =E188*F188*G188*H188 | K188: =E188*F188*G188*I188
A189: 攻击 | B189: 固定值 | C189: 绿 | D189: 40 | E189: =INDEX('05_副属性基础'!$C$2:$C$11,MATCH(A189,'05_副属性基础'!$A$2:$A$11,0)) | F189: =INDEX('02_品质等级'!$D$2:$D$6,MATCH(C189,'02_品质等级'!$A$2:$A$6,0)) | G189: =INDEX('05_副属性基础'!$I$2:$I$13,MATCH(D189,'05_副属性基础'!$G$2:$G$13,0)) | H189: =INDEX('02_品质等级'!$G$2:$G$6,MATCH(C189,'02_品质等级'!$A$2:$A$6,0)) | I189: =INDEX('02_品质等级'!$H$2:$H$6,MATCH(C189,'02_品质等级'!$A$2:$A$6,0)) | J189: =E189*F189*G189*H189 | K189: =E189*F189*G189*I189
A190: 攻击 | B190: 固定值 | C190: 绿 | D190: 45 | E190: =INDEX('05_副属性基础'!$C$2:$C$11,MATCH(A190,'05_副属性基础'!$A$2:$A$11,0)) | F190: =INDEX('02_品质等级'!$D$2:$D$6,MATCH(C190,'02_品质等级'!$A$2:$A$6,0)) | G190: =INDEX('05_副属性基础'!$I$2:$I$13,MATCH(D190,'05_副属性基础'!$G$2:$G$13,0)) | H190: =INDEX('02_品质等级'!$G$2:$G$6,MATCH(C190,'02_品质等级'!$A$2:$A$6,0)) | I190: =INDEX('02_品质等级'!$H$2:$H$6,MATCH(C190,'02_品质等级'!$A$2:$A$6,0)) | J190: =E190*F190*G190*H190 | K190: =E190*F190*G190*I190
A191: 攻击 | B191: 固定值 | C191: 绿 | D191: 50 | E191: =INDEX('05_副属性基础'!$C$2:$C$11,MATCH(A191,'05_副属性基础'!$A$2:$A$11,0)) | F191: =INDEX('02_品质等级'!$D$2:$D$6,MATCH(C191,'02_品质等级'!$A$2:$A$6,0)) | G191: =INDEX('05_副属性基础'!$I$2:$I$13,MATCH(D191,'05_副属性基础'!$G$2:$G$13,0)) | H191: =INDEX('02_品质等级'!$G$2:$G$6,MATCH(C191,'02_品质等级'!$A$2:$A$6,0)) | I191: =INDEX('02_品质等级'!$H$2:$H$6,MATCH(C191,'02_品质等级'!$A$2:$A$6,0)) | J191: =E191*F191*G191*H191 | K191: =E191*F191*G191*I191
A192: 攻击 | B192: 固定值 | C192: 绿 | D192: 55 | E192: =INDEX('05_副属性基础'!$C$2:$C$11,MATCH(A192,'05_副属性基础'!$A$2:$A$11,0)) | F192: =INDEX('02_品质等级'!$D$2:$D$6,MATCH(C192,'02_品质等级'!$A$2:$A$6,0)) | G192: =INDEX('05_副属性基础'!$I$2:$I$13,MATCH(D192,'05_副属性基础'!$G$2:$G$13,0)) | H192: =INDEX('02_品质等级'!$G$2:$G$6,MATCH(C192,'02_品质等级'!$A$2:$A$6,0)) | I192: =INDEX('02_品质等级'!$H$2:$H$6,MATCH(C192,'02_品质等级'!$A$2:$A$6,0)) | J192: =E192*F192*G192*H192 | K192: =E192*F192*G192*I192
A193: 攻击 | B193: 固定值 | C193: 绿 | D193: 60 | E193: =INDEX('05_副属性基础'!$C$2:$C$11,MATCH(A193,'05_副属性基础'!$A$2:$A$11,0)) | F193: =INDEX('02_品质等级'!$D$2:$D$6,MATCH(C193,'02_品质等级'!$A$2:$A$6,0)) | G193: =INDEX('05_副属性基础'!$I$2:$I$13,MATCH(D193,'05_副属性基础'!$G$2:$G$13,0)) | H193: =INDEX('02_品质等级'!$G$2:$G$6,MATCH(C193,'02_品质等级'!$A$2:$A$6,0)) | I193: =INDEX('02_品质等级'!$H$2:$H$6,MATCH(C193,'02_品质等级'!$A$2:$A$6,0)) | J193: =E193*F193*G193*H193 | K193: =E193*F193*G193*I193
... A601: 技能冷却等级 | B601: 固定值 | C601: 红 | D601: 60 | E601: =INDEX('05_副属性基础'!$C$2:$C$11,MATCH(A601,'05_副属性基础'!$A$2:$A$11,0)) | F601: =INDEX('02_品质等级'!$D$2:$D$6,MATCH(C601,'02_品质等级'!$A$2:$A$6,0)) | G601: =INDEX('05_副属性基础'!$I$2:$I$13,MATCH(D601,'05_副属性基础'!$G$2:$G$13,0)) | H601: =INDEX('02_品质等级'!$G$2:$G$6,MATCH(C601,'02_品质等级'!$A$2:$A$6,0)) | I601: =INDEX('02_品质等级'!$H$2:$H$6,MATCH(C601,'02_品质等级'!$A$2:$A$6,0)) | J601: =E601*F601*G601*H601 | K601: =E601*F601*G601*I601

Sheet 07_副本宝箱
A1: 层 | B1: 消耗 | C1: 固定宝箱 | D1: 额外宝箱概率 | E1: 期望宝箱 | F1: 绿宝箱概率 | G1: 蓝宝箱概率 | H1: 紫宝箱概率 | I1: 金宝箱概率 | J1: 红宝箱概率 | K1: 装备等级池
A2: 1 | B2: 钥匙 x1 | C2: 3 | D2: 0 | E2: 3 | F2: 0.515 | G2: 0.3 | H2: 0.185 | I2: 0 | J2: 0 | K2: 5:50% / 10:50%
A3: 2 | B3: 钥匙 x1 | C3: 3 | D3: 0.05 | E3: 3.05 | F3: 0.5093 | G3: 0.2993 | H3: 0.1914 | I3: 0 | J3: 0 | K3: 5:25% / 10:50% / 15:25%
A4: 3 | B4: 钥匙 x1 | C4: 3 | D4: 0.1 | E4: 3.1 | F4: 0.5036 | G4: 0.2986 | H4: 0.1978 | I4: 0 | J4: 0 | K4: 10:50% / 15:50%
A5: 4 | B5: 钥匙 x1 | C5: 3 | D5: 0.15 | E5: 3.15 | F5: 0.498 | G5: 0.2979 | H5: 0.2041 | I5: 0 | J5: 0 | K5: 10:25% / 15:50% / 20:25%
A6: 5 | B6: 钥匙 x1 | C6: 3 | D6: 0.2 | E6: 3.2 | F6: 0.4923 | G6: 0.2972 | H6: 0.2105 | I6: 0 | J6: 0 | K6: 15:25% / 20:50% / 25:25%
A7: 6 | B7: 钥匙 x1 | C7: 3 | D7: 0.25 | E7: 3.25 | F7: 0.4865 | G7: 0.2966 | H7: 0.2169 | I7: 0 | J7: 0 | K7: 20:50% / 25:50%
A8: 7 | B8: 钥匙 x1 | C8: 3 | D8: 0.3 | E8: 3.3 | F8: 0.4808 | G8: 0.2959 | H8: 0.2233 | I8: 0 | J8: 0 | K8: 20:25% / 25:50% / 30:25%
A9: 8 | B9: 钥匙 x1 | C9: 3 | D9: 0.35 | E9: 3.35 | F9: 0.4751 | G9: 0.2952 | H9: 0.2297 | I9: 0 | J9: 0 | K9: 25:50% / 30:50%
A10: 9 | B10: 钥匙 x1 | C10: 3 | D10: 0.4 | E10: 3.4 | F10: 0.4695 | G10: 0.2945 | H10: 0.236 | I10: 0 | J10: 0 | K10: 25:25% / 30:50% / 35:25%
A11: 10 | B11: 钥匙 x1 | C11: 3 | D11: 0.45 | E11: 3.45 | F11: 0.4538 | G11: 0.2938 | H11: 0.2424 | I11: 0.01 | J11: 0 | K11: 30:50% / 35:50%
A12: 11 | B12: 钥匙 x1 | C12: 3 | D12: 0.5 | E12: 3.5 | F12: 0.4391 | G12: 0.2931 | H12: 0.2488 | I12: 0.019 | J12: 0 | K12: 30:25% / 35:75%
A13: 12 | B13: 钥匙 x1 | C13: 3 | D13: 0.6 | E13: 3.6 | F13: 0.4244 | G13: 0.2924 | H13: 0.2552 | I13: 0.028 | J13: 0 | K13: 30:25% / 35:50% / 40:25%
... A31: 30 | B31: 钥匙 x1 | C31: 6 | D31: 0 | E31: 6 | F31: 0.12 | G31: 0.28 | H31: 0.37 | I31: 0.19 | J31: 0.04 | K31: 55:50% / 60:50%

Sheet 08_副本材料
A1: 层 | B1: 主材阶位 | C1: 打造档位等级 | D1: 可打造装备等级 | E1: 主材掉率 | F1: 紫主材概率 | G1: 金主材概率 | H1: 红主材概率 | I1: 副材总量/次 | J1: 单种副材期望/次
A2: 1 | B2: I | C2: 10 | D2: 10（100%） | E2: 0 | F2: 1 | G2: 0 | H2: 0 | I2: 0 | J2: =I2/4
A3: 2 | B3: I | C3: 10 | D3: 10（100%） | E3: 0 | F3: 1 | G3: 0 | H3: 0 | I3: 0 | J3: =I3/4
A4: 3 | B4: I | C4: 10 | D4: 10（100%） | E4: 0 | F4: 1 | G4: 0 | H4: 0 | I4: 0 | J4: =I4/4
A5: 4 | B5: II | C5: 20 | D5: 15 / 20（70% / 30%） | E5: 0 | F5: 1 | G5: 0 | H5: 0 | I5: 0 | J5: =I5/4
A6: 5 | B6: II | C6: 20 | D6: 15 / 20（70% / 30%） | E6: 0 | F6: 1 | G6: 0 | H6: 0 | I6: 0 | J6: =I6/4
A7: 6 | B7: I | C7: 10 | D7: 10（100%） | E7: 0.2 | F7: 1 | G7: 0 | H7: 0 | I7: 1 | J7: =I7/4
A8: 7 | B8: I | C8: 10 | D8: 10（100%） | E8: 0.21 | F8: 1 | G8: 0 | H8: 0 | I8: 2 | J8: =I8/4
A9: 8 | B9: I | C9: 10 | D9: 10（100%） | E9: 0.22 | F9: 1 | G9: 0 | H9: 0 | I9: 2 | J9: =I9/4
A10: 9 | B10: II | C10: 20 | D10: 15 / 20（70% / 30%） | E10: 0.23 | F10: 1 | G10: 0 | H10: 0 | I10: 2 | J10: =I10/4
A11: 10 | B11: III | C11: 30 | D11: 25 / 30（70% / 30%） | E11: 0.24 | F11: 1 | G11: 0 | H11: 0 | I11: 2 | J11: =I11/4
A12: 11 | B12: III | C12: 30 | D12: 25 / 30（70% / 30%） | E12: 0.25 | F12: 0.98 | G12: 0.02 | H12: 0 | I12: 2 | J12: =I12/4
A13: 12 | B13: III | C13: 30 | D13: 25 / 30（70% / 30%） | E13: 0.26 | F13: 0.97 | G13: 0.03 | H13: 0 | I13: 2 | J13: =I13/4
... A31: 30 | B31: VIII | C31: 60 | D31: 55 / 60（65% / 35%） | E31: 0.45 | F31: 0.78 | G31: 0.2 | H31: 0.02 | I31: 4 | J31: =I31/4

Sheet 09_日产验算
A1: 类型 | B1: 阶段/刷层 | C1: 代表层 | D1: 次数/日 | E1: 装备/日 | F1: 绿装/日 | G1: 蓝装/日 | H1: 紫装/日 | I1: 金装/日 | J1: 红装/日 | K1: 全分解金币上限/日 | L1: 打造档位等级 | M1: 主材总/日 | N1: 紫主材/日 | O1: 金主材/日 | P1: 红主材/日 | Q1: 副材总/日 | R1: 单种副材/日 | S1: 武器主材/日 | T1: 防具主材/日 | U1: 首饰主材/日
A2: 装备验算 | B2: 刷1层 | C2: 1 | D2: 7.86 | E2: 23.58 | F2: 9.71 | G2: 8.44 | H2: 4.99 | I2: 0.44 | J2: 0 | K2: 14321
A3: 装备验算 | B3: 刷5层 | C3: 5 | D3: 7.86 | E3: 25.15 | F3: 9.9 | G3: 8.83 | H3: 5.89 | I3: 0.53 | J3: 0 | K3: 31641
A4: 装备验算 | B4: 刷10层 | C4: 10 | D4: 7.86 | E4: 27.12 | F4: 9.84 | G4: 9.23 | H4: 7.11 | I4: 0.92 | J4: 0.01 | K4: 55271
A5: 装备验算 | B5: 刷15层 | C5: 15 | D5: 7.86 | E5: 30.65 | F5: 9.33 | G5: 9.9 | H5: 8.9 | I5: 2.49 | J5: 0.03 | K5: 83711
A6: 装备验算 | B6: 刷20层 | C6: 20 | D6: 7.86 | E6: 34.58 | F6: 8.35 | G6: 10.52 | H6: 11.02 | I6: 4.45 | J6: 0.24 | K6: 127340
A7: 装备验算 | B7: 刷25层 | C7: 25 | D7: 7.86 | E7: 38.51 | F7: 6.5 | G7: 10.9 | H7: 13.36 | I7: 6.78 | J7: 0.98 | K7: 199942
A8: 装备验算 | B8: 刷30层 | C8: 30 | D8: 7.86 | E8: 47.16 | F8: 4.53 | G8: 12.36 | H8: 17.69 | I8: 10.53 | J8: 2.07 | K8: 349752
A9: 材料验算 | B9: 前期 | C9: 10 | D9: 7.86 | L9: =INDEX('08_副本材料'!$C$2:$C$31,MATCH(C9,'08_副本材料'!$A$2:$A$31,0)) | M9: =D9*INDEX('08_副本材料'!$E$2:$E$31,MATCH(C9,'08_副本材料'!$A$2:$A$31,0)) | N9: =M9*INDEX('08_副本材料'!$F$2:$F$31,MATCH(C9,'08_副本材料'!$A$2:$A$31,0)) | O9: =M9*INDEX('08_副本材料'!$G$2:$G$31,MATCH(C9,'08_副本材料'!$A$2:$A$31,0)) | P9: =M9*INDEX('08_副本材料'!$H$2:$H$31,MATCH(C9,'08_副本材料'!$A$2:$A$31,0)) | Q9: =D9*INDEX('08_副本材料'!$I$2:$I$31,MATCH(C9,'08_副本材料'!$A$2:$A$31,0)) | R9: =Q9/4 | S9: =M9*20% | T9: =M9*55% | U9: =M9*25%
A10: 材料验算 | B10: 中期 | C10: 20 | D10: 7.86 | L10: =INDEX('08_副本材料'!$C$2:$C$31,MATCH(C10,'08_副本材料'!$A$2:$A$31,0)) | M10: =D10*INDEX('08_副本材料'!$E$2:$E$31,MATCH(C10,'08_副本材料'!$A$2:$A$31,0)) | N10: =M10*INDEX('08_副本材料'!$F$2:$F$31,MATCH(C10,'08_副本材料'!$A$2:$A$31,0)) | O10: =M10*INDEX('08_副本材料'!$G$2:$G$31,MATCH(C10,'08_副本材料'!$A$2:$A$31,0)) | P10: =M10*INDEX('08_副本材料'!$H$2:$H$31,MATCH(C10,'08_副本材料'!$A$2:$A$31,0)) | Q10: =D10*INDEX('08_副本材料'!$I$2:$I$31,MATCH(C10,'08_副本材料'!$A$2:$A$31,0)) | R10: =Q10/4 | S10: =M10*20% | T10: =M10*55% | U10: =M10*25%
A11: 材料验算 | B11: 后期 | C11: 30 | D11: 7.86 | L11: =INDEX('08_副本材料'!$C$2:$C$31,MATCH(C11,'08_副本材料'!$A$2:$A$31,0)) | M11: =D11*INDEX('08_副本材料'!$E$2:$E$31,MATCH(C11,'08_副本材料'!$A$2:$A$31,0)) | N11: =M11*INDEX('08_副本材料'!$F$2:$F$31,MATCH(C11,'08_副本材料'!$A$2:$A$31,0)) | O11: =M11*INDEX('08_副本材料'!$G$2:$G$31,MATCH(C11,'08_副本材料'!$A$2:$A$31,0)) | P11: =M11*INDEX('08_副本材料'!$H$2:$H$31,MATCH(C11,'08_副本材料'!$A$2:$A$31,0)) | Q11: =D11*INDEX('08_副本材料'!$I$2:$I$31,MATCH(C11,'08_副本材料'!$A$2:$A$31,0)) | R11: =Q11/4 | S11: =M11*20% | T11: =M11*55% | U11: =M11*25%

Sheet 10_爬塔挂机
A1: 最高层 | B1: 金币/日 | C1: 房车经验/日 | E1: 最高层材料区间 | F1: 主材阶位 | G1: 打造档位等级 | H1: 主材总/日 | I1: 紫概率 | J1: 金概率 | K1: 红概率 | L1: 紫期望/日 | M1: 金期望/日 | N1: 红期望/日 | O1: 副材总/日 | P1: 单种副材/日
A2: 1 | B2: 30000 | C2: 30
A3: 100 | B3: 190000 | C3: 250

Sheet 11_锻造台经验
A1: 锻造台Lv | B1: 升下一级经验 | C1: 累计经验 | D1: 绿装经验 | E1: 蓝装经验 | F1: 紫装经验 | G1: 金装经验 | H1: 红装经验 | I1: 备注 | K1: 装备等级段 | L1: 绿 | M1: 蓝 | N1: 紫 | O1: 金 | P1: 红
A2: 1 | B2: 10 | C2: 0 | I2: 离散曲线来自沉淀MD | K2: 5/10 | L2: 1 | M2: 2 | N2: 5 | O2: 12 | P2: 30
A3: 2 | B3: 20 | C3: =C2+B2 | I3: 离散曲线来自沉淀MD | K3: 15/20 | L3: 2 | M3: 4 | N3: 10 | O3: 24 | P3: 60
A4: 3 | B4: 30 | C4: =C3+B3 | I4: 离散曲线来自沉淀MD | K4: 25/30 | L4: 3 | M4: 6 | N4: 15 | O4: 36 | P4: 90
A5: 4 | B5: 40 | C5: =C4+B4 | I5: 离散曲线来自沉淀MD | K5: 35/40 | L5: 4 | M5: 8 | N5: 20 | O5: 48 | P5: 120
A6: 5 | B6: 50 | C6: =C5+B5 | I6: 离散曲线来自沉淀MD | K6: 45/50 | L6: 5 | M6: 10 | N6: 25 | O6: 60 | P6: 150
A7: 6 | B7: 60 | C7: =C6+B6 | I7: 离散曲线来自沉淀MD | K7: 55/60 | L7: 6 | M7: 12 | N7: 30 | O7: 72 | P7: 180
A8: 7 | B8: 70 | C8: =C7+B7 | I8: 离散曲线来自沉淀MD
A9: 8 | B9: 100 | C9: =C8+B8 | I9: 离散曲线来自沉淀MD
A10: 9 | B10: 120 | C10: =C9+B9 | I10: 离散曲线来自沉淀MD
A11: 10 | B11: 130 | C11: =C10+B10 | I11: 离散曲线来自沉淀MD
A12: 11 | B12: 140 | C12: =C11+B11 | I12: 离散曲线来自沉淀MD
A13: 12 | B13: 160 | C13: =C12+B12 | I13: 离散曲线来自沉淀MD
A14: 13 | B14: 180 | C14: =C13+B13 | I14: 离散曲线来自沉淀MD
A15: 14 | B15: 190 | C15: =C14+B14 | I15: 离散曲线来自沉淀MD
A16: 15 | B16: 210 | C16: =C15+B15 | I16: 离散曲线来自沉淀MD
A17: 16 | B17: 220 | C17: =C16+B16 | I17: 离散曲线来自沉淀MD
A18: 17 | B18: 240 | C18: =C17+B17 | I18: 离散曲线来自沉淀MD
A19: 18 | B19: 250 | C19: =C18+B18 | I19: 离散曲线来自沉淀MD
... A60: 59 | B60: 5600 | C60: =C59+B59 | I60: 离散曲线来自沉淀MD
A61: 60 | C61: =C60+B60 | I61: 离散曲线来自沉淀MD

Sheet 12_合成消耗
A1: 合成档 | B1: 角色等级要求 | C1: 产物等级池 | D1: 等级权重 | E1: 投入装备等级下限 | F1: 基础金币 | G1: 绿金币 | H1: 蓝金币 | I1: 紫金币 | J1: 金金币 | K1: 红金币
A2: 1 | C2: 10 | D2: 100% | E2: 10 | F2: 200 | G2: =$F2*INDEX('02_品质等级'!$E$2:$E$6,MATCH(LEFT(G$1,1),'02_品质等级'!$A$2:$A$6,0)) | H2: =$F2*INDEX('02_品质等级'!$E$2:$E$6,MATCH(LEFT(H$1,1),'02_品质等级'!$A$2:$A$6,0)) | I2: =$F2*INDEX('02_品质等级'!$E$2:$E$6,MATCH(LEFT(I$1,1),'02_品质等级'!$A$2:$A$6,0)) | J2: =$F2*INDEX('02_品质等级'!$E$2:$E$6,MATCH(LEFT(J$1,1),'02_品质等级'!$A$2:$A$6,0)) | K2: =$F2*INDEX('02_品质等级'!$E$2:$E$6,MATCH(LEFT(K$1,1),'02_品质等级'!$A$2:$A$6,0))
A3: 2 | B3: 10 | C3: 15 / 20 | D3: 70% / 30% | E3: 10 | F3: 700 | G3: =$F3*INDEX('02_品质等级'!$E$2:$E$6,MATCH(LEFT(G$1,1),'02_品质等级'!$A$2:$A$6,0)) | H3: =$F3*INDEX('02_品质等级'!$E$2:$E$6,MATCH(LEFT(H$1,1),'02_品质等级'!$A$2:$A$6,0)) | I3: =$F3*INDEX('02_品质等级'!$E$2:$E$6,MATCH(LEFT(I$1,1),'02_品质等级'!$A$2:$A$6,0)) | J3: =$F3*INDEX('02_品质等级'!$E$2:$E$6,MATCH(LEFT(J$1,1),'02_品质等级'!$A$2:$A$6,0)) | K3: =$F3*INDEX('02_品质等级'!$E$2:$E$6,MATCH(LEFT(K$1,1),'02_品质等级'!$A$2:$A$6,0))
A4: 3 | B4: 20 | C4: 25 / 30 | D4: 70% / 30% | E4: 20 | F4: 2000 | G4: =$F4*INDEX('02_品质等级'!$E$2:$E$6,MATCH(LEFT(G$1,1),'02_品质等级'!$A$2:$A$6,0)) | H4: =$F4*INDEX('02_品质等级'!$E$2:$E$6,MATCH(LEFT(H$1,1),'02_品质等级'!$A$2:$A$6,0)) | I4: =$F4*INDEX('02_品质等级'!$E$2:$E$6,MATCH(LEFT(I$1,1),'02_品质等级'!$A$2:$A$6,0)) | J4: =$F4*INDEX('02_品质等级'!$E$2:$E$6,MATCH(LEFT(J$1,1),'02_品质等级'!$A$2:$A$6,0)) | K4: =$F4*INDEX('02_品质等级'!$E$2:$E$6,MATCH(LEFT(K$1,1),'02_品质等级'!$A$2:$A$6,0))
A5: 4 | B5: 30 | C5: 35 / 40 | D5: 70% / 30% | E5: 30 | F5: 5000 | G5: =$F5*INDEX('02_品质等级'!$E$2:$E$6,MATCH(LEFT(G$1,1),'02_品质等级'!$A$2:$A$6,0)) | H5: =$F5*INDEX('02_品质等级'!$E$2:$E$6,MATCH(LEFT(H$1,1),'02_品质等级'!$A$2:$A$6,0)) | I5: =$F5*INDEX('02_品质等级'!$E$2:$E$6,MATCH(LEFT(I$1,1),'02_品质等级'!$A$2:$A$6,0)) | J5: =$F5*INDEX('02_品质等级'!$E$2:$E$6,MATCH(LEFT(J$1,1),'02_品质等级'!$A$2:$A$6,0)) | K5: =$F5*INDEX('02_品质等级'!$E$2:$E$6,MATCH(LEFT(K$1,1),'02_品质等级'!$A$2:$A$6,0))
A6: 5 | B6: 35 | C6: 40 / 45 | D6: 65% / 35% | E6: 40 | F6: 7600 | G6: =$F6*INDEX('02_品质等级'!$E$2:$E$6,MATCH(LEFT(G$1,1),'02_品质等级'!$A$2:$A$6,0)) | H6: =$F6*INDEX('02_品质等级'!$E$2:$E$6,MATCH(LEFT(H$1,1),'02_品质等级'!$A$2:$A$6,0)) | I6: =$F6*INDEX('02_品质等级'!$E$2:$E$6,MATCH(LEFT(I$1,1),'02_品质等级'!$A$2:$A$6,0)) | J6: =$F6*INDEX('02_品质等级'!$E$2:$E$6,MATCH(LEFT(J$1,1),'02_品质等级'!$A$2:$A$6,0)) | K6: =$F6*INDEX('02_品质等级'!$E$2:$E$6,MATCH(LEFT(K$1,1),'02_品质等级'!$A$2:$A$6,0))
A7: 6 | B7: 40 | C7: 45 / 50 | D7: 65% / 35% | E7: 45 | F7: 11000 | G7: =$F7*INDEX('02_品质等级'!$E$2:$E$6,MATCH(LEFT(G$1,1),'02_品质等级'!$A$2:$A$6,0)) | H7: =$F7*INDEX('02_品质等级'!$E$2:$E$6,MATCH(LEFT(H$1,1),'02_品质等级'!$A$2:$A$6,0)) | I7: =$F7*INDEX('02_品质等级'!$E$2:$E$6,MATCH(LEFT(I$1,1),'02_品质等级'!$A$2:$A$6,0)) | J7: =$F7*INDEX('02_品质等级'!$E$2:$E$6,MATCH(LEFT(J$1,1),'02_品质等级'!$A$2:$A$6,0)) | K7: =$F7*INDEX('02_品质等级'!$E$2:$E$6,MATCH(LEFT(K$1,1),'02_品质等级'!$A$2:$A$6,0))
A8: 7 | B8: 45 | C8: 50 / 55 | D8: 65% / 35% | E8: 50 | F8: 15000 | G8: =$F8*INDEX('02_品质等级'!$E$2:$E$6,MATCH(LEFT(G$1,1),'02_品质等级'!$A$2:$A$6,0)) | H8: =$F8*INDEX('02_品质等级'!$E$2:$E$6,MATCH(LEFT(H$1,1),'02_品质等级'!$A$2:$A$6,0)) | I8: =$F8*INDEX('02_品质等级'!$E$2:$E$6,MATCH(LEFT(I$1,1),'02_品质等级'!$A$2:$A$6,0)) | J8: =$F8*INDEX('02_品质等级'!$E$2:$E$6,MATCH(LEFT(J$1,1),'02_品质等级'!$A$2:$A$6,0)) | K8: =$F8*INDEX('02_品质等级'!$E$2:$E$6,MATCH(LEFT(K$1,1),'02_品质等级'!$A$2:$A$6,0))
A9: 8 | B9: 50 | C9: 55 / 60 | D9: 65% / 35% | E9: 55 | F9: 20000 | G9: =$F9*INDEX('02_品质等级'!$E$2:$E$6,MATCH(LEFT(G$1,1),'02_品质等级'!$A$2:$A$6,0)) | H9: =$F9*INDEX('02_品质等级'!$E$2:$E$6,MATCH(LEFT(H$1,1),'02_品质等级'!$A$2:$A$6,0)) | I9: =$F9*INDEX('02_品质等级'!$E$2:$E$6,MATCH(LEFT(I$1,1),'02_品质等级'!$A$2:$A$6,0)) | J9: =$F9*INDEX('02_品质等级'!$E$2:$E$6,MATCH(LEFT(J$1,1),'02_品质等级'!$A$2:$A$6,0)) | K9: =$F9*INDEX('02_品质等级'!$E$2:$E$6,MATCH(LEFT(K$1,1),'02_品质等级'!$A$2:$A$6,0))

Sheet 13_合成概率
A1: 锻造台Lv | B1: 绿合蓝 | C1: 绿合紫 | D1: 蓝合紫 | E1: 蓝合金 | F1: 紫合紫 | G1: 紫合金 | H1: 紫合红 | I1: 金合金 | J1: 金合红 | K1: 红合红
A2: 1 | B2: =1-C2 | C2: =8%+17%*(A2-1)/59 | D2: =1-E2 | E2: =5%+15%*(A2-1)/59 | F2: =1-G2-H2 | G2: =30%+30%*(A2-1)/59 | H2: =1%+2%*(A2-1)/59 | I2: =1-J2 | J2: =20%+20%*(A2-1)/59 | K2: 1
A3: 2 | B3: =1-C3 | C3: =8%+17%*(A3-1)/59 | D3: =1-E3 | E3: =5%+15%*(A3-1)/59 | F3: =1-G3-H3 | G3: =30%+30%*(A3-1)/59 | H3: =1%+2%*(A3-1)/59 | I3: =1-J3 | J3: =20%+20%*(A3-1)/59 | K3: 1
A4: 3 | B4: =1-C4 | C4: =8%+17%*(A4-1)/59 | D4: =1-E4 | E4: =5%+15%*(A4-1)/59 | F4: =1-G4-H4 | G4: =30%+30%*(A4-1)/59 | H4: =1%+2%*(A4-1)/59 | I4: =1-J4 | J4: =20%+20%*(A4-1)/59 | K4: 1
A5: 4 | B5: =1-C5 | C5: =8%+17%*(A5-1)/59 | D5: =1-E5 | E5: =5%+15%*(A5-1)/59 | F5: =1-G5-H5 | G5: =30%+30%*(A5-1)/59 | H5: =1%+2%*(A5-1)/59 | I5: =1-J5 | J5: =20%+20%*(A5-1)/59 | K5: 1
A6: 5 | B6: =1-C6 | C6: =8%+17%*(A6-1)/59 | D6: =1-E6 | E6: =5%+15%*(A6-1)/59 | F6: =1-G6-H6 | G6: =30%+30%*(A6-1)/59 | H6: =1%+2%*(A6-1)/59 | I6: =1-J6 | J6: =20%+20%*(A6-1)/59 | K6: 1
A7: 6 | B7: =1-C7 | C7: =8%+17%*(A7-1)/59 | D7: =1-E7 | E7: =5%+15%*(A7-1)/59 | F7: =1-G7-H7 | G7: =30%+30%*(A7-1)/59 | H7: =1%+2%*(A7-1)/59 | I7: =1-J7 | J7: =20%+20%*(A7-1)/59 | K7: 1
A8: 7 | B8: =1-C8 | C8: =8%+17%*(A8-1)/59 | D8: =1-E8 | E8: =5%+15%*(A8-1)/59 | F8: =1-G8-H8 | G8: =30%+30%*(A8-1)/59 | H8: =1%+2%*(A8-1)/59 | I8: =1-J8 | J8: =20%+20%*(A8-1)/59 | K8: 1
A9: 8 | B9: =1-C9 | C9: =8%+17%*(A9-1)/59 | D9: =1-E9 | E9: =5%+15%*(A9-1)/59 | F9: =1-G9-H9 | G9: =30%+30%*(A9-1)/59 | H9: =1%+2%*(A9-1)/59 | I9: =1-J9 | J9: =20%+20%*(A9-1)/59 | K9: 1
A10: 9 | B10: =1-C10 | C10: =8%+17%*(A10-1)/59 | D10: =1-E10 | E10: =5%+15%*(A10-1)/59 | F10: =1-G10-H10 | G10: =30%+30%*(A10-1)/59 | H10: =1%+2%*(A10-1)/59 | I10: =1-J10 | J10: =20%+20%*(A10-1)/59 | K10: 1
A11: 10 | B11: =1-C11 | C11: =8%+17%*(A11-1)/59 | D11: =1-E11 | E11: =5%+15%*(A11-1)/59 | F11: =1-G11-H11 | G11: =30%+30%*(A11-1)/59 | H11: =1%+2%*(A11-1)/59 | I11: =1-J11 | J11: =20%+20%*(A11-1)/59 | K11: 1
A12: 11 | B12: =1-C12 | C12: =8%+17%*(A12-1)/59 | D12: =1-E12 | E12: =5%+15%*(A12-1)/59 | F12: =1-G12-H12 | G12: =30%+30%*(A12-1)/59 | H12: =1%+2%*(A12-1)/59 | I12: =1-J12 | J12: =20%+20%*(A12-1)/59 | K12: 1
A13: 12 | B13: =1-C13 | C13: =8%+17%*(A13-1)/59 | D13: =1-E13 | E13: =5%+15%*(A13-1)/59 | F13: =1-G13-H13 | G13: =30%+30%*(A13-1)/59 | H13: =1%+2%*(A13-1)/59 | I13: =1-J13 | J13: =20%+20%*(A13-1)/59 | K13: 1
... A61: 60 | B61: =1-C61 | C61: =8%+17%*(A61-1)/59 | D61: =1-E61 | E61: =5%+15%*(A61-1)/59 | F61: =1-G61-H61 | G61: =30%+30%*(A61-1)/59 | H61: =1%+2%*(A61-1)/59 | I61: =1-J61 | J61: =20%+20%*(A61-1)/59 | K61: 1

Sheet 14_打造消耗
A1: 打造档 | B1: 主材阶位 | C1: 打造档位等级 | D1: 可打造装备等级 | E1: 金币(暂沿用旧档) | F1: 紫主材每种副材 | G1: 金主材每种副材 | H1: 红主材每种副材 | I1: 武器消耗副材 | J1: 防具消耗副材 | K1: 首饰消耗副材 | L1: 备注
A2: 1 | B2: I | C2: 10 | D2: 10（100%） | E2: 500 | F2: 1 | G2: 2 | H2: 3 | I2: 副材1 + 副材2 | J2: 副材2 + 副材3 | K2: 副材3 + 副材4 | L2: 每次主材 x1；副材数量为每种数量
A3: 2 | B3: II | C3: 20 | D3: 15 / 20（70% / 30%） | E3: 1200 | F3: 2 | G3: 4 | H3: 6 | I3: 副材1 + 副材2 | J3: 副材2 + 副材3 | K3: 副材3 + 副材4 | L3: 每次主材 x1；副材数量为每种数量
A4: 3 | B4: III | C4: 30 | D4: 25 / 30（70% / 30%） | E4: 2800 | F4: 4 | G4: 6 | H4: 9 | I4: 副材1 + 副材2 | J4: 副材2 + 副材3 | K4: 副材3 + 副材4 | L4: 每次主材 x1；副材数量为每种数量
A5: 4 | B5: IV | C5: 40 | D5: 35 / 40（70% / 30%） | E5: 6200 | F5: 6 | G5: 10 | H5: 15 | I5: 副材1 + 副材2 | J5: 副材2 + 副材3 | K5: 副材3 + 副材4 | L5: 每次主材 x1；副材数量为每种数量
A6: 5 | B6: V | C6: 45 | D6: 40 / 45（65% / 35%） | E6: 9000 | F6: 8 | G6: 12 | H6: 18 | I6: 副材1 + 副材2 | J6: 副材2 + 副材3 | K6: 副材3 + 副材4 | L6: 每次主材 x1；副材数量为每种数量
A7: 6 | B7: VI | C7: 50 | D7: 45 / 50（65% / 35%） | E7: 13000 | F7: 10 | G7: 15 | H7: 23 | I7: 副材1 + 副材2 | J7: 副材2 + 副材3 | K7: 副材3 + 副材4 | L7: 每次主材 x1；副材数量为每种数量
A8: 7 | B8: VII | C8: 55 | D8: 50 / 55（65% / 35%） | E8: 18000 | F8: 13 | G8: 19 | H8: 29 | I8: 副材1 + 副材2 | J8: 副材2 + 副材3 | K8: 副材3 + 副材4 | L8: 每次主材 x1；副材数量为每种数量
A9: 8 | B9: VIII | C9: 60 | D9: 55 / 60（65% / 35%） | E9: 24000 | F9: 16 | G9: 24 | H9: 36 | I9: 副材1 + 副材2 | J9: 副材2 + 副材3 | K9: 副材3 + 副材4 | L9: 每次主材 x1；副材数量为每种数量

Sheet 15_打造概率
A1: 锻造台Lv | B1: 紫主材出紫 | C1: 紫主材出金 | D1: 金主材出金 | E1: 金主材出红 | F1: 红主材出红
A2: 1 | B2: =1-C2 | C2: =10%+10%*(A2-1)/59 | D2: =1-E2 | E2: =2%+3%*(A2-1)/59 | F2: 1
A3: 2 | B3: =1-C3 | C3: =10%+10%*(A3-1)/59 | D3: =1-E3 | E3: =2%+3%*(A3-1)/59 | F3: 1
A4: 3 | B4: =1-C4 | C4: =10%+10%*(A4-1)/59 | D4: =1-E4 | E4: =2%+3%*(A4-1)/59 | F4: 1
A5: 4 | B5: =1-C5 | C5: =10%+10%*(A5-1)/59 | D5: =1-E5 | E5: =2%+3%*(A5-1)/59 | F5: 1
A6: 5 | B6: =1-C6 | C6: =10%+10%*(A6-1)/59 | D6: =1-E6 | E6: =2%+3%*(A6-1)/59 | F6: 1
A7: 6 | B7: =1-C7 | C7: =10%+10%*(A7-1)/59 | D7: =1-E7 | E7: =2%+3%*(A7-1)/59 | F7: 1
A8: 7 | B8: =1-C8 | C8: =10%+10%*(A8-1)/59 | D8: =1-E8 | E8: =2%+3%*(A8-1)/59 | F8: 1
A9: 8 | B9: =1-C9 | C9: =10%+10%*(A9-1)/59 | D9: =1-E9 | E9: =2%+3%*(A9-1)/59 | F9: 1
A10: 9 | B10: =1-C10 | C10: =10%+10%*(A10-1)/59 | D10: =1-E10 | E10: =2%+3%*(A10-1)/59 | F10: 1
A11: 10 | B11: =1-C11 | C11: =10%+10%*(A11-1)/59 | D11: =1-E11 | E11: =2%+3%*(A11-1)/59 | F11: 1
A12: 11 | B12: =1-C12 | C12: =10%+10%*(A12-1)/59 | D12: =1-E12 | E12: =2%+3%*(A12-1)/59 | F12: 1
A13: 12 | B13: =1-C13 | C13: =10%+10%*(A13-1)/59 | D13: =1-E13 | E13: =2%+3%*(A13-1)/59 | F13: 1
... A61: 60 | B61: =1-C61 | C61: =10%+10%*(A61-1)/59 | D61: =1-E61 | E61: =2%+3%*(A61-1)/59 | F61: 1

Sheet 16_分解回收
A1: 装备等级 | B1: 基础金币 | C1: 绿金币 | D1: 蓝金币 | E1: 紫金币 | F1: 金金币 | G1: 红金币 | H1: 绿经验 | I1: 蓝经验 | J1: 紫经验 | K1: 金经验 | L1: 红经验 | M1: 红装额外产出
A2: 5 | B2: 1200 | C2: =$B2*INDEX('02_品质等级'!$F$2:$F$6,MATCH(LEFT(C$1,1),'02_品质等级'!$A$2:$A$6,0)) | D2: =$B2*INDEX('02_品质等级'!$F$2:$F$6,MATCH(LEFT(D$1,1),'02_品质等级'!$A$2:$A$6,0)) | E2: =$B2*INDEX('02_品质等级'!$F$2:$F$6,MATCH(LEFT(E$1,1),'02_品质等级'!$A$2:$A$6,0)) | F2: =$B2*INDEX('02_品质等级'!$F$2:$F$6,MATCH(LEFT(F$1,1),'02_品质等级'!$A$2:$A$6,0)) | G2: =$B2*INDEX('02_品质等级'!$F$2:$F$6,MATCH(LEFT(G$1,1),'02_品质等级'!$A$2:$A$6,0)) | H2: 1 | I2: 2 | J2: 5 | K2: 12 | L2: 30 | M2: 高阶零件(23)x1
A3: 10 | B3: 1700 | C3: =$B3*INDEX('02_品质等级'!$F$2:$F$6,MATCH(LEFT(C$1,1),'02_品质等级'!$A$2:$A$6,0)) | D3: =$B3*INDEX('02_品质等级'!$F$2:$F$6,MATCH(LEFT(D$1,1),'02_品质等级'!$A$2:$A$6,0)) | E3: =$B3*INDEX('02_品质等级'!$F$2:$F$6,MATCH(LEFT(E$1,1),'02_品质等级'!$A$2:$A$6,0)) | F3: =$B3*INDEX('02_品质等级'!$F$2:$F$6,MATCH(LEFT(F$1,1),'02_品质等级'!$A$2:$A$6,0)) | G3: =$B3*INDEX('02_品质等级'!$F$2:$F$6,MATCH(LEFT(G$1,1),'02_品质等级'!$A$2:$A$6,0)) | H3: 1 | I3: 2 | J3: 5 | K3: 12 | L3: 30 | M3: 高阶零件(23)x1
A4: 15 | B4: 2300 | C4: =$B4*INDEX('02_品质等级'!$F$2:$F$6,MATCH(LEFT(C$1,1),'02_品质等级'!$A$2:$A$6,0)) | D4: =$B4*INDEX('02_品质等级'!$F$2:$F$6,MATCH(LEFT(D$1,1),'02_品质等级'!$A$2:$A$6,0)) | E4: =$B4*INDEX('02_品质等级'!$F$2:$F$6,MATCH(LEFT(E$1,1),'02_品质等级'!$A$2:$A$6,0)) | F4: =$B4*INDEX('02_品质等级'!$F$2:$F$6,MATCH(LEFT(F$1,1),'02_品质等级'!$A$2:$A$6,0)) | G4: =$B4*INDEX('02_品质等级'!$F$2:$F$6,MATCH(LEFT(G$1,1),'02_品质等级'!$A$2:$A$6,0)) | H4: 2 | I4: 4 | J4: 10 | K4: 24 | L4: 60 | M4: 高阶零件(23)x1
A5: 20 | B5: 2900 | C5: =$B5*INDEX('02_品质等级'!$F$2:$F$6,MATCH(LEFT(C$1,1),'02_品质等级'!$A$2:$A$6,0)) | D5: =$B5*INDEX('02_品质等级'!$F$2:$F$6,MATCH(LEFT(D$1,1),'02_品质等级'!$A$2:$A$6,0)) | E5: =$B5*INDEX('02_品质等级'!$F$2:$F$6,MATCH(LEFT(E$1,1),'02_品质等级'!$A$2:$A$6,0)) | F5: =$B5*INDEX('02_品质等级'!$F$2:$F$6,MATCH(LEFT(F$1,1),'02_品质等级'!$A$2:$A$6,0)) | G5: =$B5*INDEX('02_品质等级'!$F$2:$F$6,MATCH(LEFT(G$1,1),'02_品质等级'!$A$2:$A$6,0)) | H5: 2 | I5: 4 | J5: 10 | K5: 24 | L5: 60 | M5: 高阶零件(23)x1
A6: 25 | B6: 3500 | C6: =$B6*INDEX('02_品质等级'!$F$2:$F$6,MATCH(LEFT(C$1,1),'02_品质等级'!$A$2:$A$6,0)) | D6: =$B6*INDEX('02_品质等级'!$F$2:$F$6,MATCH(LEFT(D$1,1),'02_品质等级'!$A$2:$A$6,0)) | E6: =$B6*INDEX('02_品质等级'!$F$2:$F$6,MATCH(LEFT(E$1,1),'02_品质等级'!$A$2:$A$6,0)) | F6: =$B6*INDEX('02_品质等级'!$F$2:$F$6,MATCH(LEFT(F$1,1),'02_品质等级'!$A$2:$A$6,0)) | G6: =$B6*INDEX('02_品质等级'!$F$2:$F$6,MATCH(LEFT(G$1,1),'02_品质等级'!$A$2:$A$6,0)) | H6: 3 | I6: 6 | J6: 15 | K6: 36 | L6: 90 | M6: 高阶零件(23)x1
A7: 30 | B7: 4100 | C7: =$B7*INDEX('02_品质等级'!$F$2:$F$6,MATCH(LEFT(C$1,1),'02_品质等级'!$A$2:$A$6,0)) | D7: =$B7*INDEX('02_品质等级'!$F$2:$F$6,MATCH(LEFT(D$1,1),'02_品质等级'!$A$2:$A$6,0)) | E7: =$B7*INDEX('02_品质等级'!$F$2:$F$6,MATCH(LEFT(E$1,1),'02_品质等级'!$A$2:$A$6,0)) | F7: =$B7*INDEX('02_品质等级'!$F$2:$F$6,MATCH(LEFT(F$1,1),'02_品质等级'!$A$2:$A$6,0)) | G7: =$B7*INDEX('02_品质等级'!$F$2:$F$6,MATCH(LEFT(G$1,1),'02_品质等级'!$A$2:$A$6,0)) | H7: 3 | I7: 6 | J7: 15 | K7: 36 | L7: 90 | M7: 高阶零件(23)x1
A8: 35 | B8: 4700 | C8: =$B8*INDEX('02_品质等级'!$F$2:$F$6,MATCH(LEFT(C$1,1),'02_品质等级'!$A$2:$A$6,0)) | D8: =$B8*INDEX('02_品质等级'!$F$2:$F$6,MATCH(LEFT(D$1,1),'02_品质等级'!$A$2:$A$6,0)) | E8: =$B8*INDEX('02_品质等级'!$F$2:$F$6,MATCH(LEFT(E$1,1),'02_品质等级'!$A$2:$A$6,0)) | F8: =$B8*INDEX('02_品质等级'!$F$2:$F$6,MATCH(LEFT(F$1,1),'02_品质等级'!$A$2:$A$6,0)) | G8: =$B8*INDEX('02_品质等级'!$F$2:$F$6,MATCH(LEFT(G$1,1),'02_品质等级'!$A$2:$A$6,0)) | H8: 4 | I8: 8 | J8: 20 | K8: 48 | L8: 120 | M8: 高阶零件(23)x1
A9: 40 | B9: 5300 | C9: =$B9*INDEX('02_品质等级'!$F$2:$F$6,MATCH(LEFT(C$1,1),'02_品质等级'!$A$2:$A$6,0)) | D9: =$B9*INDEX('02_品质等级'!$F$2:$F$6,MATCH(LEFT(D$1,1),'02_品质等级'!$A$2:$A$6,0)) | E9: =$B9*INDEX('02_品质等级'!$F$2:$F$6,MATCH(LEFT(E$1,1),'02_品质等级'!$A$2:$A$6,0)) | F9: =$B9*INDEX('02_品质等级'!$F$2:$F$6,MATCH(LEFT(F$1,1),'02_品质等级'!$A$2:$A$6,0)) | G9: =$B9*INDEX('02_品质等级'!$F$2:$F$6,MATCH(LEFT(G$1,1),'02_品质等级'!$A$2:$A$6,0)) | H9: 4 | I9: 8 | J9: 20 | K9: 48 | L9: 120 | M9: 高阶零件(23)x1
A10: 45 | B10: 6000 | C10: =$B10*INDEX('02_品质等级'!$F$2:$F$6,MATCH(LEFT(C$1,1),'02_品质等级'!$A$2:$A$6,0)) | D10: =$B10*INDEX('02_品质等级'!$F$2:$F$6,MATCH(LEFT(D$1,1),'02_品质等级'!$A$2:$A$6,0)) | E10: =$B10*INDEX('02_品质等级'!$F$2:$F$6,MATCH(LEFT(E$1,1),'02_品质等级'!$A$2:$A$6,0)) | F10: =$B10*INDEX('02_品质等级'!$F$2:$F$6,MATCH(LEFT(F$1,1),'02_品质等级'!$A$2:$A$6,0)) | G10: =$B10*INDEX('02_品质等级'!$F$2:$F$6,MATCH(LEFT(G$1,1),'02_品质等级'!$A$2:$A$6,0)) | H10: 5 | I10: 10 | J10: 25 | K10: 60 | L10: 150 | M10: 高阶零件(23)x1
A11: 50 | B11: 7000 | C11: =$B11*INDEX('02_品质等级'!$F$2:$F$6,MATCH(LEFT(C$1,1),'02_品质等级'!$A$2:$A$6,0)) | D11: =$B11*INDEX('02_品质等级'!$F$2:$F$6,MATCH(LEFT(D$1,1),'02_品质等级'!$A$2:$A$6,0)) | E11: =$B11*INDEX('02_品质等级'!$F$2:$F$6,MATCH(LEFT(E$1,1),'02_品质等级'!$A$2:$A$6,0)) | F11: =$B11*INDEX('02_品质等级'!$F$2:$F$6,MATCH(LEFT(F$1,1),'02_品质等级'!$A$2:$A$6,0)) | G11: =$B11*INDEX('02_品质等级'!$F$2:$F$6,MATCH(LEFT(G$1,1),'02_品质等级'!$A$2:$A$6,0)) | H11: 5 | I11: 10 | J11: 25 | K11: 60 | L11: 150 | M11: 高阶零件(23)x1
A12: 55 | B12: 8500 | C12: =$B12*INDEX('02_品质等级'!$F$2:$F$6,MATCH(LEFT(C$1,1),'02_品质等级'!$A$2:$A$6,0)) | D12: =$B12*INDEX('02_品质等级'!$F$2:$F$6,MATCH(LEFT(D$1,1),'02_品质等级'!$A$2:$A$6,0)) | E12: =$B12*INDEX('02_品质等级'!$F$2:$F$6,MATCH(LEFT(E$1,1),'02_品质等级'!$A$2:$A$6,0)) | F12: =$B12*INDEX('02_品质等级'!$F$2:$F$6,MATCH(LEFT(F$1,1),'02_品质等级'!$A$2:$A$6,0)) | G12: =$B12*INDEX('02_品质等级'!$F$2:$F$6,MATCH(LEFT(G$1,1),'02_品质等级'!$A$2:$A$6,0)) | H12: 6 | I12: 12 | J12: 30 | K12: 72 | L12: 180 | M12: 高阶零件(23)x1
A13: 60 | B13: 10000 | C13: =$B13*INDEX('02_品质等级'!$F$2:$F$6,MATCH(LEFT(C$1,1),'02_品质等级'!$A$2:$A$6,0)) | D13: =$B13*INDEX('02_品质等级'!$F$2:$F$6,MATCH(LEFT(D$1,1),'02_品质等级'!$A$2:$A$6,0)) | E13: =$B13*INDEX('02_品质等级'!$F$2:$F$6,MATCH(LEFT(E$1,1),'02_品质等级'!$A$2:$A$6,0)) | F13: =$B13*INDEX('02_品质等级'!$F$2:$F$6,MATCH(LEFT(F$1,1),'02_品质等级'!$A$2:$A$6,0)) | G13: =$B13*INDEX('02_品质等级'!$F$2:$F$6,MATCH(LEFT(G$1,1),'02_品质等级'!$A$2:$A$6,0)) | H13: 6 | I13: 12 | J13: 30 | K13: 72 | L13: 180 | M13: 高阶零件(23)x1

Sheet 17_边界待确认
A1: 事项 | B1: 状态 | C1: 说明
A2: 红装洗练 | B2: 本版本先不做 | C2: 不登记任何洗练材料或金币消耗
A3: 升级系统 | B3: 已废弃 | C3: 旧 SpecialEquipmentLvUp 不计入当前版本
A4: 打孔/鉴定 | B4: 已废弃 | C4: 旧精密打孔器/鉴定卷轴不计入当前版本
A5: 装备高级材料 | B5: 高阶零件(23) | C5: 仅红装分解产出；当前作为后续材料沉淀
A6: 主材/副材 ItemId | B6: 待规划 | C6: 主材为大类 x 品质 x 等级；副材为4种
A7: 映射之匙(25) | B7: 副本入场消耗 | C7: 钥匙来源/购买/上限不在本表展开
A8: 首通旧胚料 | B8: 待重配 | C8: 05副本沉淀中旧 I-VIII 胚料首通表仅留档，不纳入新版主材/副材最终口径
A9: 爬塔房车经验 | B9: 待确认 | C9: 需确认是新道具，还是房车零件改名/经验化
A10: 已确认：打造8档 | B10: 打造只分8个档位：10/20/30/40/45/50/55/60；15/25/35仅作为档内可打造装备等级，不单独拆主材档。 | C10: 2026-07-09 用户反馈修正

Sheet 18_产销汇总
A1: 映射装备总产销汇总（前 / 中 / 后期）
A3: 阶段假设（蓝字可改）
A4: 阶段 | B4: 副本代表层 | C4: 副本次数/日 | D4: 爬塔金币最高层 | E4: 爬塔材料区间 | F4: 合成档 | G4: 打造档位等级 | H4: 备注
A5: 前期 | B5: 10 | C5: 7.86 | D5: 30-39 | E5: 30-34 | F5: 2 | G5: 30 | H5: 副本刷10层；爬塔刚进入材料产出段
A6: 中期 | B6: 20 | C6: 7.86 | D6: 60-69 | E6: 60-64 | F6: 4 | G6: 50 | H6: 副本刷20层；爬塔进入VI档材料段
A7: 后期 | B7: 30 | C7: 7.86 | D7: 90-100 | E7: 100 | F7: 8 | G7: 60 | H7: 副本刷30层；爬塔满层材料段
A9: 一、日产出汇总
A10: 指标 | B10: 单位/口径 | C10: 前期 | D10: 中期 | E10: 后期 | F10: 说明
A11: 映射之匙消耗/日 | B11: 次/日 | C11: =$C$5 | D11: =$C$6 | E11: =$C$7 | F11: 按副本次数折算
A12: 爬塔金币/日 | B12: 金币/日 | C12: =INDEX('10_爬塔挂机'!$B$2:$B$11,MATCH($D$5,'10_爬塔挂机'!$A$2:$A$11,0)) | D12: =INDEX('10_爬塔挂机'!$B$2:$B$11,MATCH($D$6,'10_爬塔挂机'!$A$2:$A$11,0)) | E12: =INDEX('10_爬塔挂机'!$B$2:$B$11,MATCH($D$7,'10_爬塔挂机'!$A$2:$A$11,0)) | F12: 爬塔挂机金币；非映射装备专属，但会进入金币总账
A13: 装备总产出/日 | B13: 件/日 | C13: =INDEX('09_日产验算'!$E$2:$E$8,MATCH("刷"&$B$5&"层",'09_日产验算'!$B$2:$B$8,0)) | D13: =INDEX('09_日产验算'!$E$2:$E$8,MATCH("刷"&$B$6&"层",'09_日产验算'!$B$2:$B$8,0)) | E13: =INDEX('09_日产验算'!$E$2:$E$8,MATCH("刷"&$B$7&"层",'09_日产验算'!$B$2:$B$8,0)) | F13: 副本宝箱开装期望
A14: 绿装/日 | B14: 件/日 | C14: =INDEX('09_日产验算'!$F$2:$F$8,MATCH("刷"&$B$5&"层",'09_日产验算'!$B$2:$B$8,0)) | D14: =INDEX('09_日产验算'!$F$2:$F$8,MATCH("刷"&$B$6&"层",'09_日产验算'!$B$2:$B$8,0)) | E14: =INDEX('09_日产验算'!$F$2:$F$8,MATCH("刷"&$B$7&"层",'09_日产验算'!$B$2:$B$8,0))
A15: 蓝装/日 | B15: 件/日 | C15: =INDEX('09_日产验算'!$G$2:$G$8,MATCH("刷"&$B$5&"层",'09_日产验算'!$B$2:$B$8,0)) | D15: =INDEX('09_日产验算'!$G$2:$G$8,MATCH("刷"&$B$6&"层",'09_日产验算'!$B$2:$B$8,0)) | E15: =INDEX('09_日产验算'!$G$2:$G$8,MATCH("刷"&$B$7&"层",'09_日产验算'!$B$2:$B$8,0))
A16: 紫装/日 | B16: 件/日 | C16: =INDEX('09_日产验算'!$H$2:$H$8,MATCH("刷"&$B$5&"层",'09_日产验算'!$B$2:$B$8,0)) | D16: =INDEX('09_日产验算'!$H$2:$H$8,MATCH("刷"&$B$6&"层",'09_日产验算'!$B$2:$B$8,0)) | E16: =INDEX('09_日产验算'!$H$2:$H$8,MATCH("刷"&$B$7&"层",'09_日产验算'!$B$2:$B$8,0))
A17: 金装/日 | B17: 件/日 | C17: =INDEX('09_日产验算'!$I$2:$I$8,MATCH("刷"&$B$5&"层",'09_日产验算'!$B$2:$B$8,0)) | D17: =INDEX('09_日产验算'!$I$2:$I$8,MATCH("刷"&$B$6&"层",'09_日产验算'!$B$2:$B$8,0)) | E17: =INDEX('09_日产验算'!$I$2:$I$8,MATCH("刷"&$B$7&"层",'09_日产验算'!$B$2:$B$8,0))
A18: 红装/日 | B18: 件/日 | C18: =INDEX('09_日产验算'!$J$2:$J$8,MATCH("刷"&$B$5&"层",'09_日产验算'!$B$2:$B$8,0)) | D18: =INDEX('09_日产验算'!$J$2:$J$8,MATCH("刷"&$B$6&"层",'09_日产验算'!$B$2:$B$8,0)) | E18: =INDEX('09_日产验算'!$J$2:$J$8,MATCH("刷"&$B$7&"层",'09_日产验算'!$B$2:$B$8,0)) | F18: 红宝箱必出红装已计入
A19: 副本主材总/日 | B19: 个/日 | C19: =$C$5*INDEX('08_副本材料'!$E$2:$E$31,MATCH($B$5,'08_副本材料'!$A$2:$A$31,0)) | D19: =$C$6*INDEX('08_副本材料'!$E$2:$E$31,MATCH($B$6,'08_副本材料'!$A$2:$A$31,0)) | E19: =$C$7*INDEX('08_副本材料'!$E$2:$E$31,MATCH($B$7,'08_副本材料'!$A$2:$A$31,0)) | F19: 副本独立主材判定
A20: 副本紫主材/日 | B20: 个/日 | C20: =C19*INDEX('08_副本材料'!$F$2:$F$31,MATCH($B$5,'08_副本材料'!$A$2:$A$31,0)) | D20: =D19*INDEX('08_副本材料'!$F$2:$F$31,MATCH($B$6,'08_副本材料'!$A$2:$A$31,0)) | E20: =E19*INDEX('08_副本材料'!$F$2:$F$31,MATCH($B$7,'08_副本材料'!$A$2:$A$31,0))
A21: 副本金主材/日 | B21: 个/日 | C21: =C19*INDEX('08_副本材料'!$G$2:$G$31,MATCH($B$5,'08_副本材料'!$A$2:$A$31,0)) | D21: =D19*INDEX('08_副本材料'!$G$2:$G$31,MATCH($B$6,'08_副本材料'!$A$2:$A$31,0)) | E21: =E19*INDEX('08_副本材料'!$G$2:$G$31,MATCH($B$7,'08_副本材料'!$A$2:$A$31,0))
A22: 副本红主材/日 | B22: 个/日 | C22: =C19*INDEX('08_副本材料'!$H$2:$H$31,MATCH($B$5,'08_副本材料'!$A$2:$A$31,0)) | D22: =D19*INDEX('08_副本材料'!$H$2:$H$31,MATCH($B$6,'08_副本材料'!$A$2:$A$31,0)) | E22: =E19*INDEX('08_副本材料'!$H$2:$H$31,MATCH($B$7,'08_副本材料'!$A$2:$A$31,0))
A23: 副本副材总/日 | B23: 个/日 | C23: =$C$5*INDEX('08_副本材料'!$I$2:$I$31,MATCH($B$5,'08_副本材料'!$A$2:$A$31,0)) | D23: =$C$6*INDEX('08_副本材料'!$I$2:$I$31,MATCH($B$6,'08_副本材料'!$A$2:$A$31,0)) | E23: =$C$7*INDEX('08_副本材料'!$I$2:$I$31,MATCH($B$7,'08_副本材料'!$A$2:$A$31,0)) | F23: 副材1-4等概率
A24: 爬塔主材总/日 | B24: 个/日 | C24: 0 | D24: 0 | E24: 0 | F24: 爬塔挂机材料
A25: 爬塔紫主材/日 | B25: 个/日 | C25: 0 | D25: 0 | E25: 0
A26: 爬塔金主材/日 | B26: 个/日 | C26: 0 | D26: 0 | E26: 0
A27: 爬塔红主材/日 | B27: 个/日 | C27: 0 | D27: 0 | E27: 0
A28: 爬塔副材总/日 | B28: 个/日 | C28: 0 | D28: 0 | E28: 0 | F28: 副材1-4等概率
A29: 主材合计/日 | B29: 个/日 | C29: =C19+C24 | D29: =D19+D24 | E29: =E19+E24 | F29: 副本 + 爬塔
A30: 紫主材合计/日 | B30: 个/日 | C30: =C20+C25 | D30: =D20+D25 | E30: =E20+E25
A31: 金主材合计/日 | B31: 个/日 | C31: =C21+C26 | D31: =D21+D26 | E31: =E21+E26
A32: 红主材合计/日 | B32: 个/日 | C32: =C22+C27 | D32: =D22+D27 | E32: =E22+E27
A33: 副材合计/日 | B33: 个/日 | C33: =C23+C28 | D33: =D23+D28 | E33: =E23+E28 | F33: 副本 + 爬塔
A34: 单种副材合计/日 | B34: 个/日 | C34: =C33/4 | D34: =D33/4 | E34: =E33/4 | F34: 副材1/2/3/4等概率
A36: 二、打造消耗承载（按每日材料全投入，三种品质不同时发生）
A37: 指标 | B37: 单位/口径 | C37: 前期 | D37: 中期 | E37: 后期 | F37: 说明
A38: 代表打造金币/次 | B38: 金币/次 | C38: =INDEX('14_打造消耗'!$E$2:$E$9,MATCH($G$5,'14_打造消耗'!$C$2:$C$9,0)) | D38: =INDEX('14_打造消耗'!$E$2:$E$9,MATCH($G$6,'14_打造消耗'!$C$2:$C$9,0)) | E38: =INDEX('14_打造消耗'!$E$2:$E$9,MATCH($G$7,'14_打造消耗'!$C$2:$C$9,0)) | F38: 取阶段假设中的打造档位等级
A39: 紫主材每种副材消耗 | B39: 个/次 | C39: =INDEX('14_打造消耗'!$F$2:$F$9,MATCH($G$5,'14_打造消耗'!$C$2:$C$9,0)) | D39: =INDEX('14_打造消耗'!$F$2:$F$9,MATCH($G$6,'14_打造消耗'!$C$2:$C$9,0)) | E39: =INDEX('14_打造消耗'!$F$2:$F$9,MATCH($G$7,'14_打造消耗'!$C$2:$C$9,0)) | F39: 每次消耗2种副材，各消耗该数值
A40: 金主材每种副材消耗 | B40: 个/次 | C40: =INDEX('14_打造消耗'!$G$2:$G$9,MATCH($G$5,'14_打造消耗'!$C$2:$C$9,0)) | D40: =INDEX('14_打造消耗'!$G$2:$G$9,MATCH($G$6,'14_打造消耗'!$C$2:$C$9,0)) | E40: =INDEX('14_打造消耗'!$G$2:$G$9,MATCH($G$7,'14_打造消耗'!$C$2:$C$9,0))
A41: 红主材每种副材消耗 | B41: 个/次 | C41: =INDEX('14_打造消耗'!$H$2:$H$9,MATCH($G$5,'14_打造消耗'!$C$2:$C$9,0)) | D41: =INDEX('14_打造消耗'!$H$2:$H$9,MATCH($G$6,'14_打造消耗'!$C$2:$C$9,0)) | E41: =INDEX('14_打造消耗'!$H$2:$H$9,MATCH($G$7,'14_打造消耗'!$C$2:$C$9,0))
A42: 紫主材可支撑打造次数/日 | B42: 次/日 | C42: =MIN(C30,C33/(2*C39)) | D42: =MIN(D30,D33/(2*D39)) | E42: =MIN(E30,E33/(2*E39)) | F42: 若全投入紫主材打造
A43: 金主材可支撑打造次数/日 | B43: 次/日 | C43: =MIN(C31,C33/(2*C40)) | D43: =MIN(D31,D33/(2*D40)) | E43: =MIN(E31,E33/(2*E40)) | F43: 若全投入金主材打造
...
