Workbook

Sheet 前7天钻石抽卡券统计
A1: 前7天钻石与抽卡券投放统计
A2: 口径：统计新手前7天可获得的钻石和抽卡券；抽卡券钻石等价按150钻石/张。
A3: 进度假设：Day7普通主线4-15、高难2-4章、无限挑战30000分、爬塔40层、竞技场1600分、大秘境7层、通行证约7级。
A4: 未纳入：商店兑换/购买消耗、竞技场赛季结算、公会随机宝箱频次、大秘境排行/积分奖励等缺少明确前7天次数的内容。
A6: 玩法 | B6: 钻石 | C6: 角色抽卡券普通 | D6: 专武抽卡券普通 | E6: 角色抽卡券限时 | F6: 专武抽卡券限时 | G6: 抽卡券合计 | H6: 钻石等价合计 | I6: 付费额外等价 | J6: 备注
A7: 7日任务 | B7: =SUMIFS($H$24:$H$999,$A$24:$A$999,$A7,$G$24:$G$999,B$6,$J$24:$J$999,"是") -> 1500 | C7: =SUMIFS($H$24:$H$999,$A$24:$A$999,$A7,$G$24:$G$999,C$6,$J$24:$J$999,"是") -> 20 | D7: =SUMIFS($H$24:$H$999,$A$24:$A$999,$A7,$G$24:$G$999,D$6,$J$24:$J$999,"是") -> 10 | E7: =SUMIFS($H$24:$H$999,$A$24:$A$999,$A7,$G$24:$G$999,E$6,$J$24:$J$999,"是") -> 0 | F7: =SUMIFS($H$24:$H$999,$A$24:$A$999,$A7,$G$24:$G$999,F$6,$J$24:$J$999,"是") -> 0 | G7: =SUM(C7:F7) -> 30 | H7: =SUMIFS($I$24:$I$999,$A$24:$A$999,$A7,$J$24:$J$999,"是") -> 8400 | I7: =SUMIFS($I$24:$I$999,$A$24:$A$999,$A7,$J$24:$J$999,"否") -> 0
A8: 主线副本 | B8: =SUMIFS($H$24:$H$999,$A$24:$A$999,$A8,$G$24:$G$999,B$6,$J$24:$J$999,"是") -> 2800 | C8: =SUMIFS($H$24:$H$999,$A$24:$A$999,$A8,$G$24:$G$999,C$6,$J$24:$J$999,"是") -> 1 | D8: =SUMIFS($H$24:$H$999,$A$24:$A$999,$A8,$G$24:$G$999,D$6,$J$24:$J$999,"是") -> 0 | E8: =SUMIFS($H$24:$H$999,$A$24:$A$999,$A8,$G$24:$G$999,E$6,$J$24:$J$999,"是") -> 15 | F8: =SUMIFS($H$24:$H$999,$A$24:$A$999,$A8,$G$24:$G$999,F$6,$J$24:$J$999,"是") -> 0 | G8: =SUM(C8:F8) -> 16 | H8: =SUMIFS($I$24:$I$999,$A$24:$A$999,$A8,$J$24:$J$999,"是") -> #REF! | I8: =SUMIFS($I$24:$I$999,$A$24:$A$999,$A8,$J$24:$J$999,"否") -> 0
A9: 任务 | B9: =SUMIFS($H$24:$H$999,$A$24:$A$999,$A9,$G$24:$G$999,B$6,$J$24:$J$999,"是") -> 1880 | C9: =SUMIFS($H$24:$H$999,$A$24:$A$999,$A9,$G$24:$G$999,C$6,$J$24:$J$999,"是") -> 0 | D9: =SUMIFS($H$24:$H$999,$A$24:$A$999,$A9,$G$24:$G$999,D$6,$J$24:$J$999,"是") -> 0 | E9: =SUMIFS($H$24:$H$999,$A$24:$A$999,$A9,$G$24:$G$999,E$6,$J$24:$J$999,"是") -> 40 | F9: =SUMIFS($H$24:$H$999,$A$24:$A$999,$A9,$G$24:$G$999,F$6,$J$24:$J$999,"是") -> 10 | G9: =SUM(C9:F9) -> 50 | H9: =SUMIFS($I$24:$I$999,$A$24:$A$999,$A9,$J$24:$J$999,"是") -> 9380 | I9: =SUMIFS($I$24:$I$999,$A$24:$A$999,$A9,$J$24:$J$999,"否") -> 0
A10: 大秘境 | B10: =SUMIFS($H$24:$H$999,$A$24:$A$999,$A10,$G$24:$G$999,B$6,$J$24:$J$999,"是") -> 0 | C10: =SUMIFS($H$24:$H$999,$A$24:$A$999,$A10,$G$24:$G$999,C$6,$J$24:$J$999,"是") -> 0 | D10: =SUMIFS($H$24:$H$999,$A$24:$A$999,$A10,$G$24:$G$999,D$6,$J$24:$J$999,"是") -> 0 | E10: =SUMIFS($H$24:$H$999,$A$24:$A$999,$A10,$G$24:$G$999,E$6,$J$24:$J$999,"是") -> 7 | F10: =SUMIFS($H$24:$H$999,$A$24:$A$999,$A10,$G$24:$G$999,F$6,$J$24:$J$999,"是") -> 1 | G10: =SUM(C10:F10) -> 8 | H10: =SUMIFS($I$24:$I$999,$A$24:$A$999,$A10,$J$24:$J$999,"是") -> 1200 | I10: =SUMIFS($I$24:$I$999,$A$24:$A$999,$A10,$J$24:$J$999,"否") -> 0
A11: 无限挑战 | B11: =SUMIFS($H$24:$H$999,$A$24:$A$999,$A11,$G$24:$G$999,B$6,$J$24:$J$999,"是") -> #REF! | C11: =SUMIFS($H$24:$H$999,$A$24:$A$999,$A11,$G$24:$G$999,C$6,$J$24:$J$999,"是") -> #REF! | D11: =SUMIFS($H$24:$H$999,$A$24:$A$999,$A11,$G$24:$G$999,D$6,$J$24:$J$999,"是") -> 0 | E11: =SUMIFS($H$24:$H$999,$A$24:$A$999,$A11,$G$24:$G$999,E$6,$J$24:$J$999,"是") -> #REF! | F11: =SUMIFS($H$24:$H$999,$A$24:$A$999,$A11,$G$24:$G$999,F$6,$J$24:$J$999,"是") -> 0 | G11: =SUM(C11:F11) -> #REF! | H11: =SUMIFS($I$24:$I$999,$A$24:$A$999,$A11,$J$24:$J$999,"是") -> #REF! | I11: =SUMIFS($I$24:$I$999,$A$24:$A$999,$A11,$J$24:$J$999,"否") -> 0
A12: 爬塔 | B12: =SUMIFS($H$24:$H$999,$A$24:$A$999,$A12,$G$24:$G$999,B$6,$J$24:$J$999,"是") -> 0 | C12: =SUMIFS($H$24:$H$999,$A$24:$A$999,$A12,$G$24:$G$999,C$6,$J$24:$J$999,"是") -> 0 | D12: =SUMIFS($H$24:$H$999,$A$24:$A$999,$A12,$G$24:$G$999,D$6,$J$24:$J$999,"是") -> 0 | E12: =SUMIFS($H$24:$H$999,$A$24:$A$999,$A12,$G$24:$G$999,E$6,$J$24:$J$999,"是") -> 0 | F12: =SUMIFS($H$24:$H$999,$A$24:$A$999,$A12,$G$24:$G$999,F$6,$J$24:$J$999,"是") -> 0 | G12: =SUM(C12:F12) -> 0 | H12: =SUMIFS($I$24:$I$999,$A$24:$A$999,$A12,$J$24:$J$999,"是") -> 9003600 | I12: =SUMIFS($I$24:$I$999,$A$24:$A$999,$A12,$J$24:$J$999,"否") -> 0
A13: 竞技场 | B13: =SUMIFS($H$24:$H$999,$A$24:$A$999,$A13,$G$24:$G$999,B$6,$J$24:$J$999,"是") -> 600 | C13: =SUMIFS($H$24:$H$999,$A$24:$A$999,$A13,$G$24:$G$999,C$6,$J$24:$J$999,"是") -> 0 | D13: =SUMIFS($H$24:$H$999,$A$24:$A$999,$A13,$G$24:$G$999,D$6,$J$24:$J$999,"是") -> 0 | E13: =SUMIFS($H$24:$H$999,$A$24:$A$999,$A13,$G$24:$G$999,E$6,$J$24:$J$999,"是") -> 0 | F13: =SUMIFS($H$24:$H$999,$A$24:$A$999,$A13,$G$24:$G$999,F$6,$J$24:$J$999,"是") -> 0 | G13: =SUM(C13:F13) -> 0 | H13: =SUMIFS($I$24:$I$999,$A$24:$A$999,$A13,$J$24:$J$999,"是") -> #N/A | I13: =SUMIFS($I$24:$I$999,$A$24:$A$999,$A13,$J$24:$J$999,"否") -> 0
A14: 签到 | B14: =SUMIFS($H$24:$H$999,$A$24:$A$999,$A14,$G$24:$G$999,B$6,$J$24:$J$999,"是") -> 150 | C14: =SUMIFS($H$24:$H$999,$A$24:$A$999,$A14,$G$24:$G$999,C$6,$J$24:$J$999,"是") -> 2 | D14: =SUMIFS($H$24:$H$999,$A$24:$A$999,$A14,$G$24:$G$999,D$6,$J$24:$J$999,"是") -> 0 | E14: =SUMIFS($H$24:$H$999,$A$24:$A$999,$A14,$G$24:$G$999,E$6,$J$24:$J$999,"是") -> 0 | F14: =SUMIFS($H$24:$H$999,$A$24:$A$999,$A14,$G$24:$G$999,F$6,$J$24:$J$999,"是") -> 0 | G14: =SUM(C14:F14) -> 2 | H14: =SUMIFS($I$24:$I$999,$A$24:$A$999,$A14,$J$24:$J$999,"是") -> 450 | I14: =SUMIFS($I$24:$I$999,$A$24:$A$999,$A14,$J$24:$J$999,"否") -> 0
A15: 通行证 | B15: =SUMIFS($H$24:$H$999,$A$24:$A$999,$A15,$G$24:$G$999,B$6,$J$24:$J$999,"是") -> 0 | C15: =SUMIFS($H$24:$H$999,$A$24:$A$999,$A15,$G$24:$G$999,C$6,$J$24:$J$999,"是") -> 0 | D15: =SUMIFS($H$24:$H$999,$A$24:$A$999,$A15,$G$24:$G$999,D$6,$J$24:$J$999,"是") -> 0 | E15: =SUMIFS($H$24:$H$999,$A$24:$A$999,$A15,$G$24:$G$999,E$6,$J$24:$J$999,"是") -> 0 | F15: =SUMIFS($H$24:$H$999,$A$24:$A$999,$A15,$G$24:$G$999,F$6,$J$24:$J$999,"是") -> 0 | G15: =SUM(C15:F15) -> 0 | H15: =SUMIFS($I$24:$I$999,$A$24:$A$999,$A15,$J$24:$J$999,"是") -> 0 | I15: =SUMIFS($I$24:$I$999,$A$24:$A$999,$A15,$J$24:$J$999,"否") -> 680
A16: 高难主线 | B16: =SUMIFS($H$24:$H$999,$A$24:$A$999,$A16,$G$24:$G$999,B$6,$J$24:$J$999,"是") -> 750 | C16: =SUMIFS($H$24:$H$999,$A$24:$A$999,$A16,$G$24:$G$999,C$6,$J$24:$J$999,"是") -> 0 | D16: =SUMIFS($H$24:$H$999,$A$24:$A$999,$A16,$G$24:$G$999,D$6,$J$24:$J$999,"是") -> 0 | E16: =SUMIFS($H$24:$H$999,$A$24:$A$999,$A16,$G$24:$G$999,E$6,$J$24:$J$999,"是") -> 15 | F16: =SUMIFS($H$24:$H$999,$A$24:$A$999,$A16,$G$24:$G$999,F$6,$J$24:$J$999,"是") -> 0 | G16: =SUM(C16:F16) -> 15 | H16: =SUMIFS($I$24:$I$999,$A$24:$A$999,$A16,$J$24:$J$999,"是") -> 6600 | I16: =SUMIFS($I$24:$I$999,$A$24:$A$999,$A16,$J$24:$J$999,"否") -> 0
A17: 免费口径合计 | B17: =SUM(B7:B16) -> #REF! | C17: =SUM(C7:C16) -> #REF! | D17: =SUM(D7:D16) -> 10 | E17: =SUM(E7:E16) -> #REF! | F17: =SUM(F7:F16) -> 11 | G17: =SUM(G7:G16) -> #REF! | H17: =SUM(H7:H16) -> #REF! | I17: =SUM(I7:I16) -> 680
A23: 玩法 | B23: 口径/模块 | C23: 来源页签 | D23: 来源位置 | E23: 原始道具 | F23: 倍数/次数 | G23: 统计道具 | H23: 前7天数量 | I23: 钻石等价 | J23: 计入免费口径 | K23: 备注
A24: 7日任务 | B24: 任务奖励 | C24: 7日任务 | D24: H16/I16 | E24: ='7日任务'!I16 -> 体力药 | F24: 1 | G24: =IF(E24="钻石","钻石",IF(ISNUMBER(SEARCH("角色抽卡券限时",E24)),"角色抽卡券限时",IF(ISNUMBER(SEARCH("专武抽卡券限时",E24)),"专武抽卡券限时",IF(ISNUMBER(SEARCH("角色抽卡券",E24)),"角色抽卡券普通",IF(ISNUMBER(SEARCH("专武抽卡券",E24)),"专武抽卡券普通",""))))) | H24: ='7日任务'!J16*F24 -> 2 | I24: =IF(G24="钻石",H24,H24*150) -> 300 | J24: 是 | K24: Day1-Day7全部任务
A25: 7日任务 | B25: 任务奖励 | C25: 7日任务 | D25: H25/I25 | E25: ='7日任务'!I27 -> 体力药 | F25: 1 | G25: =IF(E25="钻石","钻石",IF(ISNUMBER(SEARCH("角色抽卡券限时",E25)),"角色抽卡券限时",IF(ISNUMBER(SEARCH("专武抽卡券限时",E25)),"专武抽卡券限时",IF(ISNUMBER(SEARCH("角色抽卡券",E25)),"角色抽卡券普通",IF(ISNUMBER(SEARCH("专武抽卡券",E25)),"专武抽卡券普通",""))))) | H25: ='7日任务'!J27*F25 -> 2 | I25: =IF(G25="钻石",H25,H25*150) -> 300 | J25: 是 | K25: Day1-Day7全部任务
A26: 7日任务 | B26: 任务奖励 | C26: 7日任务 | D26: H35/I35 | E26: ='7日任务'!I39 -> 体力药 | F26: 1 | G26: =IF(E26="钻石","钻石",IF(ISNUMBER(SEARCH("角色抽卡券限时",E26)),"角色抽卡券限时",IF(ISNUMBER(SEARCH("专武抽卡券限时",E26)),"专武抽卡券限时",IF(ISNUMBER(SEARCH("角色抽卡券",E26)),"角色抽卡券普通",IF(ISNUMBER(SEARCH("专武抽卡券",E26)),"专武抽卡券普通",""))))) | H26: ='7日任务'!J39*F26 -> 2 | I26: =IF(G26="钻石",H26,H26*150) -> 300 | J26: 是 | K26: Day1-Day7全部任务
A27: 7日任务 | B27: 任务奖励 | C27: 7日任务 | D27: H45/I45 | E27: ='7日任务'!I51 -> 体力药 | F27: 1 | G27: =IF(E27="钻石","钻石",IF(ISNUMBER(SEARCH("角色抽卡券限时",E27)),"角色抽卡券限时",IF(ISNUMBER(SEARCH("专武抽卡券限时",E27)),"专武抽卡券限时",IF(ISNUMBER(SEARCH("角色抽卡券",E27)),"角色抽卡券普通",IF(ISNUMBER(SEARCH("专武抽卡券",E27)),"专武抽卡券普通",""))))) | H27: ='7日任务'!J51*F27 -> 2 | I27: =IF(G27="钻石",H27,H27*150) -> 300 | J27: 是 | K27: Day1-Day7全部任务
A28: 7日任务 | B28: 任务奖励 | C28: 7日任务 | D28: H55/I55 | E28: ='7日任务'!I63 -> 体力药 | F28: 1 | G28: =IF(E28="钻石","钻石",IF(ISNUMBER(SEARCH("角色抽卡券限时",E28)),"角色抽卡券限时",IF(ISNUMBER(SEARCH("专武抽卡券限时",E28)),"专武抽卡券限时",IF(ISNUMBER(SEARCH("角色抽卡券",E28)),"角色抽卡券普通",IF(ISNUMBER(SEARCH("专武抽卡券",E28)),"专武抽卡券普通",""))))) | H28: ='7日任务'!J63*F28 -> 2 | I28: =IF(G28="钻石",H28,H28*150) -> 300 | J28: 是 | K28: Day1-Day7全部任务
A29: 7日任务 | B29: 任务奖励 | C29: 7日任务 | D29: H65/I65 | E29: ='7日任务'!I75 -> 体力药 | F29: 1 | G29: =IF(E29="钻石","钻石",IF(ISNUMBER(SEARCH("角色抽卡券限时",E29)),"角色抽卡券限时",IF(ISNUMBER(SEARCH("专武抽卡券限时",E29)),"专武抽卡券限时",IF(ISNUMBER(SEARCH("角色抽卡券",E29)),"角色抽卡券普通",IF(ISNUMBER(SEARCH("专武抽卡券",E29)),"专武抽卡券普通",""))))) | H29: ='7日任务'!J75*F29 -> 2 | I29: =IF(G29="钻石",H29,H29*150) -> 300 | J29: 是 | K29: Day1-Day7全部任务
A30: 7日任务 | B30: 任务奖励 | C30: 7日任务 | D30: H75/I75 | E30: ='7日任务'!I87 -> 体力药 | F30: 1 | G30: =IF(E30="钻石","钻石",IF(ISNUMBER(SEARCH("角色抽卡券限时",E30)),"角色抽卡券限时",IF(ISNUMBER(SEARCH("专武抽卡券限时",E30)),"专武抽卡券限时",IF(ISNUMBER(SEARCH("角色抽卡券",E30)),"角色抽卡券普通",IF(ISNUMBER(SEARCH("专武抽卡券",E30)),"专武抽卡券普通",""))))) | H30: ='7日任务'!J87*F30 -> 2 | I30: =IF(G30="钻石",H30,H30*150) -> 300 | J30: 是 | K30: Day1-Day7全部任务
A31: 7日任务 | B31: 阶段奖励 | C31: 7日任务 | D31: B91/C91 | E31: ='7日任务'!B105 -> 角色抽卡券普通 | F31: 1 | G31: =IF(E31="钻石","钻石",IF(ISNUMBER(SEARCH("角色抽卡券限时",E31)),"角色抽卡券限时",IF(ISNUMBER(SEARCH("专武抽卡券限时",E31)),"专武抽卡券限时",IF(ISNUMBER(SEARCH("角色抽卡券",E31)),"角色抽卡券普通",IF(ISNUMBER(SEARCH("专武抽卡券",E31)),"专武抽卡券普通",""))))) -> 角色抽卡券普通 | H31: ='7日任务'!C105*F31 -> 10 | I31: =IF(G31="钻石",H31,H31*150) -> 1500 | J31: 是 | K31: 按560积分可领取
A32: 7日任务 | B32: 阶段奖励 | C32: 7日任务 | D32: B92/C92 | E32: ='7日任务'!B106 -> 角色抽卡券普通 | F32: 1 | G32: =IF(E32="钻石","钻石",IF(ISNUMBER(SEARCH("角色抽卡券限时",E32)),"角色抽卡券限时",IF(ISNUMBER(SEARCH("专武抽卡券限时",E32)),"专武抽卡券限时",IF(ISNUMBER(SEARCH("角色抽卡券",E32)),"角色抽卡券普通",IF(ISNUMBER(SEARCH("专武抽卡券",E32)),"专武抽卡券普通",""))))) -> 角色抽卡券普通 | H32: ='7日任务'!C106*F32 -> 10 | I32: =IF(G32="钻石",H32,H32*150) -> 1500 | J32: 是 | K32: 按560积分可领取
A33: 7日任务 | B33: 阶段奖励 | C33: 7日任务 | D33: B93/C93 | E33: ='7日任务'!B107 -> 专武抽卡券普通 | F33: 1 | G33: =IF(E33="钻石","钻石",IF(ISNUMBER(SEARCH("角色抽卡券限时",E33)),"角色抽卡券限时",IF(ISNUMBER(SEARCH("专武抽卡券限时",E33)),"专武抽卡券限时",IF(ISNUMBER(SEARCH("角色抽卡券",E33)),"角色抽卡券普通",IF(ISNUMBER(SEARCH("专武抽卡券",E33)),"专武抽卡券普通",""))))) -> 专武抽卡券普通 | H33: ='7日任务'!C107*F33 -> 10 | I33: =IF(G33="钻石",H33,H33*150) -> 1500 | J33: 是 | K33: 按560积分可领取
A34: 7日任务 | B34: 阶段奖励 | C34: 7日任务 | D34: B94/C94 | E34: ='7日任务'!B108 -> SSR角色 | F34: 1 | G34: =IF(E34="钻石","钻石",IF(ISNUMBER(SEARCH("角色抽卡券限时",E34)),"角色抽卡券限时",IF(ISNUMBER(SEARCH("专武抽卡券限时",E34)),"专武抽卡券限时",IF(ISNUMBER(SEARCH("角色抽卡券",E34)),"角色抽卡券普通",IF(ISNUMBER(SEARCH("专武抽卡券",E34)),"专武抽卡券普通",""))))) | H34: ='7日任务'!C108*F34 -> 1 | I34: =IF(G34="钻石",H34,H34*150) -> 150 | J34: 是 | K34: 按560积分可领取
A35: 7日任务 | B35: 阶段奖励 | C35: 7日任务 | D35: B96/C96 | E35: ='7日任务'!B110 -> SSR专武 | F35: 1 | G35: =IF(E35="钻石","钻石",IF(ISNUMBER(SEARCH("角色抽卡券限时",E35)),"角色抽卡券限时",IF(ISNUMBER(SEARCH("专武抽卡券限时",E35)),"专武抽卡券限时",IF(ISNUMBER(SEARCH("角色抽卡券",E35)),"角色抽卡券普通",IF(ISNUMBER(SEARCH("专武抽卡券",E35)),"专武抽卡券普通",""))))) | H35: ='7日任务'!C110*F35 -> 1 | I35: =IF(G35="钻石",H35,H35*150) -> 150 | J35: 是 | K35: 按560积分可领取
A36: 7日任务 | B36: 阶段奖励 | C36: 7日任务 | D36: D91/E91 | E36: ='7日任务'!D105 -> 钻石 | F36: 1 | G36: =IF(E36="钻石","钻石",IF(ISNUMBER(SEARCH("角色抽卡券限时",E36)),"角色抽卡券限时",IF(ISNUMBER(SEARCH("专武抽卡券限时",E36)),"专武抽卡券限时",IF(ISNUMBER(SEARCH("角色抽卡券",E36)),"角色抽卡券普通",IF(ISNUMBER(SEARCH("专武抽卡券",E36)),"专武抽卡券普通",""))))) -> 钻石 | H36: ='7日任务'!E105*F36 -> 500 | I36: =IF(G36="钻石",H36,H36*150) -> 500 | J36: 是 | K36: 按560积分可领取
A37: 7日任务 | B37: 阶段奖励 | C37: 7日任务 | D37: D92/E92 | E37: ='7日任务'!D106 -> 钻石 | F37: 1 | G37: =IF(E37="钻石","钻石",IF(ISNUMBER(SEARCH("角色抽卡券限时",E37)),"角色抽卡券限时",IF(ISNUMBER(SEARCH("专武抽卡券限时",E37)),"专武抽卡券限时",IF(ISNUMBER(SEARCH("角色抽卡券",E37)),"角色抽卡券普通",IF(ISNUMBER(SEARCH("专武抽卡券",E37)),"专武抽卡券普通",""))))) -> 钻石 | H37: ='7日任务'!E106*F37 -> 500 | I37: =IF(G37="钻石",H37,H37*150) -> 500 | J37: 是 | K37: 按560积分可领取
A38: 7日任务 | B38: 阶段奖励 | C38: 7日任务 | D38: D93/E93 | E38: ='7日任务'!D107 -> 钻石 | F38: 1 | G38: =IF(E38="钻石","钻石",IF(ISNUMBER(SEARCH("角色抽卡券限时",E38)),"角色抽卡券限时",IF(ISNUMBER(SEARCH("专武抽卡券限时",E38)),"专武抽卡券限时",IF(ISNUMBER(SEARCH("角色抽卡券",E38)),"角色抽卡券普通",IF(ISNUMBER(SEARCH("专武抽卡券",E38)),"专武抽卡券普通",""))))) -> 钻石 | H38: ='7日任务'!E107*F38 -> 500 | I38: =IF(G38="钻石",H38,H38*150) -> 500 | J38: 是 | K38: 按560积分可领取
A39: 7日任务 | B39: 阶段奖励 | C39: 7日任务 | D39: D94/E94 | E39: ='7日任务'!D108 -> 0 | F39: 1 | G39: =IF(E39="钻石","钻石",IF(ISNUMBER(SEARCH("角色抽卡券限时",E39)),"角色抽卡券限时",IF(ISNUMBER(SEARCH("专武抽卡券限时",E39)),"专武抽卡券限时",IF(ISNUMBER(SEARCH("角色抽卡券",E39)),"角色抽卡券普通",IF(ISNUMBER(SEARCH("专武抽卡券",E39)),"专武抽卡券普通",""))))) | H39: ='7日任务'!E108*F39 -> 0 | I39: =IF(G39="钻石",H39,H39*150) -> 0 | J39: 是 | K39: 按560积分可领取
A40: 7日任务 | B40: 阶段奖励 | C40: 7日任务 | D40: D96/E96 | E40: ='7日任务'!D110 -> 0 | F40: 1 | G40: =IF(E40="钻石","钻石",IF(ISNUMBER(SEARCH("角色抽卡券限时",E40)),"角色抽卡券限时",IF(ISNUMBER(SEARCH("专武抽卡券限时",E40)),"专武抽卡券限时",IF(ISNUMBER(SEARCH("角色抽卡券",E40)),"角色抽卡券普通",IF(ISNUMBER(SEARCH("专武抽卡券",E40)),"专武抽卡券普通",""))))) | H40: ='7日任务'!E110*F40 -> 0 | I40: =IF(G40="钻石",H40,H40*150) -> 0 | J40: 是 | K40: 按560积分可领取
A41: 主线副本 | B41: 首周可达一次性奖励 | C41: 主线副本 | D41: AC10/AD10 | E41: =主线副本!AC10 -> 钻石 | F41: 1 | G41: =IF(E41="钻石","钻石",IF(ISNUMBER(SEARCH("角色抽卡券限时",E41)),"角色抽卡券限时",IF(ISNUMBER(SEARCH("专武抽卡券限时",E41)),"专武抽卡券限时",IF(ISNUMBER(SEARCH("角色抽卡券",E41)),"角色抽卡券普通",IF(ISNUMBER(SEARCH("专武抽卡券",E41)),"专武抽卡券普通",""))))) -> 钻石 | H41: =主线副本!AD10*F41 -> 50 | I41: =IF(G41="钻石",H41,H41*150) -> 50 | J41: 是 | K41: Day7到普通主线4-15
A42: 主线副本 | B42: 首周可达一次性奖励 | C42: 主线副本 | D42: AC11/AD11 | E42: =主线副本!AC11 -> 钻石 | F42: 1 | G42: =IF(E42="钻石","钻石",IF(ISNUMBER(SEARCH("角色抽卡券限时",E42)),"角色抽卡券限时",IF(ISNUMBER(SEARCH("专武抽卡券限时",E42)),"专武抽卡券限时",IF(ISNUMBER(SEARCH("角色抽卡券",E42)),"角色抽卡券普通",IF(ISNUMBER(SEARCH("专武抽卡券",E42)),"专武抽卡券普通",""))))) -> 钻石 | H42: =主线副本!AD11*F42 -> 50 | I42: =IF(G42="钻石",H42,H42*150) -> 50 | J42: 是 | K42: Day7到普通主线4-15
A43: 主线副本 | B43: 首周可达一次性奖励 | C43: 主线副本 | D43: AC12/AD12 | E43: =主线副本!AC12 -> 钻石 | F43: 1 | G43: =IF(E43="钻石","钻石",IF(ISNUMBER(SEARCH("角色抽卡券限时",E43)),"角色抽卡券限时",IF(ISNUMBER(SEARCH("专武抽卡券限时",E43)),"专武抽卡券限时",IF(ISNUMBER(SEARCH("角色抽卡券",E43)),"角色抽卡券普通",IF(ISNUMBER(SEARCH("专武抽卡券",E43)),"专武抽卡券普通",""))))) -> 钻石 | H43: =主线副本!AD12*F43 -> 150 | I43: =IF(G43="钻石",H43,H43*150) -> 150 | J43: 是 | K43: Day7到普通主线4-15
A44: 主线副本 | B44: 首周可达一次性奖励 | C44: 主线副本 | D44: AC13/AD13 | E44: =主线副本!AC13 -> 钻石 | F44: 1 | G44: =IF(E44="钻石","钻石",IF(ISNUMBER(SEARCH("角色抽卡券限时",E44)),"角色抽卡券限时",IF(ISNUMBER(SEARCH("专武抽卡券限时",E44)),"专武抽卡券限时",IF(ISNUMBER(SEARCH("角色抽卡券",E44)),"角色抽卡券普通",IF(ISNUMBER(SEARCH("专武抽卡券",E44)),"专武抽卡券普通",""))))) -> 钻石 | H44: =主线副本!AD13*F44 -> 50 | I44: =IF(G44="钻石",H44,H44*150) -> 50 | J44: 是 | K44: Day7到普通主线4-15
A45: 主线副本 | B45: 首周可达一次性奖励 | C45: 主线副本 | D45: AC14/AD14 | E45: =主线副本!AC14 -> 钻石 | F45: 1 | G45: =IF(E45="钻石","钻石",IF(ISNUMBER(SEARCH("角色抽卡券限时",E45)),"角色抽卡券限时",IF(ISNUMBER(SEARCH("专武抽卡券限时",E45)),"专武抽卡券限时",IF(ISNUMBER(SEARCH("角色抽卡券",E45)),"角色抽卡券普通",IF(ISNUMBER(SEARCH("专武抽卡券",E45)),"专武抽卡券普通",""))))) -> 钻石 | H45: =主线副本!AD14*F45 -> 50 | I45: =IF(G45="钻石",H45,H45*150) -> 50 | J45: 是 | K45: Day7到普通主线4-15
A46: 主线副本 | B46: 首周可达一次性奖励 | C46: 主线副本 | D46: AC15/AD15 | E46: =主线副本!AC15 -> 钻石 | F46: 1 | G46: =IF(E46="钻石","钻石",IF(ISNUMBER(SEARCH("角色抽卡券限时",E46)),"角色抽卡券限时",IF(ISNUMBER(SEARCH("专武抽卡券限时",E46)),"专武抽卡券限时",IF(ISNUMBER(SEARCH("角色抽卡券",E46)),"角色抽卡券普通",IF(ISNUMBER(SEARCH("专武抽卡券",E46)),"专武抽卡券普通",""))))) -> 钻石 | H46: =主线副本!AD15*F46 -> 50 | I46: =IF(G46="钻石",H46,H46*150) -> 50 | J46: 是 | K46: Day7到普通主线4-15
...

Sheet 玩法钻石抽卡券统计
A1: 各玩法钻石与抽卡券投放统计
A2: 口径：统计奖励投放；排除道具定价、养成消耗、商店购买/兑换消耗。通行证付费奖励单独保留在口径列。抽卡券钻石等价按道具定价150钻石/张。
A4: 玩法 | B4: 钻石 | C4: 角色抽卡券普通 | D4: 专武抽卡券普通 | E4: 角色抽卡券限时 | F4: 专武抽卡券限时 | G4: 抽卡券合计 | H4: 钻石等价合计 | I4: 备注
A5: 7日任务 | B5: =SUMIFS($G$20:$G$999,$A$20:$A$999,$A5,$F$20:$F$999,B$4) -> 1500 | C5: =SUMIFS($G$20:$G$999,$A$20:$A$999,$A5,$F$20:$F$999,C$4) -> 20 | D5: =SUMIFS($G$20:$G$999,$A$20:$A$999,$A5,$F$20:$F$999,D$4) -> 10 | E5: =SUMIFS($G$20:$G$999,$A$20:$A$999,$A5,$F$20:$F$999,E$4) -> 0 | F5: =SUMIFS($G$20:$G$999,$A$20:$A$999,$A5,$F$20:$F$999,F$4) -> 0 | G5: =SUM(C5:F5) -> 30 | H5: =SUMIFS($H$20:$H$999,$A$20:$A$999,$A5) -> 6000
A6: 主线副本 | B6: =SUMIFS($G$20:$G$999,$A$20:$A$999,$A6,$F$20:$F$999,B$4) -> 1600 | C6: =SUMIFS($G$20:$G$999,$A$20:$A$999,$A6,$F$20:$F$999,C$4) -> 0 | D6: =SUMIFS($G$20:$G$999,$A$20:$A$999,$A6,$F$20:$F$999,D$4) -> 0 | E6: =SUMIFS($G$20:$G$999,$A$20:$A$999,$A6,$F$20:$F$999,E$4) -> 9 | F6: =SUMIFS($G$20:$G$999,$A$20:$A$999,$A6,$F$20:$F$999,F$4) -> 0 | G6: =SUM(C6:F6) -> 9 | H6: =SUMIFS($H$20:$H$999,$A$20:$A$999,$A6) -> 2950
A7: 任务 | B7: =SUMIFS($G$20:$G$999,$A$20:$A$999,$A7,$F$20:$F$999,B$4) -> 1280 | C7: =SUMIFS($G$20:$G$999,$A$20:$A$999,$A7,$F$20:$F$999,C$4) -> 0 | D7: =SUMIFS($G$20:$G$999,$A$20:$A$999,$A7,$F$20:$F$999,D$4) -> 0 | E7: =SUMIFS($G$20:$G$999,$A$20:$A$999,$A7,$F$20:$F$999,E$4) -> 40 | F7: =SUMIFS($G$20:$G$999,$A$20:$A$999,$A7,$F$20:$F$999,F$4) -> 10 | G7: =SUM(C7:F7) -> 50 | H7: =SUMIFS($H$20:$H$999,$A$20:$A$999,$A7) -> 8780
A8: 公会 | B8: =SUMIFS($G$20:$G$999,$A$20:$A$999,$A8,$F$20:$F$999,B$4) -> 150 | C8: =SUMIFS($G$20:$G$999,$A$20:$A$999,$A8,$F$20:$F$999,C$4) -> 1 | D8: =SUMIFS($G$20:$G$999,$A$20:$A$999,$A8,$F$20:$F$999,D$4) -> 1 | E8: =SUMIFS($G$20:$G$999,$A$20:$A$999,$A8,$F$20:$F$999,E$4) -> 0 | F8: =SUMIFS($G$20:$G$999,$A$20:$A$999,$A8,$F$20:$F$999,F$4) -> 0 | G8: =SUM(C8:F8) -> 2 | H8: =SUMIFS($H$20:$H$999,$A$20:$A$999,$A8) -> 450
A9: 大秘境 | B9: =SUMIFS($G$20:$G$999,$A$20:$A$999,$A9,$F$20:$F$999,B$4) -> 1254 | C9: =SUMIFS($G$20:$G$999,$A$20:$A$999,$A9,$F$20:$F$999,C$4) -> 4 | D9: =SUMIFS($G$20:$G$999,$A$20:$A$999,$A9,$F$20:$F$999,D$4) -> 4 | E9: =SUMIFS($G$20:$G$999,$A$20:$A$999,$A9,$F$20:$F$999,E$4) -> 38 | F9: =SUMIFS($G$20:$G$999,$A$20:$A$999,$A9,$F$20:$F$999,F$4) -> 26 | G9: =SUM(C9:F9) -> 72 | H9: =SUMIFS($H$20:$H$999,$A$20:$A$999,$A9) -> 12054
A10: 无限挑战 | B10: =SUMIFS($G$20:$G$999,$A$20:$A$999,$A10,$F$20:$F$999,B$4) -> #REF! | C10: =SUMIFS($G$20:$G$999,$A$20:$A$999,$A10,$F$20:$F$999,C$4) -> #REF! | D10: =SUMIFS($G$20:$G$999,$A$20:$A$999,$A10,$F$20:$F$999,D$4) -> 0 | E10: =SUMIFS($G$20:$G$999,$A$20:$A$999,$A10,$F$20:$F$999,E$4) -> #REF! | F10: =SUMIFS($G$20:$G$999,$A$20:$A$999,$A10,$F$20:$F$999,F$4) -> #REF! | G10: =SUM(C10:F10) -> #REF! | H10: =SUMIFS($H$20:$H$999,$A$20:$A$999,$A10) -> #REF!
A11: 爬塔 | B11: =SUMIFS($G$20:$G$999,$A$20:$A$999,$A11,$F$20:$F$999,B$4) -> 0 | C11: =SUMIFS($G$20:$G$999,$A$20:$A$999,$A11,$F$20:$F$999,C$4) -> 0 | D11: =SUMIFS($G$20:$G$999,$A$20:$A$999,$A11,$F$20:$F$999,D$4) -> 0 | E11: =SUMIFS($G$20:$G$999,$A$20:$A$999,$A11,$F$20:$F$999,E$4) -> 0 | F11: =SUMIFS($G$20:$G$999,$A$20:$A$999,$A11,$F$20:$F$999,F$4) -> 0 | G11: =SUM(C11:F11) -> 0 | H11: =SUMIFS($H$20:$H$999,$A$20:$A$999,$A11) -> 0
A12: 竞技场 | B12: =SUMIFS($G$20:$G$999,$A$20:$A$999,$A12,$F$20:$F$999,B$4) -> 6100 | C12: =SUMIFS($G$20:$G$999,$A$20:$A$999,$A12,$F$20:$F$999,C$4) -> 0 | D12: =SUMIFS($G$20:$G$999,$A$20:$A$999,$A12,$F$20:$F$999,D$4) -> 0 | E12: =SUMIFS($G$20:$G$999,$A$20:$A$999,$A12,$F$20:$F$999,E$4) -> 0 | F12: =SUMIFS($G$20:$G$999,$A$20:$A$999,$A12,$F$20:$F$999,F$4) -> 0 | G12: =SUM(C12:F12) -> 0 | H12: =SUMIFS($H$20:$H$999,$A$20:$A$999,$A12) -> #N/A
A13: 签到 | B13: =SUMIFS($G$20:$G$999,$A$20:$A$999,$A13,$F$20:$F$999,B$4) -> 250 | C13: =SUMIFS($G$20:$G$999,$A$20:$A$999,$A13,$F$20:$F$999,C$4) -> 8 | D13: =SUMIFS($G$20:$G$999,$A$20:$A$999,$A13,$F$20:$F$999,D$4) -> 0 | E13: =SUMIFS($G$20:$G$999,$A$20:$A$999,$A13,$F$20:$F$999,E$4) -> 0 | F13: =SUMIFS($G$20:$G$999,$A$20:$A$999,$A13,$F$20:$F$999,F$4) -> 0 | G13: =SUM(C13:F13) -> 8 | H13: =SUMIFS($H$20:$H$999,$A$20:$A$999,$A13) -> 1450
A14: 通行证 | B14: =SUMIFS($G$20:$G$999,$A$20:$A$999,$A14,$F$20:$F$999,B$4) -> 2130 | C14: =SUMIFS($G$20:$G$999,$A$20:$A$999,$A14,$F$20:$F$999,C$4) -> 10 | D14: =SUMIFS($G$20:$G$999,$A$20:$A$999,$A14,$F$20:$F$999,D$4) -> 10 | E14: =SUMIFS($G$20:$G$999,$A$20:$A$999,$A14,$F$20:$F$999,E$4) -> 0 | F14: =SUMIFS($G$20:$G$999,$A$20:$A$999,$A14,$F$20:$F$999,F$4) -> 0 | G14: =SUM(C14:F14) -> 20 | H14: =SUMIFS($H$20:$H$999,$A$20:$A$999,$A14) -> 5130
A15: 高难主线 | B15: =SUMIFS($G$20:$G$999,$A$20:$A$999,$A15,$F$20:$F$999,B$4) -> 750 | C15: =SUMIFS($G$20:$G$999,$A$20:$A$999,$A15,$F$20:$F$999,C$4) -> 0 | D15: =SUMIFS($G$20:$G$999,$A$20:$A$999,$A15,$F$20:$F$999,D$4) -> 0 | E15: =SUMIFS($G$20:$G$999,$A$20:$A$999,$A15,$F$20:$F$999,E$4) -> 15 | F15: =SUMIFS($G$20:$G$999,$A$20:$A$999,$A15,$F$20:$F$999,F$4) -> 0 | G15: =SUM(C15:F15) -> 15 | H15: =SUMIFS($H$20:$H$999,$A$20:$A$999,$A15) -> 3000
A16: Boss挑战 | B16: =SUMIFS($G$20:$G$999,$A$20:$A$999,$A16,$F$20:$F$999,B$4) -> 4750 | C16: =SUMIFS($G$20:$G$999,$A$20:$A$999,$A16,$F$20:$F$999,C$4) -> 0 | D16: =SUMIFS($G$20:$G$999,$A$20:$A$999,$A16,$F$20:$F$999,D$4) -> 15 | E16: =SUMIFS($G$20:$G$999,$A$20:$A$999,$A16,$F$20:$F$999,E$4) -> 0 | F16: =SUMIFS($G$20:$G$999,$A$20:$A$999,$A16,$F$20:$F$999,F$4) -> 0 | G16: =SUM(C16:F16) -> 15 | H16: =SUMIFS($H$20:$H$999,$A$20:$A$999,$A16) -> 7000 | I16: 一次性Boss首通奖励
A17: 合计 | B17: =SUM(B5:B16) -> #REF! | C17: =SUM(C5:C16) -> #REF! | D17: =SUM(D5:D16) -> 40 | E17: =SUM(E5:E16) -> #REF! | F17: =SUM(F5:F16) -> #REF! | G17: =SUM(G5:G16) -> #REF! | H17: =SUM(H5:H16) -> #REF!
A19: 玩法 | B19: 口径/模块 | C19: 来源页签 | D19: 来源位置 | E19: 原始道具 | F19: 统计道具 | G19: 数量 | H19: 钻石等价 | I19: 备注
A20: 7日任务 | B20: 任务奖励 | C20: 7日任务 | D20: H16/I16 | E20: ='7日任务'!I16 -> 体力药 | F20: =IF(E20="钻石","钻石",IF(ISNUMBER(SEARCH("角色抽卡券限时",E20)),"角色抽卡券限时",IF(ISNUMBER(SEARCH("专武抽卡券限时",E20)),"专武抽卡券限时",IF(ISNUMBER(SEARCH("角色抽卡券",E20)),"角色抽卡券普通",IF(ISNUMBER(SEARCH("专武抽卡券",E20)),"专武抽卡券普通",""))))) | G20: ='7日任务'!J16 -> 2 | H20: =IF(F20="",0,IF(F20="钻石",G20,G20*150)) -> 0
A21: 7日任务 | B21: 任务奖励 | C21: 7日任务 | D21: H25/I25 | E21: ='7日任务'!I27 -> 体力药 | F21: =IF(E21="钻石","钻石",IF(ISNUMBER(SEARCH("角色抽卡券限时",E21)),"角色抽卡券限时",IF(ISNUMBER(SEARCH("专武抽卡券限时",E21)),"专武抽卡券限时",IF(ISNUMBER(SEARCH("角色抽卡券",E21)),"角色抽卡券普通",IF(ISNUMBER(SEARCH("专武抽卡券",E21)),"专武抽卡券普通",""))))) | G21: ='7日任务'!J27 -> 2 | H21: =IF(F21="",0,IF(F21="钻石",G21,G21*150)) -> 0
A22: 7日任务 | B22: 任务奖励 | C22: 7日任务 | D22: H35/I35 | E22: ='7日任务'!I39 -> 体力药 | F22: =IF(E22="钻石","钻石",IF(ISNUMBER(SEARCH("角色抽卡券限时",E22)),"角色抽卡券限时",IF(ISNUMBER(SEARCH("专武抽卡券限时",E22)),"专武抽卡券限时",IF(ISNUMBER(SEARCH("角色抽卡券",E22)),"角色抽卡券普通",IF(ISNUMBER(SEARCH("专武抽卡券",E22)),"专武抽卡券普通",""))))) | G22: ='7日任务'!J39 -> 2 | H22: =IF(F22="",0,IF(F22="钻石",G22,G22*150)) -> 0
A23: 7日任务 | B23: 任务奖励 | C23: 7日任务 | D23: H45/I45 | E23: ='7日任务'!I51 -> 体力药 | F23: =IF(E23="钻石","钻石",IF(ISNUMBER(SEARCH("角色抽卡券限时",E23)),"角色抽卡券限时",IF(ISNUMBER(SEARCH("专武抽卡券限时",E23)),"专武抽卡券限时",IF(ISNUMBER(SEARCH("角色抽卡券",E23)),"角色抽卡券普通",IF(ISNUMBER(SEARCH("专武抽卡券",E23)),"专武抽卡券普通",""))))) | G23: ='7日任务'!J51 -> 2 | H23: =IF(F23="",0,IF(F23="钻石",G23,G23*150)) -> 0
A24: 7日任务 | B24: 任务奖励 | C24: 7日任务 | D24: H55/I55 | E24: ='7日任务'!I63 -> 体力药 | F24: =IF(E24="钻石","钻石",IF(ISNUMBER(SEARCH("角色抽卡券限时",E24)),"角色抽卡券限时",IF(ISNUMBER(SEARCH("专武抽卡券限时",E24)),"专武抽卡券限时",IF(ISNUMBER(SEARCH("角色抽卡券",E24)),"角色抽卡券普通",IF(ISNUMBER(SEARCH("专武抽卡券",E24)),"专武抽卡券普通",""))))) | G24: ='7日任务'!J63 -> 2 | H24: =IF(F24="",0,IF(F24="钻石",G24,G24*150)) -> 0
A25: 7日任务 | B25: 任务奖励 | C25: 7日任务 | D25: H65/I65 | E25: ='7日任务'!I75 -> 体力药 | F25: =IF(E25="钻石","钻石",IF(ISNUMBER(SEARCH("角色抽卡券限时",E25)),"角色抽卡券限时",IF(ISNUMBER(SEARCH("专武抽卡券限时",E25)),"专武抽卡券限时",IF(ISNUMBER(SEARCH("角色抽卡券",E25)),"角色抽卡券普通",IF(ISNUMBER(SEARCH("专武抽卡券",E25)),"专武抽卡券普通",""))))) | G25: ='7日任务'!J75 -> 2 | H25: =IF(F25="",0,IF(F25="钻石",G25,G25*150)) -> 0
A26: 7日任务 | B26: 任务奖励 | C26: 7日任务 | D26: H75/I75 | E26: ='7日任务'!I87 -> 体力药 | F26: =IF(E26="钻石","钻石",IF(ISNUMBER(SEARCH("角色抽卡券限时",E26)),"角色抽卡券限时",IF(ISNUMBER(SEARCH("专武抽卡券限时",E26)),"专武抽卡券限时",IF(ISNUMBER(SEARCH("角色抽卡券",E26)),"角色抽卡券普通",IF(ISNUMBER(SEARCH("专武抽卡券",E26)),"专武抽卡券普通",""))))) | G26: ='7日任务'!J87 -> 2 | H26: =IF(F26="",0,IF(F26="钻石",G26,G26*150)) -> 0
A27: 7日任务 | B27: 阶段奖励 | C27: 7日任务 | D27: B91/C91 | E27: ='7日任务'!B105 -> 角色抽卡券普通 | F27: =IF(E27="钻石","钻石",IF(ISNUMBER(SEARCH("角色抽卡券限时",E27)),"角色抽卡券限时",IF(ISNUMBER(SEARCH("专武抽卡券限时",E27)),"专武抽卡券限时",IF(ISNUMBER(SEARCH("角色抽卡券",E27)),"角色抽卡券普通",IF(ISNUMBER(SEARCH("专武抽卡券",E27)),"专武抽卡券普通",""))))) -> 角色抽卡券普通 | G27: ='7日任务'!C105 -> 10 | H27: =IF(F27="",0,IF(F27="钻石",G27,G27*150)) -> 1500
A28: 7日任务 | B28: 阶段奖励 | C28: 7日任务 | D28: B92/C92 | E28: ='7日任务'!B106 -> 角色抽卡券普通 | F28: =IF(E28="钻石","钻石",IF(ISNUMBER(SEARCH("角色抽卡券限时",E28)),"角色抽卡券限时",IF(ISNUMBER(SEARCH("专武抽卡券限时",E28)),"专武抽卡券限时",IF(ISNUMBER(SEARCH("角色抽卡券",E28)),"角色抽卡券普通",IF(ISNUMBER(SEARCH("专武抽卡券",E28)),"专武抽卡券普通",""))))) -> 角色抽卡券普通 | G28: ='7日任务'!C106 -> 10 | H28: =IF(F28="",0,IF(F28="钻石",G28,G28*150)) -> 1500
A29: 7日任务 | B29: 阶段奖励 | C29: 7日任务 | D29: B93/C93 | E29: ='7日任务'!B107 -> 专武抽卡券普通 | F29: =IF(E29="钻石","钻石",IF(ISNUMBER(SEARCH("角色抽卡券限时",E29)),"角色抽卡券限时",IF(ISNUMBER(SEARCH("专武抽卡券限时",E29)),"专武抽卡券限时",IF(ISNUMBER(SEARCH("角色抽卡券",E29)),"角色抽卡券普通",IF(ISNUMBER(SEARCH("专武抽卡券",E29)),"专武抽卡券普通",""))))) -> 专武抽卡券普通 | G29: ='7日任务'!C107 -> 10 | H29: =IF(F29="",0,IF(F29="钻石",G29,G29*150)) -> 1500
A30: 7日任务 | B30: 阶段奖励 | C30: 7日任务 | D30: B94/C94 | E30: ='7日任务'!B108 -> SSR角色 | F30: =IF(E30="钻石","钻石",IF(ISNUMBER(SEARCH("角色抽卡券限时",E30)),"角色抽卡券限时",IF(ISNUMBER(SEARCH("专武抽卡券限时",E30)),"专武抽卡券限时",IF(ISNUMBER(SEARCH("角色抽卡券",E30)),"角色抽卡券普通",IF(ISNUMBER(SEARCH("专武抽卡券",E30)),"专武抽卡券普通",""))))) | G30: ='7日任务'!C108 -> 1 | H30: =IF(F30="",0,IF(F30="钻石",G30,G30*150)) -> 0
A31: 7日任务 | B31: 阶段奖励 | C31: 7日任务 | D31: B96/C96 | E31: ='7日任务'!B110 -> SSR专武 | F31: =IF(E31="钻石","钻石",IF(ISNUMBER(SEARCH("角色抽卡券限时",E31)),"角色抽卡券限时",IF(ISNUMBER(SEARCH("专武抽卡券限时",E31)),"专武抽卡券限时",IF(ISNUMBER(SEARCH("角色抽卡券",E31)),"角色抽卡券普通",IF(ISNUMBER(SEARCH("专武抽卡券",E31)),"专武抽卡券普通",""))))) | G31: ='7日任务'!C110 -> 1 | H31: =IF(F31="",0,IF(F31="钻石",G31,G31*150)) -> 0
A32: 7日任务 | B32: 阶段奖励 | C32: 7日任务 | D32: D91/E91 | E32: ='7日任务'!D105 -> 钻石 | F32: =IF(E32="钻石","钻石",IF(ISNUMBER(SEARCH("角色抽卡券限时",E32)),"角色抽卡券限时",IF(ISNUMBER(SEARCH("专武抽卡券限时",E32)),"专武抽卡券限时",IF(ISNUMBER(SEARCH("角色抽卡券",E32)),"角色抽卡券普通",IF(ISNUMBER(SEARCH("专武抽卡券",E32)),"专武抽卡券普通",""))))) -> 钻石 | G32: ='7日任务'!E105 -> 500 | H32: =IF(F32="",0,IF(F32="钻石",G32,G32*150)) -> 500
A33: 7日任务 | B33: 阶段奖励 | C33: 7日任务 | D33: D92/E92 | E33: ='7日任务'!D106 -> 钻石 | F33: =IF(E33="钻石","钻石",IF(ISNUMBER(SEARCH("角色抽卡券限时",E33)),"角色抽卡券限时",IF(ISNUMBER(SEARCH("专武抽卡券限时",E33)),"专武抽卡券限时",IF(ISNUMBER(SEARCH("角色抽卡券",E33)),"角色抽卡券普通",IF(ISNUMBER(SEARCH("专武抽卡券",E33)),"专武抽卡券普通",""))))) -> 钻石 | G33: ='7日任务'!E106 -> 500 | H33: =IF(F33="",0,IF(F33="钻石",G33,G33*150)) -> 500
A34: 7日任务 | B34: 阶段奖励 | C34: 7日任务 | D34: D93/E93 | E34: ='7日任务'!D107 -> 钻石 | F34: =IF(E34="钻石","钻石",IF(ISNUMBER(SEARCH("角色抽卡券限时",E34)),"角色抽卡券限时",IF(ISNUMBER(SEARCH("专武抽卡券限时",E34)),"专武抽卡券限时",IF(ISNUMBER(SEARCH("角色抽卡券",E34)),"角色抽卡券普通",IF(ISNUMBER(SEARCH("专武抽卡券",E34)),"专武抽卡券普通",""))))) -> 钻石 | G34: ='7日任务'!E107 -> 500 | H34: =IF(F34="",0,IF(F34="钻石",G34,G34*150)) -> 500
A35: 7日任务 | B35: 阶段奖励 | C35: 7日任务 | D35: D94/E94 | E35: ='7日任务'!D108 -> 0 | F35: =IF(E35="钻石","钻石",IF(ISNUMBER(SEARCH("角色抽卡券限时",E35)),"角色抽卡券限时",IF(ISNUMBER(SEARCH("专武抽卡券限时",E35)),"专武抽卡券限时",IF(ISNUMBER(SEARCH("角色抽卡券",E35)),"角色抽卡券普通",IF(ISNUMBER(SEARCH("专武抽卡券",E35)),"专武抽卡券普通",""))))) | G35: ='7日任务'!E108 -> 0 | H35: =IF(F35="",0,IF(F35="钻石",G35,G35*150)) -> 0
A36: 7日任务 | B36: 阶段奖励 | C36: 7日任务 | D36: D96/E96 | E36: ='7日任务'!D110 -> 0 | F36: =IF(E36="钻石","钻石",IF(ISNUMBER(SEARCH("角色抽卡券限时",E36)),"角色抽卡券限时",IF(ISNUMBER(SEARCH("专武抽卡券限时",E36)),"专武抽卡券限时",IF(ISNUMBER(SEARCH("角色抽卡券",E36)),"角色抽卡券普通",IF(ISNUMBER(SEARCH("专武抽卡券",E36)),"专武抽卡券普通",""))))) | G36: ='7日任务'!E110 -> 0 | H36: =IF(F36="",0,IF(F36="钻石",G36,G36*150)) -> 0
A37: 主线副本 | B37: 普通通关奖励 | C37: 配置页-主线副本 | D37: S10/U10 | E37: ='配置页-主线副本'!T10 -> 金币 | F37: =IF(E37="钻石","钻石",IF(ISNUMBER(SEARCH("角色抽卡券限时",E37)),"角色抽卡券限时",IF(ISNUMBER(SEARCH("专武抽卡券限时",E37)),"专武抽卡券限时",IF(ISNUMBER(SEARCH("角色抽卡券",E37)),"角色抽卡券普通",IF(ISNUMBER(SEARCH("专武抽卡券",E37)),"专武抽卡券普通",""))))) | G37: ='配置页-主线副本'!#REF! -> #REF! | H37: =IF(F37="",0,IF(F37="钻石",G37,G37*150)) -> 0
A38: 主线副本 | B38: 普通通关奖励 | C38: 配置页-主线副本 | D38: S101/U101 | E38: ='配置页-主线副本'!T101 -> 角色经验中 | F38: =IF(E38="钻石","钻石",IF(ISNUMBER(SEARCH("角色抽卡券限时",E38)),"角色抽卡券限时",IF(ISNUMBER(SEARCH("专武抽卡券限时",E38)),"专武抽卡券限时",IF(ISNUMBER(SEARCH("角色抽卡券",E38)),"角色抽卡券普通",IF(ISNUMBER(SEARCH("专武抽卡券",E38)),"专武抽卡券普通",""))))) | G38: ='配置页-主线副本'!#REF! -> #REF! | H38: =IF(F38="",0,IF(F38="钻石",G38,G38*150)) -> 0
A39: 主线副本 | B39: 普通通关奖励 | C39: 配置页-主线副本 | D39: S105/U105 | E39: ='配置页-主线副本'!T105 -> 星盘中级道具辅2 | F39: =IF(E39="钻石","钻石",IF(ISNUMBER(SEARCH("角色抽卡券限时",E39)),"角色抽卡券限时",IF(ISNUMBER(SEARCH("专武抽卡券限时",E39)),"专武抽卡券限时",IF(ISNUMBER(SEARCH("角色抽卡券",E39)),"角色抽卡券普通",IF(ISNUMBER(SEARCH("专武抽卡券",E39)),"专武抽卡券普通",""))))) | G39: ='配置页-主线副本'!#REF! -> #REF! | H39: =IF(F39="",0,IF(F39="钻石",G39,G39*150)) -> 0
A40: 主线副本 | B40: 普通通关奖励 | C40: 配置页-主线副本 | D40: S109/U109 | E40: ='配置页-主线副本'!T109 -> 金币 | F40: =IF(E40="钻石","钻石",IF(ISNUMBER(SEARCH("角色抽卡券限时",E40)),"角色抽卡券限时",IF(ISNUMBER(SEARCH("专武抽卡券限时",E40)),"专武抽卡券限时",IF(ISNUMBER(SEARCH("角色抽卡券",E40)),"角色抽卡券普通",IF(ISNUMBER(SEARCH("专武抽卡券",E40)),"专武抽卡券普通",""))))) | G40: ='配置页-主线副本'!#REF! -> #REF! | H40: =IF(F40="",0,IF(F40="钻石",G40,G40*150)) -> 0
A41: 主线副本 | B41: 普通通关奖励 | C41: 配置页-主线副本 | D41: S113/U113 | E41: ='配置页-主线副本'!T113 -> 角色经验中 | F41: =IF(E41="钻石","钻石",IF(ISNUMBER(SEARCH("角色抽卡券限时",E41)),"角色抽卡券限时",IF(ISNUMBER(SEARCH("专武抽卡券限时",E41)),"专武抽卡券限时",IF(ISNUMBER(SEARCH("角色抽卡券",E41)),"角色抽卡券普通",IF(ISNUMBER(SEARCH("专武抽卡券",E41)),"专武抽卡券普通",""))))) | G41: ='配置页-主线副本'!#REF! -> #REF! | H41: =IF(F41="",0,IF(F41="钻石",G41,G41*150)) -> 0
A42: 主线副本 | B42: 普通通关奖励 | C42: 配置页-主线副本 | D42: S117/U117 | E42: ='配置页-主线副本'!T117 -> 角色升阶材料中攻 | F42: =IF(E42="钻石","钻石",IF(ISNUMBER(SEARCH("角色抽卡券限时",E42)),"角色抽卡券限时",IF(ISNUMBER(SEARCH("专武抽卡券限时",E42)),"专武抽卡券限时",IF(ISNUMBER(SEARCH("角色抽卡券",E42)),"角色抽卡券普通",IF(ISNUMBER(SEARCH("专武抽卡券",E42)),"专武抽卡券普通",""))))) | G42: ='配置页-主线副本'!#REF! -> #REF! | H42: =IF(F42="",0,IF(F42="钻石",G42,G42*150)) -> 0
...

Sheet 道具定价
B2: 道具备注 | C2: 道具 | D2: 道具id | E2: 道具定价(rmb) | F2: 道具定价(钻石)
A3: 外观道具 | C3: 无 | D3: 0 | E3: 0 | F3: 0
C4: 头像框 | D4: 0 | E4: 0 | F4: 0
C5: 头像 | D5: 0 | E5: 0 | F5: 0
C6: 时装 | D6: 0 | E6: 68 | F6: =E6*10 -> 680
A9: 通用资源 | C9: 体力 | D9: 3 | E9: 0.4 | F9: =E9*10 -> 4 | H9: 体力回复6分钟/1点，一天240点
C10: 钻石 | D10: 2 | E10: 0.1 | F10: =E10*10 -> 1
C11: 金币 | D11: 1 | E11: 0.0001 | F11: =E11*10 -> 0.001
C12: 玩家经验 | D12: 4 | E12: 0.04 | F12: =E12*10 -> 0.4
C13: 角色抽卡券普通 | D13: 106 | E13: 15 | F13: =E13*10 -> 150
C14: 专武抽卡券普通 | D14: 107 | E14: 15 | F14: =E14*10 -> 150
C15: 抽卡大代币 | D15: 21 | E15: 1.5 | F15: =E15*10 -> 15
C16: 抽卡小代币 | D16: 22 | E16: 0.15 | F16: =E16*10 -> 1.5
C17: 爬塔代币 | D17: 27 | E17: 0.1 | F17: =E17*10 -> 1
C18: 体力药 | D18: 105 | E18: =E9*60 -> 24 | F18: =F9*60 -> 240
C19: 竞技场代币 | D19: 19 | E19: 1 | F19: =E19*10 -> 10
C20: 角色抽卡券限时 | D20: 111 | E20: 15 | F20: =E20*10 -> 150
C21: 专武抽卡券限时 | D21: 112 | E21: 15 | F21: =E21*10 -> 150
A22: 公会 | C22: 公会个人代币 | D22: 15 | E22: 0.1 | F22: =E22*10 -> 1
C23: 公会集体代币 | D23: 14 | E23: 0.1 | F23: =E23*10 -> 1
A25: 角色升级升阶 | C25: 角色经验 | E25: 0.0001 | F25: =E25*10 -> 0.001
C26: 角色经验低500 | D26: 100 | E26: =E25*500 -> 0.05 | F26: =E26*10 -> 0.5
C27: 角色经验中2000 | D27: 101 | E27: =E25*2000 -> 0.2 | F27: =E27*10 -> 2
C28: 角色经验高10000 | D28: 102 | E28: =E25*10000 -> 1 | F28: =E28*10 -> 10
C30: 角色万能升阶材料 | E30: =E31 -> 0.4 | F30: =E30*10 -> 4
B31: 可能根据职业 分成多个类型 | C31: 角色升阶材料低 | E31: 0.4 | F31: =E31*10 -> 4
C32: 角色升阶材料中 | E32: =E31*3 -> 1.2 | F32: =E32*10 -> 12
C33: 角色升阶材料高 | E33: =E32*3 -> 3.6 | F33: =E33*10 -> 36
C34: 角色升阶材料低攻击 | D34: 1001 | E34: =E31 -> 0.4 | F34: =E34*10 -> 4
C35: 角色升阶材料中攻击 | D35: 1004 | E35: =E32 -> 1.2 | F35: =E35*10 -> 12
C36: 角色升阶材料高攻击 | D36: 1007 | E36: =E33 -> 3.6 | F36: =E36*10 -> 36
C37: 角色升阶材料低防御 | D37: 1002 | E37: =E34 -> 0.4 | F37: =E37*10 -> 4
C38: 角色升阶材料中防御 | D38: 1005 | E38: =E35 -> 1.2 | F38: =E38*10 -> 12
C39: 角色升阶材料高防御 | D39: 1008 | E39: =E36 -> 3.6 | F39: =E39*10 -> 36
C40: 角色升阶材料低辅助 | D40: 1003 | E40: =E37 -> 0.4 | F40: =E40*10 -> 4
C41: 角色升阶材料中辅助 | D41: 1006 | E41: =E38 -> 1.2 | F41: =E41*10 -> 12
C42: 角色升阶材料高辅助 | D42: 1009 | E42: =E39 -> 3.6 | F42: =E42*10 -> 36
C43: SSR角色 | E43: 750 | F43: =E43*10 -> 7500
C44: SR角色 | E44: 50 | F44: =E44*10 -> 500
C45: R角色 | E45: 9 | F45: =E45*10 -> 90
...

Sheet 角色、专武、旅券掉落池
B2: 角色掉落池 | F2: 专武掉落池 | J2: 映射装备掉落池 | N2: 旅券掉落池
B3: 武将名称 | C3: 稀有度 | D3: 武将id | F3: 武将id | G3: 武将名称 | H3: 稀有度 | J3: 映射装备id | K3: 映射装备名称 | L3: 映射装备品质 | N3: 旅券id | O3: 旅券套装id | P3: 旅券名称 | Q3: 旅券部位 | R3: 旅券品质
B4: 塔拉夏 | C4: S | D4: 1003 | F4: 52001 | G4: 秩序崩解杖 | H4: S | J4: 80001 | K4: 初级魂息喷射器 | L4: 蓝 | N4: 60001 | O4: 1 | P4: 追逐天性 | Q4: 1 | R4: 蓝
B5: 陈单单 | C5: S | D5: 1005 | F5: 52002 | G5: 热寂宣告者 | H5: S | J5: 80002 | K5: 中级魂息喷射器 | L5: 紫 | N5: 60002 | O5: 1 | P5: 追逐天性 | Q5: 2 | R5: 蓝
B6: 莉莉娅 | C6: S | D6: 1006 | F6: 52003 | G6: 永恒观测甲 | H6: S | J6: 80003 | K6: 高级魂息喷射器 | L6: 金 | N6: 60003 | O6: 1 | P6: 追逐天性 | Q6: 3 | R6: 蓝
B7: 萨萨莉安 | C7: S | D7: 1007 | F7: 52004 | G7: 纯净界域盾 | H7: S | J7: 80004 | K7: 初级纳米逆变器 | L7: 蓝 | N7: 60004 | O7: 1 | P7: 追逐天性 | Q7: 4 | R7: 蓝
B8: 伊戈尔 | C8: S | D8: 1017 | F8: 52005 | G8: 命运纺锤 | H8: S | J8: 80005 | K8: 中级纳米逆变器 | L8: 紫 | N8: 60005 | O8: 1 | P8: 追逐天性 | Q8: 5 | R8: 蓝
B9: 约瑟夫 | C9: S | D9: 1009 | F9: 52006 | G9: 时光重逢契 | H9: S | J9: 80006 | K9: 高级纳米逆变器 | L9: 金 | N9: 60006 | O9: 1 | P9: 追逐天性 | Q9: 6 | R9: 蓝
B10: 夏提拉 | C10: S | D10: 1013 | F10: 52007 | G10: 虚空裂界刃 | H10: A | J10: 80007 | K10: 初级风暴射线切割器 | L10: 蓝 | N10: 60007 | O10: 1 | P10: 追逐天性 | Q10: 1 | R10: 紫
B11: 雷诺 | C11: S | D11: 1016 | F11: 52008 | G11: 永寂追猎弓 | H11: A | J11: 80008 | K11: 中级风暴射线切割器 | L11: 紫 | N11: 60008 | O11: 1 | P11: 追逐天性 | Q11: 2 | R11: 紫
B12: 瞳 | C12: S | D12: 1032 | F12: 52009 | G12: 偏折棱光盾 | H12: A | J12: 80009 | K12: 高级风暴射线切割器 | L12: 金 | N12: 60009 | O12: 1 | P12: 追逐天性 | Q12: 3 | R12: 紫
B13: 美第奇 | C13: S | D13: 1033 | F13: 52010 | G13: 归航引路铠 | H13: A | J13: 80010 | K13: 初级旋转机枪 | L13: 蓝 | N13: 60010 | O13: 1 | P13: 追逐天性 | Q13: 4 | R13: 紫
B14: 零号 | C14: S | D14: 1034 | F14: 52011 | G14: 群星导引图 | H14: A | J14: 80011 | K14: 中级旋转机枪 | L14: 紫 | N14: 60011 | O14: 1 | P14: 追逐天性 | Q14: 5 | R14: 紫
B15: 薇莱特 | C15: S | D15: 1028 | F15: 52012 | G15: 灵脉同调仪 | H15: A | J15: 80012 | K15: 高级旋转机枪 | L15: 金 | N15: 60012 | O15: 1 | P15: 追逐天性 | Q15: 6 | R15: 紫
... B21: 陈双双 | C21: A | D21: 1011 | F21: 52018 | G21: 潮汐调和铃 | H21: B | J21: 80018 | K21: 高级赤红脉冲手炮 | L21: 金 | N21: 60018 | O21: 1 | P21: 追逐天性 | Q21: 6 | R21: 金
B22: 克莉丝汀 | C22: A | D22: 1014 | J22: 80019 | K22: 初级圣光调和杖 | L22: 蓝 | N22: 60019 | O22: 1 | P22: 追逐天性 | Q22: 1 | R22: 红
B23: 阿莱克西娅 | C23: A | D23: 1015 | J23: 80020 | K23: 中级圣光调和杖 | L23: 紫 | N23: 60020 | O23: 1 | P23: 追逐天性 | Q23: 2 | R23: 红
B24: 艾德琳 | C24: A | D24: 1012 | J24: 80021 | K24: 高级圣光调和杖 | L24: 金 | N24: 60021 | O24: 1 | P24: 追逐天性 | Q24: 3 | R24: 红
B25: 薇 | C25: A | D25: 1008 | J25: 80022 | K25: 初级灾厄刻印权杖 | L25: 蓝 | N25: 60022 | O25: 1 | P25: 追逐天性 | Q25: 4 | R25: 红
B26: 埃莉诺 | C26: A | D26: 1018 | J26: 80023 | K26: 中级灾厄刻印权杖 | L26: 紫 | N26: 60023 | O26: 1 | P26: 追逐天性 | Q26: 5 | R26: 红
B27: 乔一 | C27: A | D27: 1026 | J27: 80024 | K27: 高级灾厄刻印权杖 | L27: 金 | N27: 60024 | O27: 1 | P27: 追逐天性 | Q27: 6 | R27: 红
B28: 塞拉菲娜 | C28: A | D28: 1028 | J28: 80025 | K28: 初级虚空回响法杖 | L28: 蓝 | N28: 60025 | O28: 2 | P28: 翡冷翠郊野牧场 | Q28: 1 | R28: 蓝
B29: 桑塔 | C29: A | D29: 1031 | J29: 80026 | K29: 中级虚空回响法杖 | L29: 紫 | N29: 60026 | O29: 2 | P29: 翡冷翠郊野牧场 | Q29: 2 | R29: 蓝
B30: 卡斯帕 | C30: B | D30: 1020 | J30: 80027 | K30: 高级虚空回响法杖 | L30: 金 | N30: 60027 | O30: 2 | P30: 翡冷翠郊野牧场 | Q30: 3 | R30: 蓝
B31: 梅梅 | C31: B | D31: 1021 | J31: 80028 | K31: 初级隔热战术头盔 | L31: 蓝 | N31: 60028 | O31: 2 | P31: 翡冷翠郊野牧场 | Q31: 4 | R31: 蓝
B32: 马克 | C32: B | D32: 1023 | J32: 80029 | K32: 中级隔热战术头盔 | L32: 紫 | N32: 60029 | O32: 2 | P32: 翡冷翠郊野牧场 | Q32: 5 | R32: 蓝
B33: 卡薇 | C33: B | D33: 1024 | J33: 80030 | K33: 高级隔热战术头盔 | L33: 金 | N33: 60030 | O33: 2 | P33: 翡冷翠郊野牧场 | Q33: 6 | R33: 蓝
... B37: 梅林 | C37: B | D37: 1022 | J37: 80034 | K37: 初级共生头铠 | L37: 蓝 | N37: 60034 | O37: 2 | P37: 翡冷翠郊野牧场 | Q37: 4 | R37: 紫
J38: 80035 | K38: 中级共生头铠 | L38: 紫 | N38: 60035 | O38: 2 | P38: 翡冷翠郊野牧场 | Q38: 5 | R38: 紫
J39: 80036 | K39: 高级共生头铠 | L39: 金 | N39: 60036 | O39: 2 | P39: 翡冷翠郊野牧场 | Q39: 6 | R39: 紫
J40: 80037 | K40: 初级神经链接盔 | L40: 蓝 | N40: 60037 | O40: 2 | P40: 翡冷翠郊野牧场 | Q40: 1 | R40: 金
J41: 80038 | K41: 中级神经链接盔 | L41: 紫 | N41: 60038 | O41: 2 | P41: 翡冷翠郊野牧场 | Q41: 2 | R41: 金
J42: 80039 | K42: 高级神经链接盔 | L42: 金 | N42: 60039 | O42: 2 | P42: 翡冷翠郊野牧场 | Q42: 3 | R42: 金
J43: 80040 | K43: 初级修士法帽 | L43: 蓝 | N43: 60040 | O43: 2 | P43: 翡冷翠郊野牧场 | Q43: 4 | R43: 金
J44: 80041 | K44: 中级修士法帽 | L44: 紫 | N44: 60041 | O44: 2 | P44: 翡冷翠郊野牧场 | Q44: 5 | R44: 金
J45: 80042 | K45: 高级修士法帽 | L45: 金 | N45: 60042 | O45: 2 | P45: 翡冷翠郊野牧场 | Q45: 6 | R45: 金
J46: 80043 | K46: 初级祷言法帽 | L46: 蓝 | N46: 60043 | O46: 2 | P46: 翡冷翠郊野牧场 | Q46: 1 | R46: 红
J47: 80044 | K47: 中级祷言法帽 | L47: 紫 | N47: 60044 | O47: 2 | P47: 翡冷翠郊野牧场 | Q47: 2 | R47: 红
J48: 80045 | K48: 高级祷言法帽 | L48: 金 | N48: 60045 | O48: 2 | P48: 翡冷翠郊野牧场 | Q48: 3 | R48: 红
J49: 80046 | K49: 初级动力装甲 | L49: 蓝 | N49: 60046 | O49: 2 | P49: 翡冷翠郊野牧场 | Q49: 4 | R49: 红
...

Sheet 角色养成汇总
B2: 模块 | C2: 所需金币 | D2: 其他材料价值
B3: 角色升级 | C3: =角色升级!L5 -> 961250 | D3: =角色升级!M4 -> 1922.5 | F3: 1 | G3: 点体力 | H3: = | I3: 4000 | J3: 金币 | K3: = | L3: 4 | M3: 钻石
B4: 角色突破 | C4: =角色升阶!H8 -> 440000 | D4: =角色升阶!F8 -> 672
B5: 角色升星 | C5: 0
B6: 专武 | C6: =专武!N3 -> 263450 | D6: =专武!O2+专武!P11 -> 1989.25
B7: 角色星盘 | C7: =角色星盘!M28 -> 1655000 | D7: =角色星盘!O28 -> 5270
B8: 旅券 | C8: =旅券!P5 -> 2400000 | D8: =旅券!Q4 -> 2400
C9: =SUM(C3:C8) -> 5719700
B10: 单角色汇总 | C10: =C9*道具定价!F11 -> 5719.7 | D10: =SUM(D3:D8) -> 12253.75 | E10: =D10+C10 -> 17973.45 | F10: =E10/4 -> 4493.3625 | G10: =F10/240 -> 18.722344
G11: =D10/240/4 -> 12.764323
B13: 主角装备 | C13: =映射装备!M24 -> 4212808 | D13: =映射装备!M23*道具定价!F144 -> 42128.08
B14: 主角装备铭文

Sheet 角色升级
B2: 等级上限 | C2: 60
J4: 单角色总经验 | L4: =MAX(E7:E76) -> 1922500 | M4: =L4*道具定价!F25 -> 1922.5 | O4: 500
J5: 单角色总金币 | L5: =MAX(G7:G76) -> 961250 | O5: 1000
B6: 等级 | C6: 相对上级提升 | D6: 每级所需经验 | E6: 总经验 | F6: 每级所需金币 | G6: 总金币 | H6: 进度 | J6: 总坑深（钻石） | L6: =L4*道具定价!F25+L5*道具定价!F11 -> 2883.75 | O6: 2000
B7: {=_xlfn.SEQUENCE(C2,1,1,1)} -> 1 | D7: 100 | E7: =SUM($D$7:D7) -> 100 | F7: =ROUND(D7*0.5,0) -> 50 | G7: =SUM($F$7:F7) -> 50 | J7: 100 | O7: 5000
B8: 2 | C8: 50 | D8: =D7+C8 -> 150 | E8: =SUM($D$7:D8) -> 250 | F8: =ROUND(D8*0.5,0) -> 75 | G8: =SUM($F$7:F8) -> 125
B9: 3 | C9: 50 | D9: =D8+C9 -> 200 | E9: =SUM($D$7:D9) -> 450 | F9: =ROUND(D9*0.5,0) -> 100 | G9: =SUM($F$7:F9) -> 225
B10: 4 | C10: 50 | D10: =D9+C10 -> 250 | E10: =SUM($D$7:D10) -> 700 | F10: =ROUND(D10*0.5,0) -> 125 | G10: =SUM($F$7:F10) -> 350
B11: 5 | C11: 50 | D11: =D10+C11 -> 300 | E11: =SUM($D$7:D11) -> 1000 | F11: =ROUND(D11*0.5,0) -> 150 | G11: =SUM($F$7:F11) -> 500
B12: 6 | C12: 100 | D12: =D11+C12 -> 400 | E12: =SUM($D$7:D12) -> 1400 | F12: =ROUND(D12*0.5,0) -> 200 | G12: =SUM($F$7:F12) -> 700
B13: 7 | C13: 100 | D13: =D12+C13 -> 500 | E13: =SUM($D$7:D13) -> 1900 | F13: =ROUND(D13*0.5,0) -> 250 | G13: =SUM($F$7:F13) -> 950
B14: 8 | C14: 100 | D14: =D13+C14 -> 600 | E14: =SUM($D$7:D14) -> 2500 | F14: =ROUND(D14*0.5,0) -> 300 | G14: =SUM($F$7:F14) -> 1250
B15: 9 | C15: 100 | D15: =D14+C15 -> 700 | E15: =SUM($D$7:D15) -> 3200 | F15: =ROUND(D15*0.5,0) -> 350 | G15: =SUM($F$7:F15) -> 1600
B16: 10 | C16: 100 | D16: =D15+C16 -> 800 | E16: =SUM($D$7:D16) -> 4000 | F16: =ROUND(D16*0.5,0) -> 400 | G16: =SUM($F$7:F16) -> 2000
B17: 11 | C17: 200 | D17: =D16+C17 -> 1000 | E17: =SUM($D$7:D17) -> 5000 | F17: =ROUND(D17*0.5,0) -> 500 | G17: =SUM($F$7:F17) -> 2500
B18: 12 | C18: 200 | D18: =D17+C18 -> 1200 | E18: =SUM($D$7:D18) -> 6200 | F18: =ROUND(D18*0.5,0) -> 600 | G18: =SUM($F$7:F18) -> 3100
B19: 13 | C19: 200 | D19: =D18+C19 -> 1400 | E19: =SUM($D$7:D19) -> 7600 | F19: =ROUND(D19*0.5,0) -> 700 | G19: =SUM($F$7:F19) -> 3800
... B66: 60 | C66: 9000 | D66: =D65+C66 -> 156800 | E66: =SUM($D$7:D66) -> 1922500 | F66: =ROUND(D66*0.5,0) -> 78400 | G66: =SUM($F$7:F66) -> 961250

Sheet 角色升阶
B3: 突破等级 | C3: 突破次数 | D3: 消耗类型1 | E3: 消耗数量1 | F3: 消耗价值1 | G3: 消耗类型2 | H3: 消耗数量2 | I3: 消耗价值2 | J3: 消耗价值总 | K3: 消耗价值总 | N3: 消耗价值总 | O3: =SUM(J4:J7) -> 1112
B4: 20 | C4: 1 | D4: 角色升阶材料低 | E4: 6 | F4: =VLOOKUP(D4,道具定价!$C:$F,4,0)*E4 -> 24 | G4: 金币 | H4: 20000 | I4: =VLOOKUP(G4,道具定价!$C:$F,4,0)*H4 -> 20 | J4: =I4+F4 -> 44
B5: 30 | C5: 2 | D5: 角色升阶材料中 | E5: 6 | F5: =VLOOKUP(D5,道具定价!$C:$F,4,0)*E5 -> 72 | G5: 金币 | H5: 60000 | I5: =VLOOKUP(G5,道具定价!$C:$F,4,0)*H5 -> 60 | J5: =I5+F5 -> 132
B6: 40 | C6: 3 | D6: 角色升阶材料中 | E6: 12 | F6: =VLOOKUP(D6,道具定价!$C:$F,4,0)*E6 -> 144 | G6: 金币 | H6: 120000 | I6: =VLOOKUP(G6,道具定价!$C:$F,4,0)*H6 -> 120 | J6: =I6+F6 -> 264
B7: 50 | C7: 4 | D7: 角色升阶材料高 | E7: 12 | F7: =VLOOKUP(D7,道具定价!$C:$F,4,0)*E7 -> 432 | G7: 金币 | H7: 240000 | I7: =VLOOKUP(G7,道具定价!$C:$F,4,0)*H7 -> 240 | J7: =I7+F7 -> 672
F8: =SUM(F4:F7) -> 672 | H8: =SUM(H4:H7) -> 440000

Sheet 角色升星、角色抽卡
H2: 基础概率 | I2: 实际概率 | K2: 首次抽到 | L2: 非首次抽到 | N2: 价值 | O2: 未抽满单抽数量 | P2: 单抽数量
B3: 角色星级 | C3: 升到下一星级需要角色 | F3: 抽卡概率设定 | G3: SSR | H3: 0.01 | I3: =1/G10 -> 0.019795656 | J3: 抽卡大代币 | K3: 2 | L3: 10 | N3: =I3*道具定价!$F$15*L3 -> 2.9693484 | O3: =L3*I3 -> 0.19795656 | P3: =L3*I3 -> 0.19795656
B4: 0 | C4: 1 | G4: SR | H4: 0.1 | I4: =K28*H4/(H3+H4) -> 0.14531023 | J4: 抽卡大代币 | K4: 1 | L4: 3 | N4: =I4*道具定价!$F$16*L4 -> 0.65389603 | O4: =I4*L4 -> 0.43593069 | P4: =L4*I4 -> 0.43593069
B5: 1 | C5: 1 | G5: R | H5: =1-H4-H3 -> 0.89 | I5: =1-I4-I3 -> 0.83489412 | J5: 抽卡小代币 | K5: 3 | L5: 6 | N5: =I5*道具定价!$F$17*L5 -> 5.0093647 | O5: =I5*L5 -> 5.0093647 | P5: =L5*I5 -> 5.0093647
B6: 2 | C6: 1 | N6: =SUM(N3:N5) -> 8.6326091
B7: 3 | C7: 1 | F7: 十连保底1个SR
B8: 4 | C8: 1 | F8: 单抽定价 | G8: 150 | H8: 钻石 | N8: 单抽代币数量 | O8: 前期 | P8: 后期 | Q8: 大后期
B9: 5 | C9: 1 | F9: 保底次数 | G9: 70 | N9: 抽卡大代币 | O9: =O4 -> 0.43593069 | P9: =P4+O3 -> 0.63388724 | Q9: =P4+P3 -> 0.63388724
B10: 6 | C10: 0 | F10: 期望次数 | G10: {=SUMPRODUCT(_xlfn.ANCHORARRAY(F16),G16:G85)} -> 50.516134 | N10: 抽卡小代币 | O10: =P5 -> 5.0093647 | P10: =P5 -> 5.0093647 | Q10: =P5 -> 5.0093647
F11: SSR角色价值 | G11: =G8*G10 -> 7577.4201 | H11: 钻石
F12: SR角色价值 | G12: =G11/H4*H3 -> 757.74201 | H12: 钻石
F13: R角色价值 | G13: =G11/H5*H3 -> 85.139552 | H13: 钻石 | J13: SR/SSR10连概率
F15: 抽卡次数 | G15: 概率 | H15: 不出概率 | J15: 抽卡次数 | K15: 概率 | L15: 不出概率
F16: {=_xlfn.SEQUENCE(G9,1,1,1)} -> 1 | G16: =$H$3 -> 0.01 | H16: =1-G16 -> 0.99 | J16: 1 | K16: =H3+H4 -> 0.11 | L16: =1-K16 -> 0.89
F17: 2 | G17: =$H$3*H16 -> 0.0099 | H17: =POWER(1-$H$3,F17) -> 0.9801 | J17: 2 | K17: =$K$16*L16 -> 0.0979 | L17: =POWER(1-K$16,J17) -> 0.7921
F18: 3 | G18: =$H$3*H17 -> 0.009801 | H18: =POWER(1-$H$3,F18) -> 0.970299 | J18: 3 | K18: =$K$16*L17 -> 0.087131 | L18: =POWER(1-K$16,J18) -> 0.704969
F19: 4 | G19: =$H$3*H18 -> 0.00970299 | H19: =POWER(1-$H$3,F19) -> 0.96059601 | J19: 4 | K19: =$K$16*L18 -> 0.07754659 | L19: =POWER(1-K$16,J19) -> 0.62742241
F20: 5 | G20: =$H$3*H19 -> 0.0096059601 | H20: =POWER(1-$H$3,F20) -> 0.95099005 | J20: 5 | K20: =$K$16*L19 -> 0.069016465 | L20: =POWER(1-K$16,J20) -> 0.55840594
F21: 6 | G21: =$H$3*H20 -> 0.0095099005 | H21: =POWER(1-$H$3,F21) -> 0.94148015 | J21: 6 | K21: =$K$16*L20 -> 0.061424654 | L21: =POWER(1-K$16,J21) -> 0.49698129
F22: 7 | G22: =$H$3*H21 -> 0.0094148015 | H22: =POWER(1-$H$3,F22) -> 0.93206535 | J22: 7 | K22: =$K$16*L21 -> 0.054667942 | L22: =POWER(1-K$16,J22) -> 0.44231335 | N22: 抽卡额外货币规则
F23: 8 | G23: =$H$3*H22 -> 0.0093206535 | H23: =POWER(1-$H$3,F23) -> 0.92274469 | J23: 8 | K23: =$K$16*L22 -> 0.048654468 | L23: =POWER(1-K$16,J23) -> 0.39365888 | N23: 抽到角色时，根据已经抽到的角色数量和角色品质给予一定的额外货币（可配置）
F24: 9 | G24: =$H$3*H23 -> 0.0092274469 | H24: =POWER(1-$H$3,F24) -> 0.91351725 | J24: 9 | K24: =$K$16*L23 -> 0.043302477 | L24: =POWER(1-K$16,J24) -> 0.3503564
F25: 10 | G25: =$H$3*H24 -> 0.0091351725 | H25: =POWER(1-$H$3,F25) -> 0.90438208 | J25: 10 | K25: =1-SUM(K16:K24) -> 0.3503564 | N25: 该额外货币可以在抽卡商店兑换道具，主要兑换的内容是部分养成材料和抽卡道具（限量）
F26: 11 | G26: =$H$3*H25 -> 0.0090438208 | H26: =POWER(1-$H$3,F26) -> 0.89533825
F27: 12 | G27: =$H$3*H26 -> 0.0089533825 | H27: =POWER(1-$H$3,F27) -> 0.88638487 | K27: {=SUMPRODUCT(J16:J25,K16:K25)} -> 6.2562073
F28: 13 | G28: =$H$3*H27 -> 0.0088638487 | H28: =POWER(1-$H$3,F28) -> 0.87752102 | K28: =1/K27 -> 0.15984125
F29: 14 | G29: =$H$3*H28 -> 0.0087752102 | H29: =POWER(1-$H$3,F29) -> 0.86874581
F30: 15 | G30: =$H$3*H29 -> 0.0086874581 | H30: =POWER(1-$H$3,F30) -> 0.86005835
F31: 16 | G31: =$H$3*H30 -> 0.0086005835 | H31: =POWER(1-$H$3,F31) -> 0.85145777
F32: 17 | G32: =$H$3*H31 -> 0.0085145777 | H32: =POWER(1-$H$3,F32) -> 0.84294319
F33: 18 | G33: =$H$3*H32 -> 0.0084294319 | H33: =POWER(1-$H$3,F33) -> 0.83451376
F34: 19 | G34: =$H$3*H33 -> 0.0083451376 | H34: =POWER(1-$H$3,F34) -> 0.82616862
F35: 20 | G35: =$H$3*H34 -> 0.0082616862 | H35: =POWER(1-$H$3,F35) -> 0.81790694
F36: 21 | G36: =$H$3*H35 -> 0.0081790694 | H36: =POWER(1-$H$3,F36) -> 0.80972787
F37: 22 | G37: =$H$3*H36 -> 0.0080972787 | H37: =POWER(1-$H$3,F37) -> 0.80163059
F38: 23 | G38: =$H$3*H37 -> 0.0080163059 | H38: =POWER(1-$H$3,F38) -> 0.79361428
F39: 24 | G39: =$H$3*H38 -> 0.0079361428 | H39: =POWER(1-$H$3,F39) -> 0.78567814
F40: 25 | G40: =$H$3*H39 -> 0.0078567814 | H40: =POWER(1-$H$3,F40) -> 0.77782136
... F84: 69 | G84: =$H$3*H83 -> 0.0050488589 | H84: =POWER(1-$H$3,F84) -> 0.49983703
F85: 70 | G85: =1-SUM(G16:G84) -> 0.49983703 | H85: =POWER(1-$H$3,F85) -> 0.49483866

Sheet 专武升星、抽卡
D2: 基础概率 | E2: 实际概率 | G2: 首次抽到 | H2: 非首次抽到 | J2: 价值 | K2: 未抽满单抽数量 | L2: 单抽数量
B3: 抽卡概率设定 | C3: SSR | D3: 0.02 | E3: =1/C13 -> 0.028471905 | F3: 抽卡大代币 | G3: 2 | H3: 6 | J3: =E3*道具定价!$F$15*H3 -> 2.5624714 | K3: =H3*E3 -> 0.17083143 | L3: =H3*E3 -> 0.17083143
C4: SR | D4: 0.13 | E4: =G38*D4/(D3+D4) -> 0.16186758 | F4: 抽卡大代币 | G4: 1 | H4: 2 | J4: =E4*道具定价!$F$16*H4 -> 0.48560275 | K4: =E4*H4 -> 0.32373517 | L4: =H4*E4 -> 0.32373517
C5: R | D5: =1-D4-D3 -> 0.85 | E5: =1-E3-E4 -> 0.80966051 | F5: 抽卡小代币 | G5: 1 | H5: 4 | J5: =E5*道具定价!$F$17*H5 -> 3.238642 | K5: =E5*H5 -> 3.238642 | L5: =H5*E5 -> 3.238642
J6: =SUM(J3:J5) -> 6.2867162
J8: 单抽代币数量 | K8: 前期 | L8: 后期 | M8: 大后期
J9: 抽卡大代币 | K9: =K4 -> 0.32373517 | L9: =L4+K3 -> 0.4945666 | M9: =L4+L3 -> 0.4945666
J10: 抽卡小代币 | K10: =L5 -> 3.238642 | L10: =L5 -> 3.238642 | M10: =L5 -> 3.238642
B11: 单抽定价 | C11: 150 | D11: 钻石
B12: 保底次数 | C12: 60 | M12: 0.5 | N12: 0.2
B13: 期望次数 | C13: {=SUMPRODUCT(_xlfn.ANCHORARRAY(B17),C17:C76)} -> 35.122343 | L13: SSR | M13: SR | N13: R
B14: SSR专武价值 | C14: =C11*C13 -> 5268.3514 | D14: 钻石 | F14: SR专武价值 | G14: =C14/D4*D3 -> 810.5156 | H14: 钻石 | J14: 专武星级 | K14: 升到下一星级需要专武 | L14: 升到下一星级需要金币 | M14: 升到下一星级需要金币 | N14: 升到下一星级需要金币
F15: R专武价值 | G15: =C14/D5*D3 -> 123.96121 | H15: 钻石 | J15: 1 | K15: 1 | L15: 10000 | M15: =L15*$M$12 -> 5000 | N15: =$N$12*L15 -> 2000
B16: 抽卡次数 | C16: 概率 | D16: 不出概率 | J16: 2 | K16: 1 | L16: 20000 | M16: =L16*$M$12 -> 10000 | N16: =$N$12*L16 -> 4000
B17: {=_xlfn.SEQUENCE(C12,1,1,1)} -> 1 | C17: =$D$3 -> 0.02 | D17: =1-C17 -> 0.98 | J17: 3 | K17: 1 | L17: 50000 | M17: =L17*$M$12 -> 25000 | N17: =$N$12*L17 -> 10000
B18: 2 | C18: =$D$3*D17 -> 0.0196 | D18: =POWER(1-$D$3,B18) -> 0.9604 | J18: 4 | K18: 1 | L18: 80000 | M18: =L18*$M$12 -> 40000 | N18: =$N$12*L18 -> 16000
B19: 3 | C19: =$D$3*D18 -> 0.019208 | D19: =POWER(1-$D$3,B19) -> 0.941192 | J19: 5 | K19: 0
B20: 4 | C20: =$D$3*D19 -> 0.01882384 | D20: =POWER(1-$D$3,B20) -> 0.92236816
B21: 5 | C21: =$D$3*D20 -> 0.018447363 | D21: =POWER(1-$D$3,B21) -> 0.9039208
B22: 6 | C22: =$D$3*D21 -> 0.018078416 | D22: =POWER(1-$D$3,B22) -> 0.88584238
B23: 7 | C23: =$D$3*D22 -> 0.017716848 | D23: =POWER(1-$D$3,B23) -> 0.86812553 | F23: SR/SSR10连概率 | L23: 1,
B24: 8 | C24: =$D$3*D23 -> 0.017362511 | D24: =POWER(1-$D$3,B24) -> 0.85076302 | L24: =_xlfn.CONCAT($L$23,L15) -> 1,10000 | M24: =_xlfn.CONCAT($L$23,M15) -> 1,5000 | N24: =_xlfn.CONCAT($L$23,N15) -> 1,2000
B25: 9 | C25: =$D$3*D24 -> 0.01701526 | D25: =POWER(1-$D$3,B25) -> 0.83374776 | F25: 抽卡次数 | G25: 概率 | H25: 不出概率 | L25: =_xlfn.CONCAT($L$23,L16) -> 1,20000 | M25: =_xlfn.CONCAT($L$23,M16) -> 1,10000 | N25: =_xlfn.CONCAT($L$23,N16) -> 1,4000
B26: 10 | C26: =$D$3*D25 -> 0.016674955 | D26: =POWER(1-$D$3,B26) -> 0.81707281 | F26: 1 | G26: =D3+D4 -> 0.15 | H26: =1-G26 -> 0.85 | L26: =_xlfn.CONCAT($L$23,L17) -> 1,50000 | M26: =_xlfn.CONCAT($L$23,M17) -> 1,25000 | N26: =_xlfn.CONCAT($L$23,N17) -> 1,10000
B27: 11 | C27: =$D$3*D26 -> 0.016341456 | D27: =POWER(1-$D$3,B27) -> 0.80073135 | F27: 2 | G27: =$G$26*H26 -> 0.1275 | H27: =POWER(1-G$26,F27) -> 0.7225 | L27: =_xlfn.CONCAT($L$23,L18) -> 1,80000 | M27: =_xlfn.CONCAT($L$23,M18) -> 1,40000 | N27: =_xlfn.CONCAT($L$23,N18) -> 1,16000
B28: 12 | C28: =$D$3*D27 -> 0.016014627 | D28: =POWER(1-$D$3,B28) -> 0.78471672 | F28: 3 | G28: =$G$26*H27 -> 0.108375 | H28: =POWER(1-G$26,F28) -> 0.614125
B29: 13 | C29: =$D$3*D28 -> 0.015694334 | D29: =POWER(1-$D$3,B29) -> 0.76902239 | F29: 4 | G29: =$G$26*H28 -> 0.09211875 | H29: =POWER(1-G$26,F29) -> 0.52200625
B30: 14 | C30: =$D$3*D29 -> 0.015380448 | D30: =POWER(1-$D$3,B30) -> 0.75364194 | F30: 5 | G30: =$G$26*H29 -> 0.078300938 | H30: =POWER(1-G$26,F30) -> 0.44370531
B31: 15 | C31: =$D$3*D30 -> 0.015072839 | D31: =POWER(1-$D$3,B31) -> 0.7385691 | F31: 6 | G31: =$G$26*H30 -> 0.066555797 | H31: =POWER(1-G$26,F31) -> 0.37714952
B32: 16 | C32: =$D$3*D31 -> 0.014771382 | D32: =POWER(1-$D$3,B32) -> 0.72379772 | F32: 7 | G32: =$G$26*H31 -> 0.056572427 | H32: =POWER(1-G$26,F32) -> 0.32057709
B33: 17 | C33: =$D$3*D32 -> 0.014475954 | D33: =POWER(1-$D$3,B33) -> 0.70932177 | F33: 8 | G33: =$G$26*H32 -> 0.048086563 | H33: =POWER(1-G$26,F33) -> 0.27249053
B34: 18 | C34: =$D$3*D33 -> 0.014186435 | D34: =POWER(1-$D$3,B34) -> 0.69513533 | F34: 9 | G34: =$G$26*H33 -> 0.040873579 | H34: =POWER(1-G$26,F34) -> 0.23161695
B35: 19 | C35: =$D$3*D34 -> 0.013902707 | D35: =POWER(1-$D$3,B35) -> 0.68123262 | F35: 10 | G35: =1-SUM(G26:G34) -> 0.23161695
B36: 20 | C36: =$D$3*D35 -> 0.013624652 | D36: =POWER(1-$D$3,B36) -> 0.66760797
B37: 21 | C37: =$D$3*D36 -> 0.013352159 | D37: =POWER(1-$D$3,B37) -> 0.65425581 | G37: {=SUMPRODUCT(F26:F35,G26:G35)} -> 5.3541706
B38: 22 | C38: =$D$3*D37 -> 0.013085116 | D38: =POWER(1-$D$3,B38) -> 0.6411707 | G38: =1/G37 -> 0.18677029
B39: 23 | C39: =$D$3*D38 -> 0.012823414 | D39: =POWER(1-$D$3,B39) -> 0.62834728
B40: 24 | C40: =$D$3*D39 -> 0.012566946 | D40: =POWER(1-$D$3,B40) -> 0.61578034
B41: 25 | C41: =$D$3*D40 -> 0.012315607 | D41: =POWER(1-$D$3,B41) -> 0.60346473
B42: 26 | C42: =$D$3*D41 -> 0.012069295 | D42: =POWER(1-$D$3,B42) -> 0.59139544
...

Sheet 旅券
B2: 等级上限 | C2: 60 | E2: 装备总数 | F2: 6 | H2: 每点经验所需金币 | I2: 10
B4: 等级 | C4: 提升系数 | D4: 每级所需经验 | E4: 总经验 | F4: 每级所需金币 | G4: 总金币 | J4: 单旅券总经验 | K4: =MAX(E5:E9) -> 40000 | L4: =道具定价!$F$111*K4 -> 400 | O4: 6旅券总经验 | P4: =K4*6 -> 240000 | Q4: =道具定价!$F$111*P4 -> 2400
B5: 1 | D5: 1000 | E5: =SUM($D$5:D5) -> 1000 | F5: =D5*$I$2 -> 10000 | G5: =SUM($F$5:F5) -> 10000 | J5: 单旅券总金币 | K5: =MAX(G5:G9) -> 400000 | L5: =K5*道具定价!$F$11 -> 400 | O5: 6旅券总金币 | P5: =K5*6 -> 2400000 | Q5: =P5*道具定价!$F$11 -> 2400
B6: 2 | C6: 3 | D6: =C6*D5 -> 3000 | E6: =SUM($D$5:D6) -> 4000 | F6: =D6*$I$2 -> 30000 | G6: =SUM($F$5:F6) -> 40000 | J6: 单旅券总坑深（钻石） | L6: =SUM(L4:L5) -> 800 | O6: 6旅券总坑深（钻石） | Q6: =SUM(P4:P5) -> 2640000
B7: 3 | C7: 2 | D7: =C7*D6 -> 6000 | E7: =SUM($D$5:D7) -> 10000 | F7: =D7*$I$2 -> 60000 | G7: =SUM($F$5:F7) -> 100000
B8: 4 | C8: 2 | D8: =C8*D7 -> 12000 | E8: =SUM($D$5:D8) -> 22000 | F8: =D8*$I$2 -> 120000 | G8: =SUM($F$5:F8) -> 220000
B9: 5 | C9: 1.5 | D9: =C9*D8 -> 18000 | E9: =SUM($D$5:D9) -> 40000 | F9: =D9*$I$2 -> 180000 | G9: =SUM($F$5:F9) -> 400000
B12: 品质 | C12: 品质系数
B13: 红 | C13: 1
B14: 金 | C14: 0.8
B15: 紫 | C15: 0.6
B16: 蓝 | C16: 0.4
B18: 红 | F18: 金 | J18: 紫 | N18: 蓝
B19: 等级 | C19: 提升系数 | D19: 每级所需经验 | E19: 每级所需金币 | F19: 等级 | G19: 提升系数 | H19: 每级所需经验 | I19: 每级所需金币 | J19: 等级 | K19: 提升系数 | L19: 每级所需经验 | M19: 每级所需金币 | N19: 等级 | O19: 提升系数 | P19: 每级所需经验 | Q19: 每级所需金币
B20: 1 | D20: =D5*$C$13 -> 1000 | E20: =G5*$C$13 -> 10000 | F20: 1 | H20: =$D5*$C$14 -> 800 | I20: =$F5*$C$14 -> 8000 | J20: 1 | L20: =$D5*$C$15 -> 600 | M20: =$F5*$C$15 -> 6000 | N20: 1 | P20: =$D5*$C$16 -> 400 | Q20: =$F5*$C$16 -> 4000
B21: 2 | C21: 3 | D21: =D6*$C$13 -> 3000 | E21: =G6*$C$13 -> 40000 | F21: 2 | G21: 3 | H21: =$D6*$C$14 -> 2400 | I21: =$F6*$C$14 -> 24000 | J21: 2 | K21: 3 | L21: =$D6*$C$15 -> 1800 | M21: =$F6*$C$15 -> 18000 | N21: 2 | O21: 3 | P21: =$D6*$C$16 -> 1200 | Q21: =$F6*$C$16 -> 12000
B22: 3 | C22: 2 | D22: =D7*$C$13 -> 6000 | E22: =G7*$C$13 -> 100000 | F22: 3 | G22: 2 | H22: =$D7*$C$14 -> 4800 | I22: =$F7*$C$14 -> 48000 | J22: 3 | K22: 2 | L22: =$D7*$C$15 -> 3600 | M22: =$F7*$C$15 -> 36000 | N22: 3 | O22: 2 | P22: =$D7*$C$16 -> 2400 | Q22: =$F7*$C$16 -> 24000
B23: 4 | C23: 2 | D23: =D8*$C$13 -> 12000 | E23: =G8*$C$13 -> 220000 | F23: 4 | G23: 2 | H23: =$D8*$C$14 -> 9600 | I23: =$F8*$C$14 -> 96000 | J23: 4 | K23: 2 | L23: =$D8*$C$15 -> 7200 | M23: =$F8*$C$15 -> 72000 | N23: 4 | O23: 2 | P23: =$D8*$C$16 -> 4800 | Q23: =$F8*$C$16 -> 48000
B24: 5 | C24: 1.5 | D24: =D9*$C$13 -> 18000 | E24: =G9*$C$13 -> 400000 | F24: 5 | G24: 1.5 | H24: =$D9*$C$14 -> 14400 | I24: =$F9*$C$14 -> 144000 | J24: 5 | K24: 1.5 | L24: =$D9*$C$15 -> 10800 | M24: =$F9*$C$15 -> 108000 | N24: 5 | O24: 1.5 | P24: =$D9*$C$16 -> 7200 | Q24: =$F9*$C$16 -> 72000
B26: 分解得旅券经验
B27: 品质 | C27: 经验 | D27: 额外道具
B28: 红 | C28: =道具定价!F112/道具定价!$F$111 -> 5000 | D28: 无
B29: 金 | C29: =道具定价!F113/道具定价!$F$111 -> 1000 | D29: 无
B30: 紫 | C30: =道具定价!F114/道具定价!$F$111 -> 500 | D30: 无
B31: 蓝 | C31: =道具定价!F115/道具定价!$F$111 -> 200 | D31: 无

Sheet 专武
B2: 等级上限 | C2: 60 | L2: 单角色总经验 | N2: =MAX(E7:E76) -> 2634500 | O2: =N2*道具定价!F79 -> 1317.25
L3: 单角色总金币 | N3: =MAX(G7:G76) -> 263450
L4: 总坑深（钻石） | N4: =N2*道具定价!F79+N3*道具定价!F11 -> 1580.7
H5: 0.8 | I5: 0.7
B6: 等级 | C6: 相对上级提升 | D6: 每级所需经验 | E6: 总经验 | F6: 每级所需金币 | G6: 总金币 | H6: SR每级所需经验 | I6: R每级所需经验 | L6: 突破等级 | M6: 突破次数 | N6: 消耗类型1 | O6: 消耗数量1 | P6: 消耗价值1 | Q6: 消耗类型2 | R6: 消耗数量2 | S6: 消耗价值2 | T6: 消耗价值总
B7: {=_xlfn.SEQUENCE(C2,1,1,1)} -> 1 | D7: 100 | E7: =SUM($D$7:D7) -> 100 | F7: =ROUND(D7/10,-1) -> 10 | G7: =SUM($F$7:F7) -> 10 | H7: =ROUND(D7*$H$5,0) -> 80 | I7: =ROUND(D7*$I$5,0) -> 70 | L7: 20 | M7: 1 | N7: 角色升阶材料低 | O7: 6 | P7: =VLOOKUP(N7,道具定价!$C:$F,4,0)*O7 -> 24 | Q7: 金币 | R7: 20000 | S7: =VLOOKUP(Q7,道具定价!$C:$F,4,0)*R7 -> 20 | T7: =S7+P7 -> 44
B8: 2 | C8: 100 | D8: =D7+C8 -> 200 | E8: =SUM($D$7:D8) -> 300 | F8: =ROUND(D8/10,-1) -> 20 | G8: =SUM($F$7:F8) -> 30 | H8: =ROUND(D8*$H$5,0) -> 160 | I8: =ROUND(D8*$I$5,0) -> 140 | L8: 30 | M8: 2 | N8: 角色升阶材料中 | O8: 6 | P8: =VLOOKUP(N8,道具定价!$C:$F,4,0)*O8 -> 72 | Q8: 金币 | R8: 50000 | S8: =VLOOKUP(Q8,道具定价!$C:$F,4,0)*R8 -> 50 | T8: =S8+P8 -> 122
B9: 3 | C9: 100 | D9: =D8+C9 -> 300 | E9: =SUM($D$7:D9) -> 600 | F9: =ROUND(D9/10,-1) -> 30 | G9: =SUM($F$7:F9) -> 60 | H9: =ROUND(D9*$H$5,0) -> 240 | I9: =ROUND(D9*$I$5,0) -> 210 | L9: 40 | M9: 3 | N9: 角色升阶材料中 | O9: 12 | P9: =VLOOKUP(N9,道具定价!$C:$F,4,0)*O9 -> 144 | Q9: 金币 | R9: 100000 | S9: =VLOOKUP(Q9,道具定价!$C:$F,4,0)*R9 -> 100 | T9: =S9+P9 -> 244
B10: 4 | C10: 100 | D10: =D9+C10 -> 400 | E10: =SUM($D$7:D10) -> 1000 | F10: =ROUND(D10/10,-1) -> 40 | G10: =SUM($F$7:F10) -> 100 | H10: =ROUND(D10*$H$5,0) -> 320 | I10: =ROUND(D10*$I$5,0) -> 280 | L10: 50 | M10: 4 | N10: 角色升阶材料高 | O10: 12 | P10: =VLOOKUP(N10,道具定价!$C:$F,4,0)*O10 -> 432 | Q10: 金币 | R10: 200000 | S10: =VLOOKUP(Q10,道具定价!$C:$F,4,0)*R10 -> 200 | T10: =S10+P10 -> 632
B11: 5 | C11: 100 | D11: =D10+C11 -> 500 | E11: =SUM($D$7:D11) -> 1500 | F11: =ROUND(D11/10,-1) -> 50 | G11: =SUM($F$7:F11) -> 150 | H11: =ROUND(D11*$H$5,0) -> 400 | I11: =ROUND(D11*$I$5,0) -> 350 | P11: =SUM(P7:P10) -> 672 | R11: =SUM(R7:R10) -> 370000
B12: 6 | C12: 200 | D12: =D11+C12 -> 700 | E12: =SUM($D$7:D12) -> 2200 | F12: =ROUND(D12/10,-1) -> 70 | G12: =SUM($F$7:F12) -> 220 | H12: =ROUND(D12*$H$5,0) -> 560 | I12: =ROUND(D12*$I$5,0) -> 490
B13: 7 | C13: 200 | D13: =D12+C13 -> 900 | E13: =SUM($D$7:D13) -> 3100 | F13: =ROUND(D13/10,-1) -> 90 | G13: =SUM($F$7:F13) -> 310 | H13: =ROUND(D13*$H$5,0) -> 720 | I13: =ROUND(D13*$I$5,0) -> 630
B14: 8 | C14: 200 | D14: =D13+C14 -> 1100 | E14: =SUM($D$7:D14) -> 4200 | F14: =ROUND(D14/10,-1) -> 110 | G14: =SUM($F$7:F14) -> 420 | H14: =ROUND(D14*$H$5,0) -> 880 | I14: =ROUND(D14*$I$5,0) -> 770
B15: 9 | C15: 200 | D15: =D14+C15 -> 1300 | E15: =SUM($D$7:D15) -> 5500 | F15: =ROUND(D15/10,-1) -> 130 | G15: =SUM($F$7:F15) -> 550 | H15: =ROUND(D15*$H$5,0) -> 1040 | I15: =ROUND(D15*$I$5,0) -> 910 | M15: 作为素材经验
B16: 10 | C16: 200 | D16: =D15+C16 -> 1500 | E16: =SUM($D$7:D16) -> 7000 | F16: =ROUND(D16/10,-1) -> 150 | G16: =SUM($F$7:F16) -> 700 | H16: =ROUND(D16*$H$5,0) -> 1200 | I16: =ROUND(D16*$I$5,0) -> 1050 | L16: R | M16: 5000
B17: 11 | C17: 400 | D17: =D16+C17 -> 1900 | E17: =SUM($D$7:D17) -> 8900 | F17: =ROUND(D17/10,-1) -> 190 | G17: =SUM($F$7:F17) -> 890 | H17: =ROUND(D17*$H$5,0) -> 1520 | I17: =ROUND(D17*$I$5,0) -> 1330 | L17: SR | M17: 10000
B18: 12 | C18: 400 | D18: =D17+C18 -> 2300 | E18: =SUM($D$7:D18) -> 11200 | F18: =ROUND(D18/10,-1) -> 230 | G18: =SUM($F$7:F18) -> 1120 | H18: =ROUND(D18*$H$5,0) -> 1840 | I18: =ROUND(D18*$I$5,0) -> 1610 | L18: SSR | M18: 50000
B19: 13 | C19: 400 | D19: =D18+C19 -> 2700 | E19: =SUM($D$7:D19) -> 13900 | F19: =ROUND(D19/10,-1) -> 270 | G19: =SUM($F$7:F19) -> 1390 | H19: =ROUND(D19*$H$5,0) -> 2160 | I19: =ROUND(D19*$I$5,0) -> 1890
B20: 14 | C20: 400 | D20: =D19+C20 -> 3100 | E20: =SUM($D$7:D20) -> 17000 | F20: =ROUND(D20/10,-1) -> 310 | G20: =SUM($F$7:F20) -> 1700 | H20: =ROUND(D20*$H$5,0) -> 2480 | I20: =ROUND(D20*$I$5,0) -> 2170
B21: 15 | C21: 400 | D21: =D20+C21 -> 3500 | E21: =SUM($D$7:D21) -> 20500 | F21: =ROUND(D21/10,-1) -> 350 | G21: =SUM($F$7:F21) -> 2050 | H21: =ROUND(D21*$H$5,0) -> 2800 | I21: =ROUND(D21*$I$5,0) -> 2450
B22: 16 | C22: 600 | D22: =D21+C22 -> 4100 | E22: =SUM($D$7:D22) -> 24600 | F22: =ROUND(D22/10,-1) -> 410 | G22: =SUM($F$7:F22) -> 2460 | H22: =ROUND(D22*$H$5,0) -> 3280 | I22: =ROUND(D22*$I$5,0) -> 2870
B23: 17 | C23: 600 | D23: =D22+C23 -> 4700 | E23: =SUM($D$7:D23) -> 29300 | F23: =ROUND(D23/10,-1) -> 470 | G23: =SUM($F$7:F23) -> 2930 | H23: =ROUND(D23*$H$5,0) -> 3760 | I23: =ROUND(D23*$I$5,0) -> 3290
B24: 18 | C24: 600 | D24: =D23+C24 -> 5300 | E24: =SUM($D$7:D24) -> 34600 | F24: =ROUND(D24/10,-1) -> 530 | G24: =SUM($F$7:F24) -> 3460 | H24: =ROUND(D24*$H$5,0) -> 4240 | I24: =ROUND(D24*$I$5,0) -> 3710
B25: 19 | C25: 600 | D25: =D24+C25 -> 5900 | E25: =SUM($D$7:D25) -> 40500 | F25: =ROUND(D25/10,-1) -> 590 | G25: =SUM($F$7:F25) -> 4050 | H25: =ROUND(D25*$H$5,0) -> 4720 | I25: =ROUND(D25*$I$5,0) -> 4130
B26: 20 | C26: 600 | D26: =D25+C26 -> 6500 | E26: =SUM($D$7:D26) -> 47000 | F26: =ROUND(D26/10,-1) -> 650 | G26: =SUM($F$7:F26) -> 4700 | H26: =ROUND(D26*$H$5,0) -> 5200 | I26: =ROUND(D26*$I$5,0) -> 4550
B27: 21 | C27: 1000 | D27: =D26+C27 -> 7500 | E27: =SUM($D$7:D27) -> 54500 | F27: =ROUND(D27/10,-1) -> 750 | G27: =SUM($F$7:F27) -> 5450 | H27: =ROUND(D27*$H$5,0) -> 6000 | I27: =ROUND(D27*$I$5,0) -> 5250
B28: 22 | C28: 1000 | D28: =D27+C28 -> 8500 | E28: =SUM($D$7:D28) -> 63000 | F28: =ROUND(D28/10,-1) -> 850 | G28: =SUM($F$7:F28) -> 6300 | H28: =ROUND(D28*$H$5,0) -> 6800 | I28: =ROUND(D28*$I$5,0) -> 5950
B29: 23 | C29: 1000 | D29: =D28+C29 -> 9500 | E29: =SUM($D$7:D29) -> 72500 | F29: =ROUND(D29/10,-1) -> 950 | G29: =SUM($F$7:F29) -> 7250 | H29: =ROUND(D29*$H$5,0) -> 7600 | I29: =ROUND(D29*$I$5,0) -> 6650
B30: 24 | C30: 1000 | D30: =D29+C30 -> 10500 | E30: =SUM($D$7:D30) -> 83000 | F30: =ROUND(D30/10,-1) -> 1050 | G30: =SUM($F$7:F30) -> 8300 | H30: =ROUND(D30*$H$5,0) -> 8400 | I30: =ROUND(D30*$I$5,0) -> 7350
... B66: 60 | C66: 9000 | D66: =D65+C66 -> 174000 | E66: =SUM($D$7:D66) -> 2634500 | F66: =ROUND(D66/10,-1) -> 17400 | G66: =SUM($F$7:F66) -> 263450 | H66: =ROUND(D66*$H$5,0) -> 139200 | I66: =ROUND(D66*$I$5,0) -> 121800

Sheet 角色星盘
B2: 总点数 | D2: 免费点数 | E2: 额外点数 | I2: 等级限制 | J2: 总点数
B3: 27 | D3: 21 | E3: =B3-D3 -> 6 | H3: 外圈 | I3: 40 | J3: 9
H4: 中圈 | I4: 30 | J4: 9
