Workbook

Sheet 00_索引
A1: 文档名称 | B1: Vgame养成数值
A2: 文档类型 | B2: 养成数值
A3: 当前状态 | B3: 正式
A4: 负责人 | B4: 数值组
A5: 最后更新时间 | B5: 2026-05-28
A6: 文档目标 | B6: 定义角色养成各模块的属性投放与成长职责
A7: 使用说明 | B7: 修改数值时引用 SHEET_ID 定位；CONFIG_TARGET 指向 Config/GameConfig/Datas/ 下的配置表
A9: Sheet名 | B9: SHEET_ID | C9: 状态 | D9: 配置目标(CONFIG_TARGET) | E9: 是否可直接用于配置表 | F9: 用途
A10: 养成属性规划 | B10: 养成_属性规划总览 | C10: 正式 | D10: 无（总览页） | E10: 否 | F10: 全养成模块的属性投放职责总览和标准人基础属性
A11: 属性定价 | B11: 养成_属性定价 | C11: 正式 | D11: 无（总览页） | E11: 否 | F11: 每个属性的换算价值，以及每个属性的英文名
A12: 角色升级升阶 | B12: 养成_角色升级升阶 | C12: 正式 | D12: HeroAttribute（Hp/PhysicsAttack/MagicAttack/Armor）, HeroAscendLv | E12: 否 | F12: 角色1-60级基础属性成长和升阶突破数据
A13: 角色升星 | B13: 养成_角色升星 | C13: 正式 | D13: HeroStarAttrUp（系数列）, CalibrationPoints | E13: 否 | F13: 升星投放偏向性基础属性和二级属性
A14: 角色星盘 | B14: 养成_角色星盘 | C14: 正式 | D14: HeroStarAttrUp, CalibrationPoints, CalibrationPointsAttr | E14: 否 | F14: 星盘投放偏向性基础属性和二级属性
A15: 专武 | B15: 养成_专武 | C15: 正式 | D15: ExclWeaponLv, ExclWeaponAscendLv | E15: 否 | F15: 专武基础属性投放、突破门槛和技能等级
A16: 旅券 | B16: 养成_旅券 | C16: 正式 | D16: StrategyCards, StrategyLv | F16: 旅券属性投放和效果词条设计
A17: 映射装备 | B17: 养成_映射装备 | C17: 正式 | D17: SpecialEquipment, SpecialEquipmentEffect, SpecialEquipmentGem | F17: 映射装备基础属性、宝石系统和词条投放
A18: 映射装备配置 | B18: 养成_映射装备配置 | C18: 正式 | D18: SpecialEquipmentEffect（EffectId/Weight） | F18: 映射装备和旅券的词条ID与权重映射
A19: 不同武将系数 | B19: 养成_武将系数 | C19: 正式 | D19: HeroAttribute（通过系数计算各角色属性） | F19: 各职业/角色的生攻防系数和伤害类型定义
A20: 不同武将系数配置 | B20: 养成_武将系数配置 | C20: 正式 | D20: HeroAttribute（最终各角色属性值） | F20: 基于武将系数计算出的各角色完整属性和星盘词条
A21: 临时效果 | B21: 养成_临时效果 | C21: 正式 | D21: Skill/FightItem（效果ID和数值） | F21: 旅券/映射装备的战斗临时效果数值表
A22: Sheet1 | B22: 养成_角色列表 | C22: 草稿 | D22: Hero（角色ID和阵营） | F22: 角色名称、编号和阵营列表
A23: 配置页-推荐邮票 | B23: 养成_推荐邮票配置 | C23: 草稿 | D23: StrategyRecommendation | E23: 是 | F23: 每个有效武将配置4套推荐邮票/旅券

Sheet 养成属性规划
B2: 初始标准人属性 | C2: 生命 | D2: 攻击 | E2: 防御
C3: 5000 | D3: 1500 | E3: 1000
B5: 养成模块数值概述
B6: 概述为前期规划，具体数值请参照每个页签
B8: 养成模块 | C8: 养成定位 | J8: 投放属性 | O8: 备注
J9: 基础属性 | K9: 基础属性% | L9: 技能等级 | M9: 普通二级属性
A10: 角色裸体数值 | B10: 初始 | C10: 每个角色初始的属性 | J10: √
B11: 角色升级 | C11: 主要提供基础属性，线性成长，前中期主要属性来源 | J11: √
B12: 角色升阶 | C12: 主要提供基础属性，线性成长，前中期主要属性来源 升阶主要去卡角色技能等级和星盘等级 | J12: √
B13: 角色星盘 | C13: 稀有角色、活跃材料的投放和消耗点 普通养成行为无法点满，需要额外的稀有材料才能点满 投放一小部分基础属性，基础属性%，普通二级属性和天赋技能等级 投放的基础属性%和二级属性根据角色定位进行更改 | J13: √ | K13: √ | L13: √ | M13: √
B14: 角色升星 | C14: 主要付费内容，解锁额外天赋（提升幅度需要够大），投放基础属性百分比和二级属性 | K14: √ | L14: √ | M14: √
B15: 专武 | C15: 主要作用是承载一部分角色技能机制，同时提供一部分基础属性 或者普通二级属性 | J15: √ | K15: √ | L15: √ | M15: √
B16: 旅券 | C16: 4+2套装效果 等级上限低，相对于阴阳师，降低随机性，提高毕业预期 | J16: √ | L16: √
B17: 主角装备 | C17: 后期终局玩法，极强的随机词条，承载后期玩家的日活和养成目标 主属性固定，副属性做强的词条与上下限随机 镶嵌的宝石相当于一个带一点随机性的进度类养成 | J17: √ | K17: √ | L17: √ | M17: √
B19: 角色全属性组成
B20: 不能选择的 | D20: 可选择的
B21: 角色升级 | D21: 映射装备副词条+宝石
B22: 角色升阶 | D22: 旅券
B23: 角色星盘
B24: 角色升星
B25: 专武
B26: 映射装备主词条
B31: 养成模块数值分配 | P31: 这部分是每个角色不同的属性偏向，需要每个角色单独设计
B32: 该表格决定属性数值分配值 | P32: 输出角色（攻击%+暴击爆伤）
D33: 预计基础属性 | G33: 最终基础属性% | J33: 预计全部基础属性% | M33: 预计偏向全部二级属性 | P33: 预计偏向基础属性%+二级属性
B34: 养成模块 | C34: 基础属性投放系数 | D34: 生命 | E34: 攻击 | F34: 防御 | G34: 生命 | H34: 攻击 | I34: 防御 | J34: 生命 | K34: 攻击 | L34: 防御 | M34: 偏向值 | P34: 偏向值 | V34: 二级属性占比
V35: =SUM(L35:U35)/$M$46 -> 0
A36: 角色裸体数值 | B36: 初始 | C36: 1 | D36: =$C36*C$3 -> 5000 | E36: =$C36*D$3 -> 1500 | F36: =$C36*E$3 -> 1000 | V36: =SUM(L36:U36)/$M$46 -> 0
B37: 角色升级 | C37: 4.8 | D37: =$C37*C$3 -> 24000 | E37: =$C37*D$3 -> 7200 | F37: =$C37*E$3 -> 4800 | V37: =SUM(L37:U37)/$M$46 -> 0
B38: 角色升阶 | C38: 0 | D38: =$C38*C$3 -> 0 | E38: =$C38*D$3 -> 0 | F38: =$C38*E$3 -> 0 | V38: =SUM(L38:U38)/$M$46 -> 0
B39: 角色星盘 | C39: 2.3 | D39: =$C39*C$3 -> 11500 | E39: =$C39*D$3 -> 3450 | F39: =$C39*E$3 -> 2300 | G39: 0 | H39: 0 | I39: 0 | J39: 0 | K39: 0 | L39: 0 | M39: 0 | P39: 1.2 | V39: =SUM(L39:U39)/$M$46 -> 0.068181818
B40: 角色升星 | G40: 0.9 | H40: 0.9 | I40: 0.9 | J40: 0 | K40: 0 | L40: 0 | M40: 0 | P40: 0.6 | V40: =SUM(L40:U40)/$M$46 -> 0.034090909
B41: 专武 | C41: 4 | D41: =$C41*C$3 -> 20000 | E41: =$C41*D$3 -> 6000 | F41: =$C41*E$3 -> 4000 | G41: 0 | H41: 0 | I41: 0 | J41: 0 | K41: 0 | L41: 0 | M41: 0 | P41: 0.6 | V41: =SUM(L41:U41)/$M$46 -> 0.034090909
B42: 旅券 | C42: 6 | D42: =$C42*C$3 -> 30000 | E42: =$C42*D$3 -> 9000 | F42: =$C42*E$3 -> 6000 | G42: 0 | H42: 0 | I42: 0 | J42: 0 | K42: 0 | L42: 0 | M42: 0 | P42: 4.2 | V42: =SUM(L42:U42)/$M$46 -> 0.23863636
B43: 映射装备 | C43: 10 | D43: =$C43*C$3 -> 50000 | E43: =$C43*D$3 -> 15000 | F43: =$C43*E$3 -> 10000 | G43: 0 | H43: 0 | I43: 0 | J43: 2.4 | K43: 2.4 | L43: 2.4 | M43: 1.6 | P43: 7 | V43: =SUM(L43:U43)/$M$46 -> 0.625
J44: =SUM(J36:J43) -> 2.4 | M44: =SUM(M36:O43) -> 1.6 | P44: =SUM(P36:R43) -> 13.6
F46: 总普通投放 | G46: =J44+M44+P44 -> 17.6 | I46: 总稀有投放 | J46: =S44 -> 0 | L46: 总二级投放 | M46: =J46+G46 -> 17.6
F47: （以攻击力%为基准）
F49: 以攻击百分比为基准的属性定价
F50: 攻击百分比 | G50: 0.01 | H50: =3*G50 -> 0.03 | I50: =(M46-M44-J44)/3 -> 4.5333333
...

Sheet 角色升级升阶
B2: 参数区 | G2: 升级预计分配属性
B3: 等级上限 | C3: 60 | G3: 生命 | H3: 攻击 | I3: 防御
B4: 突破次数 | C4: 4 | G4: =养成属性规划!D37 -> 24000 | H4: =养成属性规划!E37 -> 7200 | I4: =养成属性规划!F37 -> 4800
B5: 单级成长比例 | C5: =养成属性规划!$C$37/$C$3 -> 0.08
B6: 单次突破成长 | C6: =养成属性规划!C38/C4 -> 0
B7: 品阶系数 | C7: 品阶系数在角色初始、升级、升阶和星盘处投放的基础属性数值需要乘上一个百分比
B8: R | C8: ='参数页-不同武将系数'!C16 -> 0.7
B9: SR | C9: ='参数页-不同武将系数'!C15 -> 0.8
B10: SSR | C10: ='参数页-不同武将系数'!C14 -> 1
B13: 结论区
B14: 等级 | C14: 单级成长 | D14: 单级属性系数 | E14: 生命 | F14: 攻击 | G14: 攻击 | H14: 防御 | J14: 突破等级 | K14: 突破系数 | L14: 生命 | M14: 攻击 | N14: 防御 | O14: 需求玩家等级
B15: {=_xlfn.SEQUENCE(C3,1,1,1)} -> 1 | C15: =$C$5 -> 0.08 | D15: =1+SUM($C$15:C15) -> 1.08 | E15: =ROUND($D15*养成属性规划!C$3,0) -> 5400 | F15: =ROUND($D15*养成属性规划!D$3,0) -> 1620 | G15: =F15 -> 1620 | H15: =ROUND($D15*养成属性规划!E$3,0) -> 1080 | J15: 20 | K15: 0 | L15: =ROUND($K15*养成属性规划!C$3,0) -> 0 | M15: =ROUND($K15*养成属性规划!D$3,0) -> 0 | N15: =ROUND($K15*养成属性规划!E$3,0) -> 0 | O15: 20
B16: 2 | C16: =$C$5 -> 0.08 | D16: =1+SUM($C$15:C16) -> 1.16 | E16: =ROUND($D16*养成属性规划!C$3,0) -> 5800 | F16: =ROUND($D16*养成属性规划!D$3,0) -> 1740 | G16: =F16 -> 1740 | H16: =ROUND($D16*养成属性规划!E$3,0) -> 1160 | J16: 30 | K16: 0 | L16: =ROUND($K16*养成属性规划!C$3,0) -> 0 | M16: =ROUND($K16*养成属性规划!D$3,0) -> 0 | N16: =ROUND($K16*养成属性规划!E$3,0) -> 0 | O16: 30
B17: 3 | C17: =$C$5 -> 0.08 | D17: =1+SUM($C$15:C17) -> 1.24 | E17: =ROUND($D17*养成属性规划!C$3,0) -> 6200 | F17: =ROUND($D17*养成属性规划!D$3,0) -> 1860 | G17: =F17 -> 1860 | H17: =ROUND($D17*养成属性规划!E$3,0) -> 1240 | J17: 40 | K17: 0 | L17: =ROUND($K17*养成属性规划!C$3,0) -> 0 | M17: =ROUND($K17*养成属性规划!D$3,0) -> 0 | N17: =ROUND($K17*养成属性规划!E$3,0) -> 0 | O17: 40
B18: 4 | C18: =$C$5 -> 0.08 | D18: =1+SUM($C$15:C18) -> 1.32 | E18: =ROUND($D18*养成属性规划!C$3,0) -> 6600 | F18: =ROUND($D18*养成属性规划!D$3,0) -> 1980 | G18: =F18 -> 1980 | H18: =ROUND($D18*养成属性规划!E$3,0) -> 1320 | J18: 50 | K18: 0 | L18: =ROUND($K18*养成属性规划!C$3,0) -> 0 | M18: =ROUND($K18*养成属性规划!D$3,0) -> 0 | N18: =ROUND($K18*养成属性规划!E$3,0) -> 0 | O18: 50
B19: 5 | C19: =$C$5 -> 0.08 | D19: =1+SUM($C$15:C19) -> 1.4 | E19: =ROUND($D19*养成属性规划!C$3,0) -> 7000 | F19: =ROUND($D19*养成属性规划!D$3,0) -> 2100 | G19: =F19 -> 2100 | H19: =ROUND($D19*养成属性规划!E$3,0) -> 1400 | J19: 60 | K19: 0 | L19: =ROUND($K19*养成属性规划!C$3,0) -> 0 | M19: =ROUND($K19*养成属性规划!D$3,0) -> 0 | N19: =ROUND($K19*养成属性规划!E$3,0) -> 0 | O19: 60
B20: 6 | C20: =$C$5 -> 0.08 | D20: =1+SUM($C$15:C20) -> 1.48 | E20: =ROUND($D20*养成属性规划!C$3,0) -> 7400 | F20: =ROUND($D20*养成属性规划!D$3,0) -> 2220 | G20: =F20 -> 2220 | H20: =ROUND($D20*养成属性规划!E$3,0) -> 1480
B21: 7 | C21: =$C$5 -> 0.08 | D21: =1+SUM($C$15:C21) -> 1.56 | E21: =ROUND($D21*养成属性规划!C$3,0) -> 7800 | F21: =ROUND($D21*养成属性规划!D$3,0) -> 2340 | G21: =F21 -> 2340 | H21: =ROUND($D21*养成属性规划!E$3,0) -> 1560
B22: 8 | C22: =$C$5 -> 0.08 | D22: =1+SUM($C$15:C22) -> 1.64 | E22: =ROUND($D22*养成属性规划!C$3,0) -> 8200 | F22: =ROUND($D22*养成属性规划!D$3,0) -> 2460 | G22: =F22 -> 2460 | H22: =ROUND($D22*养成属性规划!E$3,0) -> 1640
B23: 9 | C23: =$C$5 -> 0.08 | D23: =1+SUM($C$15:C23) -> 1.72 | E23: =ROUND($D23*养成属性规划!C$3,0) -> 8600 | F23: =ROUND($D23*养成属性规划!D$3,0) -> 2580 | G23: =F23 -> 2580 | H23: =ROUND($D23*养成属性规划!E$3,0) -> 1720
B24: 10 | C24: =$C$5 -> 0.08 | D24: =1+SUM($C$15:C24) -> 1.8 | E24: =ROUND($D24*养成属性规划!C$3,0) -> 9000 | F24: =ROUND($D24*养成属性规划!D$3,0) -> 2700 | G24: =F24 -> 2700 | H24: =ROUND($D24*养成属性规划!E$3,0) -> 1800
B25: 11 | C25: =$C$5 -> 0.08 | D25: =1+SUM($C$15:C25) -> 1.88 | E25: =ROUND($D25*养成属性规划!C$3,0) -> 9400 | F25: =ROUND($D25*养成属性规划!D$3,0) -> 2820 | G25: =F25 -> 2820 | H25: =ROUND($D25*养成属性规划!E$3,0) -> 1880
B26: 12 | C26: =$C$5 -> 0.08 | D26: =1+SUM($C$15:C26) -> 1.96 | E26: =ROUND($D26*养成属性规划!C$3,0) -> 9800 | F26: =ROUND($D26*养成属性规划!D$3,0) -> 2940 | G26: =F26 -> 2940 | H26: =ROUND($D26*养成属性规划!E$3,0) -> 1960
B27: 13 | C27: =$C$5 -> 0.08 | D27: =1+SUM($C$15:C27) -> 2.04 | E27: =ROUND($D27*养成属性规划!C$3,0) -> 10200 | F27: =ROUND($D27*养成属性规划!D$3,0) -> 3060 | G27: =F27 -> 3060 | H27: =ROUND($D27*养成属性规划!E$3,0) -> 2040
B28: 14 | C28: =$C$5 -> 0.08 | D28: =1+SUM($C$15:C28) -> 2.12 | E28: =ROUND($D28*养成属性规划!C$3,0) -> 10600 | F28: =ROUND($D28*养成属性规划!D$3,0) -> 3180 | G28: =F28 -> 3180 | H28: =ROUND($D28*养成属性规划!E$3,0) -> 2120
B29: 15 | C29: =$C$5 -> 0.08 | D29: =1+SUM($C$15:C29) -> 2.2 | E29: =ROUND($D29*养成属性规划!C$3,0) -> 11000 | F29: =ROUND($D29*养成属性规划!D$3,0) -> 3300 | G29: =F29 -> 3300 | H29: =ROUND($D29*养成属性规划!E$3,0) -> 2200
B30: 16 | C30: =$C$5 -> 0.08 | D30: =1+SUM($C$15:C30) -> 2.28 | E30: =ROUND($D30*养成属性规划!C$3,0) -> 11400 | F30: =ROUND($D30*养成属性规划!D$3,0) -> 3420 | G30: =F30 -> 3420 | H30: =ROUND($D30*养成属性规划!E$3,0) -> 2280
B31: 17 | C31: =$C$5 -> 0.08 | D31: =1+SUM($C$15:C31) -> 2.36 | E31: =ROUND($D31*养成属性规划!C$3,0) -> 11800 | F31: =ROUND($D31*养成属性规划!D$3,0) -> 3540 | G31: =F31 -> 3540 | H31: =ROUND($D31*养成属性规划!E$3,0) -> 2360
... B74: 60 | C74: =$C$5 -> 0.08 | D74: =1+SUM($C$15:C74) -> 5.8 | E74: =ROUND($D74*养成属性规划!C$3,0) -> 29000 | F74: =ROUND($D74*养成属性规划!D$3,0) -> 8700 | G74: =F74 -> 8700 | H74: =ROUND($D74*养成属性规划!E$3,0) -> 5800

Sheet 属性定价
B2: 以攻击百分比为基准的属性定价
B3: 含义为每1%的攻击力百分比对应的属性
B6: 攻击百分比 | C6: 0.01
B7: 防御百分比 | C7: 0.01
B8: 生命百分比 | C8: 0.01
B9: 普攻速度百分比 | C9: 0
B10: 必杀回复速度 | C10: 0.0033
B11: 暴击率 | C11: 0.0018
B12: 暴击伤害 | C12: 0.0054
B13: 各种伤害增加 | C13: 0.0033
B14: 普攻伤害加成 | C14: 0.009
B15: 技能伤害加成 | C15: 0.012
B16: 必杀伤害加成 | C16: 0.012
B17: 治疗率 | C17: 0.005
... B28: 格挡等级 | C28: 100

Sheet 角色升星
B2: 角色升星养成概述
B4: 1 | C4: 4个节点投放天赋、被动提升，预计整体升星带来的战中提升可以达到1.8-2倍
B6: 2 | C6: 2个节点投放属性百分比和稀有二级属性、普通二级属性
B8: 预计投放的属性
B10: 预计最终基础属性% | F10: 预计偏向基础属性%+二级属性 | J10: 预计偏向稀有属性%
B11: 生命 | C11: 攻击 | D11: 防御 | F11: 偏向值 | J11: 偏向值
B12: =养成属性规划!G40 -> 0.9 | C12: =养成属性规划!H40 -> 0.9 | D12: =养成属性规划!I40 -> 0.9 | F12: =养成属性规划!P40 -> 0.6 | J12: =养成属性规划!S40 -> 0
B15: 角色星级 | C15: 投放内容
B16: 1 | C16: 天赋1 | N16: 以攻击百分比为基准的属性定价
B17: 2 | C17: 天赋2 | F17: 全属性 | G17: 二级属性 | N17: 攻击百分比 | O17: =属性定价!$C$6 -> 0.01
B18: 3 | C18: 全属性15%+普通二级属性20% | F18: 0.15 | G18: 0.3 | N18: 防御百分比 | O18: =属性定价!$C$7 -> 0.01
B19: 4 | C19: 天赋3 | N19: 生命百分比 | O19: =属性定价!$C$8 -> 0.01
B20: 5 | C20: 全属性15%+稀有二级属性20% | F20: 0.15 | G20: 0.3 | N20: 普攻速度百分比 | O20: =属性定价!$C$9 -> 0
B21: 6 | C21: 天赋4 | N21: 必杀回复速度 | O21: =属性定价!$C$10 -> 0.0033 | P21: 普攻伤害
N22: 暴击率 | O22: =属性定价!$C$11 -> 0.0018 | P22: 技能伤害
N23: 暴击伤害 | O23: =属性定价!$C$12 -> 0.0054 | P23: 必杀伤害
N24: 各种伤害增加 | O24: =属性定价!$C$13 -> 0.0033
N25: 普攻伤害加成 | O25: =属性定价!$C$14 -> 0.009
N26: 技能伤害加成 | O26: =属性定价!$C$15 -> 0.012
N27: 必杀伤害加成 | O27: =属性定价!$C$16 -> 0.012
N28: 治疗率 | O28: =属性定价!$C$17 -> 0.005
N29: 冷却缩减 | O29: =属性定价!$C$18 -> 0.0025
N30: 物理伤害加成 | O30: =属性定价!$C$19 -> 0.0042
N31: 魔法伤害加成 | O31: =属性定价!$C$20 -> 0.0042
N32: 暴击等级 | O32: =属性定价!$C$21 -> 90
N33: 暴击伤害等级 | O33: =属性定价!$C$22 -> 110
N34: 能量回复等级 | O34: =属性定价!$C$23 -> 90
N35: 技能冷却等级 | O35: =属性定价!$C$24 -> 130
N36: 攻击百分比 | O36: =属性定价!$C$25 -> 0.01
N37: 攻击百分比 | O37: =属性定价!$C$26 -> 0.01
N38: 格挡率 | O38: =属性定价!$C$27 -> 0.0033333333
N39: 格挡等级 | O39: =属性定价!$C$28 -> 100

Sheet 角色星盘
B2: 星盘养成概述
B4: 1 | C4: 角色星盘承载部分角色基础属性、同时投放部分偏向的普通二级属性和基础属性%
B6: 2 | C6: 每个角色选择3个偏向的普通二级属性和基础属性%，根据角色的定位和技能设计
C8: 例如一个物理C，可以选择 攻击力%，暴击率和暴击爆伤
B10: 3 | C10: 目前一共 | D10: 27 | E10: 个点位，免费投放的点位数量为 | H10: 21 | I10: 个，其中属性点位 | K10: 8 | L10: 个，技能点位 | N10: =D10-K10 -> 19 | O10: 个
K11: 属性点位越外环，给的属性越多
B13: 4 | C13: 预计投放的基础属性
G14: 预计偏向基础属性%+二级属性
C15: 生命 | D15: 攻击 | E15: 防御 | G15: 偏向值 | J15: 实际
C16: =养成属性规划!D39 -> 11500 | D16: =养成属性规划!E39 -> 3450 | E16: =养成属性规划!F39 -> 2300 | G16: =养成属性规划!P39 -> 1.2 | J16: =$F$45 -> 1.2
B20: 每次升级基础属性
C22: 生命 | D22: 攻击 | E22: 防御
C23: =ROUND(C16/$D$10,0) -> 426 | D23: =ROUND(D16/$D$10,0) -> 128 | E23: =ROUND(E16/$D$10,0) -> 85
B26: 点位设计
B29: 内圈 | E29: 中圈 | I29: 外圈
C31: 数量 | F31: 数量 | J31: 数量
B32: 普攻升级 | C32: 3 | E32: 普攻升级 | F32: 0 | I32: 普攻升级 | J32: 0
B33: 必杀升级 | C33: 3 | E33: 必杀升级 | F33: 0 | I33: 必杀升级 | J33: 0
B34: 被动升级 | C34: 3 | E34: 被动升级 | F34: 3 | I34: 被动升级 | J34: 3
B35: 属性激活 | C35: 0 | E35: 属性激活 | F35: 4 | I35: 属性激活 | J35: 4
B36: 额外能力 | C36: 0 | E36: 额外能力 | F36: 2 | I36: 额外能力 | J36: 2
C37: =SUM(C32:C36) -> 9 | F37: =SUM(F32:F36) -> 9 | J37: =SUM(J32:J36) -> 9
I38: 总 | J38: =J37+F37+C37 -> 27
B39: 属性点位
D41: 数量 | E41: 单点属性%
B42: 内圈 | D42: 0 | E42: 0 | F42: =E42*D42 -> 0 | M42: 攻击百分比 | N42: =属性定价!$C$6 -> 0.01
B43: 中圈 | D43: 4 | E43: 0.15 | F43: =E43*D43 -> 0.6 | M43: 防御百分比 | N43: =属性定价!$C$7 -> 0.01
B44: 外圈 | D44: 4 | E44: 0.15 | F44: =E44*D44 -> 0.6 | M44: 生命百分比 | N44: =属性定价!$C$8 -> 0.01
F45: =F42+F43+F44 -> 1.2 | M45: 普攻速度百分比 | N45: =属性定价!$C$9 -> 0
M46: 必杀回复速度 | N46: =属性定价!$C$10 -> 0.0033
M47: 暴击率 | N47: =属性定价!$C$11 -> 0.0018
B48: 投放模板 | M48: 暴击伤害 | N48: =属性定价!$C$12 -> 0.0054
M49: 各种伤害增加 | N49: =属性定价!$C$13 -> 0.0033
B50: 每个角色选择3个属性进行投放 | M50: 普攻伤害加成 | N50: =属性定价!$C$14 -> 0.009
M51: 技能伤害加成 | N51: =属性定价!$C$15 -> 0.012
B52: A | C52: B | D52: C | I52: 例如物理主C | M52: 必杀伤害加成 | N52: =属性定价!$C$16 -> 0.012
B53: =SUMIF($C$56:$C$64,B52,$D$56:$D$64) -> 0.3 | C53: =SUMIF($C$56:$C$64,C52,$D$56:$D$64) -> 0.45 | D53: =SUMIF($C$56:$C$64,D52,$D$56:$D$64) -> 0.45 | I53: 暴击 | J53: 暴击伤害 | K53: 攻击百分比 | M53: 治疗率 | N53: =属性定价!$C$17 -> 0.005
B54: 次要 | M54: 冷却缩减 | N54: =属性定价!$C$18 -> 0.0025
I55: 内圈 | M55: 物理伤害加成 | N55: =属性定价!$C$19 -> 0.0042
B56: 中圈 | C56: A | D56: =$E$43 -> 0.15 | J56: 暴击率 | K56: 0.02 | M56: 魔法伤害加成 | N56: =属性定价!$C$20 -> 0.0042
...

Sheet 专武
B2: 专武养成概述
B4: 1 | C4: 专武相当于角色机制的延伸，主要投放机制为主
B6: 2 | C6: 投放的具体属性为基础属性，和预计偏向基础属性%+二级属性
B8: 3 | C8: 升级给基础属性，突破给预计偏向基础属性%+二级属性，升星给技能机制升级
B10: 预计投放的属性
F11: 预计偏向基础属性%+二级属性 | K11: 可用二级属性
B12: 生命 | C12: 攻击 | D12: 防御 | F12: 偏向值 | K12: 普攻伤害加成
B13: =养成属性规划!D41 -> 20000 | C13: =养成属性规划!E41 -> 6000 | D13: =养成属性规划!F41 -> 4000 | F13: =养成属性规划!P41 -> 0.6 | K13: 技能伤害加成
K14: 必杀伤害加成
K15: 治疗率
B16: 规划专武上限等级 | K16: 技能冷却等级
B17: 60 | K17: 暴击等级
K18: 暴击伤害等级
B19: 基础属性占比 | C19: 0.15 | K19: 能量回复等级
B20: 每级属性成长 | C20: =(1-C19)/B17 -> 0.014166667 | K20: 攻击百分比
K21: 攻击百分比
B22: 装备面板属性1=（装备基础属性+（装备等级-1）*属性成长），面板显示四舍五入 | K22: 生命百分比
K23: 防御力百分比
B24: 基础属性 | G24: 突破属性 | K24: 格挡等级
B25: =VLOOKUP(A26,$M$45:$N$47,2,0) -> 1 | H25: 预计偏向基础属性%+二级属性
A26: SSR | B26: 生命 | C26: 攻击 | D26: 防御 | F26: 玩家等级 | G26: 突破等级 | H26: SSR | I26: SR | J26: R | L26: 投放示意 | M26: 暴击等级 | N26: 暴击伤害等级 | O26: 攻击百分比 | R26: 以攻击百分比为基准的属性定价
A27: 基础 | B27: =ROUND(B13*$C$19*$B$25,0) -> 3000 | C27: =ROUND(C13*$C$19*$B$25,0) -> 900 | D27: =ROUND(D13*$C$19*$B$25,0) -> 600 | F27: 0 | G27: 0 | H27: 0.2 | I27: =ROUND(H27*$Q$46,2) -> 0.15 | J27: =H27*$Q$45 -> 0.1 | R27: 攻击百分比 | S27: =属性定价!$C$6 -> 0.01
A28: 成长 | B28: =ROUND(B13*$C$20*$B$25,2) -> 283.33 | C28: =ROUND(C13*$C$20*$B$25,2) -> 85 | D28: =ROUND(D13*$C$20*$B$25,2) -> 56.67 | F28: 20 | G28: 20 | H28: 0.25 | I28: =ROUND(H28*$Q$46,2) -> 0.19 | J28: =H28*$Q$45 -> 0.125 | L28: 20 | M28: =O28/$S$27*$S$42 -> 1800 | N28: =O28/$S$27*$S$43 -> 2200 | O28: 0.2 | R28: 防御百分比 | S28: =属性定价!$C$7 -> 0.01
F29: 30 | G29: 30 | H29: 0.3 | I29: =ROUND(H29*$Q$46,2) -> 0.23 | J29: =H29*$Q$45 -> 0.15 | L29: 30 | M29: =O29/$S$27*$S$42 -> 2700 | N29: =O29/$S$27*$S$43 -> 3300 | O29: 0.3 | R29: 生命百分比 | S29: =属性定价!$C$8 -> 0.01
F30: 40 | G30: 40 | H30: 0.35 | I30: =ROUND(H30*$Q$46,2) -> 0.26 | J30: =H30*$Q$45 -> 0.175 | L30: 40 | M30: =O30/$S$27*$S$42 -> 3600 | N30: =O30/$S$27*$S$43 -> 4400 | O30: 0.4 | R30: 普攻速度百分比 | S30: =属性定价!$C$9 -> 0
B31: 0.8 | F31: 50 | G31: 50 | H31: 0.4 | I31: =ROUND(H31*$Q$46,2) -> 0.3 | J31: =H31*$Q$45 -> 0.2 | L31: 50 | M31: =O31/$S$27*$S$42 -> 4500 | N31: =O31/$S$27*$S$43 -> 5500 | O31: 0.5 | R31: 必杀回复速度 | S31: =属性定价!$C$10 -> 0.0033
A32: SR | B32: 生命 | C32: 攻击 | D32: 防御 | L32: 60 | M32: =O32/$S$27*$S$42 -> 5400 | N32: =O32/$S$27*$S$43 -> 6600 | O32: 0.6 | R32: 暴击率 | S32: =属性定价!$C$11 -> 0.0018
A33: 基础 | B33: =ROUND(B13*$C$19*$B$31,0) -> 2400 | C33: =ROUND(C13*$C$19*$B$31,0) -> 720 | D33: =ROUND(D13*$C$19*$B$31,0) -> 480 | R33: 暴击伤害 | S33: =属性定价!$C$12 -> 0.0054
A34: 成长 | B34: =ROUND(B13*$C$20*$B$31,2) -> 226.67 | C34: =ROUND(C13*$C$20*$B$31,2) -> 68 | D34: =ROUND(D13*$C$20*$B$31,2) -> 45.33 | R34: 各种伤害增加 | S34: =属性定价!$C$13 -> 0.0033
R35: 普攻伤害加成 | S35: =属性定价!$C$14 -> 0.009
R36: 技能伤害加成 | S36: =属性定价!$C$15 -> 0.012
B37: 0.7 | R37: 必杀伤害加成 | S37: =属性定价!$C$16 -> 0.012
A38: R | B38: 生命 | C38: 攻击 | D38: 防御 | R38: 治疗率 | S38: =属性定价!$C$17 -> 0.005
A39: 基础 | B39: =ROUND(B13*$C$19*$B$37,0) -> 2100 | C39: =ROUND(C13*$C$19*$B$37,0) -> 630 | D39: =ROUND(D13*$C$19*$B$37,0) -> 420 | G39: 升星数值 | R39: 冷却缩减 | S39: =属性定价!$C$18 -> 0.0025
A40: 成长 | B40: =ROUND(B13*$C$20*$B$37,2) -> 198.33 | C40: =ROUND(C13*$C$20*$B$37,2) -> 59.5 | D40: =ROUND(D13*$C$20*$B$37,2) -> 39.67 | R40: 物理伤害加成 | S40: =属性定价!$C$19 -> 0.0042
G41: 升星不带来任何属性提升，突破星级只带来被动提升 | R41: 魔法伤害加成 | S41: =属性定价!$C$20 -> 0.0042
R42: 暴击等级 | S42: =属性定价!$C$21 -> 90
G43: 预计提升加成 | M43: 专武基础属性品质系数 | P43: 专武基础属性品质系数 | R43: 暴击伤害等级 | S43: =属性定价!$C$22 -> 110
R44: 能量回复等级 | S44: =属性定价!$C$23 -> 90
G45: 星级 | H45: 战斗加成 | M45: R | N45: 0.8 | P45: R | Q45: 0.5 | R45: 技能冷却等级 | S45: =属性定价!$C$24 -> 130
...

Sheet 旅券
B2: 旅券数值概述
B4: 1 | C4: 角色中后期的属性追求之一，承载一部分养成坑深
B6: 2 | C6: 套装属性4+2,2件套为属性，4件套为效果
B8: 3 | C8: 每套旅券带个小被动，6件总的战斗提升期望为 | F8: 0.3
B10: 4 | C10: 预计投放的基础属性 | G10: 预计投放的二级属性
C12: 生命 | D12: 攻击 | E12: 防御 | G12: 二级属性
C13: =养成属性规划!D42 -> 30000 | D13: =养成属性规划!E42 -> 9000 | E13: =养成属性规划!F42 -> 6000 | G13: =养成属性规划!P42 -> 4.2
C16: 旅券预计投入属性 | F16: 以攻击百分比为基准的属性定价
C17: 普攻伤害加成 | F17: 攻击百分比 | G17: =属性定价!$C$6 -> 0.01
C18: 技能伤害加成 | F18: 防御百分比 | G18: =属性定价!$C$7 -> 0.01
C19: 必杀伤害加成 | F19: 生命百分比 | G19: =属性定价!$C$8 -> 0.01
C20: 治疗率 | F20: 普攻速度百分比 | G20: =属性定价!$C$9 -> 0
C21: 技能冷却等级 | F21: 必杀回复速度 | G21: =属性定价!$C$10 -> 0.0033 | H21: 普攻伤害
C22: 攻击力 | F22: 暴击率 | G22: =属性定价!$C$11 -> 0.0018 | H22: 技能伤害
C23: 攻击力 | F23: 暴击伤害 | G23: =属性定价!$C$12 -> 0.0054 | H23: 必杀伤害
C24: 防御 | F24: 各种伤害增加 | G24: =属性定价!$C$13 -> 0.0033
C25: 生命 | F25: 普攻伤害加成 | G25: =属性定价!$C$14 -> 0.009
C26: 暴击等级 | F26: 技能伤害加成 | G26: =属性定价!$C$15 -> 0.012
C27: 暴击伤害等级 | F27: 必杀伤害加成 | G27: =属性定价!$C$16 -> 0.012
C28: 能量回复等级 | F28: 治疗率 | G28: =属性定价!$C$17 -> 0.005
C29: 攻击百分比 | F29: 冷却缩减 | G29: =属性定价!$C$18 -> 0.0025
C30: 攻击百分比 | F30: 物理伤害加成 | G30: =属性定价!$C$19 -> 0.0042
C31: 生命百分比 | F31: 魔法伤害加成 | G31: =属性定价!$C$20 -> 0.0042
C32: 防御力百分比 | F32: 暴击等级 | G32: =属性定价!$C$21 -> 90
C33: 格挡等级 | F33: 暴击伤害等级 | G33: =属性定价!$C$22 -> 110
F34: 能量回复等级 | G34: =属性定价!$C$23 -> 90
F35: 技能冷却等级 | G35: =属性定价!$C$24 -> 130
F36: 攻击百分比 | G36: =属性定价!$C$25 -> 0.01
F37: 攻击百分比 | G37: =属性定价!$C$26 -> 0.01
F38: 格挡率 | G38: =属性定价!$C$27 -> 0.0033333333
F39: 格挡等级 | G39: =属性定价!$C$28 -> 100
B43: 旅券主副属性二级属性分配
B45: 主属性权重 | C45: 32 | D45: =C45/SUM(C45:C46) -> 0.32
B46: 副属性权重 | C46: 68 | D46: =C46/SUM(C45:C46) -> 0.68
B48: 主属性二级属性 | C48: =D45*$G$13 -> 1.344
B49: 副属性二级属性 | C49: =D46*$G$13 -> 2.856
B54: 旅券品质系数
B56: 普通 | C56: 0.4
B57: 稀有 | C57: 0.6
B58: 史诗 | C58: 0.8
...

Sheet 配置页-旅券
B2: 主属性
A3: 品质 | B3: 生命 | C3: 生命 | D3: 攻击力 | E3: =D3 -> 攻击力 | F3: 攻击力 | G3: =F3 -> 攻击力 | H3: 防御 | I3: =H3 -> 防御 | J3: 生命百分比 | K3: =J3 -> 生命百分比 | L3: 攻击百分比 | M3: =L3 -> 攻击百分比 | N3: 攻击百分比 | O3: =N3 -> 攻击百分比 | P3: 防御百分比 | Q3: =P3 -> 防御百分比 | R3: 普攻伤害加成 | S3: =R3 -> 普攻伤害加成 | T3: 技能伤害加成 | U3: =T3 -> 技能伤害加成 | V3: 必杀伤害加成 | W3: =V3 -> 必杀伤害加成 | X3: 治疗率 | Y3: =X3 -> 治疗率 | Z3: 技能冷却等级 | AA3: =Z3 -> 技能冷却等级 | AB3: 暴击等级 | AC3: =AB3 -> 暴击等级 | AD3: 暴击伤害等级 | AE3: =AD3 -> 暴击伤害等级 | AF3: 能量回复等级 | AG3: =AF3 -> 能量回复等级 | AH3: 格挡等级 | AI3: =AH3 -> 格挡等级
A4: 2 | B4: =B$7*旅券!$C56 -> 2400 | C4: =C$7*旅券!$C56 -> 1920 | D4: =D$7*旅券!$C56 -> 720 | E4: =E$7*旅券!$C56 -> 576 | F4: =F$7*旅券!$C56 -> 720 | G4: =G$7*旅券!$C56 -> 576 | H4: =H$7*旅券!$C56 -> 480 | I4: =I$7*旅券!$C56 -> 384 | ... AI4: =AI$7*旅券!$C56 -> 288
A5: 3 | B5: =B$7*旅券!$C57 -> 3600 | C5: =C$7*旅券!$C57 -> 2880 | D5: =D$7*旅券!$C57 -> 1080 | E5: =E$7*旅券!$C57 -> 864 | F5: =F$7*旅券!$C57 -> 1080 | G5: =G$7*旅券!$C57 -> 864 | H5: =H$7*旅券!$C57 -> 720 | I5: =I$7*旅券!$C57 -> 576 | ... AI5: =AI$7*旅券!$C57 -> 432
A6: 4 | B6: =B$7*旅券!$C58 -> 4800 | C6: =C$7*旅券!$C58 -> 3840 | D6: =D$7*旅券!$C58 -> 1440 | E6: =E$7*旅券!$C58 -> 1152 | F6: =F$7*旅券!$C58 -> 1440 | G6: =G$7*旅券!$C58 -> 1152 | H6: =H$7*旅券!$C58 -> 960 | I6: =I$7*旅券!$C58 -> 768 | ... AI6: =AI$7*旅券!$C58 -> 576
A7: 5 | B7: =ROUND(VLOOKUP(B$3,旅券!$B$94:$F$111,4,0),-1) -> 6000 | C7: =ROUND(VLOOKUP(C$3,旅券!$B$94:$F$111,5,0),-1) -> 4800 | D7: =ROUND(VLOOKUP(D$3,旅券!$B$94:$F$111,4,0),-1) -> 1800 | E7: =ROUND(VLOOKUP(E$3,旅券!$B$94:$F$111,5,0),-1) -> 1440 | F7: =ROUND(VLOOKUP(F$3,旅券!$B$94:$F$111,4,0),-1) -> 1800 | G7: =ROUND(VLOOKUP(G$3,旅券!$B$94:$F$111,5,0),-1) -> 1440 | H7: =ROUND(VLOOKUP(H$3,旅券!$B$94:$F$111,4,0),-1) -> 1200 | I7: =ROUND(VLOOKUP(I$3,旅券!$B$94:$F$111,5,0),-1) -> 960 | J7: =ROUND(VLOOKUP(J$3,旅券!$B$94:$F$111,4,0),3) -> 0.09 | K7: =ROUND(VLOOKUP(K$3,旅券!$B$94:$F$111,5,0),3) -> 0.072 | L7: =ROUND(VLOOKUP(L$3,旅券!$B$94:$F$111,4,0),3) -> 0.09 | M7: =ROUND(VLOOKUP(M$3,旅券!$B$94:$F$111,5,0),3) -> 0.072 | N7: =ROUND(VLOOKUP(N$3,旅券!$B$94:$F$111,4,0),3) -> 0.09 | O7: =ROUND(VLOOKUP(O$3,旅券!$B$94:$F$111,5,0),3) -> 0.072 | P7: =ROUND(VLOOKUP(P$3,旅券!$B$94:$F$111,4,0),3) -> 0.09 | Q7: =ROUND(VLOOKUP(Q$3,旅券!$B$94:$F$111,5,0),3) -> 0.072 | R7: =ROUND(VLOOKUP(R$3,旅券!$B$94:$F$111,4,0),3) -> 0.081 | S7: =ROUND(VLOOKUP(S$3,旅券!$B$94:$F$111,5,0),3) -> 0.065 | T7: =ROUND(VLOOKUP(T$3,旅券!$B$94:$F$111,4,0),3) -> 0.108 | U7: =ROUND(VLOOKUP(U$3,旅券!$B$94:$F$111,5,0),3) -> 0.086 | V7: =ROUND(VLOOKUP(V$3,旅券!$B$94:$F$111,4,0),3) -> 0.108 | W7: =ROUND(VLOOKUP(W$3,旅券!$B$94:$F$111,5,0),3) -> 0.086 | X7: =ROUND(VLOOKUP(X$3,旅券!$B$94:$F$111,4,0),3) -> 0.045 | Y7: =ROUND(VLOOKUP(Y$3,旅券!$B$94:$F$111,5,0),3) -> 0.036 | Z7: =ROUND(VLOOKUP(Z$3,旅券!$B$94:$F$111,4,0),-1) -> 1160 | AA7: =ROUND(VLOOKUP(AA$3,旅券!$B$94:$F$111,5,0),-1) -> 930 | AB7: =ROUND(VLOOKUP(AB$3,旅券!$B$94:$F$111,4,0),-1) -> 810 | AC7: =ROUND(VLOOKUP(AC$3,旅券!$B$94:$F$111,5,0),-1) -> 650 | AD7: =ROUND(VLOOKUP(AD$3,旅券!$B$94:$F$111,4,0),-1) -> 990 | AE7: =ROUND(VLOOKUP(AE$3,旅券!$B$94:$F$111,5,0),-1) -> 790 | AF7: =ROUND(VLOOKUP(AF$3,旅券!$B$94:$F$111,4,0),-1) -> 810 | AG7: =ROUND(VLOOKUP(AG$3,旅券!$B$94:$F$111,5,0),-1) -> 650 | AH7: =ROUND(VLOOKUP(AH$3,旅券!$B$94:$F$111,4,0),-1) -> 900 | AI7: =ROUND(VLOOKUP(AI$3,旅券!$B$94:$F$111,5,0),-1) -> 720
B10: 副属性
A12: 品质 | B12: 暴击等级 | C12: 暴击伤害等级 | D12: 攻击百分比 | E12: 攻击百分比 | F12: 生命百分比 | G12: 防御百分比 | H12: 当前行是否有效
A13: 2 | B13: =ROUND(B$16*旅券!$C56,0) -> 245 | C13: =ROUND(C$16*旅券!$C56,0) -> 300 | D13: =ROUND(D$16*旅券!$C56,3) -> 0.027 | E13: =ROUND(E$16*旅券!$C56,3) -> 0.027 | F13: =ROUND(F$16*旅券!$C56,3) -> 0.027 | G13: =ROUND(G$16*旅券!$C56,3) -> 0.027 | H13: true
A14: 3 | B14: =ROUND(B$16*旅券!$C57,0) -> 368 | C14: =ROUND(C$16*旅券!$C57,0) -> 449 | D14: =ROUND(D$16*旅券!$C57,3) -> 0.041 | E14: =ROUND(E$16*旅券!$C57,3) -> 0.041 | F14: =ROUND(F$16*旅券!$C57,3) -> 0.041 | G14: =ROUND(G$16*旅券!$C57,3) -> 0.041 | H14: true
A15: 4 | B15: =ROUND(B$16*旅券!$C58,0) -> 490 | C15: =ROUND(C$16*旅券!$C58,0) -> 599 | D15: =ROUND(D$16*旅券!$C58,3) -> 0.054 | E15: =ROUND(E$16*旅券!$C58,3) -> 0.054 | F15: =ROUND(F$16*旅券!$C58,3) -> 0.054 | G15: =ROUND(G$16*旅券!$C58,3) -> 0.054 | H15: true
A16: 5 | B16: =ROUND(旅券!$E$126,0) -> 613 | C16: =ROUND(旅券!$E$127,0) -> 749 | D16: =ROUND(旅券!$E$128,3) -> 0.068 | E16: =ROUND(旅券!$E$129,3) -> 0.068 | F16: =ROUND(旅券!$E$130,3) -> 0.068 | G16: =ROUND(旅券!$E$131,3) -> 0.068 | H16: true

Sheet 配置页-推荐邮票
A1: ##var | B1: ID | C1: HeroId | D1: ## | E1: Priority | F1: StrategyId | G1: PrimAttr | H1: SecAttr | I1: IsValid
A2: ##type | B2: int | C2: int | E2: int | F2: int | G2: (array#sep=;),string | H2: (array#sep=;),string | I2: bool
A3: ##group
A4: ## | B4: 排序 | C4: 武将ID | D4: 武将名称（辅助） | E4: 推荐优先级(1=最高) | F4: 旅券套装ID | G4: 推荐主属性(4号位;5号位;6号位) | H4: 推荐副属性 | I4: 当前行是否有效
B5: =ROW()-4 -> 1 | C5: 1001 | D5: 星海 | E5: 1 | F5: 3 | G5: PhysicsAttackBonus;Crit;CritDmgBonus | H5: PhysicsAttackBonus;Crit;CritDmgBonus | I5: true
B6: =ROW()-4 -> 2 | C6: 1001 | D6: 星海 | E6: 2 | F6: 12 | G6: PhysicsAttackBonus;Crit;CritDmgBonus | H6: PhysicsAttackBonus;Crit;CritDmgBonus | I6: true
B7: =ROW()-4 -> 3 | C7: 1001 | D7: 星海 | E7: 3 | F7: 4 | G7: PhysicsAttackBonus;Crit;CritDmgBonus | H7: PhysicsAttackBonus;Crit;CritDmgBonus | I7: true
B8: =ROW()-4 -> 4 | C8: 1001 | D8: 星海 | E8: 4 | F8: 11 | G8: PhysicsAttackBonus;Crit;CritDmgBonus | H8: PhysicsAttackBonus;Crit;CritDmgBonus | I8: true
B9: =ROW()-4 -> 5 | C9: 1002 | D9: 大暑 | E9: 1 | F9: 16 | G9: ArmorBonus;HpBonus;EnergyPreAddBonus | H9: ArmorBonus;HpBonus;PhysicsAttackBonus | I9: true
B10: =ROW()-4 -> 6 | C10: 1002 | D10: 大暑 | E10: 2 | F10: 13 | G10: ArmorBonus;HpBonus;EnergyPreAddBonus | H10: ArmorBonus;HpBonus;PhysicsAttackBonus | I10: true
B11: =ROW()-4 -> 7 | C11: 1002 | D11: 大暑 | E11: 3 | F11: 15 | G11: ArmorBonus;HpBonus;EnergyPreAddBonus | H11: ArmorBonus;HpBonus;PhysicsAttackBonus | I11: true
B12: =ROW()-4 -> 8 | C12: 1002 | D12: 大暑 | E12: 4 | F12: 18 | G12: ArmorBonus;HpBonus;EnergyPreAddBonus | H12: ArmorBonus;HpBonus;PhysicsAttackBonus | I12: true
B13: =ROW()-4 -> 9 | C13: 1003 | D13: 塔拉夏 | E13: 1 | F13: 16 | G13: HpBonus;MagicAttackBonus;Crit | H13: HpBonus;MagicAttackBonus;Crit;ArmorBonus | I13: true
B14: =ROW()-4 -> 10 | C14: 1003 | D14: 塔拉夏 | E14: 2 | F14: 13 | G14: HpBonus;MagicAttackBonus;Crit | H14: HpBonus;MagicAttackBonus;Crit;ArmorBonus | I14: true
B15: =ROW()-4 -> 11 | C15: 1003 | D15: 塔拉夏 | E15: 3 | F15: 15 | G15: HpBonus;MagicAttackBonus;Crit | H15: HpBonus;MagicAttackBonus;Crit;ArmorBonus | I15: true
B16: =ROW()-4 -> 12 | C16: 1003 | D16: 塔拉夏 | E16: 4 | F16: 18 | G16: HpBonus;MagicAttackBonus;Crit | H16: HpBonus;MagicAttackBonus;Crit;ArmorBonus | I16: true
... B116: =ROW()-4 -> 112 | C116: 1040 | D116: 小寒 | E116: 4 | F116: 22 | G116: MagicAttackBonus;EnergyPreAddBonus;HpBonus | H116: MagicAttackBonus;HpBonus;ArmorBonus | I116: true

Sheet 炮台养成数值
B2: 炮台养成是独立于其他养成模块的特殊养成
B3: 只在竞技场（PVPVE）中使用
B4: 玩法简介：两个玩家同时打相同的关卡，如果没清理掉的怪会撞到玩家的屏障，导致掉血，最后血量百分比更高的玩家获胜
B6: 炮台只有两个属性
B7: 生命 | C7: 作用于PVPVE中的玩家屏障数值，具体计算方式为：屏障生命=玩家基础生命+所有炮台生命之和
B8: 攻击 | C8: 作用于PVPVE中的怪攻击击力数值，具体计算方式为：怪攻击击=怪物基础攻击+所有炮台攻击之和
B10: 参数区
C11: 炮台等级上限 | D11: 突破次数
B12: B | C12: 30 | D12: 2
B13: A | C13: 40 | D13: 3
B14: S | C14: 50 | D14: 4
B16: 品阶系数 | C16: 品阶系数在角色初始、升级、升阶和星盘处投放的基础属性数值需要乘上一个百分比
B17: B | C17: 0.5
B18: A | C18: 0.75
B19: S | C19: 1
B20: 水晶基础生命 | C20: 10000 | D20: 炮台上限生命 | E20: 9000 | F20: 炮台数量 | G20: 3 | H20: 单炮台生命 | I20: =E20/$G$20 -> 3000
B21: 水晶基础攻击 | C21: 0 | D21: 炮台上限攻击 | E21: 900 | H21: 单炮台攻击 | I21: =E21/$G$20 -> 300
B23: 正式数值区
B25: S炮台系数 | F25: A炮台系数 | J25: B炮台系数
B27: 等级 | C27: 生命 | D27: 攻击 | F27: 等级 | G27: 生命 | H27: 攻击 | J27: 等级 | K27: 生命 | L27: 攻击
B28: {=_xlfn.SEQUENCE(C14,1,1,1)} -> 1 | C28: =$I$20/$C$14*B28 -> 60 | D28: =$I$21/$C$14*B28 -> 6 | F28: {=_xlfn.SEQUENCE(C13,1,1,1)} -> 1 | G28: =C28*$C$18 -> 45 | H28: =INT(D28*$C$18) -> 4 | J28: {=_xlfn.SEQUENCE(C12,1,1,1)} -> 1 | K28: =C28*$C$17 -> 30 | L28: =INT(D28*$C$17) -> 3
B29: 2 | C29: =$I$20/$C$14*B29 -> 120 | D29: =$I$21/$C$14*B29 -> 12 | F29: 2 | G29: =C29*$C$18 -> 90 | H29: =INT(D29*$C$18) -> 9 | J29: 2 | K29: =C29*$C$17 -> 60 | L29: =INT(D29*$C$17) -> 6
B30: 3 | C30: =$I$20/$C$14*B30 -> 180 | D30: =$I$21/$C$14*B30 -> 18 | F30: 3 | G30: =C30*$C$18 -> 135 | H30: =INT(D30*$C$18) -> 13 | J30: 3 | K30: =C30*$C$17 -> 90 | L30: =INT(D30*$C$17) -> 9
B31: 4 | C31: =$I$20/$C$14*B31 -> 240 | D31: =$I$21/$C$14*B31 -> 24 | F31: 4 | G31: =C31*$C$18 -> 180 | H31: =INT(D31*$C$18) -> 18 | J31: 4 | K31: =C31*$C$17 -> 120 | L31: =INT(D31*$C$17) -> 12
B32: 5 | C32: =$I$20/$C$14*B32 -> 300 | D32: =$I$21/$C$14*B32 -> 30 | F32: 5 | G32: =C32*$C$18 -> 225 | H32: =INT(D32*$C$18) -> 22 | J32: 5 | K32: =C32*$C$17 -> 150 | L32: =INT(D32*$C$17) -> 15
B33: 6 | C33: =$I$20/$C$14*B33 -> 360 | D33: =$I$21/$C$14*B33 -> 36 | F33: 6 | G33: =C33*$C$18 -> 270 | H33: =INT(D33*$C$18) -> 27 | J33: 6 | K33: =C33*$C$17 -> 180 | L33: =INT(D33*$C$17) -> 18
B34: 7 | C34: =$I$20/$C$14*B34 -> 420 | D34: =$I$21/$C$14*B34 -> 42 | F34: 7 | G34: =C34*$C$18 -> 315 | H34: =INT(D34*$C$18) -> 31 | J34: 7 | K34: =C34*$C$17 -> 210 | L34: =INT(D34*$C$17) -> 21
B35: 8 | C35: =$I$20/$C$14*B35 -> 480 | D35: =$I$21/$C$14*B35 -> 48 | F35: 8 | G35: =C35*$C$18 -> 360 | H35: =INT(D35*$C$18) -> 36 | J35: 8 | K35: =C35*$C$17 -> 240 | L35: =INT(D35*$C$17) -> 24
B36: 9 | C36: =$I$20/$C$14*B36 -> 540 | D36: =$I$21/$C$14*B36 -> 54 | F36: 9 | G36: =C36*$C$18 -> 405 | H36: =INT(D36*$C$18) -> 40 | J36: 9 | K36: =C36*$C$17 -> 270 | L36: =INT(D36*$C$17) -> 27
B37: 10 | C37: =$I$20/$C$14*B37 -> 600 | D37: =$I$21/$C$14*B37 -> 60 | F37: 10 | G37: =C37*$C$18 -> 450 | H37: =INT(D37*$C$18) -> 45 | J37: 10 | K37: =C37*$C$17 -> 300 | L37: =INT(D37*$C$17) -> 30
B38: 11 | C38: =$I$20/$C$14*B38 -> 660 | D38: =$I$21/$C$14*B38 -> 66 | F38: 11 | G38: =C38*$C$18 -> 495 | H38: =INT(D38*$C$18) -> 49 | J38: 11 | K38: =C38*$C$17 -> 330 | L38: =INT(D38*$C$17) -> 33
B39: 12 | C39: =$I$20/$C$14*B39 -> 720 | D39: =$I$21/$C$14*B39 -> 72 | F39: 12 | G39: =C39*$C$18 -> 540 | H39: =INT(D39*$C$18) -> 54 | J39: 12 | K39: =C39*$C$17 -> 360 | L39: =INT(D39*$C$17) -> 36
B40: 13 | C40: =$I$20/$C$14*B40 -> 780 | D40: =$I$21/$C$14*B40 -> 78 | F40: 13 | G40: =C40*$C$18 -> 585 | H40: =INT(D40*$C$18) -> 58 | J40: 13 | K40: =C40*$C$17 -> 390 | L40: =INT(D40*$C$17) -> 39
... B57: 30 | C57: =$I$20/$C$14*B57 -> 1800 | D57: =$I$21/$C$14*B57 -> 180 | F57: 30 | G57: =C57*$C$18 -> 1350 | H57: =INT(D57*$C$18) -> 135 | J57: 30 | K57: =C57*$C$17 -> 900 | L57: =INT(D57*$C$17) -> 90
B58: 31 | C58: =$I$20/$C$14*B58 -> 1860 | D58: =$I$21/$C$14*B58 -> 186 | F58: 31 | G58: =C58*$C$18 -> 1395 | H58: =INT(D58*$C$18) -> 139
B59: 32 | C59: =$I$20/$C$14*B59 -> 1920 | D59: =$I$21/$C$14*B59 -> 192 | F59: 32 | G59: =C59*$C$18 -> 1440 | H59: =INT(D59*$C$18) -> 144
B60: 33 | C60: =$I$20/$C$14*B60 -> 1980 | D60: =$I$21/$C$14*B60 -> 198 | F60: 33 | G60: =C60*$C$18 -> 1485 | H60: =INT(D60*$C$18) -> 148
B61: 34 | C61: =$I$20/$C$14*B61 -> 2040 | D61: =$I$21/$C$14*B61 -> 204 | F61: 34 | G61: =C61*$C$18 -> 1530 | H61: =INT(D61*$C$18) -> 153
B62: 35 | C62: =$I$20/$C$14*B62 -> 2100 | D62: =$I$21/$C$14*B62 -> 210 | F62: 35 | G62: =C62*$C$18 -> 1575 | H62: =INT(D62*$C$18) -> 157
B63: 36 | C63: =$I$20/$C$14*B63 -> 2160 | D63: =$I$21/$C$14*B63 -> 216 | F63: 36 | G63: =C63*$C$18 -> 1620 | H63: =INT(D63*$C$18) -> 162
...

Sheet 设计页-映射装备数值
B2: 主角装备数值概述 | K2: 映射装备属性
K3: 攻击百分比
B4: 1 | C4: 玩家终局养成系统，用随机词条带来究极坑深，承载后期玩家的日活和养成目标，投放的属性占比很大 | K4: 攻击百分比
K5: 防御百分比
B6: 2 | C6: 投放基础属性、基础属性%和普通二级属性 | K6: 生命百分比
K7: 冷却缩减
B8: 3 | C8: 主属性固定，副属性做强的词条与上下限随机 | K8: 必杀回复速度
K9: 暴击率
B10: 4 | C10: 每个装备上会有孔位，数量随机，可以镶嵌宝石和铭文，每个装备上的宝石和铭文可以组成套装 | K10: 暴击伤害
K11: 物理伤害加成
B12: 5 | C12: 宝石可以合成高级宝石，铭文暂时不行 | K12: 魔法伤害加成
K13: 攻击力
C14: 总体的感受应该如下：玩家全力去追求一套毕业的装备，还是词条、孔位上理论上是会有最优解 | K14: 攻击力
K15: 防御
K16: 生命
B25: 6 | C25: 预计投放属性
C27: 基础属性 | O27: 装备副属性+宝石属性
G28: 预计全部基础属性% | K28: 预计偏向全部二级属性 | O28: 预计偏向基础属性%+二级属性+稀有二级属性
C29: 生命 | D29: 攻击 | E29: 防御 | G29: 生命 | H29: 攻击 | I29: 防御 | K29: 偏向值 | O29: 偏向值
C30: =养成属性规划!D43 -> 50000 | D30: =养成属性规划!E43 -> 15000 | E30: =养成属性规划!F43 -> 10000 | G30: =养成属性规划!J43 -> 2.4 | H30: =养成属性规划!K43 -> 2.4 | I30: =养成属性规划!L43 -> 2.4 | K30: =养成属性规划!M43 -> 1.6 | O30: =养成属性规划!P43+养成属性规划!S43 -> 7
B39: 装备主属性
C41: 基础属性分配 | F41: 主属性基础属性
C43: 装备主属性 | D43: 0.75 | F43: 生命 | G43: 攻击 | H43: 防御
C44: 宝石 | D44: 0.25 | F44: =C30*$D$43 -> 37500 | G44: =D30*$D$43 -> 11250 | H44: =E30*$D$43 -> 7500
C47: 部位类型 | D47: 部位再分类 | E47: 主属性1 | F47: 属性占比 | G47: 主属性2 | H47: 属性占比 | K47: 总计
C48: 武器 | D48: 手炮 | E48: 攻击 | F48: 0.5 | G48: 攻击 | H48: 0.5 | K48: 生命 | L48: =SUMIF($G$48:$G$57,K48,$H$48:$H$57)+SUMIF($E$48:$E$57,K48,$F$48:$F$57) -> 1 | O48: 以攻击百分比为基准的属性定价
D49: 枪 | E49: 攻击 | F49: 0.5 | G49: 暴击 | H49: 0.8 | K49: 攻击 | L49: =SUMIF($G$48:$G$57,K49,$H$48:$H$57)+SUMIF($E$48:$E$57,K49,$F$48:$F$57)-F48 -> 2.5 | O49: 攻击百分比 | Q49: =属性定价!$C$6 -> 0.01
D50: 权杖 | E50: 攻击 | F50: 0.5 | G50: 暴击 | H50: 0.8 | K50: 攻击 | L50: =SUMIF($G$48:$G$57,K50,$H$48:$H$57)+SUMIF($E$48:$E$57,K50,$F$48:$F$57)-F48 -> 2.5 | O50: 防御百分比 | Q50: =属性定价!$C$7 -> 0.01
C51: 头盔 | D51: / | E51: 生命 | F51: 0.5 | G51: 攻击% | H51: 1 | K51: 防御 | L51: =SUMIF($G$48:$G$57,K51,$H$48:$H$57)+SUMIF($E$48:$E$57,K51,$F$48:$F$57) -> 1 | O51: 生命百分比 | Q51: =属性定价!$C$8 -> 0.01
C52: 铠甲 | E52: 防御 | F52: 0.5 | G52: 防御% | H52: 1 | J52: 二级 | K52: 暴击 | L52: =SUMIF($G$48:$G$57,K52,$H$48:$H$57)+SUMIF($E$48:$E$57,K52,$F$48:$F$57)-H49 -> 1.6 | O52: 普攻速度百分比 | Q52: =属性定价!$C$9 -> 0
C53: 手套 | E53: 防御 | F53: 0.5 | G53: 攻击% | H53: 1 | K53: 暴击伤害 | L53: =SUMIF($G$48:$G$57,K53,$H$48:$H$57)+SUMIF($E$48:$E$57,K53,$F$48:$F$57) -> 1 | O53: 必杀回复速度 | Q53: =属性定价!$C$10 -> 0.0033
C54: 腰带 | E54: 生命 | F54: 0.5 | G54: 生命% | H54: 1 | K54: 攻击% | L54: =SUMIF($G$48:$G$57,K54,$H$48:$H$57)+SUMIF($E$48:$E$57,K54,$F$48:$F$57) -> 2 | O54: 暴击率 | Q54: =属性定价!$C$11 -> 0.0018
C55: 鞋子 | E55: 攻击 | F55: 0.5 | G55: 冷却缩减 | H55: 0.7 | K55: 攻击% | L55: =SUMIF($G$48:$G$57,K55,$H$48:$H$57)+SUMIF($E$48:$E$57,K55,$F$48:$F$57) -> 2 | O55: 暴击伤害 | Q55: =属性定价!$C$12 -> 0.0054
C56: 装置 | E56: 攻击 | F56: 0.5 | G56: 能量回复速度% | H56: 0.7 | K56: 防御% | L56: =SUMIF($G$48:$G$57,K56,$H$48:$H$57)+SUMIF($E$48:$E$57,K56,$F$48:$F$57) -> 1 | O56: 各种伤害增加 | Q56: =属性定价!$C$13 -> 0.0033
C57: 饰品 | E57: 暴击 | F57: 0.8 | G57: 暴击伤害 | H57: 1 | K57: 生命% | L57: =SUMIF($G$48:$G$57,K57,$H$48:$H$57)+SUMIF($E$48:$E$57,K57,$F$48:$F$57) -> 1 | O57: 普攻伤害加成 | Q57: =属性定价!$C$14 -> 0.009
K58: 能量回复速度% | L58: =SUMIF($G$48:$G$57,K58,$H$48:$H$57)+SUMIF($E$48:$E$57,K58,$F$48:$F$57) -> 0.7 | O58: 技能伤害加成 | Q58: =属性定价!$C$15 -> 0.012
K59: 冷却缩减 | L59: =SUMIF($G$48:$G$57,K59,$H$48:$H$57)+SUMIF($E$48:$E$57,K59,$F$48:$F$57) -> 0.7 | O59: 必杀伤害加成 | Q59: =属性定价!$C$16 -> 0.012
L60: =SUM(L54:L57) -> 6 | M60: =SUM(L52:L59)-L60 -> 4 | O60: 治疗率 | Q60: =属性定价!$C$17 -> 0.005
K61: 单个偏向值 | L61: =G30/L60 -> 0.4 | M61: =K30/M60 -> 0.4 | O61: 冷却缩减 | Q61: =属性定价!$C$18 -> 0.0025
O62: 物理伤害加成 | Q62: =属性定价!$C$19 -> 0.0042
...

Sheet 映射装备数值
A1: 稀有度部分
A2: 品质 | B2: 等级上限 | C2: 主属性品质系数 | D2: 副属性品质系数 | E2: 孔位上限 | F2: 孔位下限 | G2: 副词条上限 | H2: 副词条下限 | I2: 分解基础经验 | J2: 分解额外道具获得 | K2: 打孔道具消耗 | L2: 打孔金币消耗
A3: 蓝 | B3: 30 | C3: ='设计页-映射装备数值'!D150 -> 0.3 | D3: ='设计页-映射装备数值'!H164 -> 0.3 | E3: ='设计页-映射装备数值'!D314 -> 2 | F3: ='设计页-映射装备数值'!C314 -> 0 | G3: 2 | H3: 1 | I3: 500 | K3: 蓝色打孔器 | L3: 1000
A4: 紫 | B4: 40 | C4: ='设计页-映射装备数值'!D151 -> 0.5 | D4: ='设计页-映射装备数值'!H165 -> 0.5 | E4: ='设计页-映射装备数值'!D315 -> 2 | F4: ='设计页-映射装备数值'!C315 -> 0 | G4: 3 | H4: 1 | I4: 1500 | K4: 紫色打孔器 | L4: 1000
A5: 金 | B5: 50 | C5: ='设计页-映射装备数值'!D152 -> 0.75 | D5: ='设计页-映射装备数值'!H166 -> 0.75 | E5: ='设计页-映射装备数值'!D316 -> 2 | F5: ='设计页-映射装备数值'!C316 -> 0 | G5: 4 | H5: 2 | I5: 5000 | J5: 史诗装备材料5 | K5: 金色打孔器 | L5: 1000
A6: 红 | B6: 60 | C6: ='设计页-映射装备数值'!D153 -> 1 | D6: ='设计页-映射装备数值'!H167 -> 1 | E6: ='设计页-映射装备数值'!D317 -> 2 | F6: ='设计页-映射装备数值'!C317 -> 0 | G6: 5 | H6: 5 | I6: 10000 | J6: 传说装备材料5 | K6: 红色打孔器 | L6: 1000
A8: 主属性部分 | B8: 品质系数*（装备基础属性+（装备等级-1）*属性成长） | O8: 分解部分
A9: 部位 | B9: 部位再分类 | C9: 稀有度 | D9: 主属性1 | E9: 基础属性 | F9: 属性成长系数 | G9: 1级数值 | H9: 满级数值 | I9: 主属性2 | J9: 基础属性 | K9: 属性成长系数 | L9: 1级数值 | M9: 满级数值 | O9: 分解经验系数
A10: 武器 | B10: 仪器 | C10: 蓝 | D10: 攻击 | E10: =VLOOKUP($C10,$A$3:$L$6,3,0)*E13 -> 168 | F10: =VLOOKUP($C10,$A$3:$L$6,3,0)*F13 -> 25.2 | G10: =VLOOKUP($C10,$A$3:$L$6,3,0)*G13 -> 193.2 | H10: =E10+VLOOKUP(C10,$A$3:$L$6,2,0)*F10 -> 924 | I10: 暴击等级 | J10: =VLOOKUP($C10,$A$3:$L$6,3,0)*J13 -> 87 | K10: =VLOOKUP($C10,$A$3:$L$6,3,0)*K13 -> 13.2 | L10: =VLOOKUP($C10,$A$3:$L$6,3,0)*L13 -> 100.2 | M10: =J10+VLOOKUP(C10,$A$3:$L$6,2,0)*K10 -> 483 | O10: 0.8
A11: 武器 | B11: 仪器 | C11: 紫 | D11: 攻击 | E11: =VLOOKUP($C11,$A$3:$L$6,3,0)*E13 -> 280 | F11: =VLOOKUP($C11,$A$3:$L$6,3,0)*F13 -> 42 | G11: =VLOOKUP($C11,$A$3:$L$6,3,0)*G13 -> 322 | H11: =E11+VLOOKUP(C11,$A$3:$L$6,2,0)*F11 -> 1960 | I11: 暴击等级 | J11: =VLOOKUP($C11,$A$3:$L$6,3,0)*J13 -> 145 | K11: =VLOOKUP($C11,$A$3:$L$6,3,0)*K13 -> 22 | L11: =VLOOKUP($C11,$A$3:$L$6,3,0)*L13 -> 167 | M11: =J11+VLOOKUP(C11,$A$3:$L$6,2,0)*K11 -> 1025
A12: 武器 | B12: 仪器 | C12: 金 | D12: 攻击 | E12: =VLOOKUP($C12,$A$3:$L$6,3,0)*E13 -> 420 | F12: =VLOOKUP($C12,$A$3:$L$6,3,0)*F13 -> 63 | G12: =VLOOKUP($C12,$A$3:$L$6,3,0)*G13 -> 483 | H12: =E12+VLOOKUP(C12,$A$3:$L$6,2,0)*F12 -> 3570 | I12: 暴击等级 | J12: =VLOOKUP($C12,$A$3:$L$6,3,0)*J13 -> 217.5 | K12: =VLOOKUP($C12,$A$3:$L$6,3,0)*K13 -> 33 | L12: =VLOOKUP($C12,$A$3:$L$6,3,0)*L13 -> 250.5 | M12: =J12+VLOOKUP(C12,$A$3:$L$6,2,0)*K12 -> 1867.5 | O12: 分解后获得的经验=分解基础经验+当前装备已有经验*分解经验系数
A13: 武器 | B13: 仪器 | C13: 红 | D13: 攻击 | E13: ='设计页-映射装备数值'!C117 -> 560 | F13: ='设计页-映射装备数值'!G117 -> 84 | G13: =E13+F13 -> 644 | H13: =E13+VLOOKUP(C13,$A$3:$L$6,2,0)*F13 -> 5600 | I13: 暴击等级 | J13: ='设计页-映射装备数值'!E117 -> 290 | K13: ='设计页-映射装备数值'!I117 -> 44 | L13: =J13+K13 -> 334 | M13: =J13+VLOOKUP(C13,$A$3:$L$6,2,0)*K13 -> 2930
A14: 武器 | B14: 枪炮 | C14: 蓝 | D14: 攻击 | E14: =VLOOKUP($C14,$A$3:$L$6,3,0)*E17 -> 168 | F14: =VLOOKUP($C14,$A$3:$L$6,3,0)*F17 -> 25.2 | G14: =VLOOKUP($C14,$A$3:$L$6,3,0)*G17 -> 193.2 | H14: =E14+VLOOKUP(C14,$A$3:$L$6,2,0)*F14 -> 924 | I14: 攻击 | J14: =VLOOKUP($C14,$A$3:$L$6,3,0)*J17 -> 168 | K14: =VLOOKUP($C14,$A$3:$L$6,3,0)*K17 -> 25.2 | L14: =VLOOKUP($C14,$A$3:$L$6,3,0)*L17 -> 193.2 | M14: =J14+VLOOKUP(C14,$A$3:$L$6,2,0)*K14 -> 924
A15: 武器 | B15: 枪炮 | C15: 紫 | D15: 攻击 | E15: =VLOOKUP($C15,$A$3:$L$6,3,0)*E17 -> 280 | F15: =VLOOKUP($C15,$A$3:$L$6,3,0)*F17 -> 42 | G15: =VLOOKUP($C15,$A$3:$L$6,3,0)*G17 -> 322 | H15: =E15+VLOOKUP(C15,$A$3:$L$6,2,0)*F15 -> 1960 | I15: 攻击 | J15: =VLOOKUP($C15,$A$3:$L$6,3,0)*J17 -> 280 | K15: =VLOOKUP($C15,$A$3:$L$6,3,0)*K17 -> 42 | L15: =VLOOKUP($C15,$A$3:$L$6,3,0)*L17 -> 322 | M15: =J15+VLOOKUP(C15,$A$3:$L$6,2,0)*K15 -> 1960 | O15: 评分计算
A16: 武器 | B16: 枪炮 | C16: 金 | D16: 攻击 | E16: =VLOOKUP($C16,$A$3:$L$6,3,0)*E17 -> 420 | F16: =VLOOKUP($C16,$A$3:$L$6,3,0)*F17 -> 63 | G16: =VLOOKUP($C16,$A$3:$L$6,3,0)*G17 -> 483 | H16: =E16+VLOOKUP(C16,$A$3:$L$6,2,0)*F16 -> 3570 | I16: 攻击 | J16: =VLOOKUP($C16,$A$3:$L$6,3,0)*J17 -> 420 | K16: =VLOOKUP($C16,$A$3:$L$6,3,0)*K17 -> 63 | L16: =VLOOKUP($C16,$A$3:$L$6,3,0)*L17 -> 483 | M16: =J16+VLOOKUP(C16,$A$3:$L$6,2,0)*K16 -> 3570 | O16: 评分系数A | P16: 评分系数B
A17: 武器 | B17: 枪炮 | C17: 红 | D17: 攻击 | E17: ='设计页-映射装备数值'!C117 -> 560 | F17: ='设计页-映射装备数值'!G117 -> 84 | G17: =E17+F17 -> 644 | H17: =E17+VLOOKUP(C17,$A$3:$L$6,2,0)*F17 -> 5600 | I17: 攻击 | J17: ='设计页-映射装备数值'!D117 -> 560 | K17: ='设计页-映射装备数值'!H117 -> 84 | L17: =J17+K17 -> 644 | M17: =J17+VLOOKUP(C17,$A$3:$L$6,2,0)*K17 -> 5600 | O17: 20 | P17: 1.25
A18: 武器 | B18: 权杖 | C18: 蓝 | D18: 攻击 | E18: =VLOOKUP($C18,$A$3:$L$6,3,0)*E21 -> 168 | F18: =VLOOKUP($C18,$A$3:$L$6,3,0)*F21 -> 25.2 | G18: =VLOOKUP($C18,$A$3:$L$6,3,0)*G21 -> 193.2 | H18: =E18+VLOOKUP(C18,$A$3:$L$6,2,0)*F18 -> 924 | I18: 暴击等级 | J18: =VLOOKUP($C18,$A$3:$L$6,3,0)*J21 -> 87 | K18: =VLOOKUP($C18,$A$3:$L$6,3,0)*K21 -> 13.2 | L18: =VLOOKUP($C18,$A$3:$L$6,3,0)*L21 -> 100.2 | M18: =J18+VLOOKUP(C18,$A$3:$L$6,2,0)*K18 -> 483
A19: 武器 | B19: 权杖 | C19: 紫 | D19: 攻击 | E19: =VLOOKUP($C19,$A$3:$L$6,3,0)*E21 -> 280 | F19: =VLOOKUP($C19,$A$3:$L$6,3,0)*F21 -> 42 | G19: =VLOOKUP($C19,$A$3:$L$6,3,0)*G21 -> 322 | H19: =E19+VLOOKUP(C19,$A$3:$L$6,2,0)*F19 -> 1960 | I19: 暴击等级 | J19: =VLOOKUP($C19,$A$3:$L$6,3,0)*J21 -> 145 | K19: =VLOOKUP($C19,$A$3:$L$6,3,0)*K21 -> 22 | L19: =VLOOKUP($C19,$A$3:$L$6,3,0)*L21 -> 167 | M19: =J19+VLOOKUP(C19,$A$3:$L$6,2,0)*K19 -> 1025 | O19: 评分=A*装备等级上限*品质系数+B*（词条1评分基础值*词条1的roll值百分比+词条2评分基础值*词条2的roll值百分比+词条3评分基础值*词条3的roll值百分比+词条4评分基础值*词条4的roll值百分比)
A20: 武器 | B20: 权杖 | C20: 金 | D20: 攻击 | E20: =VLOOKUP($C20,$A$3:$L$6,3,0)*E21 -> 420 | F20: =VLOOKUP($C20,$A$3:$L$6,3,0)*F21 -> 63 | G20: =VLOOKUP($C20,$A$3:$L$6,3,0)*G21 -> 483 | H20: =E20+VLOOKUP(C20,$A$3:$L$6,2,0)*F20 -> 3570 | I20: 暴击等级 | J20: =VLOOKUP($C20,$A$3:$L$6,3,0)*J21 -> 217.5 | K20: =VLOOKUP($C20,$A$3:$L$6,3,0)*K21 -> 33 | L20: =VLOOKUP($C20,$A$3:$L$6,3,0)*L21 -> 250.5 | M20: =J20+VLOOKUP(C20,$A$3:$L$6,2,0)*K20 -> 1867.5
A21: 武器 | B21: 权杖 | C21: 红 | D21: 攻击 | E21: ='设计页-映射装备数值'!D117 -> 560 | F21: ='设计页-映射装备数值'!H117 -> 84 | G21: =E21+F21 -> 644 | H21: =E21+VLOOKUP(C21,$A$3:$L$6,2,0)*F21 -> 5600 | I21: 暴击等级 | J21: ='设计页-映射装备数值'!E117 -> 290 | K21: ='设计页-映射装备数值'!I117 -> 44 | L21: =J21+K21 -> 334 | M21: =J21+VLOOKUP(C21,$A$3:$L$6,2,0)*K21 -> 2930
X22: 宝石三合一同时每次消耗金币
A23: 头盔 | B23: 无 | C23: 蓝 | D23: 生命 | E23: =VLOOKUP($C23,$A$3:$L$6,3,0)*E26 -> 562.5 | F23: =VLOOKUP($C23,$A$3:$L$6,3,0)*F26 -> 84.375 | G23: =VLOOKUP($C23,$A$3:$L$6,3,0)*G26 -> 646.875 | H23: =E23+VLOOKUP(C23,$A$3:$L$6,2,0)*F23 -> 3093.75 | I23: 攻击加成 | J23: =VLOOKUP($C23,$A$3:$L$6,3,0)*J26 -> 0.012 | K23: =VLOOKUP($C23,$A$3:$L$6,3,0)*K26 -> 0.0018 | L23: =VLOOKUP($C23,$A$3:$L$6,3,0)*L26 -> 0.0138 | M23: =J23+VLOOKUP(C23,$A$3:$L$6,2,0)*K23 -> 0.066 | X23: 合成消耗金币数量
A24: 头盔 | B24: 无 | C24: 紫 | D24: 生命 | E24: =VLOOKUP($C24,$A$3:$L$6,3,0)*E26 -> 937.5 | F24: =VLOOKUP($C24,$A$3:$L$6,3,0)*F26 -> 140.625 | G24: =VLOOKUP($C24,$A$3:$L$6,3,0)*G26 -> 1078.125 | H24: =E24+VLOOKUP(C24,$A$3:$L$6,2,0)*F24 -> 6562.5 | I24: 攻击加成 | J24: =VLOOKUP($C24,$A$3:$L$6,3,0)*J26 -> 0.02 | K24: =VLOOKUP($C24,$A$3:$L$6,3,0)*K26 -> 0.003 | L24: =VLOOKUP($C24,$A$3:$L$6,3,0)*L26 -> 0.023 | M24: =J24+VLOOKUP(C24,$A$3:$L$6,2,0)*K24 -> 0.14 | X24: 1000
A25: 头盔 | B25: 无 | C25: 金 | D25: 生命 | E25: =VLOOKUP($C25,$A$3:$L$6,3,0)*E26 -> 1406.25 | F25: =VLOOKUP($C25,$A$3:$L$6,3,0)*F26 -> 210.9375 | G25: =VLOOKUP($C25,$A$3:$L$6,3,0)*G26 -> 1617.1875 | H25: =E25+VLOOKUP(C25,$A$3:$L$6,2,0)*F25 -> 11953.125 | I25: 攻击加成 | J25: =VLOOKUP($C25,$A$3:$L$6,3,0)*J26 -> 0.03 | K25: =VLOOKUP($C25,$A$3:$L$6,3,0)*K26 -> 0.0045 | L25: =VLOOKUP($C25,$A$3:$L$6,3,0)*L26 -> 0.0345 | M25: =J25+VLOOKUP(C25,$A$3:$L$6,2,0)*K25 -> 0.255 | O25: 宝石部分 | P25: 8级以及之后的数值暂未投放
A26: 头盔 | B26: 无 | C26: 红 | D26: 生命 | E26: ='设计页-映射装备数值'!C120 -> 1875 | F26: ='设计页-映射装备数值'!G120 -> 281.25 | G26: =E26+F26 -> 2156.25 | H26: =E26+VLOOKUP(C26,$A$3:$L$6,2,0)*F26 -> 18750 | I26: 攻击加成 | J26: ='设计页-映射装备数值'!D120 -> 0.04 | K26: ='设计页-映射装备数值'!H120 -> 0.006 | L26: =J26+K26 -> 0.046 | M26: =J26+VLOOKUP(C26,$A$3:$L$6,2,0)*K26 -> 0.4 | O26: 宝石颜色 | P26: 红 | Q26: 蓝 | R26: 黄 | S26: 绿 | T26: 紫 | U26: 橙 | V26: 青 | W26: 白
O27: 属性 | P27: 攻击 | Q27: 攻击 | R27: 防御 | S27: 生命 | T27: 技能冷却等级 | U27: 能量回复等级 | V27: 暴击等级 | W27: 暴击伤害等级
A28: 盔甲 | B28: 无 | C28: 蓝 | D28: 防御力 | E28: =VLOOKUP($C28,$A$3:$L$6,3,0)*E31 -> 112.5 | F28: =VLOOKUP($C28,$A$3:$L$6,3,0)*F31 -> 16.875 | G28: =VLOOKUP($C28,$A$3:$L$6,3,0)*G31 -> 129.375 | H28: =E28+VLOOKUP(C28,$A$3:$L$6,2,0)*F28 -> 618.75 | I28: 防御加成 | J28: =VLOOKUP($C28,$A$3:$L$6,3,0)*J31 -> 0.012 | K28: =VLOOKUP($C28,$A$3:$L$6,3,0)*K31 -> 0.0018 | L28: =VLOOKUP($C28,$A$3:$L$6,3,0)*L31 -> 0.0138 | M28: =J28+VLOOKUP(C28,$A$3:$L$6,2,0)*K28 -> 0.066 | O28: 1 | P28: ='设计页-映射装备数值'!D290 -> 330 | Q28: ='设计页-映射装备数值'!E290 -> 330 | R28: ='设计页-映射装备数值'!F290 -> 220 | S28: ='设计页-映射装备数值'!G290 -> 1100 | T28: ='设计页-映射装备数值'!H290 -> 130 | U28: ='设计页-映射装备数值'!I290 -> 90 | V28: ='设计页-映射装备数值'!J290 -> 90 | W28: ='设计页-映射装备数值'!K290 -> 110
A29: 盔甲 | B29: 无 | C29: 紫 | D29: 防御力 | E29: =VLOOKUP($C29,$A$3:$L$6,3,0)*E31 -> 187.5 | F29: =VLOOKUP($C29,$A$3:$L$6,3,0)*F31 -> 28.125 | G29: =VLOOKUP($C29,$A$3:$L$6,3,0)*G31 -> 215.625 | H29: =E29+VLOOKUP(C29,$A$3:$L$6,2,0)*F29 -> 1312.5 | I29: 防御加成 | J29: =VLOOKUP($C29,$A$3:$L$6,3,0)*J31 -> 0.02 | K29: =VLOOKUP($C29,$A$3:$L$6,3,0)*K31 -> 0.003 | L29: =VLOOKUP($C29,$A$3:$L$6,3,0)*L31 -> 0.023 | M29: =J29+VLOOKUP(C29,$A$3:$L$6,2,0)*K29 -> 0.14 | O29: 2 | P29: ='设计页-映射装备数值'!D291 -> 490 | Q29: ='设计页-映射装备数值'!E291 -> 490 | R29: ='设计页-映射装备数值'!F291 -> 330 | S29: ='设计页-映射装备数值'!G291 -> 1650 | T29: ='设计页-映射装备数值'!H291 -> 200 | U29: ='设计页-映射装备数值'!I291 -> 140 | V29: ='设计页-映射装备数值'!J291 -> 140 | W29: ='设计页-映射装备数值'!K291 -> 170
A30: 盔甲 | B30: 无 | C30: 金 | D30: 防御力 | E30: =VLOOKUP($C30,$A$3:$L$6,3,0)*E31 -> 281.25 | F30: =VLOOKUP($C30,$A$3:$L$6,3,0)*F31 -> 42.1875 | G30: =VLOOKUP($C30,$A$3:$L$6,3,0)*G31 -> 323.4375 | H30: =E30+VLOOKUP(C30,$A$3:$L$6,2,0)*F30 -> 2390.625 | I30: 防御加成 | J30: =VLOOKUP($C30,$A$3:$L$6,3,0)*J31 -> 0.03 | K30: =VLOOKUP($C30,$A$3:$L$6,3,0)*K31 -> 0.0045 | L30: =VLOOKUP($C30,$A$3:$L$6,3,0)*L31 -> 0.0345 | M30: =J30+VLOOKUP(C30,$A$3:$L$6,2,0)*K30 -> 0.255 | O30: 3 | P30: ='设计页-映射装备数值'!D292 -> 740 | Q30: ='设计页-映射装备数值'!E292 -> 740 | R30: ='设计页-映射装备数值'!F292 -> 490 | S30: ='设计页-映射装备数值'!G292 -> 2470 | T30: ='设计页-映射装备数值'!H292 -> 300 | U30: ='设计页-映射装备数值'!I292 -> 210 | V30: ='设计页-映射装备数值'!J292 -> 210 | W30: ='设计页-映射装备数值'!K292 -> 250
A31: 盔甲 | B31: 无 | C31: 红 | D31: 防御力 | E31: ='设计页-映射装备数值'!C124 -> 375 | F31: ='设计页-映射装备数值'!G124 -> 56.25 | G31: =E31+F31 -> 431.25 | H31: =E31+VLOOKUP(C31,$A$3:$L$6,2,0)*F31 -> 3750 | I31: 防御加成 | J31: ='设计页-映射装备数值'!D124 -> 0.04 | K31: ='设计页-映射装备数值'!H124 -> 0.006 | L31: =J31+K31 -> 0.046 | M31: =J31+VLOOKUP(C31,$A$3:$L$6,2,0)*K31 -> 0.4 | O31: 4 | P31: ='设计页-映射装备数值'!D293 -> 1110 | Q31: ='设计页-映射装备数值'!E293 -> 1110 | R31: ='设计页-映射装备数值'!F293 -> 740 | S31: ='设计页-映射装备数值'!G293 -> 3700 | T31: ='设计页-映射装备数值'!H293 -> 450 | U31: ='设计页-映射装备数值'!I293 -> 310 | V31: ='设计页-映射装备数值'!J293 -> 310 | W31: ='设计页-映射装备数值'!K293 -> 380
O32: 5 | P32: ='设计页-映射装备数值'!D294 -> 1670 | Q32: ='设计页-映射装备数值'!E294 -> 1670 | R32: ='设计页-映射装备数值'!F294 -> 1110 | S32: ='设计页-映射装备数值'!G294 -> 5560 | T32: ='设计页-映射装备数值'!H294 -> 670 | U32: ='设计页-映射装备数值'!I294 -> 470 | V32: ='设计页-映射装备数值'!J294 -> 470 | W32: ='设计页-映射装备数值'!K294 -> 570
A33: 手套 | B33: 无 | C33: 蓝 | D33: 防御力 | E33: =VLOOKUP($C33,$A$3:$L$6,3,0)*E36 -> 112.5 | F33: =VLOOKUP($C33,$A$3:$L$6,3,0)*F36 -> 16.875 | G33: =VLOOKUP($C33,$A$3:$L$6,3,0)*G36 -> 129.375 | H33: =E33+VLOOKUP(C33,$A$3:$L$6,2,0)*F33 -> 618.75 | I33: 攻击加成 | J33: =VLOOKUP($C33,$A$3:$L$6,3,0)*J36 -> 0.012 | K33: =VLOOKUP($C33,$A$3:$L$6,3,0)*K36 -> 0.0018 | L33: =VLOOKUP($C33,$A$3:$L$6,3,0)*L36 -> 0.0138 | M33: =J33+VLOOKUP(C33,$A$3:$L$6,2,0)*K33 -> 0.066 | O33: 6 | P33: ='设计页-映射装备数值'!D295 -> 2500 | Q33: ='设计页-映射装备数值'!E295 -> 2500 | R33: ='设计页-映射装备数值'!F295 -> 1670 | S33: ='设计页-映射装备数值'!G295 -> 8330 | T33: ='设计页-映射装备数值'!H295 -> 1010 | U33: ='设计页-映射装备数值'!I295 -> 700 | V33: ='设计页-映射装备数值'!J295 -> 700 | W33: ='设计页-映射装备数值'!K295 -> 860
A34: 手套 | B34: 无 | C34: 紫 | D34: 防御力 | E34: =VLOOKUP($C34,$A$3:$L$6,3,0)*E36 -> 187.5 | F34: =VLOOKUP($C34,$A$3:$L$6,3,0)*F36 -> 28.125 | G34: =VLOOKUP($C34,$A$3:$L$6,3,0)*G36 -> 215.625 | H34: =E34+VLOOKUP(C34,$A$3:$L$6,2,0)*F34 -> 1312.5 | I34: 攻击加成 | J34: =VLOOKUP($C34,$A$3:$L$6,3,0)*J36 -> 0.02 | K34: =VLOOKUP($C34,$A$3:$L$6,3,0)*K36 -> 0.003 | L34: =VLOOKUP($C34,$A$3:$L$6,3,0)*L36 -> 0.023 | M34: =J34+VLOOKUP(C34,$A$3:$L$6,2,0)*K34 -> 0.14 | O34: 7 | P34: ='设计页-映射装备数值'!D296 -> 3750 | Q34: ='设计页-映射装备数值'!E296 -> 3750 | R34: ='设计页-映射装备数值'!F296 -> 2500 | S34: ='设计页-映射装备数值'!G296 -> 12500 | T34: ='设计页-映射装备数值'!H296 -> 1520 | U34: ='设计页-映射装备数值'!I296 -> 1050 | V34: ='设计页-映射装备数值'!J296 -> 1050 | W34: ='设计页-映射装备数值'!K296 -> 1280
A35: 手套 | B35: 无 | C35: 金 | D35: 防御力 | E35: =VLOOKUP($C35,$A$3:$L$6,3,0)*E36 -> 281.25 | F35: =VLOOKUP($C35,$A$3:$L$6,3,0)*F36 -> 42.1875 | G35: =VLOOKUP($C35,$A$3:$L$6,3,0)*G36 -> 323.4375 | H35: =E35+VLOOKUP(C35,$A$3:$L$6,2,0)*F35 -> 2390.625 | I35: 攻击加成 | J35: =VLOOKUP($C35,$A$3:$L$6,3,0)*J36 -> 0.03 | K35: =VLOOKUP($C35,$A$3:$L$6,3,0)*K36 -> 0.0045 | L35: =VLOOKUP($C35,$A$3:$L$6,3,0)*L36 -> 0.0345 | M35: =J35+VLOOKUP(C35,$A$3:$L$6,2,0)*K35 -> 0.255 | O35: 8 | P35: ='设计页-映射装备数值'!D297 -> 5630 | Q35: ='设计页-映射装备数值'!E297 -> 5630 | R35: ='设计页-映射装备数值'!F297 -> 3750 | S35: ='设计页-映射装备数值'!G297 -> 18750 | T35: ='设计页-映射装备数值'!H297 -> 2280 | U35: ='设计页-映射装备数值'!I297 -> 1580 | V35: ='设计页-映射装备数值'!J297 -> 1580 | W35: ='设计页-映射装备数值'!K297 -> 1920
A36: 手套 | B36: 无 | C36: 红 | D36: 防御力 | E36: ='设计页-映射装备数值'!C128 -> 375 | F36: ='设计页-映射装备数值'!G128 -> 56.25 | G36: =E36+F36 -> 431.25 | H36: =E36+VLOOKUP(C36,$A$3:$L$6,2,0)*F36 -> 3750 | I36: 攻击加成 | J36: ='设计页-映射装备数值'!D128 -> 0.04 | K36: ='设计页-映射装备数值'!H128 -> 0.006 | L36: =J36+K36 -> 0.046 | M36: =J36+VLOOKUP(C36,$A$3:$L$6,2,0)*K36 -> 0.4 | O36: 9 | P36: ='设计页-映射装备数值'!D298 -> 8440 | Q36: ='设计页-映射装备数值'!E298 -> 8440 | R36: ='设计页-映射装备数值'!F298 -> 5630 | S36: ='设计页-映射装备数值'!G298 -> 28130 | T36: ='设计页-映射装备数值'!H298 -> 3410 | U36: ='设计页-映射装备数值'!I298 -> 2360 | V36: ='设计页-映射装备数值'!J298 -> 2360 | W36: ='设计页-映射装备数值'!K298 -> 2890
A38: 腰带 | B38: 无 | C38: 蓝 | D38: 生命 | E38: =VLOOKUP($C38,$A$3:$L$6,3,0)*E41 -> 562.5 | F38: =VLOOKUP($C38,$A$3:$L$6,3,0)*F41 -> 84.375 | G38: =VLOOKUP($C38,$A$3:$L$6,3,0)*G41 -> 646.875 | H38: =E38+VLOOKUP(C38,$A$3:$L$6,2,0)*F38 -> 3093.75 | I38: 生命加成 | J38: =VLOOKUP($C38,$A$3:$L$6,3,0)*J41 -> 0.012 | K38: =VLOOKUP($C38,$A$3:$L$6,3,0)*K41 -> 0.0018 | L38: =VLOOKUP($C38,$A$3:$L$6,3,0)*L41 -> 0.0138 | M38: =J38+VLOOKUP(C38,$A$3:$L$6,2,0)*K38 -> 0.066
A39: 腰带 | B39: 无 | C39: 紫 | D39: 生命 | E39: =VLOOKUP($C39,$A$3:$L$6,3,0)*E41 -> 937.5 | F39: =VLOOKUP($C39,$A$3:$L$6,3,0)*F41 -> 140.625 | G39: =VLOOKUP($C39,$A$3:$L$6,3,0)*G41 -> 1078.125 | H39: =E39+VLOOKUP(C39,$A$3:$L$6,2,0)*F39 -> 6562.5 | I39: 生命加成 | J39: =VLOOKUP($C39,$A$3:$L$6,3,0)*J41 -> 0.02 | K39: =VLOOKUP($C39,$A$3:$L$6,3,0)*K41 -> 0.003 | L39: =VLOOKUP($C39,$A$3:$L$6,3,0)*L41 -> 0.023 | M39: =J39+VLOOKUP(C39,$A$3:$L$6,2,0)*K39 -> 0.14
A40: 腰带 | B40: 无 | C40: 金 | D40: 生命 | E40: =VLOOKUP($C40,$A$3:$L$6,3,0)*E41 -> 1406.25 | F40: =VLOOKUP($C40,$A$3:$L$6,3,0)*F41 -> 210.9375 | G40: =VLOOKUP($C40,$A$3:$L$6,3,0)*G41 -> 1617.1875 | H40: =E40+VLOOKUP(C40,$A$3:$L$6,2,0)*F40 -> 11953.125 | I40: 生命加成 | J40: =VLOOKUP($C40,$A$3:$L$6,3,0)*J41 -> 0.03 | K40: =VLOOKUP($C40,$A$3:$L$6,3,0)*K41 -> 0.0045 | L40: =VLOOKUP($C40,$A$3:$L$6,3,0)*L41 -> 0.0345 | M40: =J40+VLOOKUP(C40,$A$3:$L$6,2,0)*K40 -> 0.255
A41: 腰带 | B41: 无 | C41: 红 | D41: 生命 | E41: ='设计页-映射装备数值'!C132 -> 1875 | F41: ='设计页-映射装备数值'!G132 -> 281.25 | G41: =E41+F41 -> 2156.25 | H41: =E41+VLOOKUP(C41,$A$3:$L$6,2,0)*F41 -> 18750 | I41: 生命加成 | J41: ='设计页-映射装备数值'!D132 -> 0.04 | K41: ='设计页-映射装备数值'!H132 -> 0.006 | L41: =J41+K41 -> 0.046 | M41: =J41+VLOOKUP(C41,$A$3:$L$6,2,0)*K41 -> 0.4
A43: 鞋子 | B43: 无 | C43: 蓝 | D43: 攻击 | E43: =VLOOKUP($C43,$A$3:$L$6,3,0)*E46 -> 168 | F43: =VLOOKUP($C43,$A$3:$L$6,3,0)*F46 -> 25.2 | G43: =VLOOKUP($C43,$A$3:$L$6,3,0)*G46 -> 193.2 | H43: =E43+VLOOKUP(C43,$A$3:$L$6,2,0)*F43 -> 924 | I43: 冷却缩减等级 | J43: =VLOOKUP($C43,$A$3:$L$6,3,0)*J46 -> 109.2 | K43: =VLOOKUP($C43,$A$3:$L$6,3,0)*K46 -> 16.5 | L43: =VLOOKUP($C43,$A$3:$L$6,3,0)*L46 -> 125.7 | M43: =J43+VLOOKUP(C43,$A$3:$L$6,2,0)*K43 -> 604.2
...

Sheet 配置页-普通装备技能
B2: 装备名称 | C2: buffid | D2: 额外固定副属性 | E2: 额外固定副属性值
B3: =普通映射装备数值!D3 -> 初级喷射器 | C3: 311001 | D3: =普通映射装备数值!U3 -> 攻击 | E3: =普通映射装备数值!V3 -> 0.01 | F3: =_xlfn.CONCAT(D3,E3) -> 攻击0.01
B4: =普通映射装备数值!D4 -> 中级喷射器 | C4: 311101 | D4: =普通映射装备数值!U4 -> 攻击 | E4: =普通映射装备数值!V4 -> 0.015 | F4: =_xlfn.CONCAT(D4,E4) -> 攻击0.015
B5: =普通映射装备数值!D5 -> 高级喷射器 | C5: 311201 | D5: =普通映射装备数值!U5 -> 攻击 | E5: =普通映射装备数值!V5 -> 0.02 | F5: =_xlfn.CONCAT(D5,E5) -> 攻击0.02
B6: =普通映射装备数值!D6 -> 初级逆变器 | C6: 311301 | D6: =普通映射装备数值!U6 -> 攻击 | E6: =普通映射装备数值!V6 -> 0.01 | F6: =_xlfn.CONCAT(D6,E6) -> 攻击0.01
B7: =普通映射装备数值!D7 -> 中级逆变器 | C7: 311401 | D7: =普通映射装备数值!U7 -> 攻击 | E7: =普通映射装备数值!V7 -> 0.015 | F7: =_xlfn.CONCAT(D7,E7) -> 攻击0.015
B8: =普通映射装备数值!D8 -> 高级逆变器 | C8: 311501 | D8: =普通映射装备数值!U8 -> 攻击 | E8: =普通映射装备数值!V8 -> 0.02 | F8: =_xlfn.CONCAT(D8,E8) -> 攻击0.02
B9: =普通映射装备数值!D9 -> 初级切割器 | C9: 311601 | D9: =普通映射装备数值!U9 -> 穿透伤害加成 | E9: =普通映射装备数值!V9 -> 0.02 | F9: =_xlfn.CONCAT(D9,E9) -> 穿透伤害加成0.02
B10: =普通映射装备数值!D10 -> 中级切割器 | C10: 311701 | D10: =普通映射装备数值!U10 -> 穿透伤害加成 | E10: =普通映射装备数值!V10 -> 0.03 | F10: =_xlfn.CONCAT(D10,E10) -> 穿透伤害加成0.03
B11: =普通映射装备数值!D11 -> 高级切割器 | C11: 311801 | D11: =普通映射装备数值!U11 -> 穿透伤害加成 | E11: =普通映射装备数值!V11 -> 0.04 | F11: =_xlfn.CONCAT(D11,E11) -> 穿透伤害加成0.04
B12: =普通映射装备数值!D12 -> 初级旋转机枪 | C12: 311901 | D12: =普通映射装备数值!U12 -> 普攻速度百分比 | E12: =普通映射装备数值!V12 -> 0.018 | F12: =_xlfn.CONCAT(D12,E12) -> 普攻速度百分比0.018
B13: =普通映射装备数值!D13 -> 中级旋转机枪 | C13: 312001 | D13: =普通映射装备数值!U13 -> 普攻速度百分比 | E13: =普通映射装备数值!V13 -> 0.028 | F13: =_xlfn.CONCAT(D13,E13) -> 普攻速度百分比0.028
B14: =普通映射装备数值!D14 -> 高级旋转机枪 | C14: 312101 | D14: =普通映射装备数值!U14 -> 普攻速度百分比 | E14: =普通映射装备数值!V14 -> 0.04 | F14: =_xlfn.CONCAT(D14,E14) -> 普攻速度百分比0.04
... B155: =普通映射装备数值!D155 -> 高级契约指环 | C155: 382201 | D155: =普通映射装备数值!U155 -> 攻击 | E155: =普通映射装备数值!V155 -> 630 | F155: =_xlfn.CONCAT(D155,E155) -> 攻击630

Sheet 普通映射装备数值
G1: 原始 | O1: 最终
C2: ID | D2: 名称 | E2: 部位 | F2: 稀有度 | G2: 主属性1 | H2: 1级数值 | I2: 属性成长系数 | J2: 主属性2 | K2: 1级数值 | L2: 属性成长系数 | M2: 主属性1系数 | N2: 主属性2系数 | O2: 主属性1 | P2: 1级数值 | Q2: 属性成长系数 | R2: 主属性2 | S2: 1级数值 | T2: 属性成长系数 | U2: 额外固定副属性 | V2: 额外固定副属性值 | X2: buffid
C3: 80001 | D3: 初级喷射器 | E3: 仪器 | F3: Blue | G3: =IFERROR(INDEX(映射装备数值!D:D,SUMPRODUCT((映射装备数值!$C$10:$C$56=IF($F3="Blue","蓝",IF($F3="Purple","紫",IF($F3="Orange","金",IF($F3="Red","红",$F3)))))*((映射装备数值!$A$10:$A$56=$E3)+(映射装备数值!$B$10:$B$56=$E3))*ROW(映射装备数值!$A$10:$A$56))),"未匹配") -> 攻击 | H3: =IFERROR(INDEX(映射装备数值!G:G,SUMPRODUCT((映射装备数值!$C$10:$C$56=IF($F3="Blue","蓝",IF($F3="Purple","紫",IF($F3="Orange","金",IF($F3="Red","红",$F3)))))*((映射装备数值!$A$10:$A$56=$E3)+(映射装备数值!$B$10:$B$56=$E3))*ROW(映射装备数值!$A$10:$A$56))),"未匹配") -> 193.2 | I3: =IFERROR(INDEX(映射装备数值!F:F,SUMPRODUCT((映射装备数值!$C$10:$C$56=IF($F3="Blue","蓝",IF($F3="Purple","紫",IF($F3="Orange","金",IF($F3="Red","红",$F3)))))*((映射装备数值!$A$10:$A$56=$E3)+(映射装备数值!$B$10:$B$56=$E3))*ROW(映射装备数值!$A$10:$A$56))),"未匹配") -> 25.2 | J3: =IFERROR(INDEX(映射装备数值!I:I,SUMPRODUCT((映射装备数值!$C$10:$C$56=IF($F3="Blue","蓝",IF($F3="Purple","紫",IF($F3="Orange","金",IF($F3="Red","红",$F3)))))*((映射装备数值!$A$10:$A$56=$E3)+(映射装备数值!$B$10:$B$56=$E3))*ROW(映射装备数值!$A$10:$A$56))),"未匹配") -> 暴击等级 | K3: =IFERROR(INDEX(映射装备数值!L:L,SUMPRODUCT((映射装备数值!$C$10:$C$56=IF($F3="Blue","蓝",IF($F3="Purple","紫",IF($F3="Orange","金",IF($F3="Red","红",$F3)))))*((映射装备数值!$A$10:$A$56=$E3)+(映射装备数值!$B$10:$B$56=$E3))*ROW(映射装备数值!$A$10:$A$56))),"未匹配") -> 100.2 | L3: =IFERROR(INDEX(映射装备数值!K:K,SUMPRODUCT((映射装备数值!$C$10:$C$56=IF($F3="Blue","蓝",IF($F3="Purple","紫",IF($F3="Orange","金",IF($F3="Red","红",$F3)))))*((映射装备数值!$A$10:$A$56=$E3)+(映射装备数值!$B$10:$B$56=$E3))*ROW(映射装备数值!$A$10:$A$56))),"未匹配") -> 13.2 | M3: 1.1 | N3: 0.9 | O3: =G3 -> 攻击 | P3: =ROUND(H3*$M3,IF(H3<1,3,0)) -> 213 | Q3: =ROUND(I3*$M3,IF(I3<1,3,0)) -> 28 | R3: =J3 -> 暴击等级 | S3: =ROUND(K3*$N3,IF(K3<1,3,0)) -> 90 | T3: =ROUND(L3*$N3,IF(L3<1,4,0)) -> 12 | U3: 攻击 | V3: 0.01 | W3: 80001
C4: 80002 | D4: 中级喷射器 | E4: 仪器 | F4: Purple | G4: =IFERROR(INDEX(映射装备数值!D:D,SUMPRODUCT((映射装备数值!$C$10:$C$56=IF($F4="Blue","蓝",IF($F4="Purple","紫",IF($F4="Orange","金",IF($F4="Red","红",$F4)))))*((映射装备数值!$A$10:$A$56=$E4)+(映射装备数值!$B$10:$B$56=$E4))*ROW(映射装备数值!$A$10:$A$56))),"未匹配") -> 攻击 | H4: =IFERROR(INDEX(映射装备数值!G:G,SUMPRODUCT((映射装备数值!$C$10:$C$56=IF($F4="Blue","蓝",IF($F4="Purple","紫",IF($F4="Orange","金",IF($F4="Red","红",$F4)))))*((映射装备数值!$A$10:$A$56=$E4)+(映射装备数值!$B$10:$B$56=$E4))*ROW(映射装备数值!$A$10:$A$56))),"未匹配") -> 322 | I4: =IFERROR(INDEX(映射装备数值!F:F,SUMPRODUCT((映射装备数值!$C$10:$C$56=IF($F4="Blue","蓝",IF($F4="Purple","紫",IF($F4="Orange","金",IF($F4="Red","红",$F4)))))*((映射装备数值!$A$10:$A$56=$E4)+(映射装备数值!$B$10:$B$56=$E4))*ROW(映射装备数值!$A$10:$A$56))),"未匹配") -> 42 | J4: =IFERROR(INDEX(映射装备数值!I:I,SUMPRODUCT((映射装备数值!$C$10:$C$56=IF($F4="Blue","蓝",IF($F4="Purple","紫",IF($F4="Orange","金",IF($F4="Red","红",$F4)))))*((映射装备数值!$A$10:$A$56=$E4)+(映射装备数值!$B$10:$B$56=$E4))*ROW(映射装备数值!$A$10:$A$56))),"未匹配") -> 暴击等级 | K4: =IFERROR(INDEX(映射装备数值!L:L,SUMPRODUCT((映射装备数值!$C$10:$C$56=IF($F4="Blue","蓝",IF($F4="Purple","紫",IF($F4="Orange","金",IF($F4="Red","红",$F4)))))*((映射装备数值!$A$10:$A$56=$E4)+(映射装备数值!$B$10:$B$56=$E4))*ROW(映射装备数值!$A$10:$A$56))),"未匹配") -> 167 | L4: =IFERROR(INDEX(映射装备数值!K:K,SUMPRODUCT((映射装备数值!$C$10:$C$56=IF($F4="Blue","蓝",IF($F4="Purple","紫",IF($F4="Orange","金",IF($F4="Red","红",$F4)))))*((映射装备数值!$A$10:$A$56=$E4)+(映射装备数值!$B$10:$B$56=$E4))*ROW(映射装备数值!$A$10:$A$56))),"未匹配") -> 22 | M4: 1.1 | N4: 0.9 | O4: =G4 -> 攻击 | P4: =ROUND(H4*$M4,IF(H4<1,3,0)) -> 354 | Q4: =ROUND(I4*$M4,IF(I4<1,3,0)) -> 46 | R4: =J4 -> 暴击等级 | S4: =ROUND(K4*$N4,IF(K4<1,3,0)) -> 150 | T4: =ROUND(L4*$N4,IF(L4<1,4,0)) -> 20 | U4: 攻击 | V4: 0.015 | W4: 80002
C5: 80003 | D5: 高级喷射器 | E5: 仪器 | F5: Orange | G5: =IFERROR(INDEX(映射装备数值!D:D,SUMPRODUCT((映射装备数值!$C$10:$C$56=IF($F5="Blue","蓝",IF($F5="Purple","紫",IF($F5="Orange","金",IF($F5="Red","红",$F5)))))*((映射装备数值!$A$10:$A$56=$E5)+(映射装备数值!$B$10:$B$56=$E5))*ROW(映射装备数值!$A$10:$A$56))),"未匹配") -> 攻击 | H5: =IFERROR(INDEX(映射装备数值!G:G,SUMPRODUCT((映射装备数值!$C$10:$C$56=IF($F5="Blue","蓝",IF($F5="Purple","紫",IF($F5="Orange","金",IF($F5="Red","红",$F5)))))*((映射装备数值!$A$10:$A$56=$E5)+(映射装备数值!$B$10:$B$56=$E5))*ROW(映射装备数值!$A$10:$A$56))),"未匹配") -> 483 | I5: =IFERROR(INDEX(映射装备数值!F:F,SUMPRODUCT((映射装备数值!$C$10:$C$56=IF($F5="Blue","蓝",IF($F5="Purple","紫",IF($F5="Orange","金",IF($F5="Red","红",$F5)))))*((映射装备数值!$A$10:$A$56=$E5)+(映射装备数值!$B$10:$B$56=$E5))*ROW(映射装备数值!$A$10:$A$56))),"未匹配") -> 63 | J5: =IFERROR(INDEX(映射装备数值!I:I,SUMPRODUCT((映射装备数值!$C$10:$C$56=IF($F5="Blue","蓝",IF($F5="Purple","紫",IF($F5="Orange","金",IF($F5="Red","红",$F5)))))*((映射装备数值!$A$10:$A$56=$E5)+(映射装备数值!$B$10:$B$56=$E5))*ROW(映射装备数值!$A$10:$A$56))),"未匹配") -> 暴击等级 | K5: =IFERROR(INDEX(映射装备数值!L:L,SUMPRODUCT((映射装备数值!$C$10:$C$56=IF($F5="Blue","蓝",IF($F5="Purple","紫",IF($F5="Orange","金",IF($F5="Red","红",$F5)))))*((映射装备数值!$A$10:$A$56=$E5)+(映射装备数值!$B$10:$B$56=$E5))*ROW(映射装备数值!$A$10:$A$56))),"未匹配") -> 250.5 | L5: =IFERROR(INDEX(映射装备数值!K:K,SUMPRODUCT((映射装备数值!$C$10:$C$56=IF($F5="Blue","蓝",IF($F5="Purple","紫",IF($F5="Orange","金",IF($F5="Red","红",$F5)))))*((映射装备数值!$A$10:$A$56=$E5)+(映射装备数值!$B$10:$B$56=$E5))*ROW(映射装备数值!$A$10:$A$56))),"未匹配") -> 33 | M5: 1.1 | N5: 0.9 | O5: =G5 -> 攻击 | P5: =ROUND(H5*$M5,IF(H5<1,3,0)) -> 531 | Q5: =ROUND(I5*$M5,IF(I5<1,3,0)) -> 69 | R5: =J5 -> 暴击等级 | S5: =ROUND(K5*$N5,IF(K5<1,3,0)) -> 225 | T5: =ROUND(L5*$N5,IF(L5<1,4,0)) -> 30 | U5: 攻击 | V5: 0.02 | W5: 80003
C6: 80004 | D6: 初级逆变器 | E6: 仪器 | F6: Blue | G6: =IFERROR(INDEX(映射装备数值!D:D,SUMPRODUCT((映射装备数值!$C$10:$C$56=IF($F6="Blue","蓝",IF($F6="Purple","紫",IF($F6="Orange","金",IF($F6="Red","红",$F6)))))*((映射装备数值!$A$10:$A$56=$E6)+(映射装备数值!$B$10:$B$56=$E6))*ROW(映射装备数值!$A$10:$A$56))),"未匹配") -> 攻击 | H6: =IFERROR(INDEX(映射装备数值!G:G,SUMPRODUCT((映射装备数值!$C$10:$C$56=IF($F6="Blue","蓝",IF($F6="Purple","紫",IF($F6="Orange","金",IF($F6="Red","红",$F6)))))*((映射装备数值!$A$10:$A$56=$E6)+(映射装备数值!$B$10:$B$56=$E6))*ROW(映射装备数值!$A$10:$A$56))),"未匹配") -> 193.2 | I6: =IFERROR(INDEX(映射装备数值!F:F,SUMPRODUCT((映射装备数值!$C$10:$C$56=IF($F6="Blue","蓝",IF($F6="Purple","紫",IF($F6="Orange","金",IF($F6="Red","红",$F6)))))*((映射装备数值!$A$10:$A$56=$E6)+(映射装备数值!$B$10:$B$56=$E6))*ROW(映射装备数值!$A$10:$A$56))),"未匹配") -> 25.2 | J6: =IFERROR(INDEX(映射装备数值!I:I,SUMPRODUCT((映射装备数值!$C$10:$C$56=IF($F6="Blue","蓝",IF($F6="Purple","紫",IF($F6="Orange","金",IF($F6="Red","红",$F6)))))*((映射装备数值!$A$10:$A$56=$E6)+(映射装备数值!$B$10:$B$56=$E6))*ROW(映射装备数值!$A$10:$A$56))),"未匹配") -> 暴击等级 | K6: =IFERROR(INDEX(映射装备数值!L:L,SUMPRODUCT((映射装备数值!$C$10:$C$56=IF($F6="Blue","蓝",IF($F6="Purple","紫",IF($F6="Orange","金",IF($F6="Red","红",$F6)))))*((映射装备数值!$A$10:$A$56=$E6)+(映射装备数值!$B$10:$B$56=$E6))*ROW(映射装备数值!$A$10:$A$56))),"未匹配") -> 100.2 | L6: =IFERROR(INDEX(映射装备数值!K:K,SUMPRODUCT((映射装备数值!$C$10:$C$56=IF($F6="Blue","蓝",IF($F6="Purple","紫",IF($F6="Orange","金",IF($F6="Red","红",$F6)))))*((映射装备数值!$A$10:$A$56=$E6)+(映射装备数值!$B$10:$B$56=$E6))*ROW(映射装备数值!$A$10:$A$56))),"未匹配") -> 13.2 | M6: 0.95 | N6: 1.05 | O6: =G6 -> 攻击 | P6: =ROUND(H6*$M6,IF(H6<1,3,0)) -> 184 | Q6: =ROUND(I6*$M6,IF(I6<1,3,0)) -> 24 | R6: =J6 -> 暴击等级 | S6: =ROUND(K6*$N6,IF(K6<1,3,0)) -> 105 | T6: =ROUND(L6*$N6,IF(L6<1,4,0)) -> 14 | U6: 攻击 | V6: 0.01 | W6: 80004
