Workbook

Sheet 战斗属性
B2: 属性类别 | C2: 具体属性 | D2: 属性说明 | E2: 数据类型 | F2: 默认值 | G2: 展示位置 | H2: 备注
B3: 基础属性 | C3: 生命 | D3: 角色生命值，生命值为0角色死亡 | E3: int | F3: 0 | G3: 基础属性 | H3: 分为裸体属性和额外属性，裸体属性只包含角色基础、角色升级、角色能效
C4: 攻击 | D4: 影响战斗中角色物理伤害 | E4: int | F4: 0 | G4: 基础属性 | H4: 分为裸体属性和额外属性，裸体属性只包含角色基础、角色升级、角色能效
C5: 攻击 | D5: 影响战斗中角色魔法伤害 | E5: int | F5: 0 | G5: 基础属性 | H5: 分为裸体属性和额外属性，裸体属性只包含角色基础、角色升级、角色能效
C6: 防御力 | D6: 影响战斗中减伤效果 | E6: int | F6: 0 | G6: 基础属性 | H6: 分为裸体属性和额外属性，裸体属性只包含角色基础、角色升级、角色能效
B8: 战斗属性 | C8: 能量上限 | D8: 能量值上限，能量达到上限角色即可释放必杀技 | E8: int | F8: 100 | G8: 建议展示在必杀技能中 | H8: 达到该值时，角色可以释放必杀，建议配置在角色表
C9: 能量初始值 | D9: 角色进入战斗时初始的能量值 | E9: int | F9: 0 | G9: 建议展示在必杀技能中 | H9: 角色进入战斗时初始的能量值，建议配置在角色表
C10: 能量回复速度 | D10: 角色每秒获取的能量值 | E10: float | F10: 2.5 | G10: 进阶属性 | H10: 每秒能量的回复值
C11: 暴击 | D11: 影响战斗中造成暴击的概率 | E11: float | F11: 0.05 | G11: 进阶属性
C12: 暴击伤害 | D12: 影响战斗中造成暴击的伤害倍数 | E12: float | F12: 2 | G12: 进阶属性
C13: 闪避 | D13: 降低战斗中受到伤害的概率 | E13: float | F13: 0 | G13: 进阶属性 | H13: 暂时只在角色技能和被动中投放
C14: 命中 | D14: 影响战斗中造成伤害的概率 | E14: float | F14: 1 | G14: 进阶属性 | H14: 暂时只在角色技能和被动中投放
C15: 效果命中 | D15: 提高战斗中负面效果命中概率，暂时不使用，可以忽略 | E15: float | F15: 0 | G15: 进阶属性
C16: 效果抵抗 | D16: 降低战斗中负面效果命中概率，暂时不使用，可以忽略 | E16: float | F16: 0 | G16: 进阶属性
C17: 无视防御 | D17: 降低战斗中对方的防御效果 | E17: float | F17: 0 | G17: 面板不显示 | H17: 最多100%
C18: 普攻攻击速度 | D18: 影响战斗中角色每秒发射的普攻，例如3点攻速代表1秒发射3次普攻 | E18: float | F18: 每个角色不同 | G18: 进阶属性 | H18: 英雄普攻1秒进行打X个子弹，计算方式为x*(1+攻速加成%)=最终攻速 例如该角色1s释放2次普攻，攻击速度加成为100%，则该角色显示的攻速为4 另外建议每个角色的攻击速度单独配置在角色表中
C19: 伤害加成 | D19: 增加战斗中造成的伤害（所有的伤害加成属于同一乘区） | E19: float | F19: 0 | G19: 面板不显示 | H19: 暂时只在角色技能和被动中投放
C20: 物理伤害加成 | D20: 增加战斗中造成的物理伤害 | E20: float | F20: 0 | G20: 面板不显示 | H20: 暂时只在角色技能和被动中投放
C21: 魔法伤害加成 | D21: 增加战斗中造成的魔法伤害 | E21: float | F21: 0 | G21: 面板不显示 | H21: 暂时只在角色技能和被动中投放
C22: 普攻伤害加成 | D22: 增加战斗中普攻造成的伤害 | E22: float | F22: 0 | G22: 面板显示
C23: 技能伤害加成 | D23: 增加战斗中技能造成的伤害 | E23: float | F23: 0 | G23: 面板显示
C24: 必杀伤害加成 | D24: 增加战斗中必杀造成的伤害 | E24: float | F24: 0 | G24: 面板显示
C25: 单体伤害加成 | D25: 增加战斗中穿单体果造成的伤害 | E25: float | F25: 0 | G25: 面板显示
C26: 穿透伤害加成 | D26: 增加战斗中穿透效果造成的伤害 | E26: float | F26: 0 | G26: 面板显示
C27: 范围伤害加成 | D27: 增加战斗中范围效果造成的伤害 | E27: float | F27: 0 | G27: 面板显示
C28: 持续伤害加成 | D28: 增加战斗中持续效果造成的伤害（包括流血、灼烧、中毒） | E28: float | F28: 0 | G28: 面板显示
C29: 流血伤害加成 | D29: 增加战斗中流血效果造成的伤害 | E29: float | F29: 0 | G29: 面板不显示
C30: 灼烧伤害加成 | D30: 增加战斗中持续效果造成的伤害 | E30: float | F30: 0 | G30: 面板不显示
C31: 中毒伤害加成 | D31: 增加战斗中持续效果造成的伤害 | E31: float | F31: 0 | G31: 面板不显示
C32: 伤害减免 | D32: 减免战斗中造成的伤害 | E32: float | F32: 0 | G32: 面板不显示
C33: 治疗加成 | D33: 治疗时，调整治疗值 | E33: float | F33: 0 | G33: 面板不显示
... C35: 受治疗加成 | D35: 受到治疗时，调整治疗值 | E35: float | F35: 0 | G35: 面板不显示
C36: 施加护盾加成 | D36: 战斗中释放护盾时，数值加成 | E36: float | F36: 0 | G36: 面板不显示 | H36: 暂时只在角色技能和被动中投放
C37: 受到护盾加成 | D37: 战斗中受到护盾时，数值加成 | E37: float | F37: 0 | G37: 面板不显示 | H37: 暂时只在角色技能和被动中投放
C38: 释放盾牌加成 | D38: 战斗中释放护盾时，盾牌生命数值加成 | E38: float | F38: 0 | G38: 面板不显示 | H38: 暂时只在角色技能和被动中投放
C39: 格挡 | D39: 受到伤害时，触发格挡的概率 | E39: float | F39: 0 | G39: 面板不显示 | H39: 暂时只在角色技能和被动中投放
C40: 格挡强度 | D40: 触发格挡时，受到的最终伤害 | E40: float | F40: 0 | G40: 面板不显示 | H40: 暂时只在角色技能和被动中投放
C41: 破击 | D41: 降低敌方触发格挡的概率 | E41: float | F41: 0 | G41: 面板不显示 | H41: 暂时只在角色技能和被动中投放
C42: 冷却缩减 | D42: 释放技能的冷却缩减 | E42: float | F42: 0 | G42: 面板不显示 | H42: 角色技能释放的技能间隔缩减，最高上限为75%，可拉出来配置 例如一个角色的技能间隔为5s，获得20%的技能冷却缩减，则技能间隔变为4s
C43: 玩法伤害加成 | D43: 增加战斗中造成的伤害 | E43: float | F43: 0 | G43: 面板不显示 | H43: 玩法中才会投放，和伤害加成和减免不是一个乘区
...

Sheet 战斗公式
B3: 战斗计算规则
B5: 攻击行为
B7: 流程1 | C7: 每次攻击先判定是否命中
B9: 命中概率为=（攻击者命中 - 受击者闪避）， 如果数值大于等于1则必然命中，数值小于等于X则取最小命中概率X，在0-1之间随机，X为10%
B10: 技能未命中的情况默认不触发后续机制，除非有特殊说明
B13: 流程2 | C13: 进行伤害类型的判断
B15: 真实伤害
B16: 不进行伤害公式计算，不受护盾影响，直接扣除给定数值的生命（百分比or固定值）
B18: 物理伤害or魔法伤害
B19: 走以下伤害数值的计算
B21: 流程3 | C21: 计算初步伤害数值
B24: 伤害基数=带入伤害公式的数值，在子弹或攻击组件中计算得出
B25: 物理伤害/魔法伤害取决于伤害组件的配置，公式相同，作为逻辑标签使用
B26: 伤害=伤害基数*[（1-(受击者 防御*（1 - 攻击者 无视防御）/【(受击者 防御 *（1- 攻击者 无视防御）+X)】，X为常数根据需求调整（可配置在全局表中），最低伤害保底：伤害基数 * 5%
L27: X的值为 | M27: 24000
B28: 流程4 | C28: 判断是否暴击
B30: 由攻击者 暴击率 属性决定 ，数值大于等于1必暴击，数值小于等于0必不暴击
B31: 命中后判定暴击
B32: 如果勾选必定暴击，则判断为暴击，如果没勾选，则进行随机
B33: 如果暴击
B34: 暴击伤害 = 伤害 * 攻击者暴击伤害
B37: 流程5 | C37: 判断是否格挡 | E37: 如果既格挡又暴击，则在表现上只显示格挡
B39: 由攻击者 破击率 属性决定和防御者格挡率决定是否触发格挡
B40: 格挡概率=受击者格挡率-攻击者破击率，最低为0，最高为1
B41: 如果格挡
B42: 格挡后伤害=计算暴击后的伤害*(1-基础格挡伤害X-格挡强度）
D43: X | E43: 0.5
D44: 格挡强度∈【0,1】
B45: 举例
B46: 受击者的格挡强度为20%，受击者计算完暴击后，应该受到的伤害为1000，此时触发了格挡
B47: 触发格挡后，受到的伤害为1000*（1-50-20%）=300
B53: 流程6 | C53: 计算最终伤害
B54: 最终伤害 =
B55: 计算完暴击、格挡后伤害 *（1+ 攻击者 伤害加成）*（1 - 受击者 伤害减免）*（1 + 受击者受到伤害增加）*（1+ 攻击者 玩法伤害加成）*（1 - 受击者 玩法伤害减免）
B58: 所有类型的伤害加成的乘区相同
B59: 例如：A角色拥有10%伤害增加，20%单体伤害增加，30%群体伤害增加，40%技能伤害增加，50%必杀伤害增加，60%的物理伤害增加和70%的魔法伤害增加
B60: 那么他放单体物理技能时的伤害增加值为10%+20%+40%+60%=130%
B61: 那么他放群体魔法必杀时的伤害增加值为10%+30%+50%+70%=160%
B63: 公式中 受击者 伤害减免属性 计算结果 最大不超过X%，X为75
B64: 最终伤害数值保底为X,X为1
...

Sheet 标准模型
C2: 战斗节奏
C3: 整场战斗时间
C5: 前期 | D5: 中期 | E5: 后期
B6: 总体战斗时长（秒） | C6: 60 | D6: 120 | E6: 150
B7: boss战时长占比 | C7: 0.5 | D7: 0.75 | E7: 0.8
B9: boss战时长（秒） | C9: =C6*C7 -> 30 | D9: =D6*D7 -> 90 | E9: =E6*E7 -> 120
C11: 在标准模型下预估整场boss战的时长和节奏,以3人放普攻、5人放必杀
C12: 考虑主要的是pve体验，玩家的生命值和防御主要决定有效生命值，实际表现为挨怪物多少下打会死，攻击力主要表现为打怪物的时间
C13: 理论上怪攻击击和同等级的玩家应该相同，所以玩家的攻防血比应该就是怪攻击击自己多少下会死
C14: 假设怪物的dps系数为
C15: 1 | D15: 攻击力/s
C17: 实际血攻防投放比例比
C18: 生命 | D18: 攻击 | E18: 防御
C19: 10 | D19: 3 | E19: 2
C21: 基础属性组成
B22: 裸体属性 | C22: 1 | D22: 初始属性
C23: 2 | D23: 升级属性
C24: 3 | D24: 升阶属性
C25: 4 | D25: 星盘属性的固定值
C27: 5 | D27: 专武属性
C28: 6 | D28: 旅券
C29: 7 | D29: 主角装备属性
B31: 角色基础属性拍定 | C31: 生命 | D31: 攻击 | E31: 防御
C32: 5000 | D32: 1500 | E32: 1000
C33: 10 | D33: 3 | E33: 2
B36: 角色基础属性投放预计
C37: 裸体属性 | G37: 额外属性
C38: 初始属性 | D38: 升级属性 | E38: 升阶属性 | F38: 星盘属性 | G38: 专武属性 | H38: 旅券 | I38: 主角装备属性 | M38: 裸体总和 | N38: 额外总和
B39: 基础属性投放系数 | C39: 1 | D39: 4.2 | E39: 1.5 | F39: 1.2 | G39: 4 | H39: 6 | I39: 10 | M39: =SUM(C39:F39) -> 7.9 | N39: =SUM(G39:I39) -> 20
B42: 初始标准人属性 | C42: 生命 | D42: 攻击 | E42: 防御
C43: =C32 -> 5000 | D43: =D32 -> 1500 | E43: =E32 -> 1000 | G43: 减伤率 | H43: =ROUND(E43/(E43+战斗公式!$M$27),2) -> 0.04 | I43: eHP | J43: =ROUND(C43/(1-H43),0) -> 5208
I44: ttk | J44: =J43/(D43*$C$15) -> 3.472 | K44: 秒
A46: 中期 | B46: 无百分比标准人属性
B48: 裸体属性 | C48: 生命 | D48: 攻击 | E48: 防御
C49: =C$32*$M$39 -> 39500 | D49: =D$32*$M$39 -> 11850 | E49: =E$32*$M$39 -> 7900
B51: 额外基础属性 | C51: 生命 | D51: 攻击 | E51: 防御
C52: =$N$39*C$32 -> 100000 | D52: =$N$39*D$32 -> 30000 | E52: =$N$39*E$32 -> 20000
B54: 总基础属性 | C54: 生命 | D54: 攻击 | E54: 防御
C55: =C49+C52 -> 139500 | D55: =D49+D52 -> 41850 | E55: =E49+E52 -> 27900 | G55: 减伤率 | H55: =ROUND(E55/(E55+战斗公式!$M$27),2) -> 0.54 | I55: eHP | J55: =ROUND(C55/(1-H55),0) -> 303261
I56: ttk | J56: =J55/(D55*$C$15) -> 7.2463799 | K56: 秒
...

Sheet 怪物标准模型
B2: 怪物标准模型等级
B3: 500
C4: 生命 | D4: 攻击 | E4: 防御 | F4: 生命 | G4: 攻击 | H4: 防御 | I4: 生命 | J4: 攻击 | K4: 防御 | O4: 普攻系数倍率 | P4: 技能系数倍率 | Q4: 必杀系数倍率 | R4: 战斗支持倍率 | S4: 暴击率 | T4: 暴击伤害 | U4: 普攻乘区 | V4: 必杀乘区 | W4: 增伤乘区 | AG4: 人数系数 | AH4: 攻击系数修正 | AI4: BOSS生命系数修正 | AJ4: 小怪生命系数修正 | AK4: 小怪攻击系数修正
B5: 最低 | C5: =标准模型!$C$49/$B$3 -> 79 | D5: =标准模型!$D$49/$B$3 -> 23.7 | E5: =标准模型!$E$49/$B$3 -> 15.8 | F5: =标准模型!$C$52/$B$3 -> 200 | G5: =标准模型!$D$52/$B$3 -> 60 | H5: =标准模型!$E$52/$B$3 -> 40 | I5: 0 | J5: =标准模型!$I$65/$B$3 -> 0.0072 | K5: =标准模型!$J$65/$B$3 -> 0.0072 | O5: =标准模型!C76*标准模型!H84 -> 0.5 | P5: 0 | Q5: =标准模型!C77*标准模型!H84 -> 0.275 | R5: 1 | S5: =战斗属性!$F$11 -> 0.05 | T5: =战斗属性!$F$12 -> 2 | U5: 1 | V5: 1 | W5: 1 | AG5: 1 | AH5: 0.3 | AI5: 2.15 | AJ5: 1.8 | AK5: 1
B6: 最高 | C6: =标准模型!$C$49 -> 39500 | D6: =标准模型!$D$49 -> 11850 | E6: =标准模型!$E$49 -> 7900 | F6: =标准模型!$C$52 -> 100000 | G6: =标准模型!$D$52 -> 30000 | H6: =标准模型!$E$52 -> 20000 | I6: 0 | J6: =标准模型!$I$65 -> 3.6 | K6: =标准模型!$J$65 -> 3.6 | O6: =标准模型!C76 -> 1 | P6: =标准模型!$C$78 -> 0.4 | Q6: =标准模型!$C$77 -> 0.55 | R6: =标准模型!$C$90 -> 1.2 | S6: =标准模型!$G$65 -> 0.7 | T6: =标准模型!$H$65+战斗属性!$F$12 -> 3.95 | U6: =标准模型!$H$99+1 -> 1 | V6: =标准模型!$H$101+1 -> 1.5452991 | W6: =标准模型!$C$105+1 -> 2.6 | AG6: 5 | AH6: 2.3 | AI6: 1 | AJ6: 1 | AK6: 1
B7: 曲率 | C7: 0.999999 | D7: 0.999999 | E7: 0.999999 | F7: 0.999999 | G7: 0.999999 | H7: 0.999999 | I7: 0.999999 | J7: 0.999999 | K7: 0.999999 | O7: 0.999999 | P7: 1.0015 | Q7: 0.999999 | R7: 0.999999 | S7: 0.999999 | T7: 0.999999 | U7: 0.999999 | V7: 0.999999 | W7: 0.999999 | AG7: 0.9925 | AH7: 1.002 | AI7: 0.95 | AJ7: 0.98 | AK7: 0.997 | AR7: 普通怪 | AS7: 普通盾怪 | AT7: 2级普通怪 | AU7: 站桩怪 | AV7: 炮灰怪 | AW7: 精英怪 | AX7: 精英盾怪 | AY7: BOSS | AZ7: 装备副本BOSS
AL9: BOSS | AO9: 小怪 | AR9: TTK时间 | AS9: TTK时间 | AT9: TTK时间 | AU9: TTK时间 | AV9: TTK时间 | AW9: TTK时间 | AX9: TTK时间 | AY9: TTK时间 | AZ9: TTK时间
C10: 裸体基础属性 | F10: 额外基础属性 | I10: 基础属性百分比 | L10: 算百分比后基础 | O10: 生命放大倍率 | Z10: 最终基础属性 | AL10: 单位秒，最终基础属性 | AO10: 单位秒，最终基础属性 | AR10: 1 | AS10: 3 | AT10: 1.8 | AU10: 0.5 | AV10: 0.15 | AW10: 4 | AX10: 9 | AY10: 60 | AZ10: 30
B11: 等级 | C11: 生命 | D11: 攻击 | E11: 防御 | F11: 生命 | G11: 攻击 | H11: 防御 | I11: 生命 | J11: 攻击 | K11: 防御 | L11: 生命 | M11: 攻击 | N11: 防御 | O11: 普攻系数倍率 | P11: 技能系数倍率 | Q11: 必杀系数倍率 | R11: 战斗支持倍率 | S11: 暴击率 | T11: 暴击伤害 | U11: 普攻乘区 | V11: 必杀乘区 | W11: 增伤乘区 | X11: 无必杀增伤倍率 | Y11: 有必杀增伤倍率 | Z11: 生命 | AA11: 攻击 | AB11: 防御 | AC11: 减伤率 | AD11: ehp | AE11: 无必杀TTK（单位/秒） | AF11: TTK（单位/秒） | AG11: 人数系数 | AH11: 攻击系数修正 | AI11: BOSS生命系数修正 | AJ11: 小怪生命系数修正 | AK11: 小怪攻击系数修正 | AL11: 生命 | AM11: 攻击 | AN11: 防御 | AO11: 生命 | AP11: 攻击 | AR11: 生命 | AS11: 生命 | AT11: 生命 | AU11: 生命 | AV11: 生命 | AW11: 生命 | AX11: 生命 | AY11: 生命 | AZ11: 生命 | BB11: 等级
B12: {=_xlfn.SEQUENCE(B3,1,1,1)} -> 1 | C12: =C$5+(C$6-C$5)*(POWER(C$7,$B12-1)-1)/(POWER(C$7,$B$3-1)-1) -> 79 | D12: =D$5+(D$6-D$5)*(POWER(D$7,$B12-1)-1)/(POWER(D$7,$B$3-1)-1) -> 23.7 | E12: =E$5+(E$6-E$5)*(POWER(E$7,$B12-1)-1)/(POWER(E$7,$B$3-1)-1) -> 15.8 | F12: =F$5+(F$6-F$5)*(POWER(F$7,$B12-1)-1)/(POWER(F$7,$B$3-1)-1) -> 200 | G12: =G$5+(G$6-G$5)*(POWER(G$7,$B12-1)-1)/(POWER(G$7,$B$3-1)-1) -> 60 | H12: =H$5+(H$6-H$5)*(POWER(H$7,$B12-1)-1)/(POWER(H$7,$B$3-1)-1) -> 40 | I12: =I$5+(I$6-I$5)*(POWER(I$7,$B12-1)-1)/(POWER(I$7,$B$3-1)-1) -> 0 | J12: =标准模型!$I$65/1*$B12/$B$3 -> 0.0072 | K12: =J12*标准模型!$J$63 -> 0.0072 | L12: =C12*(1+I12)+F12 -> 279 | M12: =D12*(1+J12)+G12 -> 83.87064 | N12: =E12*(1+K12)+H12 -> 55.91376 | O12: =O$5+(O$6-O$5)*(POWER(O$7,$B12-1)-1)/(POWER(O$7,$B$3-1)-1) -> 0.5 | P12: =P$5+(P$6-P$5)*(POWER(P$7,$B12-1)-1)/(POWER(P$7,$B$3-1)-1) -> 0 | Q12: =Q$5+(Q$6-Q$5)*(POWER(Q$7,$B12-1)-1)/(POWER(Q$7,$B$3-1)-1) -> 0.275 | R12: =R$5+(R$6-R$5)*(POWER(R$7,$B12-1)-1)/(POWER(R$7,$B$3-1)-1) -> 1 | S12: =S$5+(S$6-S$5)*(POWER(S$7,$B12-1)-1)/(POWER(S$7,$B$3-1)-1) -> 0.05 | T12: =T$5+(T$6-T$5)*(POWER(T$7,$B12-1)-1)/(POWER(T$7,$B$3-1)-1) -> 2 | U12: =U$5+(U$6-U$5)*(POWER(U$7,$B12-1)-1)/(POWER(U$7,$B$3-1)-1) -> 1 | V12: =V$5+(V$6-V$5)*(POWER(V$7,$B12-1)-1)/(POWER(V$7,$B$3-1)-1) -> 1 | W12: =W$5+(W$6-W$5)*(POWER(W$7,$B12-1)-1)/(POWER(W$7,$B$3-1)-1) -> 1 | X12: =(1+S12*(T12-1))*U12*W12*(O12+P12)*R12 -> 0.525 | Y12: =(1+S12*(T12-1))*(O12+P12+Q12)*U12*V12*W12*R12 -> 0.81375 | Z12: =Y12*L12 -> 227.03625 | AA12: =M12 -> 83.87064 | AB12: =N12 -> 55.91376 | AC12: =AB12/(AB12+战斗公式!$M$27) -> 0.0023243249 | AD12: =Z12/(1-AC12) -> 227.56519 | AE12: =AD12/AA12/X12 -> 5.1681673 | AF12: =AD12/AA12/Y12 -> 3.3343015 | AG12: =AG$5+(AG$6-AG$5)*(POWER(AG$7,$B12-1)-1)/(POWER(AG$7,$B$3-1)-1) -> 1 | AH12: =$AH$5+($AH$6-$AH$5)*(POWER($AH$7,$B12-1)-1)/(POWER($AH$7,$B$3-1)-1) -> 0.3 | AI12: =$AI$5+($AI$6-$AI$5)*(POWER($AI$7,$B12-1)-1)/(POWER($AI$7,$B$3-1)-1) -> 2.15 | AJ12: =$AJ$5+($AJ$6-$AJ$5)*(POWER($AJ$7,$B12-1)-1)/(POWER($AJ$7,$B$3-1)-1) -> 1.8 | AK12: =$AK$5+($AK$6-$AK$5)*(POWER($AK$7,$B12-1)-1)/(POWER($AK$7,$B$3-1)-1) -> 1 | AL12: =ROUND(Z12/AF12*AG12,0) -> 68 | AM12: =ROUND(AA12*AH12,0) -> 25 | AN12: =ROUND(AB12,0) -> 56 | AO12: =ROUND(Z12/$AE12*AG12*AJ12,0) -> 79 | AP12: =ROUND(AM12*AK12,0) -> 25 | AR12: =ROUNDUP(AR$10*$AO12,0) -> 79 | AS12: =ROUNDUP(AS$10*$AO12,0) -> 237 | AT12: =ROUNDUP(AT$10*$AO12,0) -> 143 | AU12: =ROUNDUP(AU$10*$AO12,0) -> 40 | AV12: =ROUNDUP(AV$10*$AO12,0) -> 12 | AW12: =ROUNDUP(AW$10*$AO12,0) -> 316 | AX12: =ROUNDUP(AX$10*$AO12,0) -> 711 | AY12: =ROUND(AL12*$AY$10*AI12,0) -> 8772 | AZ12: =ROUND(AL12*$AZ$10*AI12,0) -> 4386 | BB12: =B12 -> 1
B13: 2 | C13: =C$5+(C$6-C$5)*(POWER(C$7,$B13-1)-1)/(POWER(C$7,$B$3-1)-1) -> 158.01967 | D13: =D$5+(D$6-D$5)*(POWER(D$7,$B13-1)-1)/(POWER(D$7,$B$3-1)-1) -> 47.405902 | E13: =E$5+(E$6-E$5)*(POWER(E$7,$B13-1)-1)/(POWER(E$7,$B$3-1)-1) -> 31.603935 | F13: =F$5+(F$6-F$5)*(POWER(F$7,$B13-1)-1)/(POWER(F$7,$B$3-1)-1) -> 400.0498 | G13: =G$5+(G$6-G$5)*(POWER(G$7,$B13-1)-1)/(POWER(G$7,$B$3-1)-1) -> 120.01494 | H13: =H$5+(H$6-H$5)*(POWER(H$7,$B13-1)-1)/(POWER(H$7,$B$3-1)-1) -> 80.009961 | I13: =I$5+(I$6-I$5)*(POWER(I$7,$B13-1)-1)/(POWER(I$7,$B$3-1)-1) -> 0 | J13: =标准模型!$I$65/1*$B13/$B$3 -> 0.0144 | K13: =J13*标准模型!$J$63 -> 0.0144 | L13: =C13*(1+I13)+F13 -> 558.06948 | M13: =D13*(1+J13)+G13 -> 168.10349 | N13: =E13*(1+K13)+H13 -> 112.06899 | O13: =O$5+(O$6-O$5)*(POWER(O$7,$B13-1)-1)/(POWER(O$7,$B$3-1)-1) -> 0.50100225 | P13: =P$5+(P$6-P$5)*(POWER(P$7,$B13-1)-1)/(POWER(P$7,$B$3-1)-1) -> 0.00053925713 | Q13: =Q$5+(Q$6-Q$5)*(POWER(Q$7,$B13-1)-1)/(POWER(Q$7,$B$3-1)-1) -> 0.27555124 | R13: =R$5+(R$6-R$5)*(POWER(R$7,$B13-1)-1)/(POWER(R$7,$B$3-1)-1) -> 1.0004009 | S13: =S$5+(S$6-S$5)*(POWER(S$7,$B13-1)-1)/(POWER(S$7,$B$3-1)-1) -> 0.05130293 | T13: =T$5+(T$6-T$5)*(POWER(T$7,$B13-1)-1)/(POWER(T$7,$B$3-1)-1) -> 2.0039088 | U13: =U$5+(U$6-U$5)*(POWER(U$7,$B13-1)-1)/(POWER(U$7,$B$3-1)-1) -> 1 | V13: =V$5+(V$6-V$5)*(POWER(V$7,$B13-1)-1)/(POWER(V$7,$B$3-1)-1) -> 1.0010931 | W13: =W$5+(W$6-W$5)*(POWER(W$7,$B13-1)-1)/(POWER(W$7,$B$3-1)-1) -> 1.0032072 | X13: =(1+S13*(T13-1))*U13*W13*(O13+P13)*R13 -> 0.52927613 | Y13: =(1+S13*(T13-1))*(O13+P13+Q13)*U13*V13*W13*R13 -> 0.82096139 | Z13: =Y13*L13 -> 458.15349 | AA13: =M13 -> 168.10349 | AB13: =N13 -> 112.06899 | AC13: =AB13/(AB13+战斗公式!$M$27) -> 0.0046478381 | AD13: =Z13/(1-AC13) -> 460.29286 | AE13: =AD13/AA13/X13 -> 5.1733898 | AF13: =AD13/AA13/Y13 -> 3.3352991 | AG13: =AG$5+(AG$6-AG$5)*(POWER(AG$7,$B13-1)-1)/(POWER(AG$7,$B$3-1)-1) -> 1.0307177 | AH13: =$AH$5+($AH$6-$AH$5)*(POWER($AH$7,$B13-1)-1)/(POWER($AH$7,$B$3-1)-1) -> 0.30233898 | AI13: =$AI$5+($AI$6-$AI$5)*(POWER($AI$7,$B13-1)-1)/(POWER($AI$7,$B$3-1)-1) -> 2.0925 | AJ13: =$AJ$5+($AJ$6-$AJ$5)*(POWER($AJ$7,$B13-1)-1)/(POWER($AJ$7,$B$3-1)-1) -> 1.7839993 | AK13: =$AK$5+($AK$6-$AK$5)*(POWER($AK$7,$B13-1)-1)/(POWER($AK$7,$B$3-1)-1) -> 1 | AL13: =ROUND(Z13/AF13*AG13,0) -> 142 | AM13: =ROUND(AA13*AH13,0) -> 51 | AN13: =ROUND(AB13,0) -> 112 | AO13: =ROUND(Z13/$AE13*AG13*AJ13,0) -> 163 | AP13: =ROUND(AM13*AK13,0) -> 51 | AR13: =ROUNDUP(AR$10*$AO13,0) -> 163 | AS13: =ROUNDUP(AS$10*$AO13,0) -> 489 | AT13: =ROUNDUP(AT$10*$AO13,0) -> 294 | AU13: =ROUNDUP(AU$10*$AO13,0) -> 82 | AV13: =ROUNDUP(AV$10*$AO13,0) -> 25 | AW13: =ROUNDUP(AW$10*$AO13,0) -> 652 | AX13: =ROUNDUP(AX$10*$AO13,0) -> 1467 | AY13: =ROUND(AL13*$AY$10*AI13,0) -> 17828 | AZ13: =ROUND(AL13*$AZ$10*AI13,0) -> 8914 | BB13: =B13 -> 2
B14: 3 | C14: =C$5+(C$6-C$5)*(POWER(C$7,$B14-1)-1)/(POWER(C$7,$B$3-1)-1) -> 237.03927 | D14: =D$5+(D$6-D$5)*(POWER(D$7,$B14-1)-1)/(POWER(D$7,$B$3-1)-1) -> 71.11178 | E14: =E$5+(E$6-E$5)*(POWER(E$7,$B14-1)-1)/(POWER(E$7,$B$3-1)-1) -> 47.407853 | F14: =F$5+(F$6-F$5)*(POWER(F$7,$B14-1)-1)/(POWER(F$7,$B$3-1)-1) -> 600.09941 | G14: =G$5+(G$6-G$5)*(POWER(G$7,$B14-1)-1)/(POWER(G$7,$B$3-1)-1) -> 180.02982 | H14: =H$5+(H$6-H$5)*(POWER(H$7,$B14-1)-1)/(POWER(H$7,$B$3-1)-1) -> 120.01988 | I14: =I$5+(I$6-I$5)*(POWER(I$7,$B14-1)-1)/(POWER(I$7,$B$3-1)-1) -> 0 | J14: =标准模型!$I$65/1*$B14/$B$3 -> 0.0216 | K14: =J14*标准模型!$J$63 -> 0.0216 | L14: =C14*(1+I14)+F14 -> 837.13867 | M14: =D14*(1+J14)+G14 -> 252.67762 | N14: =E14*(1+K14)+H14 -> 168.45174 | O14: =O$5+(O$6-O$5)*(POWER(O$7,$B14-1)-1)/(POWER(O$7,$B$3-1)-1) -> 0.50200451 | P14: =P$5+(P$6-P$5)*(POWER(P$7,$B14-1)-1)/(POWER(P$7,$B$3-1)-1) -> 0.0010793231 | Q14: =Q$5+(Q$6-Q$5)*(POWER(Q$7,$B14-1)-1)/(POWER(Q$7,$B$3-1)-1) -> 0.27610248 | R14: =R$5+(R$6-R$5)*(POWER(R$7,$B14-1)-1)/(POWER(R$7,$B$3-1)-1) -> 1.0008018 | S14: =S$5+(S$6-S$5)*(POWER(S$7,$B14-1)-1)/(POWER(S$7,$B$3-1)-1) -> 0.052605858 | T14: =T$5+(T$6-T$5)*(POWER(T$7,$B14-1)-1)/(POWER(T$7,$B$3-1)-1) -> 2.0078176 | U14: =U$5+(U$6-U$5)*(POWER(U$7,$B14-1)-1)/(POWER(U$7,$B$3-1)-1) -> 1 | V14: =V$5+(V$6-V$5)*(POWER(V$7,$B14-1)-1)/(POWER(V$7,$B$3-1)-1) -> 1.0021861 | W14: =W$5+(W$6-W$5)*(POWER(W$7,$B14-1)-1)/(POWER(W$7,$B$3-1)-1) -> 1.0064144 | X14: =(1+S14*(T14-1))*U14*W14*(O14+P14)*R14 -> 0.53358144 | Y14: =(1+S14*(T14-1))*(O14+P14+Q14)*U14*V14*W14*R14 -> 0.82822827 | Z14: =Y14*L14 -> 693.34191 | AA14: =M14 -> 252.67762 | AB14: =N14 -> 168.45174 | AC14: =AB14/(AB14+战斗公式!$M$27) -> 0.0069699022 | AD14: =Z14/(1-AC14) -> 698.20836 | AE14: =AD14/AA14/X14 -> 5.1786619 | AF14: =AD14/AA14/Y14 -> 3.336324 | AG14: =AG$5+(AG$6-AG$5)*(POWER(AG$7,$B14-1)-1)/(POWER(AG$7,$B$3-1)-1) -> 1.0612049 | AH14: =$AH$5+($AH$6-$AH$5)*(POWER($AH$7,$B14-1)-1)/(POWER($AH$7,$B$3-1)-1) -> 0.30468264 | AI14: =$AI$5+($AI$6-$AI$5)*(POWER($AI$7,$B14-1)-1)/(POWER($AI$7,$B$3-1)-1) -> 2.037875 | AJ14: =$AJ$5+($AJ$6-$AJ$5)*(POWER($AJ$7,$B14-1)-1)/(POWER($AJ$7,$B$3-1)-1) -> 1.7683187 | AK14: =$AK$5+($AK$6-$AK$5)*(POWER($AK$7,$B14-1)-1)/(POWER($AK$7,$B$3-1)-1) -> 1 | AL14: =ROUND(Z14/AF14*AG14,0) -> 221 | AM14: =ROUND(AA14*AH14,0) -> 77 | AN14: =ROUND(AB14,0) -> 168 | AO14: =ROUND(Z14/$AE14*AG14*AJ14,0) -> 251 | AP14: =ROUND(AM14*AK14,0) -> 77 | AR14: =ROUNDUP(AR$10*$AO14,0) -> 251 | AS14: =ROUNDUP(AS$10*$AO14,0) -> 753 | AT14: =ROUNDUP(AT$10*$AO14,0) -> 452 | AU14: =ROUNDUP(AU$10*$AO14,0) -> 126 | AV14: =ROUNDUP(AV$10*$AO14,0) -> 38 | AW14: =ROUNDUP(AW$10*$AO14,0) -> 1004 | AX14: =ROUNDUP(AX$10*$AO14,0) -> 2259 | AY14: =ROUND(AL14*$AY$10*AI14,0) -> 27022 | AZ14: =ROUND(AL14*$AZ$10*AI14,0) -> 13511 | BB14: =B14 -> 3
B15: 4 | C15: =C$5+(C$6-C$5)*(POWER(C$7,$B15-1)-1)/(POWER(C$7,$B$3-1)-1) -> 316.05878 | D15: =D$5+(D$6-D$5)*(POWER(D$7,$B15-1)-1)/(POWER(D$7,$B$3-1)-1) -> 94.817634 | E15: =E$5+(E$6-E$5)*(POWER(E$7,$B15-1)-1)/(POWER(E$7,$B$3-1)-1) -> 63.211756 | F15: =F$5+(F$6-F$5)*(POWER(F$7,$B15-1)-1)/(POWER(F$7,$B$3-1)-1) -> 800.14881 | G15: =G$5+(G$6-G$5)*(POWER(G$7,$B15-1)-1)/(POWER(G$7,$B$3-1)-1) -> 240.04464 | H15: =H$5+(H$6-H$5)*(POWER(H$7,$B15-1)-1)/(POWER(H$7,$B$3-1)-1) -> 160.02976 | I15: =I$5+(I$6-I$5)*(POWER(I$7,$B15-1)-1)/(POWER(I$7,$B$3-1)-1) -> 0 | J15: =标准模型!$I$65/1*$B15/$B$3 -> 0.0288 | K15: =J15*标准模型!$J$63 -> 0.0288 | L15: =C15*(1+I15)+F15 -> 1116.2076 | M15: =D15*(1+J15)+G15 -> 337.59303 | N15: =E15*(1+K15)+H15 -> 225.06202 | O15: =O$5+(O$6-O$5)*(POWER(O$7,$B15-1)-1)/(POWER(O$7,$B$3-1)-1) -> 0.50300676 | P15: =P$5+(P$6-P$5)*(POWER(P$7,$B15-1)-1)/(POWER(P$7,$B$3-1)-1) -> 0.0016201992 | Q15: =Q$5+(Q$6-Q$5)*(POWER(Q$7,$B15-1)-1)/(POWER(Q$7,$B$3-1)-1) -> 0.27665372 | R15: =R$5+(R$6-R$5)*(POWER(R$7,$B15-1)-1)/(POWER(R$7,$B$3-1)-1) -> 1.0012027 | S15: =S$5+(S$6-S$5)*(POWER(S$7,$B15-1)-1)/(POWER(S$7,$B$3-1)-1) -> 0.053908785 | T15: =T$5+(T$6-T$5)*(POWER(T$7,$B15-1)-1)/(POWER(T$7,$B$3-1)-1) -> 2.0117264 | U15: =U$5+(U$6-U$5)*(POWER(U$7,$B15-1)-1)/(POWER(U$7,$B$3-1)-1) -> 1 | V15: =V$5+(V$6-V$5)*(POWER(V$7,$B15-1)-1)/(POWER(V$7,$B$3-1)-1) -> 1.0032792 | W15: =W$5+(W$6-W$5)*(POWER(W$7,$B15-1)-1)/(POWER(W$7,$B$3-1)-1) -> 1.0096216 | X15: =(1+S15*(T15-1))*U15*W15*(O15+P15)*R15 -> 0.53791611 | Y15: =(1+S15*(T15-1))*(O15+P15+Q15)*U15*V15*W15*R15 -> 0.83555102 | Z15: =Y15*L15 -> 932.6484 | AA15: =M15 -> 337.59303 | AB15: =N15 -> 225.06202 | AC15: =AB15/(AB15+战斗公式!$M$27) -> 0.009290462 | AD15: =Z15/(1-AC15) -> 941.39439 | AE15: =AD15/AA15/X15 -> 5.1839833 | AF15: =AD15/AA15/Y15 -> 3.3373762 | AG15: =AG$5+(AG$6-AG$5)*(POWER(AG$7,$B15-1)-1)/(POWER(AG$7,$B$3-1)-1) -> 1.0914635 | AH15: =$AH$5+($AH$6-$AH$5)*(POWER($AH$7,$B15-1)-1)/(POWER($AH$7,$B$3-1)-1) -> 0.30703098 | AI15: =$AI$5+($AI$6-$AI$5)*(POWER($AI$7,$B15-1)-1)/(POWER($AI$7,$B$3-1)-1) -> 1.9859812 | AJ15: =$AJ$5+($AJ$6-$AJ$5)*(POWER($AJ$7,$B15-1)-1)/(POWER($AJ$7,$B$3-1)-1) -> 1.7529516 | AK15: =$AK$5+($AK$6-$AK$5)*(POWER($AK$7,$B15-1)-1)/(POWER($AK$7,$B$3-1)-1) -> 1 | AL15: =ROUND(Z15/AF15*AG15,0) -> 305 | AM15: =ROUND(AA15*AH15,0) -> 104 | AN15: =ROUND(AB15,0) -> 225 | AO15: =ROUND(Z15/$AE15*AG15*AJ15,0) -> 344 | AP15: =ROUND(AM15*AK15,0) -> 104 | AR15: =ROUNDUP(AR$10*$AO15,0) -> 344 | AS15: =ROUNDUP(AS$10*$AO15,0) -> 1032 | AT15: =ROUNDUP(AT$10*$AO15,0) -> 620 | AU15: =ROUNDUP(AU$10*$AO15,0) -> 172 | AV15: =ROUNDUP(AV$10*$AO15,0) -> 52 | AW15: =ROUNDUP(AW$10*$AO15,0) -> 1376 | AX15: =ROUNDUP(AX$10*$AO15,0) -> 3096 | AY15: =ROUND(AL15*$AY$10*AI15,0) -> 36343 | AZ15: =ROUND(AL15*$AZ$10*AI15,0) -> 18172 | BB15: =B15 -> 4
B16: 5 | C16: =C$5+(C$6-C$5)*(POWER(C$7,$B16-1)-1)/(POWER(C$7,$B$3-1)-1) -> 395.07822 | D16: =D$5+(D$6-D$5)*(POWER(D$7,$B16-1)-1)/(POWER(D$7,$B$3-1)-1) -> 118.52346 | E16: =E$5+(E$6-E$5)*(POWER(E$7,$B16-1)-1)/(POWER(E$7,$B$3-1)-1) -> 79.015643 | F16: =F$5+(F$6-F$5)*(POWER(F$7,$B16-1)-1)/(POWER(F$7,$B$3-1)-1) -> 1000.198 | G16: =G$5+(G$6-G$5)*(POWER(G$7,$B16-1)-1)/(POWER(G$7,$B$3-1)-1) -> 300.0594 | H16: =H$5+(H$6-H$5)*(POWER(H$7,$B16-1)-1)/(POWER(H$7,$B$3-1)-1) -> 200.0396 | I16: =I$5+(I$6-I$5)*(POWER(I$7,$B16-1)-1)/(POWER(I$7,$B$3-1)-1) -> 0 | J16: =标准模型!$I$65/1*$B16/$B$3 -> 0.036 | K16: =J16*标准模型!$J$63 -> 0.036 | L16: =C16*(1+I16)+F16 -> 1395.2762 | M16: =D16*(1+J16)+G16 -> 422.84971 | N16: =E16*(1+K16)+H16 -> 281.89981 | O16: =O$5+(O$6-O$5)*(POWER(O$7,$B16-1)-1)/(POWER(O$7,$B$3-1)-1) -> 0.50400901 | P16: =P$5+(P$6-P$5)*(POWER(P$7,$B16-1)-1)/(POWER(P$7,$B$3-1)-1) -> 0.0021618867 | Q16: =Q$5+(Q$6-Q$5)*(POWER(Q$7,$B16-1)-1)/(POWER(Q$7,$B$3-1)-1) -> 0.27720495 | R16: =R$5+(R$6-R$5)*(POWER(R$7,$B16-1)-1)/(POWER(R$7,$B$3-1)-1) -> 1.0016036 | S16: =S$5+(S$6-S$5)*(POWER(S$7,$B16-1)-1)/(POWER(S$7,$B$3-1)-1) -> 0.055211711 | T16: =T$5+(T$6-T$5)*(POWER(T$7,$B16-1)-1)/(POWER(T$7,$B$3-1)-1) -> 2.0156351 | U16: =U$5+(U$6-U$5)*(POWER(U$7,$B16-1)-1)/(POWER(U$7,$B$3-1)-1) -> 1 | V16: =V$5+(V$6-V$5)*(POWER(V$7,$B16-1)-1)/(POWER(V$7,$B$3-1)-1) -> 1.0043722 | W16: =W$5+(W$6-W$5)*(POWER(W$7,$B16-1)-1)/(POWER(W$7,$B$3-1)-1) -> 1.0128288 | X16: =(1+S16*(T16-1))*U16*W16*(O16+P16)*R16 -> 0.54228032 | Y16: =(1+S16*(T16-1))*(O16+P16+Q16)*U16*V16*W16*R16 -> 0.84293006 | Z16: =Y16*L16 -> 1176.1203 | AA16: =M16 -> 422.84971 | AB16: =N16 -> 281.89981 | AC16: =AB16/(AB16+战斗公式!$M$27) -> 0.011609463 | AD16: =Z16/(1-AC16) -> 1189.9348 | AE16: =AD16/AA16/X16 -> 5.1893537 | AF16: =AD16/AA16/Y16 -> 3.3384554 | AG16: =AG$5+(AG$6-AG$5)*(POWER(AG$7,$B16-1)-1)/(POWER(AG$7,$B$3-1)-1) -> 1.1214952 | AH16: =$AH$5+($AH$6-$AH$5)*(POWER($AH$7,$B16-1)-1)/(POWER($AH$7,$B$3-1)-1) -> 0.30938402 | AI16: =$AI$5+($AI$6-$AI$5)*(POWER($AI$7,$B16-1)-1)/(POWER($AI$7,$B$3-1)-1) -> 1.9366822 | AJ16: =$AJ$5+($AJ$6-$AJ$5)*(POWER($AJ$7,$B16-1)-1)/(POWER($AJ$7,$B$3-1)-1) -> 1.7378919 | AK16: =$AK$5+($AK$6-$AK$5)*(POWER($AK$7,$B16-1)-1)/(POWER($AK$7,$B$3-1)-1) -> 1 | AL16: =ROUND(Z16/AF16*AG16,0) -> 395 | AM16: =ROUND(AA16*AH16,0) -> 131 | AN16: =ROUND(AB16,0) -> 282 | AO16: =ROUND(Z16/$AE16*AG16*AJ16,0) -> 442 | AP16: =ROUND(AM16*AK16,0) -> 131 | AR16: =ROUNDUP(AR$10*$AO16,0) -> 442 | AS16: =ROUNDUP(AS$10*$AO16,0) -> 1326 | AT16: =ROUNDUP(AT$10*$AO16,0) -> 796 | AU16: =ROUNDUP(AU$10*$AO16,0) -> 221 | AV16: =ROUNDUP(AV$10*$AO16,0) -> 67 | AW16: =ROUNDUP(AW$10*$AO16,0) -> 1768 | AX16: =ROUNDUP(AX$10*$AO16,0) -> 3978 | AY16: =ROUND(AL16*$AY$10*AI16,0) -> 45899 | AZ16: =ROUND(AL16*$AZ$10*AI16,0) -> 22950 | BB16: =B16 -> 5
B17: 6 | C17: =C$5+(C$6-C$5)*(POWER(C$7,$B17-1)-1)/(POWER(C$7,$B$3-1)-1) -> 474.09757 | D17: =D$5+(D$6-D$5)*(POWER(D$7,$B17-1)-1)/(POWER(D$7,$B$3-1)-1) -> 142.22927 | E17: =E$5+(E$6-E$5)*(POWER(E$7,$B17-1)-1)/(POWER(E$7,$B$3-1)-1) -> 94.819515 | F17: =F$5+(F$6-F$5)*(POWER(F$7,$B17-1)-1)/(POWER(F$7,$B$3-1)-1) -> 1200.247 | G17: =G$5+(G$6-G$5)*(POWER(G$7,$B17-1)-1)/(POWER(G$7,$B$3-1)-1) -> 360.07411 | H17: =H$5+(H$6-H$5)*(POWER(H$7,$B17-1)-1)/(POWER(H$7,$B$3-1)-1) -> 240.0494 | I17: =I$5+(I$6-I$5)*(POWER(I$7,$B17-1)-1)/(POWER(I$7,$B$3-1)-1) -> 0 | J17: =标准模型!$I$65/1*$B17/$B$3 -> 0.0432 | K17: =J17*标准模型!$J$63 -> 0.0432 | L17: =C17*(1+I17)+F17 -> 1674.3446 | M17: =D17*(1+J17)+G17 -> 508.44768 | N17: =E17*(1+K17)+H17 -> 338.96512 | O17: =O$5+(O$6-O$5)*(POWER(O$7,$B17-1)-1)/(POWER(O$7,$B$3-1)-1) -> 0.50501126 | P17: =P$5+(P$6-P$5)*(POWER(P$7,$B17-1)-1)/(POWER(P$7,$B$3-1)-1) -> 0.0027043866 | Q17: =Q$5+(Q$6-Q$5)*(POWER(Q$7,$B17-1)-1)/(POWER(Q$7,$B$3-1)-1) -> 0.27775619 | R17: =R$5+(R$6-R$5)*(POWER(R$7,$B17-1)-1)/(POWER(R$7,$B$3-1)-1) -> 1.0020045 | S17: =S$5+(S$6-S$5)*(POWER(S$7,$B17-1)-1)/(POWER(S$7,$B$3-1)-1) -> 0.056514635 | T17: =T$5+(T$6-T$5)*(POWER(T$7,$B17-1)-1)/(POWER(T$7,$B$3-1)-1) -> 2.0195439 | U17: =U$5+(U$6-U$5)*(POWER(U$7,$B17-1)-1)/(POWER(U$7,$B$3-1)-1) -> 1 | V17: =V$5+(V$6-V$5)*(POWER(V$7,$B17-1)-1)/(POWER(V$7,$B$3-1)-1) -> 1.0054653 | W17: =W$5+(W$6-W$5)*(POWER(W$7,$B17-1)-1)/(POWER(W$7,$B$3-1)-1) -> 1.016036 | X17: =(1+S17*(T17-1))*U17*W17*(O17+P17)*R17 -> 0.54667427 | Y17: =(1+S17*(T17-1))*(O17+P17+Q17)*U17*V17*W17*R17 -> 0.85036578 | Z17: =Y17*L17 -> 1423.8054 | AA17: =M17 -> 508.44768 | AB17: =N17 -> 338.96512 | AC17: =AB17/(AB17+战斗公式!$M$27) -> 0.01392685 | AD17: =Z17/(1-AC17) -> 1443.9145 | AE17: =AD17/AA17/X17 -> 5.1947731 | AF17: =AD17/AA17/Y17 -> 3.3395614 | AG17: =AG$5+(AG$6-AG$5)*(POWER(AG$7,$B17-1)-1)/(POWER(AG$7,$B$3-1)-1) -> 1.1513017 | AH17: =$AH$5+($AH$6-$AH$5)*(POWER($AH$7,$B17-1)-1)/(POWER($AH$7,$B$3-1)-1) -> 0.31174177 | AI17: =$AI$5+($AI$6-$AI$5)*(POWER($AI$7,$B17-1)-1)/(POWER($AI$7,$B$3-1)-1) -> 1.8898481 | AJ17: =$AJ$5+($AJ$6-$AJ$5)*(POWER($AJ$7,$B17-1)-1)/(POWER($AJ$7,$B$3-1)-1) -> 1.7231334 | AK17: =$AK$5+($AK$6-$AK$5)*(POWER($AK$7,$B17-1)-1)/(POWER($AK$7,$B$3-1)-1) -> 1 | AL17: =ROUND(Z17/AF17*AG17,0) -> 491 | AM17: =ROUND(AA17*AH17,0) -> 159 | AN17: =ROUND(AB17,0) -> 339 | AO17: =ROUND(Z17/$AE17*AG17*AJ17,0) -> 544 | AP17: =ROUND(AM17*AK17,0) -> 159 | AR17: =ROUNDUP(AR$10*$AO17,0) -> 544 | AS17: =ROUNDUP(AS$10*$AO17,0) -> 1632 | AT17: =ROUNDUP(AT$10*$AO17,0) -> 980 | AU17: =ROUNDUP(AU$10*$AO17,0) -> 272 | AV17: =ROUNDUP(AV$10*$AO17,0) -> 82 | AW17: =ROUNDUP(AW$10*$AO17,0) -> 2176 | AX17: =ROUNDUP(AX$10*$AO17,0) -> 4896 | AY17: =ROUND(AL17*$AY$10*AI17,0) -> 55675 | AZ17: =ROUND(AL17*$AZ$10*AI17,0) -> 27837 | BB17: =B17 -> 6
B18: 7 | C18: =C$5+(C$6-C$5)*(POWER(C$7,$B18-1)-1)/(POWER(C$7,$B$3-1)-1) -> 553.11685 | D18: =D$5+(D$6-D$5)*(POWER(D$7,$B18-1)-1)/(POWER(D$7,$B$3-1)-1) -> 165.93506 | E18: =E$5+(E$6-E$5)*(POWER(E$7,$B18-1)-1)/(POWER(E$7,$B$3-1)-1) -> 110.62337 | F18: =F$5+(F$6-F$5)*(POWER(F$7,$B18-1)-1)/(POWER(F$7,$B$3-1)-1) -> 1400.2958 | G18: =G$5+(G$6-G$5)*(POWER(G$7,$B18-1)-1)/(POWER(G$7,$B$3-1)-1) -> 420.08875 | H18: =H$5+(H$6-H$5)*(POWER(H$7,$B18-1)-1)/(POWER(H$7,$B$3-1)-1) -> 280.05916 | I18: =I$5+(I$6-I$5)*(POWER(I$7,$B18-1)-1)/(POWER(I$7,$B$3-1)-1) -> 0 | J18: =标准模型!$I$65/1*$B18/$B$3 -> 0.0504 | K18: =J18*标准模型!$J$63 -> 0.0504 | L18: =C18*(1+I18)+F18 -> 1953.4127 | M18: =D18*(1+J18)+G18 -> 594.38693 | N18: =E18*(1+K18)+H18 -> 396.25795 | O18: =O$5+(O$6-O$5)*(POWER(O$7,$B18-1)-1)/(POWER(O$7,$B$3-1)-1) -> 0.50601351 | P18: =P$5+(P$6-P$5)*(POWER(P$7,$B18-1)-1)/(POWER(P$7,$B$3-1)-1) -> 0.0032477003 | Q18: =Q$5+(Q$6-Q$5)*(POWER(Q$7,$B18-1)-1)/(POWER(Q$7,$B$3-1)-1) -> 0.27830743 | R18: =R$5+(R$6-R$5)*(POWER(R$7,$B18-1)-1)/(POWER(R$7,$B$3-1)-1) -> 1.0024054 | S18: =S$5+(S$6-S$5)*(POWER(S$7,$B18-1)-1)/(POWER(S$7,$B$3-1)-1) -> 0.057817558 | T18: =T$5+(T$6-T$5)*(POWER(T$7,$B18-1)-1)/(POWER(T$7,$B$3-1)-1) -> 2.0234527 | U18: =U$5+(U$6-U$5)*(POWER(U$7,$B18-1)-1)/(POWER(U$7,$B$3-1)-1) -> 1 | V18: =V$5+(V$6-V$5)*(POWER(V$7,$B18-1)-1)/(POWER(V$7,$B$3-1)-1) -> 1.0065583 | W18: =W$5+(W$6-W$5)*(POWER(W$7,$B18-1)-1)/(POWER(W$7,$B$3-1)-1) -> 1.0192432 | X18: =(1+S18*(T18-1))*U18*W18*(O18+P18)*R18 -> 0.55109814 | Y18: =(1+S18*(T18-1))*(O18+P18+Q18)*U18*V18*W18*R18 -> 0.85785859 | Z18: =Y18*L18 -> 1675.7518 | AA18: =M18 -> 594.38693 | AB18: =N18 -> 396.25795 | AC18: =AB18/(AB18+战斗公式!$M$27) -> 0.016242571 | AD18: =Z18/(1-AC18) -> 1703.4198 | AE18: =AD18/AA18/X18 -> 5.2002412 | AF18: =AD18/AA18/Y18 -> 3.3406942 | AG18: =AG$5+(AG$6-AG$5)*(POWER(AG$7,$B18-1)-1)/(POWER(AG$7,$B$3-1)-1) -> 1.1808846 | AH18: =$AH$5+($AH$6-$AH$5)*(POWER($AH$7,$B18-1)-1)/(POWER($AH$7,$B$3-1)-1) -> 0.31410423 | AI18: =$AI$5+($AI$6-$AI$5)*(POWER($AI$7,$B18-1)-1)/(POWER($AI$7,$B$3-1)-1) -> 1.8453557 | AJ18: =$AJ$5+($AJ$6-$AJ$5)*(POWER($AJ$7,$B18-1)-1)/(POWER($AJ$7,$B$3-1)-1) -> 1.7086701 | AK18: =$AK$5+($AK$6-$AK$5)*(POWER($AK$7,$B18-1)-1)/(POWER($AK$7,$B$3-1)-1) -> 1 | AL18: =ROUND(Z18/AF18*AG18,0) -> 592 | AM18: =ROUND(AA18*AH18,0) -> 187 | AN18: =ROUND(AB18,0) -> 396 | AO18: =ROUND(Z18/$AE18*AG18*AJ18,0) -> 650 | AP18: =ROUND(AM18*AK18,0) -> 187 | AR18: =ROUNDUP(AR$10*$AO18,0) -> 650 | AS18: =ROUNDUP(AS$10*$AO18,0) -> 1950 | AT18: =ROUNDUP(AT$10*$AO18,0) -> 1170 | AU18: =ROUNDUP(AU$10*$AO18,0) -> 325 | AV18: =ROUNDUP(AV$10*$AO18,0) -> 98 | AW18: =ROUNDUP(AW$10*$AO18,0) -> 2600 | AX18: =ROUNDUP(AX$10*$AO18,0) -> 5850 | AY18: =ROUND(AL18*$AY$10*AI18,0) -> 65547 | AZ18: =ROUND(AL18*$AZ$10*AI18,0) -> 32774 | BB18: =B18 -> 7
B19: 8 | C19: =C$5+(C$6-C$5)*(POWER(C$7,$B19-1)-1)/(POWER(C$7,$B$3-1)-1) -> 632.13605 | D19: =D$5+(D$6-D$5)*(POWER(D$7,$B19-1)-1)/(POWER(D$7,$B$3-1)-1) -> 189.64081 | E19: =E$5+(E$6-E$5)*(POWER(E$7,$B19-1)-1)/(POWER(E$7,$B$3-1)-1) -> 126.42721 | F19: =F$5+(F$6-F$5)*(POWER(F$7,$B19-1)-1)/(POWER(F$7,$B$3-1)-1) -> 1600.3444 | G19: =G$5+(G$6-G$5)*(POWER(G$7,$B19-1)-1)/(POWER(G$7,$B$3-1)-1) -> 480.10333 | H19: =H$5+(H$6-H$5)*(POWER(H$7,$B19-1)-1)/(POWER(H$7,$B$3-1)-1) -> 320.06889 | I19: =I$5+(I$6-I$5)*(POWER(I$7,$B19-1)-1)/(POWER(I$7,$B$3-1)-1) -> 0 | J19: =标准模型!$I$65/1*$B19/$B$3 -> 0.0576 | K19: =J19*标准模型!$J$63 -> 0.0576 | L19: =C19*(1+I19)+F19 -> 2232.4805 | M19: =D19*(1+J19)+G19 -> 680.66745 | N19: =E19*(1+K19)+H19 -> 453.7783 | O19: =O$5+(O$6-O$5)*(POWER(O$7,$B19-1)-1)/(POWER(O$7,$B$3-1)-1) -> 0.50701575 | P19: =P$5+(P$6-P$5)*(POWER(P$7,$B19-1)-1)/(POWER(P$7,$B$3-1)-1) -> 0.003791829 | Q19: =Q$5+(Q$6-Q$5)*(POWER(Q$7,$B19-1)-1)/(POWER(Q$7,$B$3-1)-1) -> 0.27885866 | R19: =R$5+(R$6-R$5)*(POWER(R$7,$B19-1)-1)/(POWER(R$7,$B$3-1)-1) -> 1.0028063 | S19: =S$5+(S$6-S$5)*(POWER(S$7,$B19-1)-1)/(POWER(S$7,$B$3-1)-1) -> 0.05912048 | T19: =T$5+(T$6-T$5)*(POWER(T$7,$B19-1)-1)/(POWER(T$7,$B$3-1)-1) -> 2.0273614 | U19: =U$5+(U$6-U$5)*(POWER(U$7,$B19-1)-1)/(POWER(U$7,$B$3-1)-1) -> 1 | V19: =V$5+(V$6-V$5)*(POWER(V$7,$B19-1)-1)/(POWER(V$7,$B$3-1)-1) -> 1.0076514 | W19: =W$5+(W$6-W$5)*(POWER(W$7,$B19-1)-1)/(POWER(W$7,$B$3-1)-1) -> 1.0224504 | X19: =(1+S19*(T19-1))*U19*W19*(O19+P19)*R19 -> 0.55555212 | Y19: =(1+S19*(T19-1))*(O19+P19+Q19)*U19*V19*W19*R19 -> 0.86540889 | Z19: =Y19*L19 -> 1932.0084 | AA19: =M19 -> 680.66745 | AB19: =N19 -> 453.7783 | AC19: =AB19/(AB19+战斗公式!$M$27) -> 0.018556572 | AD19: =Z19/(1-AC19) -> 1968.5378 | AE19: =AD19/AA19/X19 -> 5.2057577 | AF19: =AD19/AA19/Y19 -> 3.3418535 | AG19: =AG$5+(AG$6-AG$5)*(POWER(AG$7,$B19-1)-1)/(POWER(AG$7,$B$3-1)-1) -> 1.2102456 | AH19: =$AH$5+($AH$6-$AH$5)*(POWER($AH$7,$B19-1)-1)/(POWER($AH$7,$B$3-1)-1) -> 0.31647142 | AI19: =$AI$5+($AI$6-$AI$5)*(POWER($AI$7,$B19-1)-1)/(POWER($AI$7,$B$3-1)-1) -> 1.8030879 | AJ19: =$AJ$5+($AJ$6-$AJ$5)*(POWER($AJ$7,$B19-1)-1)/(POWER($AJ$7,$B$3-1)-1) -> 1.694496 | AK19: =$AK$5+($AK$6-$AK$5)*(POWER($AK$7,$B19-1)-1)/(POWER($AK$7,$B$3-1)-1) -> 1 | AL19: =ROUND(Z19/AF19*AG19,0) -> 700 | AM19: =ROUND(AA19*AH19,0) -> 215 | AN19: =ROUND(AB19,0) -> 454 | AO19: =ROUND(Z19/$AE19*AG19*AJ19,0) -> 761 | AP19: =ROUND(AM19*AK19,0) -> 215 | AR19: =ROUNDUP(AR$10*$AO19,0) -> 761 | AS19: =ROUNDUP(AS$10*$AO19,0) -> 2283 | AT19: =ROUNDUP(AT$10*$AO19,0) -> 1370 | AU19: =ROUNDUP(AU$10*$AO19,0) -> 381 | AV19: =ROUNDUP(AV$10*$AO19,0) -> 115 | AW19: =ROUNDUP(AW$10*$AO19,0) -> 3044 | AX19: =ROUNDUP(AX$10*$AO19,0) -> 6849 | AY19: =ROUND(AL19*$AY$10*AI19,0) -> 75730 | AZ19: =ROUND(AL19*$AZ$10*AI19,0) -> 37865 | BB19: =B19 -> 8
B20: 9 | C20: =C$5+(C$6-C$5)*(POWER(C$7,$B20-1)-1)/(POWER(C$7,$B$3-1)-1) -> 711.15517 | D20: =D$5+(D$6-D$5)*(POWER(D$7,$B20-1)-1)/(POWER(D$7,$B$3-1)-1) -> 213.34655 | E20: =E$5+(E$6-E$5)*(POWER(E$7,$B20-1)-1)/(POWER(E$7,$B$3-1)-1) -> 142.23103 | F20: =F$5+(F$6-F$5)*(POWER(F$7,$B20-1)-1)/(POWER(F$7,$B$3-1)-1) -> 1800.3928 | G20: =G$5+(G$6-G$5)*(POWER(G$7,$B20-1)-1)/(POWER(G$7,$B$3-1)-1) -> 540.11785 | H20: =H$5+(H$6-H$5)*(POWER(H$7,$B20-1)-1)/(POWER(H$7,$B$3-1)-1) -> 360.07857 | I20: =I$5+(I$6-I$5)*(POWER(I$7,$B20-1)-1)/(POWER(I$7,$B$3-1)-1) -> 0 | J20: =标准模型!$I$65/1*$B20/$B$3 -> 0.0648 | K20: =J20*标准模型!$J$63 -> 0.0648 | L20: =C20*(1+I20)+F20 -> 2511.548 | M20: =D20*(1+J20)+G20 -> 767.28926 | N20: =E20*(1+K20)+H20 -> 511.52617 | O20: =O$5+(O$6-O$5)*(POWER(O$7,$B20-1)-1)/(POWER(O$7,$B$3-1)-1) -> 0.508018 | P20: =P$5+(P$6-P$5)*(POWER(P$7,$B20-1)-1)/(POWER(P$7,$B$3-1)-1) -> 0.0043367739 | Q20: =Q$5+(Q$6-Q$5)*(POWER(Q$7,$B20-1)-1)/(POWER(Q$7,$B$3-1)-1) -> 0.2794099 | R20: =R$5+(R$6-R$5)*(POWER(R$7,$B20-1)-1)/(POWER(R$7,$B$3-1)-1) -> 1.0032072 | S20: =S$5+(S$6-S$5)*(POWER(S$7,$B20-1)-1)/(POWER(S$7,$B$3-1)-1) -> 0.0604234 | T20: =T$5+(T$6-T$5)*(POWER(T$7,$B20-1)-1)/(POWER(T$7,$B$3-1)-1) -> 2.0312702 | U20: =U$5+(U$6-U$5)*(POWER(U$7,$B20-1)-1)/(POWER(U$7,$B$3-1)-1) -> 1 | V20: =V$5+(V$6-V$5)*(POWER(V$7,$B20-1)-1)/(POWER(V$7,$B$3-1)-1) -> 1.0087444 | W20: =W$5+(W$6-W$5)*(POWER(W$7,$B20-1)-1)/(POWER(W$7,$B$3-1)-1) -> 1.0256576 | X20: =(1+S20*(T20-1))*U20*W20*(O20+P20)*R20 -> 0.56003641 | Y20: =(1+S20*(T20-1))*(O20+P20+Q20)*U20*V20*W20*R20 -> 0.87301709 | Z20: =Y20*L20 -> 2192.6243 | AA20: =M20 -> 767.28926 | AB20: =N20 -> 511.52617 | AC20: =AB20/(AB20+战斗公式!$M$27) -> 0.020868801 | AD20: =Z20/(1-AC20) -> 2239.357 | AE20: =AD20/AA20/X20 -> 5.2113226 | AF20: =AD20/AA20/Y20 -> 3.3430393 | AG20: =AG$5+(AG$6-AG$5)*(POWER(AG$7,$B20-1)-1)/(POWER(AG$7,$B$3-1)-1) -> 1.2393864 | AH20: =$AH$5+($AH$6-$AH$5)*(POWER($AH$7,$B20-1)-1)/(POWER($AH$7,$B$3-1)-1) -> 0.31884334 | AI20: =$AI$5+($AI$6-$AI$5)*(POWER($AI$7,$B20-1)-1)/(POWER($AI$7,$B$3-1)-1) -> 1.7629335 | AJ20: =$AJ$5+($AJ$6-$AJ$5)*(POWER($AJ$7,$B20-1)-1)/(POWER($AJ$7,$B$3-1)-1) -> 1.6806054 | AK20: =$AK$5+($AK$6-$AK$5)*(POWER($AK$7,$B20-1)-1)/(POWER($AK$7,$B$3-1)-1) -> 1 | AL20: =ROUND(Z20/AF20*AG20,0) -> 813 | AM20: =ROUND(AA20*AH20,0) -> 245 | AN20: =ROUND(AB20,0) -> 512 | AO20: =ROUND(Z20/$AE20*AG20*AJ20,0) -> 876 | AP20: =ROUND(AM20*AK20,0) -> 245 | AR20: =ROUNDUP(AR$10*$AO20,0) -> 876 | AS20: =ROUNDUP(AS$10*$AO20,0) -> 2628 | AT20: =ROUNDUP(AT$10*$AO20,0) -> 1577 | AU20: =ROUNDUP(AU$10*$AO20,0) -> 438 | AV20: =ROUNDUP(AV$10*$AO20,0) -> 132 | AW20: =ROUNDUP(AW$10*$AO20,0) -> 3504 | AX20: =ROUNDUP(AX$10*$AO20,0) -> 7884 | AY20: =ROUND(AL20*$AY$10*AI20,0) -> 85996 | AZ20: =ROUND(AL20*$AZ$10*AI20,0) -> 42998 | BB20: =B20 -> 9
B21: 10 | C21: =C$5+(C$6-C$5)*(POWER(C$7,$B21-1)-1)/(POWER(C$7,$B$3-1)-1) -> 790.17421 | D21: =D$5+(D$6-D$5)*(POWER(D$7,$B21-1)-1)/(POWER(D$7,$B$3-1)-1) -> 237.05226 | E21: =E$5+(E$6-E$5)*(POWER(E$7,$B21-1)-1)/(POWER(E$7,$B$3-1)-1) -> 158.03484 | F21: =F$5+(F$6-F$5)*(POWER(F$7,$B21-1)-1)/(POWER(F$7,$B$3-1)-1) -> 2000.441 | G21: =G$5+(G$6-G$5)*(POWER(G$7,$B21-1)-1)/(POWER(G$7,$B$3-1)-1) -> 600.13231 | H21: =H$5+(H$6-H$5)*(POWER(H$7,$B21-1)-1)/(POWER(H$7,$B$3-1)-1) -> 400.08821 | I21: =I$5+(I$6-I$5)*(POWER(I$7,$B21-1)-1)/(POWER(I$7,$B$3-1)-1) -> 0 | J21: =标准模型!$I$65/1*$B21/$B$3 -> 0.072 | K21: =J21*标准模型!$J$63 -> 0.072 | L21: =C21*(1+I21)+F21 -> 2790.6152 | M21: =D21*(1+J21)+G21 -> 854.25234 | N21: =E21*(1+K21)+H21 -> 569.50156 | O21: =O$5+(O$6-O$5)*(POWER(O$7,$B21-1)-1)/(POWER(O$7,$B$3-1)-1) -> 0.50902025 | P21: =P$5+(P$6-P$5)*(POWER(P$7,$B21-1)-1)/(POWER(P$7,$B$3-1)-1) -> 0.0048825362 | Q21: =Q$5+(Q$6-Q$5)*(POWER(Q$7,$B21-1)-1)/(POWER(Q$7,$B$3-1)-1) -> 0.27996114 | R21: =R$5+(R$6-R$5)*(POWER(R$7,$B21-1)-1)/(POWER(R$7,$B$3-1)-1) -> 1.0036081 | S21: =S$5+(S$6-S$5)*(POWER(S$7,$B21-1)-1)/(POWER(S$7,$B$3-1)-1) -> 0.061726319 | T21: =T$5+(T$6-T$5)*(POWER(T$7,$B21-1)-1)/(POWER(T$7,$B$3-1)-1) -> 2.035179 | U21: =U$5+(U$6-U$5)*(POWER(U$7,$B21-1)-1)/(POWER(U$7,$B$3-1)-1) -> 1 | V21: =V$5+(V$6-V$5)*(POWER(V$7,$B21-1)-1)/(POWER(V$7,$B$3-1)-1) -> 1.0098375 | W21: =W$5+(W$6-W$5)*(POWER(W$7,$B21-1)-1)/(POWER(W$7,$B$3-1)-1) -> 1.0288648 | X21: =(1+S21*(T21-1))*U21*W21*(O21+P21)*R21 -> 0.5645512 | Y21: =(1+S21*(T21-1))*(O21+P21+Q21)*U21*V21*W21*R21 -> 0.8806836 | Z21: =Y21*L21 -> 2457.6491 | AA21: =M21 -> 854.25234 | AB21: =N21 -> 569.50156 | AC21: =AB21/(AB21+战斗公式!$M$27) -> 0.023179207 | AD21: =Z21/(1-AC21) -> 2515.9672 | AE21: =AD21/AA21/X21 -> 5.2169355 | AF21: =AD21/AA21/Y21 -> 3.3442512 | AG21: =AG$5+(AG$6-AG$5)*(POWER(AG$7,$B21-1)-1)/(POWER(AG$7,$B$3-1)-1) -> 1.2683086 | AH21: =$AH$5+($AH$6-$AH$5)*(POWER($AH$7,$B21-1)-1)/(POWER($AH$7,$B$3-1)-1) -> 0.32122 | AI21: =$AI$5+($AI$6-$AI$5)*(POWER($AI$7,$B21-1)-1)/(POWER($AI$7,$B$3-1)-1) -> 1.7247868 | AJ21: =$AJ$5+($AJ$6-$AJ$5)*(POWER($AJ$7,$B21-1)-1)/(POWER($AJ$7,$B$3-1)-1) -> 1.6669926 | AK21: =$AK$5+($AK$6-$AK$5)*(POWER($AK$7,$B21-1)-1)/(POWER($AK$7,$B$3-1)-1) -> 1 | AL21: =ROUND(Z21/AF21*AG21,0) -> 932 | AM21: =ROUND(AA21*AH21,0) -> 274 | AN21: =ROUND(AB21,0) -> 570 | AO21: =ROUND(Z21/$AE21*AG21*AJ21,0) -> 996 | AP21: =ROUND(AM21*AK21,0) -> 274 | AR21: =ROUNDUP(AR$10*$AO21,0) -> 996 | AS21: =ROUNDUP(AS$10*$AO21,0) -> 2988 | AT21: =ROUNDUP(AT$10*$AO21,0) -> 1793 | AU21: =ROUNDUP(AU$10*$AO21,0) -> 498 | AV21: =ROUNDUP(AV$10*$AO21,0) -> 150 | AW21: =ROUNDUP(AW$10*$AO21,0) -> 3984 | AX21: =ROUNDUP(AX$10*$AO21,0) -> 8964 | AY21: =ROUND(AL21*$AY$10*AI21,0) -> 96450 | AZ21: =ROUND(AL21*$AZ$10*AI21,0) -> 48225 | BB21: =B21 -> 10
B22: 11 | C22: =C$5+(C$6-C$5)*(POWER(C$7,$B22-1)-1)/(POWER(C$7,$B$3-1)-1) -> 869.19317 | D22: =D$5+(D$6-D$5)*(POWER(D$7,$B22-1)-1)/(POWER(D$7,$B$3-1)-1) -> 260.75795 | E22: =E$5+(E$6-E$5)*(POWER(E$7,$B22-1)-1)/(POWER(E$7,$B$3-1)-1) -> 173.83863 | F22: =F$5+(F$6-F$5)*(POWER(F$7,$B22-1)-1)/(POWER(F$7,$B$3-1)-1) -> 2200.489 | G22: =G$5+(G$6-G$5)*(POWER(G$7,$B22-1)-1)/(POWER(G$7,$B$3-1)-1) -> 660.14671 | H22: =H$5+(H$6-H$5)*(POWER(H$7,$B22-1)-1)/(POWER(H$7,$B$3-1)-1) -> 440.09781 | I22: =I$5+(I$6-I$5)*(POWER(I$7,$B22-1)-1)/(POWER(I$7,$B$3-1)-1) -> 0 | J22: =标准模型!$I$65/1*$B22/$B$3 -> 0.0792 | K22: =J22*标准模型!$J$63 -> 0.0792 | L22: =C22*(1+I22)+F22 -> 3069.6822 | M22: =D22*(1+J22)+G22 -> 941.55669 | N22: =E22*(1+K22)+H22 -> 627.70446 | O22: =O$5+(O$6-O$5)*(POWER(O$7,$B22-1)-1)/(POWER(O$7,$B$3-1)-1) -> 0.51002249 | P22: =P$5+(P$6-P$5)*(POWER(P$7,$B22-1)-1)/(POWER(P$7,$B$3-1)-1) -> 0.0054291171 | Q22: =Q$5+(Q$6-Q$5)*(POWER(Q$7,$B22-1)-1)/(POWER(Q$7,$B$3-1)-1) -> 0.28051237 | R22: =R$5+(R$6-R$5)*(POWER(R$7,$B22-1)-1)/(POWER(R$7,$B$3-1)-1) -> 1.004009 | S22: =S$5+(S$6-S$5)*(POWER(S$7,$B22-1)-1)/(POWER(S$7,$B$3-1)-1) -> 0.063029237 | T22: =T$5+(T$6-T$5)*(POWER(T$7,$B22-1)-1)/(POWER(T$7,$B$3-1)-1) -> 2.0390877 | U22: =U$5+(U$6-U$5)*(POWER(U$7,$B22-1)-1)/(POWER(U$7,$B$3-1)-1) -> 1 | V22: =V$5+(V$6-V$5)*(POWER(V$7,$B22-1)-1)/(POWER(V$7,$B$3-1)-1) -> 1.0109305 | W22: =W$5+(W$6-W$5)*(POWER(W$7,$B22-1)-1)/(POWER(W$7,$B$3-1)-1) -> 1.032072 | X22: =(1+S22*(T22-1))*U22*W22*(O22+P22)*R22 -> 0.56909667 | Y22: =(1+S22*(T22-1))*(O22+P22+Q22)*U22*V22*W22*R22 -> 0.88840883 | Z22: =Y22*L22 -> 2727.1328 | AA22: =M22 -> 941.55669 | AB22: =N22 -> 627.70446 | AC22: =AB22/(AB22+战斗公式!$M$27) -> 0.025487737 | AD22: =Z22/(1-AC22) -> 2798.4592 | AE22: =AD22/AA22/X22 -> 5.2225963 | AF22: =AD22/AA22/Y22 -> 3.3454892 | AG22: =AG$5+(AG$6-AG$5)*(POWER(AG$7,$B22-1)-1)/(POWER(AG$7,$B$3-1)-1) -> 1.297014 | AH22: =$AH$5+($AH$6-$AH$5)*(POWER($AH$7,$B22-1)-1)/(POWER($AH$7,$B$3-1)-1) -> 0.32360142 | AI22: =$AI$5+($AI$6-$AI$5)*(POWER($AI$7,$B22-1)-1)/(POWER($AI$7,$B$3-1)-1) -> 1.6885475 | AJ22: =$AJ$5+($AJ$6-$AJ$5)*(POWER($AJ$7,$B22-1)-1)/(POWER($AJ$7,$B$3-1)-1) -> 1.6536521 | AK22: =$AK$5+($AK$6-$AK$5)*(POWER($AK$7,$B22-1)-1)/(POWER($AK$7,$B$3-1)-1) -> 1 | AL22: =ROUND(Z22/AF22*AG22,0) -> 1057 | AM22: =ROUND(AA22*AH22,0) -> 305 | AN22: =ROUND(AB22,0) -> 628 | AO22: =ROUND(Z22/$AE22*AG22*AJ22,0) -> 1120 | AP22: =ROUND(AM22*AK22,0) -> 305 | AR22: =ROUNDUP(AR$10*$AO22,0) -> 1120 | AS22: =ROUNDUP(AS$10*$AO22,0) -> 3360 | AT22: =ROUNDUP(AT$10*$AO22,0) -> 2016 | AU22: =ROUNDUP(AU$10*$AO22,0) -> 560 | AV22: =ROUNDUP(AV$10*$AO22,0) -> 168 | AW22: =ROUNDUP(AW$10*$AO22,0) -> 4480 | AX22: =ROUNDUP(AX$10*$AO22,0) -> 10080 | AY22: =ROUND(AL22*$AY$10*AI22,0) -> 107088 | AZ22: =ROUND(AL22*$AZ$10*AI22,0) -> 53544 | BB22: =B22 -> 11
B23: 12 | C23: =C$5+(C$6-C$5)*(POWER(C$7,$B23-1)-1)/(POWER(C$7,$B$3-1)-1) -> 948.21205 | D23: =D$5+(D$6-D$5)*(POWER(D$7,$B23-1)-1)/(POWER(D$7,$B$3-1)-1) -> 284.46362 | E23: =E$5+(E$6-E$5)*(POWER(E$7,$B23-1)-1)/(POWER(E$7,$B$3-1)-1) -> 189.64241 | F23: =F$5+(F$6-F$5)*(POWER(F$7,$B23-1)-1)/(POWER(F$7,$B$3-1)-1) -> 2400.5368 | G23: =G$5+(G$6-G$5)*(POWER(G$7,$B23-1)-1)/(POWER(G$7,$B$3-1)-1) -> 720.16105 | H23: =H$5+(H$6-H$5)*(POWER(H$7,$B23-1)-1)/(POWER(H$7,$B$3-1)-1) -> 480.10737 | I23: =I$5+(I$6-I$5)*(POWER(I$7,$B23-1)-1)/(POWER(I$7,$B$3-1)-1) -> 0 | J23: =标准模型!$I$65/1*$B23/$B$3 -> 0.0864 | K23: =J23*标准模型!$J$63 -> 0.0864 | L23: =C23*(1+I23)+F23 -> 3348.7489 | M23: =D23*(1+J23)+G23 -> 1029.2023 | N23: =E23*(1+K23)+H23 -> 686.13488 | O23: =O$5+(O$6-O$5)*(POWER(O$7,$B23-1)-1)/(POWER(O$7,$B$3-1)-1) -> 0.51102473 | P23: =P$5+(P$6-P$5)*(POWER(P$7,$B23-1)-1)/(POWER(P$7,$B$3-1)-1) -> 0.0059765179 | Q23: =Q$5+(Q$6-Q$5)*(POWER(Q$7,$B23-1)-1)/(POWER(Q$7,$B$3-1)-1) -> 0.2810636 | R23: =R$5+(R$6-R$5)*(POWER(R$7,$B23-1)-1)/(POWER(R$7,$B$3-1)-1) -> 1.0044099 | S23: =S$5+(S$6-S$5)*(POWER(S$7,$B23-1)-1)/(POWER(S$7,$B$3-1)-1) -> 0.064332154 | T23: =T$5+(T$6-T$5)*(POWER(T$7,$B23-1)-1)/(POWER(T$7,$B$3-1)-1) -> 2.0429965 | U23: =U$5+(U$6-U$5)*(POWER(U$7,$B23-1)-1)/(POWER(U$7,$B$3-1)-1) -> 1 | V23: =V$5+(V$6-V$5)*(POWER(V$7,$B23-1)-1)/(POWER(V$7,$B$3-1)-1) -> 1.0120236 | W23: =W$5+(W$6-W$5)*(POWER(W$7,$B23-1)-1)/(POWER(W$7,$B$3-1)-1) -> 1.0352791 | X23: =(1+S23*(T23-1))*U23*W23*(O23+P23)*R23 -> 0.57367303 | Y23: =(1+S23*(T23-1))*(O23+P23+Q23)*U23*V23*W23*R23 -> 0.8961932 | Z23: =Y23*L23 -> 3001.126 | AA23: =M23 -> 1029.2023 | AB23: =N23 -> 686.13488 | AC23: =AB23/(AB23+战斗公式!$M$27) -> 0.027794342 | AD23: =Z23/(1-AC23) -> 3086.9251 | AE23: =AD23/AA23/X23 -> 5.2283047 | AF23: =AD23/AA23/Y23 -> 3.3467531 | AG23: =AG$5+(AG$6-AG$5)*(POWER(AG$7,$B23-1)-1)/(POWER(AG$7,$B$3-1)-1) -> 1.325504 | AH23: =$AH$5+($AH$6-$AH$5)*(POWER($AH$7,$B23-1)-1)/(POWER($AH$7,$B$3-1)-1) -> 0.3259876 | AI23: =$AI$5+($AI$6-$AI$5)*(POWER($AI$7,$B23-1)-1)/(POWER($AI$7,$B$3-1)-1) -> 1.6541201 | AJ23: =$AJ$5+($AJ$6-$AJ$5)*(POWER($AJ$7,$B23-1)-1)/(POWER($AJ$7,$B$3-1)-1) -> 1.6405784 | AK23: =$AK$5+($AK$6-$AK$5)*(POWER($AK$7,$B23-1)-1)/(POWER($AK$7,$B$3-1)-1) -> 1 | AL23: =ROUND(Z23/AF23*AG23,0) -> 1189 | AM23: =ROUND(AA23*AH23,0) -> 336 | AN23: =ROUND(AB23,0) -> 686 | AO23: =ROUND(Z23/$AE23*AG23*AJ23,0) -> 1248 | AP23: =ROUND(AM23*AK23,0) -> 336 | AR23: =ROUNDUP(AR$10*$AO23,0) -> 1248 | AS23: =ROUNDUP(AS$10*$AO23,0) -> 3744 | AT23: =ROUNDUP(AT$10*$AO23,0) -> 2247 | AU23: =ROUNDUP(AU$10*$AO23,0) -> 624 | AV23: =ROUNDUP(AV$10*$AO23,0) -> 188 | AW23: =ROUNDUP(AW$10*$AO23,0) -> 4992 | AX23: =ROUNDUP(AX$10*$AO23,0) -> 11232 | AY23: =ROUND(AL23*$AY$10*AI23,0) -> 118005 | AZ23: =ROUND(AL23*$AZ$10*AI23,0) -> 59002 | BB23: =B23 -> 12
B24: 13 | C24: =C$5+(C$6-C$5)*(POWER(C$7,$B24-1)-1)/(POWER(C$7,$B$3-1)-1) -> 1027.2309 | D24: =D$5+(D$6-D$5)*(POWER(D$7,$B24-1)-1)/(POWER(D$7,$B$3-1)-1) -> 308.16926 | E24: =E$5+(E$6-E$5)*(POWER(E$7,$B24-1)-1)/(POWER(E$7,$B$3-1)-1) -> 205.44617 | F24: =F$5+(F$6-F$5)*(POWER(F$7,$B24-1)-1)/(POWER(F$7,$B$3-1)-1) -> 2600.5844 | G24: =G$5+(G$6-G$5)*(POWER(G$7,$B24-1)-1)/(POWER(G$7,$B$3-1)-1) -> 780.17533 | H24: =H$5+(H$6-H$5)*(POWER(H$7,$B24-1)-1)/(POWER(H$7,$B$3-1)-1) -> 520.11689 | I24: =I$5+(I$6-I$5)*(POWER(I$7,$B24-1)-1)/(POWER(I$7,$B$3-1)-1) -> 0 | J24: =标准模型!$I$65/1*$B24/$B$3 -> 0.0936 | K24: =J24*标准模型!$J$63 -> 0.0936 | L24: =C24*(1+I24)+F24 -> 3627.8153 | M24: =D24*(1+J24)+G24 -> 1117.1892 | N24: =E24*(1+K24)+H24 -> 744.79282 | O24: =O$5+(O$6-O$5)*(POWER(O$7,$B24-1)-1)/(POWER(O$7,$B$3-1)-1) -> 0.51202698 | P24: =P$5+(P$6-P$5)*(POWER(P$7,$B24-1)-1)/(POWER(P$7,$B$3-1)-1) -> 0.0065247398 | Q24: =Q$5+(Q$6-Q$5)*(POWER(Q$7,$B24-1)-1)/(POWER(Q$7,$B$3-1)-1) -> 0.28161484 | R24: =R$5+(R$6-R$5)*(POWER(R$7,$B24-1)-1)/(POWER(R$7,$B$3-1)-1) -> 1.0048108 | S24: =S$5+(S$6-S$5)*(POWER(S$7,$B24-1)-1)/(POWER(S$7,$B$3-1)-1) -> 0.065635069 | T24: =T$5+(T$6-T$5)*(POWER(T$7,$B24-1)-1)/(POWER(T$7,$B$3-1)-1) -> 2.0469052 | U24: =U$5+(U$6-U$5)*(POWER(U$7,$B24-1)-1)/(POWER(U$7,$B$3-1)-1) -> 1 | V24: =V$5+(V$6-V$5)*(POWER(V$7,$B24-1)-1)/(POWER(V$7,$B$3-1)-1) -> 1.0131166 | W24: =W$5+(W$6-W$5)*(POWER(W$7,$B24-1)-1)/(POWER(W$7,$B$3-1)-1) -> 1.0384863 | X24: =(1+S24*(T24-1))*U24*W24*(O24+P24)*R24 -> 0.57828047 | Y24: =(1+S24*(T24-1))*(O24+P24+Q24)*U24*V24*W24*R24 -> 0.90403714 | Z24: =Y24*L24 -> 3279.6798 | AA24: =M24 -> 1117.1892 | AB24: =N24 -> 744.79282 | AC24: =AB24/(AB24+战斗公式!$M$27) -> 0.030098972 | AD24: =Z24/(1-AC24) -> 3381.4582 | AE24: =AD24/AA24/X24 -> 5.2340607 | AF24: =AD24/AA24/Y24 -> 3.3480428 | AG24: =AG$5+(AG$6-AG$5)*(POWER(AG$7,$B24-1)-1)/(POWER(AG$7,$B$3-1)-1) -> 1.3537804 | AH24: =$AH$5+($AH$6-$AH$5)*(POWER($AH$7,$B24-1)-1)/(POWER($AH$7,$B$3-1)-1) -> 0.32837856 | AI24: =$AI$5+($AI$6-$AI$5)*(POWER($AI$7,$B24-1)-1)/(POWER($AI$7,$B$3-1)-1) -> 1.6214141 | AJ24: =$AJ$5+($AJ$6-$AJ$5)*(POWER($AJ$7,$B24-1)-1)/(POWER($AJ$7,$B$3-1)-1) -> 1.6277662 | AK24: =$AK$5+($AK$6-$AK$5)*(POWER($AK$7,$B24-1)-1)/(POWER($AK$7,$B$3-1)-1) -> 1 | AL24: =ROUND(Z24/AF24*AG24,0) -> 1326 | AM24: =ROUND(AA24*AH24,0) -> 367 | AN24: =ROUND(AB24,0) -> 745 | AO24: =ROUND(Z24/$AE24*AG24*AJ24,0) -> 1381 | AP24: =ROUND(AM24*AK24,0) -> 367 | AR24: =ROUNDUP(AR$10*$AO24,0) -> 1381 | AS24: =ROUNDUP(AS$10*$AO24,0) -> 4143 | AT24: =ROUNDUP(AT$10*$AO24,0) -> 2486 | AU24: =ROUNDUP(AU$10*$AO24,0) -> 691 | AV24: =ROUNDUP(AV$10*$AO24,0) -> 208 | AW24: =ROUNDUP(AW$10*$AO24,0) -> 5524 | AX24: =ROUNDUP(AX$10*$AO24,0) -> 12429 | AY24: =ROUND(AL24*$AY$10*AI24,0) -> 129000 | AZ24: =ROUND(AL24*$AZ$10*AI24,0) -> 64500 | BB24: =B24 -> 13
... B511: 500 | C511: =C$5+(C$6-C$5)*(POWER(C$7,$B511-1)-1)/(POWER(C$7,$B$3-1)-1) -> 39500 | D511: =D$5+(D$6-D$5)*(POWER(D$7,$B511-1)-1)/(POWER(D$7,$B$3-1)-1) -> 11850 | E511: =E$5+(E$6-E$5)*(POWER(E$7,$B511-1)-1)/(POWER(E$7,$B$3-1)-1) -> 7900 | F511: =F$5+(F$6-F$5)*(POWER(F$7,$B511-1)-1)/(POWER(F$7,$B$3-1)-1) -> 100000 | G511: =G$5+(G$6-G$5)*(POWER(G$7,$B511-1)-1)/(POWER(G$7,$B$3-1)-1) -> 30000 | H511: =H$5+(H$6-H$5)*(POWER(H$7,$B511-1)-1)/(POWER(H$7,$B$3-1)-1) -> 20000 | I511: =I$5+(I$6-I$5)*(POWER(I$7,$B511-1)-1)/(POWER(I$7,$B$3-1)-1) -> 0 | J511: =标准模型!$I$65/1*$B511/$B$3 -> 3.6 | K511: =J511*标准模型!$J$63 -> 3.6 | L511: =C511*(1+I511)+F511 -> 139500 | M511: =D511*(1+J511)+G511 -> 84510 | N511: =E511*(1+K511)+H511 -> 56340 | O511: =O$5+(O$6-O$5)*(POWER(O$7,$B511-1)-1)/(POWER(O$7,$B$3-1)-1) -> 1 | P511: =P$5+(P$6-P$5)*(POWER(P$7,$B511-1)-1)/(POWER(P$7,$B$3-1)-1) -> 0.4 | Q511: =Q$5+(Q$6-Q$5)*(POWER(Q$7,$B511-1)-1)/(POWER(Q$7,$B$3-1)-1) -> 0.55 | R511: =R$5+(R$6-R$5)*(POWER(R$7,$B511-1)-1)/(POWER(R$7,$B$3-1)-1) -> 1.2 | S511: =S$5+(S$6-S$5)*(POWER(S$7,$B511-1)-1)/(POWER(S$7,$B$3-1)-1) -> 0.7 | T511: =T$5+(T$6-T$5)*(POWER(T$7,$B511-1)-1)/(POWER(T$7,$B$3-1)-1) -> 3.95 | U511: =U$5+(U$6-U$5)*(POWER(U$7,$B511-1)-1)/(POWER(U$7,$B$3-1)-1) -> 1 | V511: =V$5+(V$6-V$5)*(POWER(V$7,$B511-1)-1)/(POWER(V$7,$B$3-1)-1) -> 1.5452991 | W511: =W$5+(W$6-W$5)*(POWER(W$7,$B511-1)-1)/(POWER(W$7,$B$3-1)-1) -> 2.6 | X511: =(1+S511*(T511-1))*U511*W511*(O511+P511)*R511 -> 13.38792 | Y511: =(1+S511*(T511-1))*(O511+P511+Q511)*U511*V511*W511*R511 -> 28.815904 | Z511: =Y511*L511 -> 4019818.6 | AA511: =M511 -> 84510 | AB511: =N511 -> 56340 | AC511: =AB511/(AB511+战斗公式!$M$27) -> 0.7012696 | AD511: =Z511/(1-AC511) -> 13456343 | AE511: =AD511/AA511/X511 -> 11.893395 | AF511: =AD511/AA511/Y511 -> 5.5256922 | AG511: =AG$5+(AG$6-AG$5)*(POWER(AG$7,$B511-1)-1)/(POWER(AG$7,$B$3-1)-1) -> 5 | AH511: =$AH$5+($AH$6-$AH$5)*(POWER($AH$7,$B511-1)-1)/(POWER($AH$7,$B$3-1)-1) -> 2.3 | AI511: =$AI$5+($AI$6-$AI$5)*(POWER($AI$7,$B511-1)-1)/(POWER($AI$7,$B$3-1)-1) -> 1 | AJ511: =$AJ$5+($AJ$6-$AJ$5)*(POWER($AJ$7,$B511-1)-1)/(POWER($AJ$7,$B$3-1)-1) -> 1 | AK511: =$AK$5+($AK$6-$AK$5)*(POWER($AK$7,$B511-1)-1)/(POWER($AK$7,$B$3-1)-1) -> 1 | AL511: =ROUND(Z511/AF511*AG511,0) -> 3637389 | AM511: =ROUND(AA511*AH511,0) -> 194373 | AN511: =ROUND(AB511,0) -> 56340 | AO511: =ROUND(Z511/$AE511*AG511*AJ511,0) -> 1689937 | AP511: =ROUND(AM511*AK511,0) -> 194373 | AR511: =ROUNDUP(AR$10*$AO511,0) -> 1689937 | AS511: =ROUNDUP(AS$10*$AO511,0) -> 5069811 | AT511: =ROUNDUP(AT$10*$AO511,0) -> 3041887 | AU511: =ROUNDUP(AU$10*$AO511,0) -> 844969 | AV511: =ROUNDUP(AV$10*$AO511,0) -> 253491 | AW511: =ROUNDUP(AW$10*$AO511,0) -> 6759748 | AX511: =ROUNDUP(AX$10*$AO511,0) -> 15209433 | AY511: =ROUND(AL511*$AY$10*AI511,0) -> 218243340 | AZ511: =ROUND(AL511*$AZ$10*AI511,0) -> 109121670 | BB511: =B511 -> 500

Sheet 技能系数
B2: 技能系数 | C2: 16.5 | G2: 技能系数计算 | J2: 拆分系数 | N2: 品质系数 | Q2: 攻血比
B3: 技能当前品质 | C3: R
B4: 单体伤害 | G4: 基础技能系数 | H4: =标准模型!H81 -> 2 | J4: 1 | K4: 0.7 | L4: =$L$7/$K$7*K4 -> 4.76 | N4: R | O4: 0.9 | Q4: 血量 | R4: 12 | S4: =$S$5*$R$5/R4 -> 3
B5: 单体系数 | C5: 1 | G5: 基础冷却时间 | H5: =标准模型!H78 -> 10 | J5: 2 | K5: 0.8 | L5: =$L$7/$K$7*K5 -> 5.44 | N5: SR | O5: 0.95 | Q5: 攻击 | R5: 3 | S5: 12
B6: 品质系数 | C6: =$C$3 -> R | D6: =VLOOKUP(C6,$N$4:$O$6,2,0) -> 0.9 | G6: 实际冷却时间 | H6: 12 | J6: 3 | K6: 0.9 | L6: =$L$7/$K$7*K6 -> 6.12 | N6: SSR | O6: 1 | Q6: 防御 | R6: 2 | S6: =$S$5*$R$5/R6 -> 18
B7: 攻速 | C7: 7 | G7: 最终技能系数 | H7: =H4*H6/H5 -> 2.4 | J7: 4 | K7: 1 | L7: 6.8
B8: 伤害系数 | C8: =C5/C7*D6*C2 -> 2.1214286 | G8: 普攻基础系数 | H8: =100% -> 1
G9: 必杀基础系数 | H9: =标准模型!H82 -> 16.5
B10: 穿透子弹
B11: 穿透子弹系数 | C11: 0.7
B12: 品质系数 | C12: =$C$3 -> R | D12: =VLOOKUP(C12,$N$4:$O$6,2,0) -> 0.9
B13: 攻速 | C13: 1
B14: 伤害系数 | C14: =C11/C13*D12*C2 -> 10.395
B16: 跟踪子弹 | N16: 普攻、必杀系数 | O16: 0.5 | P16: 0.65 | Q16: 0.8 | R16: 1
B17: 跟踪子弹系数 | C17: 0.93
B18: 品质系数 | C18: =$C$3 -> R | D18: =VLOOKUP(C18,$N$4:$O$6,2,0) -> 0.9 | N18: 技能系数 | O18: 0.5 | P18: 0.75 | Q18: 1
B19: 攻速 | C19: 1 | T19: %/ | U19: %
B20: 伤害系数 | C20: =C17/C19*D18*C2 -> 13.8105 | O20: =MROUND($R$20*O16,5) -> 20 | P20: =MROUND($R$20*P16,5) -> 25 | Q20: =MROUND($R$20*Q16,5) -> 30 | R20: 40 | T20: =_xlfn.CONCAT(O20,$T$19,P20,$T$19,Q20,$T$19,R20,$U$19) -> 20%/25%/30%/40%
O22: =MROUND(O18*$R$20,5) -> 20 | P22: =MROUND(P18*$R$20,5) -> 30 | Q22: =MROUND(Q18*$R$20,5) -> 40 | T22: =_xlfn.CONCAT(O22,$T$19,P22,$T$19,Q22,$U$19) -> 20%/30%/40%
B23: AOE子弹
B24: AOE系数 | C24: 0.75
B25: 品质系数 | C25: =$C$3 -> R | D25: =VLOOKUP(C25,$N$4:$O$6,2,0) -> 0.9
B26: 标准范围半径 | C26: 1
B27: 实际范围半径（标准倍数） | C27: 1
B28: 衰减系数 | C28: 1.2
B29: 攻速 | C29: 1
B30: 伤害系数 | C30: =POWER(C26,C28)/POWER(C27,C28)*C24*D25*C2/C29 -> 11.1375
B32: DOT
B33: DOT系数 | C33: 1.2
B34: 品质系数 | C34: =$C$3 -> R | D34: =VLOOKUP(C34,$N$4:$O$6,2,0) -> 0.9
B35: DOT持续时间 | C35: 5
B36: DOT标准持续时间 | C36: 5
B37: DOT持续系数 | C37: 1.39 | D37: =POWER(C35,C37)/POWER(C36,C37)/C35*C36 -> 1
B38: DOT标准最大层数 | C38: 5
B39: DOT最大层数 | C39: 2
B40: DOT最大层数系数 | C40: 1.21 | D40: =POWER(C38,C40)/POWER(C39,C40)*C39/C38 -> 1.2121808
B41: DOT单层系数 | C41: =C33/C35*D37*D40*D34*C2 -> 4.3202124
B44: 回血
B45: 回血系数 | C45: =标准模型!I75 -> 0.19090909
B46: 品质系数 | C46: =$C$3 -> R | D46: =VLOOKUP(C46,$N$4:$O$6,2,0) -> 0.9
...

Sheet Boss技能系数
A1: Boss技能系数测算
A3: 基础参数 | B3: 数值 | C3: 说明 | D3: 技能档位 | E3: 基准倍率 | F3: 默认CD(s) | G3: 说明 | I3: 释放屏蔽 | J3: 倍率 | K3: 说明 | M3: 范围类型 | N3: 倍率 | O3: 说明 | Q3: 穿透类型 | R3: 倍率 | S3: 说明
A4: 最终TTK(s) | B4: 5.5 | C4: 100%命中下后期Boss目标击杀时间 | D4: 普攻 | E4: 1 | F4: 1.5 | G4: 高频稳定压血 | I4: 不屏蔽 | J4: 1 | K4: 不挤占其他行为 | M4: 单体 | N4: 1 | O4: 单目标 | Q4: 不穿透 | R4: 1 | S4: 命中后停止
A5: 普攻基准倍率 | B5: 0.8 | C5: 单次普攻伤害基准 | D5: 中技能 | E5: 1.75 | F5: 8 | G5: 核心威胁，承接普通Boss机制 | I5: 屏蔽普攻 | J5: 1 | K5: 释放期间替代部分普攻 | M5: 直线 | N5: 1 | O5: 直线/矩形路径 | Q5: 穿透 | R5: 0.7 | S5: 可命中多目标/多次
A6: 中技能基准倍率 | B6: 2 | C6: 单次中技能伤害基准 | D6: 必杀 | E6: 2.5 | F6: 25 | G6: 阶段大招/高压窗口 | I6: 屏蔽中技能 | J6: 1 | K6: 释放期间替代部分技能 | M6: 扇形 | N6: 1 | O6: 前方扇形 | Q6: 无限穿透 | R6: 0.3 | S6: 不受命中次数限制，激光类型
A7: 必杀基准倍率 | B7: 3 | C7: 单次必杀伤害基准 | I7: 屏蔽全部 | J7: 1 | K7: 大招占用完整行为窗 | M7: 圆形 | N7: 1 | O7: 地面圆形区域
A8: 每秒致死预算系数 | B8: 1 | C8: 用于把最终技能系数换算为TTK压力 | M8: 环形 | N8: 1 | O8: 内外圈区域
A9: 范围大小每单位系数 | B9: 0.05 | C9: 范围每超出标准1单位，提升5%威胁；低于标准最低按0.85 | M9: 全屏 | N9: 0.5 | O9: 全场范围
A10: 额外弹体系数 | B10: 0.08 | C10: 每多1个弹体，降低提升8%威胁
A11: 额外波次系数 | B11: 0.12 | C11: 每多1波，降低12%威胁
A12: 持续命中系数 | B12: 0.08 | C12: 持续技能按可命中段数追加威胁
A13: 控制每秒系数 | B13: 0.12 | C13: 控制越久，威胁越高
A14: 填写说明：黄色为可调输入；绿色为公式。最终技能系数 = 基准倍率 × 参数综合系数；100%命中掉血占比 = 最终技能系数 ÷ 最终TTK。
A15: Boss名 | B15: 技能名 | C15: 技能档位 | D15: 基准倍率 | E15: CD(s) | F15: 释放屏蔽 | G15: 屏蔽系数 | H15: 范围类型 | I15: 范围类型系数 | J15: 范围半径/宽度 | K15: 标准范围 | L15: 范围大小系数 | M15: 穿透类型 | N15: 穿透系数 | O15: 弹体数 | P15: 弹体系数 | Q15: 波次数 | R15: 波次系数 | S15: 持续时间(s) | T15: 命中间隔(s) | U15: 持续系数 | V15: 控制时长(s) | W15: 控制系数 | X15: 机制修正 | Y15: 参数综合系数 | Z15: 最终技能系数
A16: Boss模板 | B16: 普攻 | C16: 普攻 | D16: =IF($C16="","",VLOOKUP($C16,$D$4:$F$6,2,FALSE)) -> 1 | E16: =IF($C16="","",VLOOKUP($C16,$D$4:$F$6,3,FALSE)) -> 1.5 | F16: 不屏蔽 | G16: =IF($C16="","",VLOOKUP($F16,$I$4:$J$7,2,FALSE)) -> 1 | H16: 单体 | I16: =IF($C16="","",VLOOKUP($H16,$M$4:$N$9,2,FALSE)) -> 1 | J16: 0 | K16: 0 | L16: =IF($C16="","",IF($J16>0,MAX(0.85,1-($J16-$K16)*$B$9),1)) -> 1 | M16: 不穿透 | N16: =IF($C16="","",VLOOKUP($M16,$Q$4:$R$6,2,FALSE)) -> 1 | O16: 1 | P16: =IF($C16="","",1-MAX($O16-1,0)*$B$10) -> 1 | Q16: 1 | R16: =IF($C16="","",1-MAX($Q16-1,0)*$B$11) -> 1 | S16: 0 | T16: 0 | U16: =IF($C16="","",IF($S16>0,1+MAX($S16/MAX($T16,0.1)-1,0)*$B$12,1)) -> 1 | V16: 0 | W16: =IF($C16="","",1-MAX($V16,0)*$B$13) -> 1 | X16: 1 | Y16: =IF($C16="","",PRODUCT($G16,$I16,$L16,$N16,$P16,$R16,$U16,$W16,$X16)) -> 1 | Z16: =IF($C16="","",$D16*$Y16) -> 1
A17: Boss模板 | B17: 扇形中技能 | C17: 中技能 | D17: =IF($C17="","",VLOOKUP($C17,$D$4:$F$6,2,FALSE)) -> 1.75 | E17: =IF($C17="","",VLOOKUP($C17,$D$4:$F$6,3,FALSE)) -> 8 | F17: 屏蔽普攻 | G17: =IF($C17="","",VLOOKUP($F17,$I$4:$J$7,2,FALSE)) -> 1 | H17: 扇形 | I17: =IF($C17="","",VLOOKUP($H17,$M$4:$N$9,2,FALSE)) -> 1 | J17: 6 | K17: 4 | L17: =IF($C17="","",IF($J17>0,MAX(0.85,1-($J17-$K17)*$B$9),1)) -> 0.9 | M17: 穿透 | N17: =IF($C17="","",VLOOKUP($M17,$Q$4:$R$6,2,FALSE)) -> 0.7 | O17: 1 | P17: =IF($C17="","",1-MAX($O17-1,0)*$B$10) -> 1 | Q17: 1 | R17: =IF($C17="","",1-MAX($Q17-1,0)*$B$11) -> 1 | S17: 0 | T17: 0 | U17: =IF($C17="","",IF($S17>0,1+MAX($S17/MAX($T17,0.1)-1,0)*$B$12,1)) -> 1 | V17: 0 | W17: =IF($C17="","",1-MAX($V17,0)*$B$13) -> 1 | X17: 1 | Y17: =IF($C17="","",PRODUCT($G17,$I17,$L17,$N17,$P17,$R17,$U17,$W17,$X17)) -> 0.63 | Z17: =IF($C17="","",$D17*$Y17) -> 1.1025
A18: Boss模板 | B18: 多波必杀 | C18: 必杀 | D18: =IF($C18="","",VLOOKUP($C18,$D$4:$F$6,2,FALSE)) -> 2.5 | E18: =IF($C18="","",VLOOKUP($C18,$D$4:$F$6,3,FALSE)) -> 25 | F18: 屏蔽全部 | G18: =IF($C18="","",VLOOKUP($F18,$I$4:$J$7,2,FALSE)) -> 1 | H18: 圆形 | I18: =IF($C18="","",VLOOKUP($H18,$M$4:$N$9,2,FALSE)) -> 1 | J18: 8 | K18: 4 | L18: =IF($C18="","",IF($J18>0,MAX(0.85,1-($J18-$K18)*$B$9),1)) -> 0.85 | M18: 不穿透 | N18: =IF($C18="","",VLOOKUP($M18,$Q$4:$R$6,2,FALSE)) -> 1 | O18: 1 | P18: =IF($C18="","",1-MAX($O18-1,0)*$B$10) -> 1 | Q18: 1 | R18: =IF($C18="","",1-MAX($Q18-1,0)*$B$11) -> 1 | S18: 0 | T18: 0 | U18: =IF($C18="","",IF($S18>0,1+MAX($S18/MAX($T18,0.1)-1,0)*$B$12,1)) -> 1 | V18: 0 | W18: =IF($C18="","",1-MAX($V18,0)*$B$13) -> 1 | X18: 1.1 | Y18: =IF($C18="","",PRODUCT($G18,$I18,$L18,$N18,$P18,$R18,$U18,$W18,$X18)) -> 0.935 | Z18: =IF($C18="","",$D18*$Y18) -> 2.3375
D19: =IF($C19="","",VLOOKUP($C19,$D$4:$F$6,2,FALSE)) | E19: =IF($C19="","",VLOOKUP($C19,$D$4:$F$6,3,FALSE)) | G19: =IF($C19="","",VLOOKUP($F19,$I$4:$J$7,2,FALSE)) | I19: =IF($C19="","",VLOOKUP($H19,$M$4:$N$9,2,FALSE)) | J19: 0 | K19: 0 | L19: =IF($C19="","",IF($J19>0,MAX(0.85,1+($J19-$K19)*$B$9),1)) | N19: =IF($C19="","",VLOOKUP($M19,$Q$4:$R$6,2,FALSE)) | O19: 1 | P19: =IF($C19="","",1+MAX($O19-1,0)*$B$10) | Q19: 1 | R19: =IF($C19="","",1+MAX($Q19-1,0)*$B$11) | S19: 0 | T19: 0 | U19: =IF($C19="","",IF($S19>0,1+MAX($S19/MAX($T19,0.1)-1,0)*$B$12,1)) | V19: 0 | W19: =IF($C19="","",1+MAX($V19,0)*$B$13) | X19: 1 | Y19: =IF($C19="","",PRODUCT($G19,$I19,$L19,$N19,$P19,$R19,$U19,$W19,$X19)) | Z19: =IF($C19="","",$D19*$Y19) | AA19: =IF($C19="","",$Z19/$B$4) | AB19: =IF($C19="","",$Z19/$E19) | AC19: =IF($C19="","",$D19/$Y19)
D20: =IF($C20="","",VLOOKUP($C20,$D$4:$F$6,2,FALSE)) | E20: =IF($C20="","",VLOOKUP($C20,$D$4:$F$6,3,FALSE)) | G20: =IF($C20="","",VLOOKUP($F20,$I$4:$J$7,2,FALSE)) | I20: =IF($C20="","",VLOOKUP($H20,$M$4:$N$9,2,FALSE)) | J20: 0 | K20: 0 | L20: =IF($C20="","",IF($J20>0,MAX(0.85,1+($J20-$K20)*$B$9),1)) | N20: =IF($C20="","",VLOOKUP($M20,$Q$4:$R$6,2,FALSE)) | O20: 1 | P20: =IF($C20="","",1+MAX($O20-1,0)*$B$10) | Q20: 1 | R20: =IF($C20="","",1+MAX($Q20-1,0)*$B$11) | S20: 0 | T20: 0 | U20: =IF($C20="","",IF($S20>0,1+MAX($S20/MAX($T20,0.1)-1,0)*$B$12,1)) | V20: 0 | W20: =IF($C20="","",1+MAX($V20,0)*$B$13) | X20: 1 | Y20: =IF($C20="","",PRODUCT($G20,$I20,$L20,$N20,$P20,$R20,$U20,$W20,$X20)) | Z20: =IF($C20="","",$D20*$Y20) | AA20: =IF($C20="","",$Z20/$B$4) | AB20: =IF($C20="","",$Z20/$E20) | AC20: =IF($C20="","",$D20/$Y20)
D21: =IF($C21="","",VLOOKUP($C21,$D$4:$F$6,2,FALSE)) | E21: =IF($C21="","",VLOOKUP($C21,$D$4:$F$6,3,FALSE)) | G21: =IF($C21="","",VLOOKUP($F21,$I$4:$J$7,2,FALSE)) | I21: =IF($C21="","",VLOOKUP($H21,$M$4:$N$9,2,FALSE)) | J21: 0 | K21: 0 | L21: =IF($C21="","",IF($J21>0,MAX(0.85,1+($J21-$K21)*$B$9),1)) | N21: =IF($C21="","",VLOOKUP($M21,$Q$4:$R$6,2,FALSE)) | O21: 1 | P21: =IF($C21="","",1+MAX($O21-1,0)*$B$10) | Q21: 1 | R21: =IF($C21="","",1+MAX($Q21-1,0)*$B$11) | S21: 0 | T21: 0 | U21: =IF($C21="","",IF($S21>0,1+MAX($S21/MAX($T21,0.1)-1,0)*$B$12,1)) | V21: 0 | W21: =IF($C21="","",1+MAX($V21,0)*$B$13) | X21: 1 | Y21: =IF($C21="","",PRODUCT($G21,$I21,$L21,$N21,$P21,$R21,$U21,$W21,$X21)) | Z21: =IF($C21="","",$D21*$Y21) | AA21: =IF($C21="","",$Z21/$B$4) | AB21: =IF($C21="","",$Z21/$E21) | AC21: =IF($C21="","",$D21/$Y21)
D22: =IF($C22="","",VLOOKUP($C22,$D$4:$F$6,2,FALSE)) | E22: =IF($C22="","",VLOOKUP($C22,$D$4:$F$6,3,FALSE)) | G22: =IF($C22="","",VLOOKUP($F22,$I$4:$J$7,2,FALSE)) | I22: =IF($C22="","",VLOOKUP($H22,$M$4:$N$9,2,FALSE)) | J22: 0 | K22: 0 | L22: =IF($C22="","",IF($J22>0,MAX(0.85,1+($J22-$K22)*$B$9),1)) | N22: =IF($C22="","",VLOOKUP($M22,$Q$4:$R$6,2,FALSE)) | O22: 1 | P22: =IF($C22="","",1+MAX($O22-1,0)*$B$10) | Q22: 1 | R22: =IF($C22="","",1+MAX($Q22-1,0)*$B$11) | S22: 0 | T22: 0 | U22: =IF($C22="","",IF($S22>0,1+MAX($S22/MAX($T22,0.1)-1,0)*$B$12,1)) | V22: 0 | W22: =IF($C22="","",1+MAX($V22,0)*$B$13) | X22: 1 | Y22: =IF($C22="","",PRODUCT($G22,$I22,$L22,$N22,$P22,$R22,$U22,$W22,$X22)) | Z22: =IF($C22="","",$D22*$Y22) | AA22: =IF($C22="","",$Z22/$B$4) | AB22: =IF($C22="","",$Z22/$E22) | AC22: =IF($C22="","",$D22/$Y22)
D23: =IF($C23="","",VLOOKUP($C23,$D$4:$F$6,2,FALSE)) | E23: =IF($C23="","",VLOOKUP($C23,$D$4:$F$6,3,FALSE)) | G23: =IF($C23="","",VLOOKUP($F23,$I$4:$J$7,2,FALSE)) | I23: =IF($C23="","",VLOOKUP($H23,$M$4:$N$9,2,FALSE)) | J23: 0 | K23: 0 | L23: =IF($C23="","",IF($J23>0,MAX(0.85,1+($J23-$K23)*$B$9),1)) | N23: =IF($C23="","",VLOOKUP($M23,$Q$4:$R$6,2,FALSE)) | O23: 1 | P23: =IF($C23="","",1+MAX($O23-1,0)*$B$10) | Q23: 1 | R23: =IF($C23="","",1+MAX($Q23-1,0)*$B$11) | S23: 0 | T23: 0 | U23: =IF($C23="","",IF($S23>0,1+MAX($S23/MAX($T23,0.1)-1,0)*$B$12,1)) | V23: 0 | W23: =IF($C23="","",1+MAX($V23,0)*$B$13) | X23: 1 | Y23: =IF($C23="","",PRODUCT($G23,$I23,$L23,$N23,$P23,$R23,$U23,$W23,$X23)) | Z23: =IF($C23="","",$D23*$Y23) | AA23: =IF($C23="","",$Z23/$B$4) | AB23: =IF($C23="","",$Z23/$E23) | AC23: =IF($C23="","",$D23/$Y23)
